Workbook

Sheet Tahsin
A2: Tester : | D2: Severity | E2: Issues
A3: Project Name: | D3: High | E3: =COUNTIF(K14:K1005, "High") -> 0
A4: Project URL: | D4: Medium | E4: =COUNTIF(K14:K1006, "Medium") -> 0
A5: Developer: | D5: Low | E5: =COUNTIF(K14:K1007, "Low") -> 0
A6: OS:
A7: Environment | D7: Total Test Cases: | E7: =SUM(E3:E5) -> 0
D8: Test Case Solved :
A14: Test Case ID | B14: Module | C14: Sub Module | D14: Test Case Description | E14: Preconditions | F14: Test Steps | G14: Test Data | H14: Expected Result | I14: Actual Result | J14: Status | K14: Severity | L14: Screen Shots | M14: Suggestion | N14: Feedback

Sheet Fahad
A1: Tester : | B1: Mohammed Fahad Faisal | D1: Severity | E1: Issues
A2: Project Name: | D2: High | E2: =COUNTIF(Fahad!K9:K1005, "High") -> 22 | G2: https://www.google.com/url?q=https://drive.google.com/drive/folders/1FRBcKQaBHzPnXLwXsJ50fxP5fJZiGNoG&sa=D&source=editors&ust=1777270765470635&usg=AOvVaw1xT38euCF2HCZ8KvY8sS0Y
A3: Developer: | D3: Medium | E3: =COUNTIF(Fahad!K9:K1006, "Medium") -> 11
A4: OS: | B4: Windows 11 Pro Version:24H2 OS build:26100.4946 | D4: Low | E4: =COUNTIF(Fahad!K9:K1007, "Low") -> 1
A5: Environment: | B5: Brave 1.81.135 (Official Build) (64-bit) Chromium: 139.0.7258.127 | O5: Place solve if the issue resolves | \/ | P5: Mention which Stack solved the issue | \/
D6: Total Test Cases: | E6: =SUM(E2:E4) -> 34
D7: Test Case Solved : | E7: =COUNTIF(O10:O1002, "Solved") -> 14
A9: Test ID | B9: Module | C9: Sub Module | D9: Test Case Description | E9: Preconditions | F9: Test Steps | G9: Test Data | H9: Expected Result | I9: Actual Result | J9: Status | K9: Severity | L9: Screen Shots | M9: Suggestion | N9: Feedback | O9: Feedback | P9: Stack | Q9: Comment
A10: BR_001 | B10: Splash Screen | C10: Splash Screen | D10: Splash flow missing | E10: User need to download the app on their IOS device | F10: 1. Open app 2. Signup using valid credentials | G10: User credentials | H10: All flash screens should be positioned accurately according to the Figma design. | I10: Missing flash screen on selecting gender | J10: Fail | K10: Medium | L10: 001.MP4 | M10: 001.1.png | O10: Unsolved | P10: App | Q10: I solve the issue
A12: BR_002 | B12: Splash Screen | C12: Splash Screen | D12: Splash image missing | E12: User need to download the app on their IOS device | F12: 1. Open app 2. Signup using valid credentials | G12: User credentials | H12: The image on the splash screen should be positioned precisely. | I12: Image missing in splash screen | J12: Fail | K12: Medium | L12: 002.png | O12: Solved | P12: App | Q12: I fix the issue
A14: BR_003 | B14: Splash Screen | C14: Splash Screen | D14: The buttons are shifting along with the splash screen. | E14: User need to download the app on their IOS device | F14: 1. Open app 2. Signup using valid credentials | G14: User credentials | H14: Only the image should be scrollable, not the options. | I14: Buttons are also moving with the picture. | J14: Fail | K14: Medium | L14: 003.MP4 | O14: Unsolved | P14: App | Q14: Button also change able because last button is Let get started
A16: BR_004 | B16: Login | C16: Login | D16: The login page doesn’t include links to the terms of service or privacy policy. | E16: User need to download the app on their IOS device | F16: 1. Open app 2. Goto login page | G16: User credentials | H16: Privacy policies should be properly linked on the screen. | I16: The Privacy policy aren’t connected. | J16: Fail | K16: High | L16: 004.png | O16: Unsolved | P16: App | Q16: Not in design It is on account section
A18: BR_005 | B18: Achievement | C18: Achievement | D18: Beginner profile is set to level one, but it requires 200 steps to unlock that level. | E18: User need to download the app on their IOS device | F18: 1. Open app 2. Signup using valid credentials 3. Click on settings | G18: User credentials | H18: The beginner profile level should start at zero, and after completing 200 steps, it will unlock level one. | I18: The level starts at one, and the achievement also locks at level one. | J18: Fail | K18: Medium | L18: 005.png | O18: Solved | P18: Back-End
A20: BR_006 | B20: Profile | C20: Profile | D20: A profile input validation issue has been detected. | E20: User need to download the app on their IOS device | F20: 1. Open app 2. Signup using valid credentials 3. Click on settings 4. Select Profile | G20: User credentials | H20: Proper maintenance of input field validation is essential. | I20: Input validation missing in app | J20: Fail | K20: High | L20: 006.png | O20: Unsolved | P20: App | Q20: I fix the issue
A22: BR_007 | B22: Password | C22: Password | D22: The password update error toast message is showing with the success toast message color. | E22: User need to download the app on their IOS device | F22: 1. Open app 2. Signup using valid credentials 3. Click on settings 4. Select Update password | G22: User credentials | H22: Error toast message should be displayed properly | I22: The error toast message color is set to the same as the success toast message. | J22: Fail | K22: Low | L22: 007.png | O22: Unsolved | P22: App | Q22: I fix the issue
A24: BR_008 | B24: Weight tracker | C24: BMI | D24: BMI calculation error | E24: User need to download the app on their IOS device | F24: 1. Open app 2. Signup using valid credentials 3. Click on settings 4. Select weight tracker | G24: User credentials | H24: BMI calculation in app should be accurate | I24: Error in BMI calculation | J24: Fail | K24: High | L24: 008.png | O24: Solved | P24: Back-End
A26: BR_009 | B26: Login | C26: Login | D26: Faced error in login | E26: User need to download the app on their IOS device | F26: 1. Open app 2. Goto login page | G26: User credentials | H26: User should not face any issue in login | I26: Faced bad request on login time | J26: Fail | K26: High | L26: 009.png | O26: Solved | P26: Back-End
A28: BR_010 | B28: Challenge | C28: Challenge | D28: Progress count issue | E28: User need to download the app on their IOS device | F28: 1. Open app 2. Login using valid credentials 3. Goto challenges 4. Click on current challenge | G28: User credentials | H28: Progress calculations need to be precise. | I28: Mismatch in progress calculation | J28: Fail | K28: High | L28: 010.MP4 | O28: Unsolved | P28: App | Q28: I fix the issue
A30: BR_011 | B30: Achievement | C30: Achievement | D30: Unlocked the 7th achievement instead of the 6th one. | E30: User need to download the app on their IOS device | F30: 1. Open app 2. Signup using valid credentials 3. Click on settings | G30: User credentials | H30: Achievements should be unlocked in ascending order. | I30: 7th achievement unlocked instead of the 6th | J30: Fail | K30: High | L30: 011.png | O30: Solved | P30: Back-End | Q30: I fix the issue
A32: BR_012 | B32: Challenge | C32: Challenge | D32: The "Continue Steps" button isn’t working, making it nonfunctional. | E32: User need to download the app on their IOS device | F32: 1. Open app 2. Login using valid credentials 3. Goto challenges | G32: User credentials | H32: All buttons should work accurately. | I32: button not working | J32: Fail | K32: High | L32: 012.mov | O32: Solved | P32: App | Q32: I solved the issue
A34: BR_013 | B34: Challenge | C34: Challenge | D34: Miss calculations in challenges | E34: User need to download the app on their IOS device | F34: 1. Open app 2. Login using valid credentials 3. Goto challenges | G34: User credentials | H34: All challenge data should function smoothly. | I34: A data mismatch has been detected. | J34: Fail | K34: High | L34: 013.MP4 | O34: Solved | P34: Back-End | Q34: I fix the issue
A36: BR_014 | B36: OTP | C36: OTP | D36: Double OTP page is displayed | E36: User need to download the app on their IOS device | F36: 1. Open app 2. goto Login page 3. Click on forget password 4. Enter mail and goto OTP page | G36: User credentials | H36: OTP page should displayed single time | I36: OTP page shows twice | J36: Fail | K36: Medium | L36: 014.PNG | O36: Unsolved | P36: App | Q36: It is not issue if you double click on otp then it show double otp. It check it on my end
A38: BR_015 | B38: Home | C38: Home | D38: Save the data from the previous account and show it in the new account. | E38: User need to download the app on their IOS device | F38: 1. Open app 2. Login using valid credentials 3. Goto Home | G38: User credentials | H38: Data from a deleted account should not be stored. | I38: Showed deleted account data on the new account | J38: Fail | K38: High | L38: 015.PNG
A40: BR_016 | B40: Challenge | C40: Challenge | D40: Failed to join public challenges | E40: User need to download the app on their IOS device | F40: 1. Open app 2. Login using valid credentials 3. Goto Public challenges | G40: User credentials | H40: Usere should be able to join public created challenges | I40: Failed to join in public created challenges | J40: Fail | K40: High | L40: 016.png | O40: Solved | P40: App | Q40: I fix the issue
A42: BR_017 | B42: Help & Support | C42: Contact Support | D42: The social media and website links aren’t integrated. | E42: User need to download the app on their IOS device | F42: 1. Open app 2. Login using valid credentials 3. Goto Help & Support 4. Click on contact support | G42: User credentials | H42: Social media accounts and the website should be properly connected to ensure authenticity. | I42: Missing social media and website links | J42: Fail | K42: Medium | L42: 017.png | P42: App | Q42: Client not provide.Only showing the static data
A44: BR_018 | B44: Privacy Policy | C44: Privacy Policy | D44: Missing privacy policy content in app | E44: User need to download the app on their IOS device | F44: 1. Open app 2. Login using valid credentials 3. Goto Privacy Policy | G44: User credentials | H44: The privacy policy should be clearly displayed in the app to ensure authenticity. | I44: Privacy policy content is missing. | J44: Fail | K44: Medium | L44: 018.png | O44: Unsolved | P44: App | Q44: It is comming from backend. If dashboard upload privacy policy then it show
A46: BR_019 | B46: Terms of service | C46: Terms of service | D46: Missing terms of service content in app | E46: User need to download the app on their IOS device | F46: 1. Open app 2. Login using valid credentials 3. Goto Terms of service | G46: User credentials | H46: The terms of service should be clearly displayed in the app to ensure authenticity. | I46: Terms of service content is missing. | J46: Fail | K46: Medium | L46: 019.png | O46: Solved | P46: App | Q46: It is comming from backend. If dashboard upload Terms of Service then it show
A48: BR_020 | B48: Challenge | C48: Challenge | D48: The step count for the public challenge isn’t working as it should. | E48: User need to download the app on their IOS device | F48: 1. Open app 2. Login using valid credentials 3. Goto Public challenges 4. Join in public challenges | G48: User credentials | H48: Steps should be counted accurately in public challenges. | I48: Facing calculation error and steps are not counting in public challenges | J48: Fail | K48: High | L48: 020.png | O48: Solved | P48: Back-End
A50: BR_021 | B50: Challenge | C50: Challenge | D50: Missmatch calculation in created challenges | E50: User need to download the app on their IOS device | F50: 1. Open app 2. Login using valid credentials 3. Goto Public challenges 4. Join in public challenges | G50: User credentials | H50: Calclations should be accurate | I50: Miss calculation has been noticed | J50: Fail | K50: High | L50: 021.png | O50: Solved | P50: Back-End
A52: BR_022 | B52: Delete Account | C52: Delete Account | D52: Failed to redirect to the signup page after deleting the account. | E52: User need to download the app on their IOS device | F52: 1. Open app 2. Login using valid credentials 3. Goto Settings 4. Click on delete account | G52: User credentials | H52: After deleting an account, the user should be redirected to the signup page. | I52: Unable to redirect the user to the signup page. | J52: Fail | K52: High | L52: 022.MP4 | O52: Solved | P52: App | Q52: I fix the issue
A54: BR_023 | B54: Forget Password | C54: Forget Password | D54: User is able to reset password for deleted account | E54: User need to download the app on their IOS device | F54: 1. Open app 2. Goto login page 3. Click on forget password | G54: User credentials | H54: Only registered email should receive OTP | I54: Normal mail also can receive OTP | J54: Fail | K54: High | L54: 023.mov | O54: Solved | P54: App | Q54: I fix the issue
A56: BR_024 | B56: Challenge | C56: Challenge | D56: The challenge lasts for two timelines, one measured in weeks and the other in days. | E56: User need to download the app on their IOS device | F56: 1. Open app 2. Login using valid credentials 3. Goto Public challenges 4. Join in public challenges | G56: User credentials | H56: It should only take one time | I56: It takes two time inputs, one in weeks and the other with a start and end date, which makes it a bit confusing. | J56: Fail | K56: Medium | L56: 024.png | O56: Solved | P56: App | Q56: It is previously designed.For this reason. Here user have to calculate start date and end date of challenge and based on week input
A58: BR_025 | B58: Daily Task | C58: Daily Task | D58: Multiple task completion screen appeared after the user finished their daily task. | E58: User need to download the app on their IOS device | F58: 1. Open app 2. Signup using valid credentials 3. Complete daily task | G58: User credentials | H58: After completing daily task, completion screen should appear only one time | I58: Multiple completion screen has been seen in app | J58: Fail | K58: Medium | L58: 025.MP4 | O58: Unsolved | P58: App | Q58: I fix the issue
A60: BR_026 | B60: Progress | C60: Progress | D60: Work progress calculation and daily target calculation are different. | E60: User need to download the app on their IOS device | F60: 1. Open app 2. Signup using valid credentials 3. Complete daily task | G60: User credentials | H60: The daily target goal calculation needs to be accurate and clearly displayed. | I60: Progress calculation error | J60: Fail | K60: High | L60: 026.png
A62: BR_027 | B62: Weight tracker | C62: BMI | D62: The weight can be changed, but you need to close and relaunch the app. | E62: User need to download the app on their IOS device | F62: 1. Open app 2. Signup using valid credentials 3. Click on settings 4. Select weight tracker | G62: User credentials | H62: The weight should update dynamically without needing to close or relaunch the app. | I62: Unable to update weight in real time | J62: Fail | K62: High | L62: 027.mov
A64: BR_028 | B64: Report | C64: Report | D64: Missing Statistic on report page | E64: User need to download the app on their IOS device | F64: 1. Open app 2. Signup using valid credentials 3. Click report | G64: User credentials | H64: The design and alignment should be as perfect as in Figma. | I64: Statistic missing in the frontend | J64: Fail | K64: High | L64: 028.png
A66: BR_029 | B66: Home | C66: Home | D66: Failed to display progress in proper week | E66: User need to download the app on their IOS device | F66: 1. Open app 2. Login using valid credentials 3. Goto Home | G66: User credentials | H66: The filter on the calendar should display correctly in either week or month view. | I66: Unable to display the progress for the day in the week. | J66: Fail | K66: High | L66: 029.png
A68: BR_030 | B68: Report | C68: Report | D68: Failed to display accurate calender in report page | E68: User need to download the app on their IOS device | F68: 1. Open app 2. Signup using valid credentials 3. Click report | G68: User credentials | H68: The calendar should be displayed accurately in the app. | I68: Unable to display the correct calendar in the app. | J68: Fail | K68: High | L68: 030.png
A70: BR_031 | B70: Splash Screen | C70: Splash Screen | D70: Failed to proceed with default steps | E70: User need to download the app on their IOS device | F70: 1. Open app 2. Signup using valid credentials | G70: User credentials | H70: If steps is not manually selected by user, then the default steps (1000 steps) should be used to procced | I70: The user cannot proceed to the next page without manually selecting the steps. | J70: Fail | K70: High | L70: 031.png
A72: BR_032 | B72: Login | C72: Login | D72: Failed to sigin | E72: User need to download the app on their IOS device | F72: 1. Open app 2. Goto login page | G72: User credentials | H72: User should be able to signin without facing any issue | I72: Failed to signin properly | J72: Fail | K72: High | L72: 032.png
...

Sheet Summary Report
A1: Module | B1: Sub Module | C1: Test Case ID | D1: Bug Count | E1: Bug Rate % | F1: Bug Severity
A2: =IFERROR(__xludf.DUMMYFUNCTION("SORT( SPLIT( UNIQUE( FILTER('Main Report'!B11:B100 & ""♦"" & 'Main Report'!C11:C100, LEN('Main Report'!C11:C100)) ), ""♦"" ), 1, TRUE, 2, TRUE ) "),"Achievement") -> Achievement | B2: =IFERROR(__xludf.DUMMYFUNCTION("""COMPUTED_VALUE"""),"Achievement") -> Achievement | C2: =IFERROR(__xludf.DUMMYFUNCTION("TEXTJOIN("", "", TRUE, FILTER('Main Report'!A11:A100, ('Main Report'!B11:B100=A2) * ('Main Report'!C11:C100=B2) ) ) "),"BR-001, BR-002") -> BR-001, BR-002 | D2: =IFERROR(__xludf.DUMMYFUNCTION("COUNTA(UNIQUE(TRANSPOSE(SPLIT(C2, "", "")))) "),2.0) -> 2 | E2: =IF(D2="", "", TEXT((D2 / 'Main Report'!$E$7), "0.00%")) -> 5.88% | F2: =IFERROR(__xludf.DUMMYFUNCTION("IF(C2="""", """", TEXTJOIN("", "", TRUE, ""High: "" & COUNTIF(FILTER('Main Report'!K11:K100, ISNUMBER(MATCH('Main Report'!A11:A100, SPLIT(C2, "", ""), 0))), ""High"") & CHAR(10) & ""Medium: "" & COUNTIF(FILTER('Main Report'!K11:K100, ISNU"&"MBER(MATCH('Main Report'!A11:A100, SPLIT(C2, "", ""), 0))), ""Medium"") & CHAR(10) & ""Low: "" & COUNTIF(FILTER('Main Report'!K11:K100, ISNUMBER(MATCH('Main Report'!A11:A100, SPLIT(C2, "", ""), 0))), ""Low"") ) ) "),"High: 1 Medium: 1 Low: 0") -> High: 1 Medium: 1 Low: 0
A3: =IFERROR(__xludf.DUMMYFUNCTION("""COMPUTED_VALUE"""),"Challenge") -> Challenge | B3: =IFERROR(__xludf.DUMMYFUNCTION("""COMPUTED_VALUE"""),"Challenge") -> Challenge | C3: =IFERROR(__xludf.DUMMYFUNCTION("TEXTJOIN("", "", TRUE, FILTER('Main Report'!A12:A101, ('Main Report'!B12:B101=A3) * ('Main Report'!C12:C101=B3) ) ) "),"BR-003, BR-004, BR-005, BR-006, BR-007, BR-008, BR-009") -> BR-003, BR-004, BR-005, BR-006, BR-007, BR-008, BR-009 | D3: =IFERROR(__xludf.DUMMYFUNCTION("COUNTA(UNIQUE(TRANSPOSE(SPLIT(C3, "", "")))) "),7.0) -> 7 | E3: =IF(D3="", "", TEXT((D3 / 'Main Report'!$E$7), "0.00%")) -> 20.59% | F3: =IFERROR(__xludf.DUMMYFUNCTION("IF(C3="""", """", TEXTJOIN("", "", TRUE, ""High: "" & COUNTIF(FILTER('Main Report'!K12:K101, ISNUMBER(MATCH('Main Report'!A12:A101, SPLIT(C3, "", ""), 0))), ""High"") & CHAR(10) & ""Medium: "" & COUNTIF(FILTER('Main Report'!K12:K101, ISNU"&"MBER(MATCH('Main Report'!A12:A101, SPLIT(C3, "", ""), 0))), ""Medium"") & CHAR(10) & ""Low: "" & COUNTIF(FILTER('Main Report'!K12:K101, ISNUMBER(MATCH('Main Report'!A12:A101, SPLIT(C3, "", ""), 0))), ""Low"") ) ) "),"High: 6 Medium: 1 Low: 0") -> High: 6 Medium: 1 Low: 0
A4: =IFERROR(__xludf.DUMMYFUNCTION("""COMPUTED_VALUE"""),"Daily Task") -> Daily Task | B4: =IFERROR(__xludf.DUMMYFUNCTION("""COMPUTED_VALUE"""),"Daily Task") -> Daily Task | C4: =IFERROR(__xludf.DUMMYFUNCTION("TEXTJOIN("", "", TRUE, FILTER('Main Report'!A13:A102, ('Main Report'!B13:B102=A4) * ('Main Report'!C13:C102=B4) ) ) "),"BR-010") -> BR-010 | D4: =IFERROR(__xludf.DUMMYFUNCTION("COUNTA(UNIQUE(TRANSPOSE(SPLIT(C4, "", "")))) "),1.0) -> 1 | E4: =IF(D4="", "", TEXT((D4 / 'Main Report'!$E$7), "0.00%")) -> 2.94% | F4: =IFERROR(__xludf.DUMMYFUNCTION("IF(C4="""", """", TEXTJOIN("", "", TRUE, ""High: "" & COUNTIF(FILTER('Main Report'!K13:K102, ISNUMBER(MATCH('Main Report'!A13:A102, SPLIT(C4, "", ""), 0))), ""High"") & CHAR(10) & ""Medium: "" & COUNTIF(FILTER('Main Report'!K13:K102, ISNU"&"MBER(MATCH('Main Report'!A13:A102, SPLIT(C4, "", ""), 0))), ""Medium"") & CHAR(10) & ""Low: "" & COUNTIF(FILTER('Main Report'!K13:K102, ISNUMBER(MATCH('Main Report'!A13:A102, SPLIT(C4, "", ""), 0))), ""Low"") ) ) "),"High: 0 Medium: 1 Low: 0") -> High: 0 Medium: 1 Low: 0
A5: =IFERROR(__xludf.DUMMYFUNCTION("""COMPUTED_VALUE"""),"Delete Account") -> Delete Account | B5: =IFERROR(__xludf.DUMMYFUNCTION("""COMPUTED_VALUE"""),"Delete Account") -> Delete Account | C5: =IFERROR(__xludf.DUMMYFUNCTION("TEXTJOIN("", "", TRUE, FILTER('Main Report'!A14:A103, ('Main Report'!B14:B103=A5) * ('Main Report'!C14:C103=B5) ) ) "),"BR-011") -> BR-011 | D5: =IFERROR(__xludf.DUMMYFUNCTION("COUNTA(UNIQUE(TRANSPOSE(SPLIT(C5, "", "")))) "),1.0) -> 1 | E5: =IF(D5="", "", TEXT((D5 / 'Main Report'!$E$7), "0.00%")) -> 2.94% | F5: =IFERROR(__xludf.DUMMYFUNCTION("IF(C5="""", """", TEXTJOIN("", "", TRUE, ""High: "" & COUNTIF(FILTER('Main Report'!K14:K103, ISNUMBER(MATCH('Main Report'!A14:A103, SPLIT(C5, "", ""), 0))), ""High"") & CHAR(10) & ""Medium: "" & COUNTIF(FILTER('Main Report'!K14:K103, ISNU"&"MBER(MATCH('Main Report'!A14:A103, SPLIT(C5, "", ""), 0))), ""Medium"") & CHAR(10) & ""Low: "" & COUNTIF(FILTER('Main Report'!K14:K103, ISNUMBER(MATCH('Main Report'!A14:A103, SPLIT(C5, "", ""), 0))), ""Low"") ) ) "),"High: 1 Medium: 0 Low: 0") -> High: 1 Medium: 0 Low: 0
A6: =IFERROR(__xludf.DUMMYFUNCTION("""COMPUTED_VALUE"""),"Forget Password") -> Forget Password | B6: =IFERROR(__xludf.DUMMYFUNCTION("""COMPUTED_VALUE"""),"Forget Password") -> Forget Password | C6: =IFERROR(__xludf.DUMMYFUNCTION("TEXTJOIN("", "", TRUE, FILTER('Main Report'!A15:A104, ('Main Report'!B15:B104=A6) * ('Main Report'!C15:C104=B6) ) ) "),"BR-012") -> BR-012 | D6: =IFERROR(__xludf.DUMMYFUNCTION("COUNTA(UNIQUE(TRANSPOSE(SPLIT(C6, "", "")))) "),1.0) -> 1 | E6: =IF(D6="", "", TEXT((D6 / 'Main Report'!$E$7), "0.00%")) -> 2.94% | F6: =IFERROR(__xludf.DUMMYFUNCTION("IF(C6="""", """", TEXTJOIN("", "", TRUE, ""High: "" & COUNTIF(FILTER('Main Report'!K15:K104, ISNUMBER(MATCH('Main Report'!A15:A104, SPLIT(C6, "", ""), 0))), ""High"") & CHAR(10) & ""Medium: "" & COUNTIF(FILTER('Main Report'!K15:K104, ISNU"&"MBER(MATCH('Main Report'!A15:A104, SPLIT(C6, "", ""), 0))), ""Medium"") & CHAR(10) & ""Low: "" & COUNTIF(FILTER('Main Report'!K15:K104, ISNUMBER(MATCH('Main Report'!A15:A104, SPLIT(C6, "", ""), 0))), ""Low"") ) ) "),"High: 1 Medium: 0 Low: 0") -> High: 1 Medium: 0 Low: 0
A7: =IFERROR(__xludf.DUMMYFUNCTION("""COMPUTED_VALUE"""),"Help & Support") -> Help & Support | B7: =IFERROR(__xludf.DUMMYFUNCTION("""COMPUTED_VALUE"""),"Contact Support") -> Contact Support | C7: =IFERROR(__xludf.DUMMYFUNCTION("TEXTJOIN("", "", TRUE, FILTER('Main Report'!A16:A105, ('Main Report'!B16:B105=A7) * ('Main Report'!C16:C105=B7) ) ) "),"BR-013") -> BR-013 | D7: =IFERROR(__xludf.DUMMYFUNCTION("COUNTA(UNIQUE(TRANSPOSE(SPLIT(C7, "", "")))) "),1.0) -> 1 | E7: =IF(D7="", "", TEXT((D7 / 'Main Report'!$E$7), "0.00%")) -> 2.94% | F7: =IFERROR(__xludf.DUMMYFUNCTION("IF(C7="""", """", TEXTJOIN("", "", TRUE, ""High: "" & COUNTIF(FILTER('Main Report'!K16:K105, ISNUMBER(MATCH('Main Report'!A16:A105, SPLIT(C7, "", ""), 0))), ""High"") & CHAR(10) & ""Medium: "" & COUNTIF(FILTER('Main Report'!K16:K105, ISNU"&"MBER(MATCH('Main Report'!A16:A105, SPLIT(C7, "", ""), 0))), ""Medium"") & CHAR(10) & ""Low: "" & COUNTIF(FILTER('Main Report'!K16:K105, ISNUMBER(MATCH('Main Report'!A16:A105, SPLIT(C7, "", ""), 0))), ""Low"") ) ) "),"High: 0 Medium: 1 Low: 0") -> High: 0 Medium: 1 Low: 0
A8: =IFERROR(__xludf.DUMMYFUNCTION("""COMPUTED_VALUE"""),"Home") -> Home | B8: =IFERROR(__xludf.DUMMYFUNCTION("""COMPUTED_VALUE"""),"Home") -> Home | C8: =IFERROR(__xludf.DUMMYFUNCTION("TEXTJOIN("", "", TRUE, FILTER('Main Report'!A17:A106, ('Main Report'!B17:B106=A8) * ('Main Report'!C17:C106=B8) ) ) "),"BR-014, BR-015") -> BR-014, BR-015 | D8: =IFERROR(__xludf.DUMMYFUNCTION("COUNTA(UNIQUE(TRANSPOSE(SPLIT(C8, "", "")))) "),2.0) -> 2 | E8: =IF(D8="", "", TEXT((D8 / 'Main Report'!$E$7), "0.00%")) -> 5.88% | F8: =IFERROR(__xludf.DUMMYFUNCTION("IF(C8="""", """", TEXTJOIN("", "", TRUE, ""High: "" & COUNTIF(FILTER('Main Report'!K17:K106, ISNUMBER(MATCH('Main Report'!A17:A106, SPLIT(C8, "", ""), 0))), ""High"") & CHAR(10) & ""Medium: "" & COUNTIF(FILTER('Main Report'!K17:K106, ISNU"&"MBER(MATCH('Main Report'!A17:A106, SPLIT(C8, "", ""), 0))), ""Medium"") & CHAR(10) & ""Low: "" & COUNTIF(FILTER('Main Report'!K17:K106, ISNUMBER(MATCH('Main Report'!A17:A106, SPLIT(C8, "", ""), 0))), ""Low"") ) ) "),"High: 2 Medium: 0 Low: 0") -> High: 2 Medium: 0 Low: 0
A9: =IFERROR(__xludf.DUMMYFUNCTION("""COMPUTED_VALUE"""),"Login") -> Login | B9: =IFERROR(__xludf.DUMMYFUNCTION("""COMPUTED_VALUE"""),"Login") -> Login | C9: =IFERROR(__xludf.DUMMYFUNCTION("TEXTJOIN("", "", TRUE, FILTER('Main Report'!A18:A107, ('Main Report'!B18:B107=A9) * ('Main Report'!C18:C107=B9) ) ) "),"BR-016, BR-017, BR-018") -> BR-016, BR-017, BR-018 | D9: =IFERROR(__xludf.DUMMYFUNCTION("COUNTA(UNIQUE(TRANSPOSE(SPLIT(C9, "", "")))) "),3.0) -> 3 | E9: =IF(D9="", "", TEXT((D9 / 'Main Report'!$E$7), "0.00%")) -> 8.82% | F9: =IFERROR(__xludf.DUMMYFUNCTION("IF(C9="""", """", TEXTJOIN("", "", TRUE, ""High: "" & COUNTIF(FILTER('Main Report'!K18:K107, ISNUMBER(MATCH('Main Report'!A18:A107, SPLIT(C9, "", ""), 0))), ""High"") & CHAR(10) & ""Medium: "" & COUNTIF(FILTER('Main Report'!K18:K107, ISNU"&"MBER(MATCH('Main Report'!A18:A107, SPLIT(C9, "", ""), 0))), ""Medium"") & CHAR(10) & ""Low: "" & COUNTIF(FILTER('Main Report'!K18:K107, ISNUMBER(MATCH('Main Report'!A18:A107, SPLIT(C9, "", ""), 0))), ""Low"") ) ) "),"High: 3 Medium: 0 Low: 0") -> High: 3 Medium: 0 Low: 0
A10: =IFERROR(__xludf.DUMMYFUNCTION("""COMPUTED_VALUE"""),"OTP") -> OTP | B10: =IFERROR(__xludf.DUMMYFUNCTION("""COMPUTED_VALUE"""),"OTP") -> OTP | C10: =IFERROR(__xludf.DUMMYFUNCTION("TEXTJOIN("", "", TRUE, FILTER('Main Report'!A19:A108, ('Main Report'!B19:B108=A10) * ('Main Report'!C19:C108=B10) ) ) "),"BR-019") -> BR-019 | D10: =IFERROR(__xludf.DUMMYFUNCTION("COUNTA(UNIQUE(TRANSPOSE(SPLIT(C10, "", "")))) "),1.0) -> 1 | E10: =IF(D10="", "", TEXT((D10 / 'Main Report'!$E$7), "0.00%")) -> 2.94% | F10: =IFERROR(__xludf.DUMMYFUNCTION("IF(C10="""", """", TEXTJOIN("", "", TRUE, ""High: "" & COUNTIF(FILTER('Main Report'!K19:K108, ISNUMBER(MATCH('Main Report'!A19:A108, SPLIT(C10, "", ""), 0))), ""High"") & CHAR(10) & ""Medium: "" & COUNTIF(FILTER('Main Report'!K19:K108, IS"&"NUMBER(MATCH('Main Report'!A19:A108, SPLIT(C10, "", ""), 0))), ""Medium"") & CHAR(10) & ""Low: "" & COUNTIF(FILTER('Main Report'!K19:K108, ISNUMBER(MATCH('Main Report'!A19:A108, SPLIT(C10, "", ""), 0))), ""Low"") ) ) "),"High: 0 Medium: 1 Low: 0") -> High: 0 Medium: 1 Low: 0
A11: =IFERROR(__xludf.DUMMYFUNCTION("""COMPUTED_VALUE"""),"Password") -> Password | B11: =IFERROR(__xludf.DUMMYFUNCTION("""COMPUTED_VALUE"""),"Password") -> Password | C11: =IFERROR(__xludf.DUMMYFUNCTION("TEXTJOIN("", "", TRUE, FILTER('Main Report'!A20:A109, ('Main Report'!B20:B109=A11) * ('Main Report'!C20:C109=B11) ) ) "),"BR-020") -> BR-020 | D11: =IFERROR(__xludf.DUMMYFUNCTION("COUNTA(UNIQUE(TRANSPOSE(SPLIT(C11, "", "")))) "),1.0) -> 1 | E11: =IF(D11="", "", TEXT((D11 / 'Main Report'!$E$7), "0.00%")) -> 2.94% | F11: =IFERROR(__xludf.DUMMYFUNCTION("IF(C11="""", """", TEXTJOIN("", "", TRUE, ""High: "" & COUNTIF(FILTER('Main Report'!K20:K109, ISNUMBER(MATCH('Main Report'!A20:A109, SPLIT(C11, "", ""), 0))), ""High"") & CHAR(10) & ""Medium: "" & COUNTIF(FILTER('Main Report'!K20:K109, IS"&"NUMBER(MATCH('Main Report'!A20:A109, SPLIT(C11, "", ""), 0))), ""Medium"") & CHAR(10) & ""Low: "" & COUNTIF(FILTER('Main Report'!K20:K109, ISNUMBER(MATCH('Main Report'!A20:A109, SPLIT(C11, "", ""), 0))), ""Low"") ) ) "),"High: 0 Medium: 0 Low: 1") -> High: 0 Medium: 0 Low: 1
A12: =IFERROR(__xludf.DUMMYFUNCTION("""COMPUTED_VALUE"""),"Preferences") -> Preferences | B12: =IFERROR(__xludf.DUMMYFUNCTION("""COMPUTED_VALUE"""),"Preferences") -> Preferences | C12: =IFERROR(__xludf.DUMMYFUNCTION("TEXTJOIN("", "", TRUE, FILTER('Main Report'!A21:A110, ('Main Report'!B21:B110=A12) * ('Main Report'!C21:C110=B12) ) ) "),"BR-021") -> BR-021 | D12: =IFERROR(__xludf.DUMMYFUNCTION("COUNTA(UNIQUE(TRANSPOSE(SPLIT(C12, "", "")))) "),1.0) -> 1 | E12: =IF(D12="", "", TEXT((D12 / 'Main Report'!$E$7), "0.00%")) -> 2.94% | F12: =IFERROR(__xludf.DUMMYFUNCTION("IF(C12="""", """", TEXTJOIN("", "", TRUE, ""High: "" & COUNTIF(FILTER('Main Report'!K21:K110, ISNUMBER(MATCH('Main Report'!A21:A110, SPLIT(C12, "", ""), 0))), ""High"") & CHAR(10) & ""Medium: "" & COUNTIF(FILTER('Main Report'!K21:K110, IS"&"NUMBER(MATCH('Main Report'!A21:A110, SPLIT(C12, "", ""), 0))), ""Medium"") & CHAR(10) & ""Low: "" & COUNTIF(FILTER('Main Report'!K21:K110, ISNUMBER(MATCH('Main Report'!A21:A110, SPLIT(C12, "", ""), 0))), ""Low"") ) ) "),"High: 1 Medium: 0 Low: 0") -> High: 1 Medium: 0 Low: 0
A13: =IFERROR(__xludf.DUMMYFUNCTION("""COMPUTED_VALUE"""),"Privacy Policy") -> Privacy Policy | B13: =IFERROR(__xludf.DUMMYFUNCTION("""COMPUTED_VALUE"""),"Privacy Policy") -> Privacy Policy | C13: =IFERROR(__xludf.DUMMYFUNCTION("TEXTJOIN("", "", TRUE, FILTER('Main Report'!A22:A111, ('Main Report'!B22:B111=A13) * ('Main Report'!C22:C111=B13) ) ) "),"BR-022") -> BR-022 | D13: =IFERROR(__xludf.DUMMYFUNCTION("COUNTA(UNIQUE(TRANSPOSE(SPLIT(C13, "", "")))) "),1.0) -> 1 | E13: =IF(D13="", "", TEXT((D13 / 'Main Report'!$E$7), "0.00%")) -> 2.94% | F13: =IFERROR(__xludf.DUMMYFUNCTION("IF(C13="""", """", TEXTJOIN("", "", TRUE, ""High: "" & COUNTIF(FILTER('Main Report'!K22:K111, ISNUMBER(MATCH('Main Report'!A22:A111, SPLIT(C13, "", ""), 0))), ""High"") & CHAR(10) & ""Medium: "" & COUNTIF(FILTER('Main Report'!K22:K111, IS"&"NUMBER(MATCH('Main Report'!A22:A111, SPLIT(C13, "", ""), 0))), ""Medium"") & CHAR(10) & ""Low: "" & COUNTIF(FILTER('Main Report'!K22:K111, ISNUMBER(MATCH('Main Report'!A22:A111, SPLIT(C13, "", ""), 0))), ""Low"") ) ) "),"High: 0 Medium: 1 Low: 0") -> High: 0 Medium: 1 Low: 0
A14: =IFERROR(__xludf.DUMMYFUNCTION("""COMPUTED_VALUE"""),"Profile") -> Profile | B14: =IFERROR(__xludf.DUMMYFUNCTION("""COMPUTED_VALUE"""),"Profile") -> Profile | C14: =IFERROR(__xludf.DUMMYFUNCTION("TEXTJOIN("", "", TRUE, FILTER('Main Report'!A23:A112, ('Main Report'!B23:B112=A14) * ('Main Report'!C23:C112=B14) ) ) "),"BR-023") -> BR-023 | D14: =IFERROR(__xludf.DUMMYFUNCTION("COUNTA(UNIQUE(TRANSPOSE(SPLIT(C14, "", "")))) "),1.0) -> 1 | E14: =IF(D14="", "", TEXT((D14 / 'Main Report'!$E$7), "0.00%")) -> 2.94% | F14: =IFERROR(__xludf.DUMMYFUNCTION("IF(C14="""", """", TEXTJOIN("", "", TRUE, ""High: "" & COUNTIF(FILTER('Main Report'!K23:K112, ISNUMBER(MATCH('Main Report'!A23:A112, SPLIT(C14, "", ""), 0))), ""High"") & CHAR(10) & ""Medium: "" & COUNTIF(FILTER('Main Report'!K23:K112, IS"&"NUMBER(MATCH('Main Report'!A23:A112, SPLIT(C14, "", ""), 0))), ""Medium"") & CHAR(10) & ""Low: "" & COUNTIF(FILTER('Main Report'!K23:K112, ISNUMBER(MATCH('Main Report'!A23:A112, SPLIT(C14, "", ""), 0))), ""Low"") ) ) "),"High: 1 Medium: 0 Low: 0") -> High: 1 Medium: 0 Low: 0
A15: =IFERROR(__xludf.DUMMYFUNCTION("""COMPUTED_VALUE"""),"Progress") -> Progress | B15: =IFERROR(__xludf.DUMMYFUNCTION("""COMPUTED_VALUE"""),"Progress") -> Progress | C15: =IFERROR(__xludf.DUMMYFUNCTION("TEXTJOIN("", "", TRUE, FILTER('Main Report'!A24:A113, ('Main Report'!B24:B113=A15) * ('Main Report'!C24:C113=B15) ) ) "),"BR-024") -> BR-024 | D15: =IFERROR(__xludf.DUMMYFUNCTION("COUNTA(UNIQUE(TRANSPOSE(SPLIT(C15, "", "")))) "),1.0) -> 1 | E15: =IF(D15="", "", TEXT((D15 / 'Main Report'!$E$7), "0.00%")) -> 2.94% | F15: =IFERROR(__xludf.DUMMYFUNCTION("IF(C15="""", """", TEXTJOIN("", "", TRUE, ""High: "" & COUNTIF(FILTER('Main Report'!K24:K113, ISNUMBER(MATCH('Main Report'!A24:A113, SPLIT(C15, "", ""), 0))), ""High"") & CHAR(10) & ""Medium: "" & COUNTIF(FILTER('Main Report'!K24:K113, IS"&"NUMBER(MATCH('Main Report'!A24:A113, SPLIT(C15, "", ""), 0))), ""Medium"") & CHAR(10) & ""Low: "" & COUNTIF(FILTER('Main Report'!K24:K113, ISNUMBER(MATCH('Main Report'!A24:A113, SPLIT(C15, "", ""), 0))), ""Low"") ) ) "),"High: 1 Medium: 0 Low: 0") -> High: 1 Medium: 0 Low: 0
A16: =IFERROR(__xludf.DUMMYFUNCTION("""COMPUTED_VALUE"""),"Report") -> Report | B16: =IFERROR(__xludf.DUMMYFUNCTION("""COMPUTED_VALUE"""),"Report") -> Report | C16: =IFERROR(__xludf.DUMMYFUNCTION("TEXTJOIN("", "", TRUE, FILTER('Main Report'!A25:A114, ('Main Report'!B25:B114=A16) * ('Main Report'!C25:C114=B16) ) ) "),"BR-025, BR-026") -> BR-025, BR-026 | D16: =IFERROR(__xludf.DUMMYFUNCTION("COUNTA(UNIQUE(TRANSPOSE(SPLIT(C16, "", "")))) "),2.0) -> 2 | E16: =IF(D16="", "", TEXT((D16 / 'Main Report'!$E$7), "0.00%")) -> 5.88% | F16: =IFERROR(__xludf.DUMMYFUNCTION("IF(C16="""", """", TEXTJOIN("", "", TRUE, ""High: "" & COUNTIF(FILTER('Main Report'!K25:K114, ISNUMBER(MATCH('Main Report'!A25:A114, SPLIT(C16, "", ""), 0))), ""High"") & CHAR(10) & ""Medium: "" & COUNTIF(FILTER('Main Report'!K25:K114, IS"&"NUMBER(MATCH('Main Report'!A25:A114, SPLIT(C16, "", ""), 0))), ""Medium"") & CHAR(10) & ""Low: "" & COUNTIF(FILTER('Main Report'!K25:K114, ISNUMBER(MATCH('Main Report'!A25:A114, SPLIT(C16, "", ""), 0))), ""Low"") ) ) "),"High: 2 Medium: 0 Low: 0") -> High: 2 Medium: 0 Low: 0
A17: =IFERROR(__xludf.DUMMYFUNCTION("""COMPUTED_VALUE"""),"Splash Screen") -> Splash Screen | B17: =IFERROR(__xludf.DUMMYFUNCTION("""COMPUTED_VALUE"""),"Splash Screen") -> Splash Screen | C17: =IFERROR(__xludf.DUMMYFUNCTION("TEXTJOIN("", "", TRUE, FILTER('Main Report'!A26:A115, ('Main Report'!B26:B115=A17) * ('Main Report'!C26:C115=B17) ) ) "),"BR-027, BR-028, BR-029, BR-030") -> BR-027, BR-028, BR-029, BR-030 | D17: =IFERROR(__xludf.DUMMYFUNCTION("COUNTA(UNIQUE(TRANSPOSE(SPLIT(C17, "", "")))) "),4.0) -> 4 | E17: =IF(D17="", "", TEXT((D17 / 'Main Report'!$E$7), "0.00%")) -> 11.76% | F17: =IFERROR(__xludf.DUMMYFUNCTION("IF(C17="""", """", TEXTJOIN("", "", TRUE, ""High: "" & COUNTIF(FILTER('Main Report'!K26:K115, ISNUMBER(MATCH('Main Report'!A26:A115, SPLIT(C17, "", ""), 0))), ""High"") & CHAR(10) & ""Medium: "" & COUNTIF(FILTER('Main Report'!K26:K115, IS"&"NUMBER(MATCH('Main Report'!A26:A115, SPLIT(C17, "", ""), 0))), ""Medium"") & CHAR(10) & ""Low: "" & COUNTIF(FILTER('Main Report'!K26:K115, ISNUMBER(MATCH('Main Report'!A26:A115, SPLIT(C17, "", ""), 0))), ""Low"") ) ) "),"High: 1 Medium: 3 Low: 0") -> High: 1 Medium: 3 Low: 0
A18: =IFERROR(__xludf.DUMMYFUNCTION("""COMPUTED_VALUE"""),"Terms of service") -> Terms of service | B18: =IFERROR(__xludf.DUMMYFUNCTION("""COMPUTED_VALUE"""),"Terms of service") -> Terms of service | C18: =IFERROR(__xludf.DUMMYFUNCTION("TEXTJOIN("", "", TRUE, FILTER('Main Report'!A27:A116, ('Main Report'!B27:B116=A18) * ('Main Report'!C27:C116=B18) ) ) "),"BR-031") -> BR-031 | D18: =IFERROR(__xludf.DUMMYFUNCTION("COUNTA(UNIQUE(TRANSPOSE(SPLIT(C18, "", "")))) "),1.0) -> 1 | E18: =IF(D18="", "", TEXT((D18 / 'Main Report'!$E$7), "0.00%")) -> 2.94% | F18: =IFERROR(__xludf.DUMMYFUNCTION("IF(C18="""", """", TEXTJOIN("", "", TRUE, ""High: "" & COUNTIF(FILTER('Main Report'!K27:K116, ISNUMBER(MATCH('Main Report'!A27:A116, SPLIT(C18, "", ""), 0))), ""High"") & CHAR(10) & ""Medium: "" & COUNTIF(FILTER('Main Report'!K27:K116, IS"&"NUMBER(MATCH('Main Report'!A27:A116, SPLIT(C18, "", ""), 0))), ""Medium"") & CHAR(10) & ""Low: "" & COUNTIF(FILTER('Main Report'!K27:K116, ISNUMBER(MATCH('Main Report'!A27:A116, SPLIT(C18, "", ""), 0))), ""Low"") ) ) "),"High: 0 Medium: 1 Low: 0") -> High: 0 Medium: 1 Low: 0
A19: =IFERROR(__xludf.DUMMYFUNCTION("""COMPUTED_VALUE"""),"Weight tracker") -> Weight tracker | B19: =IFERROR(__xludf.DUMMYFUNCTION("""COMPUTED_VALUE"""),"BMI") -> BMI | C19: =IFERROR(__xludf.DUMMYFUNCTION("TEXTJOIN("", "", TRUE, FILTER('Main Report'!A28:A117, ('Main Report'!B28:B117=A19) * ('Main Report'!C28:C117=B19) ) ) "),"BR-032, BR-033, BR-034") -> BR-032, BR-033, BR-034 | D19: =IFERROR(__xludf.DUMMYFUNCTION("COUNTA(UNIQUE(TRANSPOSE(SPLIT(C19, "", "")))) "),3.0) -> 3 | E19: =IF(D19="", "", TEXT((D19 / 'Main Report'!$E$7), "0.00%")) -> 8.82% | F19: =IFERROR(__xludf.DUMMYFUNCTION("IF(C19="""", """", TEXTJOIN("", "", TRUE, ""High: "" & COUNTIF(FILTER('Main Report'!K28:K117, ISNUMBER(MATCH('Main Report'!A28:A117, SPLIT(C19, "", ""), 0))), ""High"") & CHAR(10) & ""Medium: "" & COUNTIF(FILTER('Main Report'!K28:K117, IS"&"NUMBER(MATCH('Main Report'!A28:A117, SPLIT(C19, "", ""), 0))), ""Medium"") & CHAR(10) & ""Low: "" & COUNTIF(FILTER('Main Report'!K28:K117, ISNUMBER(MATCH('Main Report'!A28:A117, SPLIT(C19, "", ""), 0))), ""Low"") ) ) "),"High: 2 Medium: 1 Low: 0") -> High: 2 Medium: 1 Low: 0
C20: =IFERROR(__xludf.DUMMYFUNCTION("TEXTJOIN("", "", TRUE, FILTER('Main Report'!A29:A118, ('Main Report'!B29:B118=A20) * ('Main Report'!C29:C118=B20) ) ) "),"") | E20: =IF(D20="", "", TEXT((D20 / 'Main Report'!$E$7), "0.00%")) | F20: =IFERROR(__xludf.DUMMYFUNCTION("IF(C20="""", """", TEXTJOIN("", "", TRUE, ""High: "" & COUNTIF(FILTER('Main Report'!K29:K118, ISNUMBER(MATCH('Main Report'!A29:A118, SPLIT(C20, "", ""), 0))), ""High"") & CHAR(10) & ""Medium: "" & COUNTIF(FILTER('Main Report'!K29:K118, IS"&"NUMBER(MATCH('Main Report'!A29:A118, SPLIT(C20, "", ""), 0))), ""Medium"") & CHAR(10) & ""Low: "" & COUNTIF(FILTER('Main Report'!K29:K118, ISNUMBER(MATCH('Main Report'!A29:A118, SPLIT(C20, "", ""), 0))), ""Low"") ) ) "),"")
C21: =IFERROR(__xludf.DUMMYFUNCTION("TEXTJOIN("", "", TRUE, FILTER('Main Report'!A30:A119, ('Main Report'!B30:B119=A21) * ('Main Report'!C30:C119=B21) ) ) "),"") | E21: =IF(D21="", "", TEXT((D21 / 'Main Report'!$E$7), "0.00%")) | F21: =IFERROR(__xludf.DUMMYFUNCTION("IF(C21="""", """", TEXTJOIN("", "", TRUE, ""High: "" & COUNTIF(FILTER('Main Report'!K30:K119, ISNUMBER(MATCH('Main Report'!A30:A119, SPLIT(C21, "", ""), 0))), ""High"") & CHAR(10) & ""Medium: "" & COUNTIF(FILTER('Main Report'!K30:K119, IS"&"NUMBER(MATCH('Main Report'!A30:A119, SPLIT(C21, "", ""), 0))), ""Medium"") & CHAR(10) & ""Low: "" & COUNTIF(FILTER('Main Report'!K30:K119, ISNUMBER(MATCH('Main Report'!A30:A119, SPLIT(C21, "", ""), 0))), ""Low"") ) ) "),"")

Sheet Main Report
A2: Tester : | B2: Mohammed Fahad Faisal | D2: Severity | E2: Issues
A3: Project Name: | D3: High | E3: =COUNTIF(Tahsin!K14:K1005, "High") + COUNTIF(Fahad!K10:K1006, "High") -> 22
A4: Project URL: | D4: Medium | E4: =COUNTIF(Tahsin!K14:K1006, "Medium") + COUNTIF(Fahad!K10:K1007, "Medium") -> 11
A5: Developer: | D5: Low | E5: =COUNTIF(Fahad!K10:K1008, "Low") + COUNTIF(Tahsin!K14:K1009, "Low") -> 1
A6: OS:
A7: Environment | D7: Total Test Cases: | E7: =SUM(E3:E5) -> 34 | O7: Place solve if the issue resolves | \/ | P7: Mention which Stack solved the issue | \/
D8: Test Case Solved : | E8: =COUNTIF(O11:O1003, "Solved") -> 0
A10: Test Case ID | B10: Module | C10: Sub Module | D10: Test Case Description | E10: Preconditions | F10: Test Steps | G10: Test Data | H10: Expected Result | I10: Actual Result | J10: Status | K10: Severity | L10: Screen Shots | M10: Suggestion | N10: Tester | O10: Feedback | P10: Stack | Q10: Comment
A11: {=IF((LEN(B11:B100)+LEN(C11:C100))>0, "BR-" & TEXT(ROW(B11:B100)-ROW(B11)+1,"000"), "")} -> BR-001 | B11: =IFERROR(__xludf.DUMMYFUNCTION("QUERY( { ARRAYFORMULA({TRIM(Fahad!B10:B999), Fahad!C10:M999, IF(LEN(Fahad!B10:B999), ""Fahad"", """")}); ARRAYFORMULA({TRIM(Tahsin!B15:B999), Tahsin!C15:M999, IF(LEN(Tahsin!B15:B999), ""Tahsin"", """")}) }, ""SELECT * WHERE Col1 IS NOT NULL "&"ORDER BY Col1 ASC, Col2 ASC"", 0 ) "),"Achievement") -> Achievement | C11: =IFERROR(__xludf.DUMMYFUNCTION("""COMPUTED_VALUE"""),"Achievement") -> Achievement | D11: =IFERROR(__xludf.DUMMYFUNCTION("""COMPUTED_VALUE"""),"Beginner profile is set to level one, but it requires 200 steps to unlock that level.") -> Beginner profile is set to level one, but it requires 200 steps to unlock that level. | E11: =IFERROR(__xludf.DUMMYFUNCTION("""COMPUTED_VALUE"""),"User need to download the app on their IOS device") -> User need to download the app on their IOS device | F11: =IFERROR(__xludf.DUMMYFUNCTION("""COMPUTED_VALUE"""),"1. Open app 2. Signup using valid credentials 3. Click on settings ") -> 1. Open app 2. Signup using valid credentials 3. Click on settings | G11: =IFERROR(__xludf.DUMMYFUNCTION("""COMPUTED_VALUE"""),"User credentials") -> User credentials | H11: =IFERROR(__xludf.DUMMYFUNCTION("""COMPUTED_VALUE"""),"The beginner profile level should start at zero, and after completing 200 steps, it will unlock level one.") -> The beginner profile level should start at zero, and after completing 200 steps, it will unlock level one. | I11: =IFERROR(__xludf.DUMMYFUNCTION("""COMPUTED_VALUE"""),"The level starts at one, and the achievement also locks at level one.") -> The level starts at one, and the achievement also locks at level one. | J11: =IFERROR(__xludf.DUMMYFUNCTION("""COMPUTED_VALUE"""),"Fail") -> Fail | K11: =IFERROR(__xludf.DUMMYFUNCTION("""COMPUTED_VALUE"""),"Medium") -> Medium | L11: =IFERROR(__xludf.DUMMYFUNCTION("""COMPUTED_VALUE"""),"005.png") -> 005.png | N11: =IFERROR(__xludf.DUMMYFUNCTION("""COMPUTED_VALUE"""),"Fahad") -> Fahad
A12: BR-002 | B12: =IFERROR(__xludf.DUMMYFUNCTION("""COMPUTED_VALUE"""),"Achievement") -> Achievement | C12: =IFERROR(__xludf.DUMMYFUNCTION("""COMPUTED_VALUE"""),"Achievement") -> Achievement | D12: =IFERROR(__xludf.DUMMYFUNCTION("""COMPUTED_VALUE"""),"Unlocked the 7th achievement instead of the 6th one.") -> Unlocked the 7th achievement instead of the 6th one. | E12: =IFERROR(__xludf.DUMMYFUNCTION("""COMPUTED_VALUE"""),"User need to download the app on their IOS device") -> User need to download the app on their IOS device | F12: =IFERROR(__xludf.DUMMYFUNCTION("""COMPUTED_VALUE"""),"1. Open app 2. Signup using valid credentials 3. Click on settings ") -> 1. Open app 2. Signup using valid credentials 3. Click on settings | G12: =IFERROR(__xludf.DUMMYFUNCTION("""COMPUTED_VALUE"""),"User credentials") -> User credentials | H12: =IFERROR(__xludf.DUMMYFUNCTION("""COMPUTED_VALUE"""),"Achievements should be unlocked in ascending order.") -> Achievements should be unlocked in ascending order. | I12: =IFERROR(__xludf.DUMMYFUNCTION("""COMPUTED_VALUE"""),"7th achievement unlocked instead of the 6th") -> 7th achievement unlocked instead of the 6th | J12: =IFERROR(__xludf.DUMMYFUNCTION("""COMPUTED_VALUE"""),"Fail") -> Fail | K12: =IFERROR(__xludf.DUMMYFUNCTION("""COMPUTED_VALUE"""),"High") -> High | L12: =IFERROR(__xludf.DUMMYFUNCTION("""COMPUTED_VALUE"""),"011.png") -> 011.png | N12: =IFERROR(__xludf.DUMMYFUNCTION("""COMPUTED_VALUE"""),"Fahad") -> Fahad
A13: BR-003 | B13: =IFERROR(__xludf.DUMMYFUNCTION("""COMPUTED_VALUE"""),"Challenge") -> Challenge | C13: =IFERROR(__xludf.DUMMYFUNCTION("""COMPUTED_VALUE"""),"Challenge") -> Challenge | D13: =IFERROR(__xludf.DUMMYFUNCTION("""COMPUTED_VALUE"""),"Progress count issue") -> Progress count issue | E13: =IFERROR(__xludf.DUMMYFUNCTION("""COMPUTED_VALUE"""),"User need to download the app on their IOS device") -> User need to download the app on their IOS device | F13: =IFERROR(__xludf.DUMMYFUNCTION("""COMPUTED_VALUE"""),"1. Open app 2. Login using valid credentials 3. Goto challenges 4. Click on current challenge") -> 1. Open app 2. Login using valid credentials 3. Goto challenges 4. Click on current challenge | G13: =IFERROR(__xludf.DUMMYFUNCTION("""COMPUTED_VALUE"""),"User credentials") -> User credentials | H13: =IFERROR(__xludf.DUMMYFUNCTION("""COMPUTED_VALUE"""),"Progress calculations need to be precise.") -> Progress calculations need to be precise. | I13: =IFERROR(__xludf.DUMMYFUNCTION("""COMPUTED_VALUE"""),"Mismatch in progress calculation") -> Mismatch in progress calculation | J13: =IFERROR(__xludf.DUMMYFUNCTION("""COMPUTED_VALUE"""),"Fail") -> Fail | K13: =IFERROR(__xludf.DUMMYFUNCTION("""COMPUTED_VALUE"""),"High") -> High | L13: =IFERROR(__xludf.DUMMYFUNCTION("""COMPUTED_VALUE"""),"010.MP4") -> 010.MP4 | N13: =IFERROR(__xludf.DUMMYFUNCTION("""COMPUTED_VALUE"""),"Fahad") -> Fahad
A14: BR-004 | B14: =IFERROR(__xludf.DUMMYFUNCTION("""COMPUTED_VALUE"""),"Challenge") -> Challenge | C14: =IFERROR(__xludf.DUMMYFUNCTION("""COMPUTED_VALUE"""),"Challenge") -> Challenge | D14: =IFERROR(__xludf.DUMMYFUNCTION("""COMPUTED_VALUE"""),"The ""Continue Steps"" button isn’t working, making it nonfunctional.") -> The "Continue Steps" button isn’t working, making it nonfunctional. | E14: =IFERROR(__xludf.DUMMYFUNCTION("""COMPUTED_VALUE"""),"User need to download the app on their IOS device") -> User need to download the app on their IOS device | F14: =IFERROR(__xludf.DUMMYFUNCTION("""COMPUTED_VALUE"""),"1. Open app 2. Login using valid credentials 3. Goto challenges") -> 1. Open app 2. Login using valid credentials 3. Goto challenges | G14: =IFERROR(__xludf.DUMMYFUNCTION("""COMPUTED_VALUE"""),"User credentials") -> User credentials | H14: =IFERROR(__xludf.DUMMYFUNCTION("""COMPUTED_VALUE"""),"All buttons should work accurately.") -> All buttons should work accurately. | I14: =IFERROR(__xludf.DUMMYFUNCTION("""COMPUTED_VALUE"""),"button not working") -> button not working | J14: =IFERROR(__xludf.DUMMYFUNCTION("""COMPUTED_VALUE"""),"Fail") -> Fail | K14: =IFERROR(__xludf.DUMMYFUNCTION("""COMPUTED_VALUE"""),"High") -> High | L14: =IFERROR(__xludf.DUMMYFUNCTION("""COMPUTED_VALUE"""),"012.mov") -> 012.mov | N14: =IFERROR(__xludf.DUMMYFUNCTION("""COMPUTED_VALUE"""),"Fahad") -> Fahad
A15: BR-005 | B15: =IFERROR(__xludf.DUMMYFUNCTION("""COMPUTED_VALUE"""),"Challenge") -> Challenge | C15: =IFERROR(__xludf.DUMMYFUNCTION("""COMPUTED_VALUE"""),"Challenge") -> Challenge | D15: =IFERROR(__xludf.DUMMYFUNCTION("""COMPUTED_VALUE"""),"Miss calculations in challenges") -> Miss calculations in challenges | E15: =IFERROR(__xludf.DUMMYFUNCTION("""COMPUTED_VALUE"""),"User need to download the app on their IOS device") -> User need to download the app on their IOS device | F15: =IFERROR(__xludf.DUMMYFUNCTION("""COMPUTED_VALUE"""),"1. Open app 2. Login using valid credentials 3. Goto challenges") -> 1. Open app 2. Login using valid credentials 3. Goto challenges | G15: =IFERROR(__xludf.DUMMYFUNCTION("""COMPUTED_VALUE"""),"User credentials") -> User credentials | H15: =IFERROR(__xludf.DUMMYFUNCTION("""COMPUTED_VALUE"""),"All challenge data should function smoothly.") -> All challenge data should function smoothly. | I15: =IFERROR(__xludf.DUMMYFUNCTION("""COMPUTED_VALUE"""),"A data mismatch has been detected.") -> A data mismatch has been detected. | J15: =IFERROR(__xludf.DUMMYFUNCTION("""COMPUTED_VALUE"""),"Fail") -> Fail | K15: =IFERROR(__xludf.DUMMYFUNCTION("""COMPUTED_VALUE"""),"High") -> High | L15: =IFERROR(__xludf.DUMMYFUNCTION("""COMPUTED_VALUE"""),"013.MP4") -> 013.MP4 | N15: =IFERROR(__xludf.DUMMYFUNCTION("""COMPUTED_VALUE"""),"Fahad") -> Fahad
A16: BR-006 | B16: =IFERROR(__xludf.DUMMYFUNCTION("""COMPUTED_VALUE"""),"Challenge") -> Challenge | C16: =IFERROR(__xludf.DUMMYFUNCTION("""COMPUTED_VALUE"""),"Challenge") -> Challenge | D16: =IFERROR(__xludf.DUMMYFUNCTION("""COMPUTED_VALUE"""),"Failed to join public challenges") -> Failed to join public challenges | E16: =IFERROR(__xludf.DUMMYFUNCTION("""COMPUTED_VALUE"""),"User need to download the app on their IOS device") -> User need to download the app on their IOS device | F16: =IFERROR(__xludf.DUMMYFUNCTION("""COMPUTED_VALUE"""),"1. Open app 2. Login using valid credentials 3. Goto Public challenges") -> 1. Open app 2. Login using valid credentials 3. Goto Public challenges | G16: =IFERROR(__xludf.DUMMYFUNCTION("""COMPUTED_VALUE"""),"User credentials") -> User credentials | H16: =IFERROR(__xludf.DUMMYFUNCTION("""COMPUTED_VALUE"""),"Usere should be able to join public created challenges") -> Usere should be able to join public created challenges | I16: =IFERROR(__xludf.DUMMYFUNCTION("""COMPUTED_VALUE"""),"Failed to join in public created challenges") -> Failed to join in public created challenges | J16: =IFERROR(__xludf.DUMMYFUNCTION("""COMPUTED_VALUE"""),"Fail") -> Fail | K16: =IFERROR(__xludf.DUMMYFUNCTION("""COMPUTED_VALUE"""),"High") -> High | L16: =IFERROR(__xludf.DUMMYFUNCTION("""COMPUTED_VALUE"""),"016.png") -> 016.png | N16: =IFERROR(__xludf.DUMMYFUNCTION("""COMPUTED_VALUE"""),"Fahad") -> Fahad
A17: BR-007 | B17: =IFERROR(__xludf.DUMMYFUNCTION("""COMPUTED_VALUE"""),"Challenge") -> Challenge | C17: =IFERROR(__xludf.DUMMYFUNCTION("""COMPUTED_VALUE"""),"Challenge") -> Challenge | D17: =IFERROR(__xludf.DUMMYFUNCTION("""COMPUTED_VALUE"""),"The step count for the public challenge isn’t working as it should.") -> The step count for the public challenge isn’t working as it should. | E17: =IFERROR(__xludf.DUMMYFUNCTION("""COMPUTED_VALUE"""),"User need to download the app on their IOS device") -> User need to download the app on their IOS device | F17: =IFERROR(__xludf.DUMMYFUNCTION("""COMPUTED_VALUE"""),"1. Open app 2. Login using valid credentials 3. Goto Public challenges 4. Join in public challenges") -> 1. Open app 2. Login using valid credentials 3. Goto Public challenges 4. Join in public challenges | G17: =IFERROR(__xludf.DUMMYFUNCTION("""COMPUTED_VALUE"""),"User credentials") -> User credentials | H17: =IFERROR(__xludf.DUMMYFUNCTION("""COMPUTED_VALUE"""),"Steps should be counted accurately in public challenges.") -> Steps should be counted accurately in public challenges. | I17: =IFERROR(__xludf.DUMMYFUNCTION("""COMPUTED_VALUE"""),"Facing calculation error and steps are not counting in public challenges") -> Facing calculation error and steps are not counting in public challenges | J17: =IFERROR(__xludf.DUMMYFUNCTION("""COMPUTED_VALUE"""),"Fail") -> Fail | K17: =IFERROR(__xludf.DUMMYFUNCTION("""COMPUTED_VALUE"""),"High") -> High | L17: =IFERROR(__xludf.DUMMYFUNCTION("""COMPUTED_VALUE"""),"020.png") -> 020.png | N17: =IFERROR(__xludf.DUMMYFUNCTION("""COMPUTED_VALUE"""),"Fahad") -> Fahad
A18: BR-008 | B18: =IFERROR(__xludf.DUMMYFUNCTION("""COMPUTED_VALUE"""),"Challenge") -> Challenge | C18: =IFERROR(__xludf.DUMMYFUNCTION("""COMPUTED_VALUE"""),"Challenge") -> Challenge | D18: =IFERROR(__xludf.DUMMYFUNCTION("""COMPUTED_VALUE"""),"Missmatch calculation in created challenges") -> Missmatch calculation in created challenges | E18: =IFERROR(__xludf.DUMMYFUNCTION("""COMPUTED_VALUE"""),"User need to download the app on their IOS device") -> User need to download the app on their IOS device | F18: =IFERROR(__xludf.DUMMYFUNCTION("""COMPUTED_VALUE"""),"1. Open app 2. Login using valid credentials 3. Goto Public challenges 4. Join in public challenges") -> 1. Open app 2. Login using valid credentials 3. Goto Public challenges 4. Join in public challenges | G18: =IFERROR(__xludf.DUMMYFUNCTION("""COMPUTED_VALUE"""),"User credentials") -> User credentials | H18: =IFERROR(__xludf.DUMMYFUNCTION("""COMPUTED_VALUE"""),"Calclations should be accurate ") -> Calclations should be accurate | I18: =IFERROR(__xludf.DUMMYFUNCTION("""COMPUTED_VALUE"""),"Miss calculation has been noticed") -> Miss calculation has been noticed | J18: =IFERROR(__xludf.DUMMYFUNCTION("""COMPUTED_VALUE"""),"Fail") -> Fail | K18: =IFERROR(__xludf.DUMMYFUNCTION("""COMPUTED_VALUE"""),"High") -> High | L18: =IFERROR(__xludf.DUMMYFUNCTION("""COMPUTED_VALUE"""),"021.png") -> 021.png | N18: =IFERROR(__xludf.DUMMYFUNCTION("""COMPUTED_VALUE"""),"Fahad") -> Fahad
A19: BR-009 | B19: =IFERROR(__xludf.DUMMYFUNCTION("""COMPUTED_VALUE"""),"Challenge") -> Challenge | C19: =IFERROR(__xludf.DUMMYFUNCTION("""COMPUTED_VALUE"""),"Challenge") -> Challenge | D19: =IFERROR(__xludf.DUMMYFUNCTION("""COMPUTED_VALUE"""),"The challenge lasts for two timelines, one measured in weeks and the other in days.") -> The challenge lasts for two timelines, one measured in weeks and the other in days. | E19: =IFERROR(__xludf.DUMMYFUNCTION("""COMPUTED_VALUE"""),"User need to download the app on their IOS device") -> User need to download the app on their IOS device | F19: =IFERROR(__xludf.DUMMYFUNCTION("""COMPUTED_VALUE"""),"1. Open app 2. Login using valid credentials 3. Goto Public challenges 4. Join in public challenges") -> 1. Open app 2. Login using valid credentials 3. Goto Public challenges 4. Join in public challenges | G19: =IFERROR(__xludf.DUMMYFUNCTION("""COMPUTED_VALUE"""),"User credentials") -> User credentials | H19: =IFERROR(__xludf.DUMMYFUNCTION("""COMPUTED_VALUE"""),"It should only take one time") -> It should only take one time | I19: =IFERROR(__xludf.DUMMYFUNCTION("""COMPUTED_VALUE"""),"It takes two time inputs, one in weeks and the other with a start and end date, which makes it a bit confusing.") -> It takes two time inputs, one in weeks and the other with a start and end date, which makes it a bit confusing. | J19: =IFERROR(__xludf.DUMMYFUNCTION("""COMPUTED_VALUE"""),"Fail") -> Fail | K19: =IFERROR(__xludf.DUMMYFUNCTION("""COMPUTED_VALUE"""),"Medium") -> Medium | L19: =IFERROR(__xludf.DUMMYFUNCTION("""COMPUTED_VALUE"""),"024.png") -> 024.png | N19: =IFERROR(__xludf.DUMMYFUNCTION("""COMPUTED_VALUE"""),"Fahad") -> Fahad
A20: BR-010 | B20: =IFERROR(__xludf.DUMMYFUNCTION("""COMPUTED_VALUE"""),"Daily Task") -> Daily Task | C20: =IFERROR(__xludf.DUMMYFUNCTION("""COMPUTED_VALUE"""),"Daily Task") -> Daily Task | D20: =IFERROR(__xludf.DUMMYFUNCTION("""COMPUTED_VALUE"""),"Multiple task completion screen appeared after the user finished their daily task.") -> Multiple task completion screen appeared after the user finished their daily task. | E20: =IFERROR(__xludf.DUMMYFUNCTION("""COMPUTED_VALUE"""),"User need to download the app on their IOS device") -> User need to download the app on their IOS device | F20: =IFERROR(__xludf.DUMMYFUNCTION("""COMPUTED_VALUE"""),"1. Open app 2. Signup using valid credentials 3. Complete daily task") -> 1. Open app 2. Signup using valid credentials 3. Complete daily task | G20: =IFERROR(__xludf.DUMMYFUNCTION("""COMPUTED_VALUE"""),"User credentials") -> User credentials | H20: =IFERROR(__xludf.DUMMYFUNCTION("""COMPUTED_VALUE"""),"After completing daily task, completion screen should appear only one time ") -> After completing daily task, completion screen should appear only one time | I20: =IFERROR(__xludf.DUMMYFUNCTION("""COMPUTED_VALUE"""),"Multiple completion screen has been seen in app") -> Multiple completion screen has been seen in app | J20: =IFERROR(__xludf.DUMMYFUNCTION("""COMPUTED_VALUE"""),"Fail") -> Fail | K20: =IFERROR(__xludf.DUMMYFUNCTION("""COMPUTED_VALUE"""),"Medium") -> Medium | L20: =IFERROR(__xludf.DUMMYFUNCTION("""COMPUTED_VALUE"""),"025.MP4") -> 025.MP4 | N20: =IFERROR(__xludf.DUMMYFUNCTION("""COMPUTED_VALUE"""),"Fahad") -> Fahad
A21: BR-011 | B21: =IFERROR(__xludf.DUMMYFUNCTION("""COMPUTED_VALUE"""),"Delete Account") -> Delete Account | C21: =IFERROR(__xludf.DUMMYFUNCTION("""COMPUTED_VALUE"""),"Delete Account") -> Delete Account | D21: =IFERROR(__xludf.DUMMYFUNCTION("""COMPUTED_VALUE"""),"Failed to redirect to the signup page after deleting the account.") -> Failed to redirect to the signup page after deleting the account. | E21: =IFERROR(__xludf.DUMMYFUNCTION("""COMPUTED_VALUE"""),"User need to download the app on their IOS device") -> User need to download the app on their IOS device | F21: =IFERROR(__xludf.DUMMYFUNCTION("""COMPUTED_VALUE"""),"1. Open app 2. Login using valid credentials 3. Goto Settings 4. Click on delete account") -> 1. Open app 2. Login using valid credentials 3. Goto Settings 4. Click on delete account | G21: =IFERROR(__xludf.DUMMYFUNCTION("""COMPUTED_VALUE"""),"User credentials") -> User credentials | H21: =IFERROR(__xludf.DUMMYFUNCTION("""COMPUTED_VALUE"""),"After deleting an account, the user should be redirected to the signup page.") -> After deleting an account, the user should be redirected to the signup page. | I21: =IFERROR(__xludf.DUMMYFUNCTION("""COMPUTED_VALUE"""),"Unable to redirect the user to the signup page.") -> Unable to redirect the user to the signup page. | J21: =IFERROR(__xludf.DUMMYFUNCTION("""COMPUTED_VALUE"""),"Fail") -> Fail | K21: =IFERROR(__xludf.DUMMYFUNCTION("""COMPUTED_VALUE"""),"High") -> High | L21: =IFERROR(__xludf.DUMMYFUNCTION("""COMPUTED_VALUE"""),"022.MP4") -> 022.MP4 | N21: =IFERROR(__xludf.DUMMYFUNCTION("""COMPUTED_VALUE"""),"Fahad") -> Fahad
A22: BR-012 | B22: =IFERROR(__xludf.DUMMYFUNCTION("""COMPUTED_VALUE"""),"Forget Password") -> Forget Password | C22: =IFERROR(__xludf.DUMMYFUNCTION("""COMPUTED_VALUE"""),"Forget Password") -> Forget Password | D22: =IFERROR(__xludf.DUMMYFUNCTION("""COMPUTED_VALUE"""),"User is able to reset password for deleted account") -> User is able to reset password for deleted account | E22: =IFERROR(__xludf.DUMMYFUNCTION("""COMPUTED_VALUE"""),"User need to download the app on their IOS device") -> User need to download the app on their IOS device | F22: =IFERROR(__xludf.DUMMYFUNCTION("""COMPUTED_VALUE"""),"1. Open app 2. Goto login page 3. Click on forget password") -> 1. Open app 2. Goto login page 3. Click on forget password | G22: =IFERROR(__xludf.DUMMYFUNCTION("""COMPUTED_VALUE"""),"User credentials") -> User credentials | H22: =IFERROR(__xludf.DUMMYFUNCTION("""COMPUTED_VALUE"""),"Only registered email should receive OTP ") -> Only registered email should receive OTP | I22: =IFERROR(__xludf.DUMMYFUNCTION("""COMPUTED_VALUE"""),"Normal mail also can receive OTP") -> Normal mail also can receive OTP | J22: =IFERROR(__xludf.DUMMYFUNCTION("""COMPUTED_VALUE"""),"Fail") -> Fail | K22: =IFERROR(__xludf.DUMMYFUNCTION("""COMPUTED_VALUE"""),"High") -> High | L22: =IFERROR(__xludf.DUMMYFUNCTION("""COMPUTED_VALUE"""),"023.mov") -> 023.mov | N22: =IFERROR(__xludf.DUMMYFUNCTION("""COMPUTED_VALUE"""),"Fahad") -> Fahad
A23: BR-013 | B23: =IFERROR(__xludf.DUMMYFUNCTION("""COMPUTED_VALUE"""),"Help & Support") -> Help & Support | C23: =IFERROR(__xludf.DUMMYFUNCTION("""COMPUTED_VALUE"""),"Contact Support") -> Contact Support | D23: =IFERROR(__xludf.DUMMYFUNCTION("""COMPUTED_VALUE"""),"The social media and website links aren’t integrated.") -> The social media and website links aren’t integrated. | E23: =IFERROR(__xludf.DUMMYFUNCTION("""COMPUTED_VALUE"""),"User need to download the app on their IOS device") -> User need to download the app on their IOS device | F23: =IFERROR(__xludf.DUMMYFUNCTION("""COMPUTED_VALUE"""),"1. Open app 2. Login using valid credentials 3. Goto Help & Support 4. Click on contact support") -> 1. Open app 2. Login using valid credentials 3. Goto Help & Support 4. Click on contact support | G23: =IFERROR(__xludf.DUMMYFUNCTION("""COMPUTED_VALUE"""),"User credentials") -> User credentials | H23: =IFERROR(__xludf.DUMMYFUNCTION("""COMPUTED_VALUE"""),"Social media accounts and the website should be properly connected to ensure authenticity.") -> Social media accounts and the website should be properly connected to ensure authenticity. | I23: =IFERROR(__xludf.DUMMYFUNCTION("""COMPUTED_VALUE"""),"Missing social media and website links") -> Missing social media and website links | J23: =IFERROR(__xludf.DUMMYFUNCTION("""COMPUTED_VALUE"""),"Fail") -> Fail | K23: =IFERROR(__xludf.DUMMYFUNCTION("""COMPUTED_VALUE"""),"Medium") -> Medium | L23: =IFERROR(__xludf.DUMMYFUNCTION("""COMPUTED_VALUE"""),"017.png") -> 017.png | N23: =IFERROR(__xludf.DUMMYFUNCTION("""COMPUTED_VALUE"""),"Fahad") -> Fahad
