Workbook

Sheet Main Report
A2: Tester : | B2: Mohammed Fahad Faisal Tahsin Ahmmed | D2: Severity | E2: Issues
A3: Project Name: | B3: VALR | D3: High | E3: =COUNTIF(Tahsin!K14:K1005, "High") + COUNTIF(Fahad!K9:K1005, "High") -> 20
A4: Project URL: | D4: Medium | E4: =COUNTIF(Tahsin!K14:K1006, "Medium") + COUNTIF(Fahad!K9:K1006, "Medium") -> 12
A5: Developer: | B5: AI-Hunter | D5: Low | E5: =COUNTIF(Fahad!K9:K1007, "Low") + COUNTIF(Tahsin!K14:K1009, "Low") -> 5
A6: OS:
A7: Environment | D7: Total Test Cases: | E7: =SUM(E3:E5) -> 37
D8: Test Case Solved : | E8: =COUNTIF(O11:O1003, "Solved") -> 21
A10: Test Case ID | B10: Module | C10: Sub Module | D10: Test Case Description | E10: Preconditions | F10: Test Steps | G10: Test Data | H10: Expected Result | I10: Actual Result | J10: Status | K10: Severity | L10: Screen Shots | M10: Suggestion | N10: Tester | O10: Feedback | P10: Comment
A11: {=IF((LEN(B11:B100)+LEN(C11:C100))>0, "BR-" & TEXT(ROW(B11:B100)-ROW(B11)+1,"000"), "")} -> BR-001 | B11: =IFERROR(__xludf.DUMMYFUNCTION("QUERY( { ARRAYFORMULA({TRIM(Fahad!B9:B999), Fahad!C9:M999, IF(LEN(Fahad!B9:B999), ""Fahad"", """")}); ARRAYFORMULA({TRIM(Tahsin!B15:B999), Tahsin!C15:M999, IF(LEN(Tahsin!B15:B999), ""Tahsin"", """")}) }, ""SELECT * WHERE Col1 IS NOT NULL ORD"&"ER BY Col1 ASC, Col2 ASC"", 0 ) "),"Claim") -> Claim | C11: =IFERROR(__xludf.DUMMYFUNCTION("""COMPUTED_VALUE"""),"Accessibility (Screen Reader)") -> Accessibility (Screen Reader) | D11: =IFERROR(__xludf.DUMMYFUNCTION("""COMPUTED_VALUE"""),"Verify Screen Reader stops reading when the user navigates back from the 'Claim' flow.") -> Verify Screen Reader stops reading when the user navigates back from the 'Claim' flow. | E11: =IFERROR(__xludf.DUMMYFUNCTION("""COMPUTED_VALUE"""),"User is logged in to the Valr application.") -> User is logged in to the Valr application. | F11: =IFERROR(__xludf.DUMMYFUNCTION("""COMPUTED_VALUE"""),"1) Tap the 'Claim' button to initiate the flow. 2) While the screen reader is actively speaking, tap the **Back** button (device or in-app).") -> 1) Tap the 'Claim' button to initiate the flow. 2) While the screen reader is actively speaking, tap the **Back** button (device or in-app). | G11: =IFERROR(__xludf.DUMMYFUNCTION("""COMPUTED_VALUE"""),"N/A (Functional Test)") -> N/A (Functional Test) | H11: =IFERROR(__xludf.DUMMYFUNCTION("""COMPUTED_VALUE"""),"The screen reader/TalkBack readout **must stop immediately** upon navigating away from the 'Claim' screen.") -> The screen reader/TalkBack readout **must stop immediately** upon navigating away from the 'Claim' screen. | I11: =IFERROR(__xludf.DUMMYFUNCTION("""COMPUTED_VALUE"""),"The screen reader continues to read the entire question/text until the portion is ended, even after navigating back.") -> The screen reader continues to read the entire question/text until the portion is ended, even after navigating back. | J11: =IFERROR(__xludf.DUMMYFUNCTION("""COMPUTED_VALUE"""),"Fail") -> Fail | K11: =IFERROR(__xludf.DUMMYFUNCTION("""COMPUTED_VALUE"""),"High") -> High | L11: =IFERROR(__xludf.DUMMYFUNCTION("""COMPUTED_VALUE"""),"Sound .mp4") -> Sound .mp4 | N11: =IFERROR(__xludf.DUMMYFUNCTION("""COMPUTED_VALUE"""),"Tahsin") -> Tahsin
A12: BR-002 | B12: =IFERROR(__xludf.DUMMYFUNCTION("""COMPUTED_VALUE"""),"Claim Form") -> Claim Form | C12: =IFERROR(__xludf.DUMMYFUNCTION("""COMPUTED_VALUE"""),"Claim Form") -> Claim Form | D12: =IFERROR(__xludf.DUMMYFUNCTION("""COMPUTED_VALUE"""),"Darft is not functioning properly") -> Darft is not functioning properly | E12: =IFERROR(__xludf.DUMMYFUNCTION("""COMPUTED_VALUE"""),"User need to install the apk in their phone") -> User need to install the apk in their phone | F12: =IFERROR(__xludf.DUMMYFUNCTION("""COMPUTED_VALUE"""),"1. Open app 2. Signin using valid credentials 3. Subscribe and click on claim 4. Fill form with necessary information") -> 1. Open app 2. Signin using valid credentials 3. Subscribe and click on claim 4. Fill form with necessary information | G12: =IFERROR(__xludf.DUMMYFUNCTION("""COMPUTED_VALUE"""),"email : misak59277@foxroids.com pass : 123456abcde") -> email : misak59277@foxroids.com pass : 123456abcde | H12: =IFERROR(__xludf.DUMMYFUNCTION("""COMPUTED_VALUE"""),"The draft system should be implemented in its complete form.") -> The draft system should be implemented in its complete form. | I12: =IFERROR(__xludf.DUMMYFUNCTION("""COMPUTED_VALUE"""),"Only the data from the first 7 pages can be saved as a draft, while the remaining data is not stored correctly.") -> Only the data from the first 7 pages can be saved as a draft, while the remaining data is not stored correctly. | J12: =IFERROR(__xludf.DUMMYFUNCTION("""COMPUTED_VALUE"""),"Fail") -> Fail | K12: =IFERROR(__xludf.DUMMYFUNCTION("""COMPUTED_VALUE"""),"High") -> High | L12: =IFERROR(__xludf.DUMMYFUNCTION("""COMPUTED_VALUE"""),"https://drive.google.com/file/d/1hfjRYWtx56grOZvxa7Mk-osFuIBctrwV/view?usp=drive_link") -> https://drive.google.com/file/d/1hfjRYWtx56grOZvxa7Mk-osFuIBctrwV/view?usp=drive_link | N12: =IFERROR(__xludf.DUMMYFUNCTION("""COMPUTED_VALUE"""),"Fahad") -> Fahad | O12: Solved
A13: BR-003 | B13: =IFERROR(__xludf.DUMMYFUNCTION("""COMPUTED_VALUE"""),"Claim Now") -> Claim Now | C13: =IFERROR(__xludf.DUMMYFUNCTION("""COMPUTED_VALUE"""),"First Page") -> First Page | D13: =IFERROR(__xludf.DUMMYFUNCTION("""COMPUTED_VALUE"""),"Validate that the Back button functions correctly on “Have you ever applied for VA benefits” page") -> Validate that the Back button functions correctly on “Have you ever applied for VA benefits” page | E13: =IFERROR(__xludf.DUMMYFUNCTION("""COMPUTED_VALUE"""),"Paid user is logged in and on the “Have you ever applied for VA benefits” page under Claim Now section") -> Paid user is logged in and on the “Have you ever applied for VA benefits” page under Claim Now section | F13: =IFERROR(__xludf.DUMMYFUNCTION("""COMPUTED_VALUE"""),"1) Open the app 2) Log in as a paid user 3) Navigate to Claim Now section 4) Proceed to “Have you ever applied for VA benefits” page 5) Tap on the Back button") -> 1) Open the app 2) Log in as a paid user 3) Navigate to Claim Now section 4) Proceed to “Have you ever applied for VA benefits” page 5) Tap on the Back button | G13: =IFERROR(__xludf.DUMMYFUNCTION("""COMPUTED_VALUE"""),"N/A") -> N/A | H13: =IFERROR(__xludf.DUMMYFUNCTION("""COMPUTED_VALUE"""),"User should be navigated to the previous page when tapping the Back button") -> User should be navigated to the previous page when tapping the Back button | I13: =IFERROR(__xludf.DUMMYFUNCTION("""COMPUTED_VALUE"""),"Back button is unresponsive and does not navigate to the previous page") -> Back button is unresponsive and does not navigate to the previous page | J13: =IFERROR(__xludf.DUMMYFUNCTION("""COMPUTED_VALUE"""),"Fail") -> Fail | K13: =IFERROR(__xludf.DUMMYFUNCTION("""COMPUTED_VALUE"""),"High") -> High | L13: =IFERROR(__xludf.DUMMYFUNCTION("""COMPUTED_VALUE"""),"Claim Now Back Button.mp4") -> Claim Now Back Button.mp4 | N13: =IFERROR(__xludf.DUMMYFUNCTION("""COMPUTED_VALUE"""),"Tahsin") -> Tahsin | O13: Solved
A14: BR-004 | B14: =IFERROR(__xludf.DUMMYFUNCTION("""COMPUTED_VALUE"""),"Claim/Narrative") -> Claim/Narrative | C14: =IFERROR(__xludf.DUMMYFUNCTION("""COMPUTED_VALUE"""),"Session Management") -> Session Management | D14: =IFERROR(__xludf.DUMMYFUNCTION("""COMPUTED_VALUE"""),"Verify that generated narratives and intermediate claim data are saved and persist across application restarts.") -> Verify that generated narratives and intermediate claim data are saved and persist across application restarts. | E14: =IFERROR(__xludf.DUMMYFUNCTION("""COMPUTED_VALUE"""),"A narrative has been successfully generated and then Reopen the Apps") -> A narrative has been successfully generated and then Reopen the Apps | F14: =IFERROR(__xludf.DUMMYFUNCTION("""COMPUTED_VALUE"""),"1. Complete the claim process, ending with the Narrative Generation screen. 2. Close the Valr application. 3. Re-open the Valr application. 4. Navigate back to the 'Claim' section/flow.") -> 1. Complete the claim process, ending with the Narrative Generation screen. 2. Close the Valr application. 3. Re-open the Valr application. 4. Navigate back to the 'Claim' section/flow. | G14: =IFERROR(__xludf.DUMMYFUNCTION("""COMPUTED_VALUE"""),"N/A (Data Persistence Test)") -> N/A (Data Persistence Test) | H14: =IFERROR(__xludf.DUMMYFUNCTION("""COMPUTED_VALUE"""),"The application should resume the claim process from the point where the narrative was generated, or the generated narrative should be viewable in a 'Drafts' or 'History' section. **All previously entered information must be retained.**") -> The application should resume the claim process from the point where the narrative was generated, or the generated narrative should be viewable in a 'Drafts' or 'History' section. **All previously entered information must be retained.** | I14: =IFERROR(__xludf.DUMMYFUNCTION("""COMPUTED_VALUE"""),"Upon re-opening the application and navigating back to the Claim section, the process starts from the beginning, and all previously entered information and the generated narrative are lost.") -> Upon re-opening the application and navigating back to the Claim section, the process starts from the beginning, and all previously entered information and the generated narrative are lost. | J14: =IFERROR(__xludf.DUMMYFUNCTION("""COMPUTED_VALUE"""),"Fail") -> Fail | K14: =IFERROR(__xludf.DUMMYFUNCTION("""COMPUTED_VALUE"""),"High") -> High | N14: =IFERROR(__xludf.DUMMYFUNCTION("""COMPUTED_VALUE"""),"Tahsin") -> Tahsin | O14: Solved
A15: BR-005 | B15: =IFERROR(__xludf.DUMMYFUNCTION("""COMPUTED_VALUE"""),"Contact us") -> Contact us | C15: =IFERROR(__xludf.DUMMYFUNCTION("""COMPUTED_VALUE"""),"Support") -> Support | D15: =IFERROR(__xludf.DUMMYFUNCTION("""COMPUTED_VALUE"""),"Missing back button in the contact us page") -> Missing back button in the contact us page | E15: =IFERROR(__xludf.DUMMYFUNCTION("""COMPUTED_VALUE"""),"User need to install the apk in their phone") -> User need to install the apk in their phone | F15: =IFERROR(__xludf.DUMMYFUNCTION("""COMPUTED_VALUE"""),"1. Open app 2. Goto settings 3. Click on contact us") -> 1. Open app 2. Goto settings 3. Click on contact us | G15: =IFERROR(__xludf.DUMMYFUNCTION("""COMPUTED_VALUE"""),"email: deleri6454@haotuwu.com pass: 12345Abcdef@") -> email: deleri6454@haotuwu.com pass: 12345Abcdef@ | H15: =IFERROR(__xludf.DUMMYFUNCTION("""COMPUTED_VALUE"""),"After getting support, user should be able to use back button to go previous page or home page") -> After getting support, user should be able to use back button to go previous page or home page | I15: =IFERROR(__xludf.DUMMYFUNCTION("""COMPUTED_VALUE"""),"Failed to back due to missing back button") -> Failed to back due to missing back button | J15: =IFERROR(__xludf.DUMMYFUNCTION("""COMPUTED_VALUE"""),"Fail") -> Fail | K15: =IFERROR(__xludf.DUMMYFUNCTION("""COMPUTED_VALUE"""),"Low") -> Low | L15: =IFERROR(__xludf.DUMMYFUNCTION("""COMPUTED_VALUE"""),"https://drive.google.com/file/d/105rCPxfDdEAZ02Qnw84gjSIzklP4lRzM/view?usp=drive_link") -> https://drive.google.com/file/d/105rCPxfDdEAZ02Qnw84gjSIzklP4lRzM/view?usp=drive_link | N15: =IFERROR(__xludf.DUMMYFUNCTION("""COMPUTED_VALUE"""),"Fahad") -> Fahad | O15: Solved
A16: BR-006 | B16: =IFERROR(__xludf.DUMMYFUNCTION("""COMPUTED_VALUE"""),"Forget Password") -> Forget Password | C16: =IFERROR(__xludf.DUMMYFUNCTION("""COMPUTED_VALUE"""),"Forget Password") -> Forget Password | D16: =IFERROR(__xludf.DUMMYFUNCTION("""COMPUTED_VALUE"""),"OTP page failed to load") -> OTP page failed to load | E16: =IFERROR(__xludf.DUMMYFUNCTION("""COMPUTED_VALUE"""),"User need to install the apk in their phone") -> User need to install the apk in their phone | F16: =IFERROR(__xludf.DUMMYFUNCTION("""COMPUTED_VALUE"""),"1. Open app 2. Click on SignIn 3. Click on Forget Password") -> 1. Open app 2. Click on SignIn 3. Click on Forget Password | G16: =IFERROR(__xludf.DUMMYFUNCTION("""COMPUTED_VALUE"""),"email : misak59277@foxroids.com pass : 123456abcdef") -> email : misak59277@foxroids.com pass : 123456abcdef | H16: =IFERROR(__xludf.DUMMYFUNCTION("""COMPUTED_VALUE"""),"User should be able to navigate to the OTP page after entering their email and then click on ""Send"".") -> User should be able to navigate to the OTP page after entering their email and then click on "Send". | I16: =IFERROR(__xludf.DUMMYFUNCTION("""COMPUTED_VALUE"""),"Failed to load the OTP page, but the OTP was sent to the registered email.") -> Failed to load the OTP page, but the OTP was sent to the registered email. | J16: =IFERROR(__xludf.DUMMYFUNCTION("""COMPUTED_VALUE"""),"Fail") -> Fail | K16: =IFERROR(__xludf.DUMMYFUNCTION("""COMPUTED_VALUE"""),"High") -> High | L16: =IFERROR(__xludf.DUMMYFUNCTION("""COMPUTED_VALUE"""),"https://drive.google.com/file/d/1VESCJdD9F7mHvgbacoa6uvf8QUV8dCcm/view?usp=drive_link") -> https://drive.google.com/file/d/1VESCJdD9F7mHvgbacoa6uvf8QUV8dCcm/view?usp=drive_link | N16: =IFERROR(__xludf.DUMMYFUNCTION("""COMPUTED_VALUE"""),"Fahad") -> Fahad | O16: Solved
A17: BR-007 | B17: =IFERROR(__xludf.DUMMYFUNCTION("""COMPUTED_VALUE"""),"Generated PDF") -> Generated PDF | C17: =IFERROR(__xludf.DUMMYFUNCTION("""COMPUTED_VALUE"""),"Generated PDF") -> Generated PDF | D17: =IFERROR(__xludf.DUMMYFUNCTION("""COMPUTED_VALUE"""),"Unable to display the submitted date.") -> Unable to display the submitted date. | E17: =IFERROR(__xludf.DUMMYFUNCTION("""COMPUTED_VALUE"""),"User need to install the apk in their phone") -> User need to install the apk in their phone | F17: =IFERROR(__xludf.DUMMYFUNCTION("""COMPUTED_VALUE"""),"1. Open app 2. Purchase subscription 3. Click on Claim now 4. Fillup form") -> 1. Open app 2. Purchase subscription 3. Click on Claim now 4. Fillup form | G17: =IFERROR(__xludf.DUMMYFUNCTION("""COMPUTED_VALUE"""),"email: deleri6454@haotuwu.com pass: 12345Abcdef@") -> email: deleri6454@haotuwu.com pass: 12345Abcdef@ | H17: =IFERROR(__xludf.DUMMYFUNCTION("""COMPUTED_VALUE"""),"The submission data should appear in the form after it is generated.") -> The submission data should appear in the form after it is generated. | I17: =IFERROR(__xludf.DUMMYFUNCTION("""COMPUTED_VALUE"""),"The generated PDF date is missing in the submission form.") -> The generated PDF date is missing in the submission form. | J17: =IFERROR(__xludf.DUMMYFUNCTION("""COMPUTED_VALUE"""),"Fail") -> Fail | K17: =IFERROR(__xludf.DUMMYFUNCTION("""COMPUTED_VALUE"""),"Medium") -> Medium | L17: =IFERROR(__xludf.DUMMYFUNCTION("""COMPUTED_VALUE"""),"https://drive.google.com/file/d/10Em3R92lXlh1lD6g-j9jvDq9BroejUmg/view?usp=drive_link") -> https://drive.google.com/file/d/10Em3R92lXlh1lD6g-j9jvDq9BroejUmg/view?usp=drive_link | N17: =IFERROR(__xludf.DUMMYFUNCTION("""COMPUTED_VALUE"""),"Fahad") -> Fahad | O17: Solved
A18: BR-008 | B18: =IFERROR(__xludf.DUMMYFUNCTION("""COMPUTED_VALUE"""),"Home Page") -> Home Page | C18: =IFERROR(__xludf.DUMMYFUNCTION("""COMPUTED_VALUE"""),"FAQ Section") -> FAQ Section | D18: =IFERROR(__xludf.DUMMYFUNCTION("""COMPUTED_VALUE"""),"Validate that FAQ section is displayed on the Home page") -> Validate that FAQ section is displayed on the Home page | E18: =IFERROR(__xludf.DUMMYFUNCTION("""COMPUTED_VALUE"""),"User is on Home screen with app successfully loaded") -> User is on Home screen with app successfully loaded | F18: =IFERROR(__xludf.DUMMYFUNCTION("""COMPUTED_VALUE"""),"1) Open the app 2) Navigate to Home page 3) Scroll through the page and look for the FAQ section") -> 1) Open the app 2) Navigate to Home page 3) Scroll through the page and look for the FAQ section | G18: =IFERROR(__xludf.DUMMYFUNCTION("""COMPUTED_VALUE"""),"N/A") -> N/A | H18: =IFERROR(__xludf.DUMMYFUNCTION("""COMPUTED_VALUE"""),"FAQ section should be visible and accessible from the Home page") -> FAQ section should be visible and accessible from the Home page | I18: =IFERROR(__xludf.DUMMYFUNCTION("""COMPUTED_VALUE"""),"The FAQ section is missing from the Home page") -> The FAQ section is missing from the Home page | J18: =IFERROR(__xludf.DUMMYFUNCTION("""COMPUTED_VALUE"""),"Fail") -> Fail | K18: =IFERROR(__xludf.DUMMYFUNCTION("""COMPUTED_VALUE"""),"Medium") -> Medium | N18: =IFERROR(__xludf.DUMMYFUNCTION("""COMPUTED_VALUE"""),"Tahsin") -> Tahsin | O18: Solved
A19: BR-009 | B19: =IFERROR(__xludf.DUMMYFUNCTION("""COMPUTED_VALUE"""),"Home Page") -> Home Page | C19: =IFERROR(__xludf.DUMMYFUNCTION("""COMPUTED_VALUE"""),"Menu Button") -> Menu Button | D19: =IFERROR(__xludf.DUMMYFUNCTION("""COMPUTED_VALUE"""),"Validate that menu button labels are fully visible in 3-button navigation mode") -> Validate that menu button labels are fully visible in 3-button navigation mode | E19: =IFERROR(__xludf.DUMMYFUNCTION("""COMPUTED_VALUE"""),"User is on Home screen with device set to 3-button navigation mode") -> User is on Home screen with device set to 3-button navigation mode | F19: =IFERROR(__xludf.DUMMYFUNCTION("""COMPUTED_VALUE"""),"1) Open the app 2) Ensure system navigation mode is set to 3-button navigation 3) Observe menu button labels at the bottom of the home screen") -> 1) Open the app 2) Ensure system navigation mode is set to 3-button navigation 3) Observe menu button labels at the bottom of the home screen | G19: =IFERROR(__xludf.DUMMYFUNCTION("""COMPUTED_VALUE"""),"N/A") -> N/A | H19: =IFERROR(__xludf.DUMMYFUNCTION("""COMPUTED_VALUE"""),"Menu button labels should be fully visible and not cut off regardless of navigation mode") -> Menu button labels should be fully visible and not cut off regardless of navigation mode | I19: =IFERROR(__xludf.DUMMYFUNCTION("""COMPUTED_VALUE"""),"Menu button labels appear cut off or partially hidden in 3-button navigation mode") -> Menu button labels appear cut off or partially hidden in 3-button navigation mode | J19: =IFERROR(__xludf.DUMMYFUNCTION("""COMPUTED_VALUE"""),"Fail") -> Fail | K19: =IFERROR(__xludf.DUMMYFUNCTION("""COMPUTED_VALUE"""),"Medium") -> Medium | L19: =IFERROR(__xludf.DUMMYFUNCTION("""COMPUTED_VALUE"""),"https://jam.dev/c/2a594fde-28d0-4558-b2f6-62229c282228") -> https://jam.dev/c/2a594fde-28d0-4558-b2f6-62229c282228 | N19: =IFERROR(__xludf.DUMMYFUNCTION("""COMPUTED_VALUE"""),"Tahsin") -> Tahsin | O19: Solved | P19: This is not an AI ChatBot
A20: BR-010 | B20: =IFERROR(__xludf.DUMMYFUNCTION("""COMPUTED_VALUE"""),"Login") -> Login | C20: =IFERROR(__xludf.DUMMYFUNCTION("""COMPUTED_VALUE"""),"Login") -> Login | D20: =IFERROR(__xludf.DUMMYFUNCTION("""COMPUTED_VALUE"""),"Failed to login") -> Failed to login | E20: =IFERROR(__xludf.DUMMYFUNCTION("""COMPUTED_VALUE"""),"User need to install the apk in their phone") -> User need to install the apk in their phone | F20: =IFERROR(__xludf.DUMMYFUNCTION("""COMPUTED_VALUE"""),"1. Open app 2. Click on SignIn") -> 1. Open app 2. Click on SignIn | G20: =IFERROR(__xludf.DUMMYFUNCTION("""COMPUTED_VALUE"""),"email : misak59277@foxroids.com pass : 123456abcdef") -> email : misak59277@foxroids.com pass : 123456abcdef | H20: =IFERROR(__xludf.DUMMYFUNCTION("""COMPUTED_VALUE"""),"User can login to app without any issue") -> User can login to app without any issue | I20: =IFERROR(__xludf.DUMMYFUNCTION("""COMPUTED_VALUE"""),"Failed to login by valid credentials") -> Failed to login by valid credentials | J20: =IFERROR(__xludf.DUMMYFUNCTION("""COMPUTED_VALUE"""),"Fail") -> Fail | K20: =IFERROR(__xludf.DUMMYFUNCTION("""COMPUTED_VALUE"""),"High") -> High | L20: =IFERROR(__xludf.DUMMYFUNCTION("""COMPUTED_VALUE"""),"https://drive.google.com/file/d/1Ci9kFRKVy5VBTVboR0fy0ArvSwheuSvr/view?usp=drive_link") -> https://drive.google.com/file/d/1Ci9kFRKVy5VBTVboR0fy0ArvSwheuSvr/view?usp=drive_link | M20: =IFERROR(__xludf.DUMMYFUNCTION("""COMPUTED_VALUE"""),"User can login on 2nd attempt by those credentials but not in 1st attempt") -> User can login on 2nd attempt by those credentials but not in 1st attempt | N20: =IFERROR(__xludf.DUMMYFUNCTION("""COMPUTED_VALUE"""),"Fahad") -> Fahad | O20: Solved
A21: BR-011 | B21: =IFERROR(__xludf.DUMMYFUNCTION("""COMPUTED_VALUE"""),"Mental Health") -> Mental Health | C21: =IFERROR(__xludf.DUMMYFUNCTION("""COMPUTED_VALUE"""),"Mental Health") -> Mental Health | D21: =IFERROR(__xludf.DUMMYFUNCTION("""COMPUTED_VALUE"""),"Page flow missing") -> Page flow missing | E21: =IFERROR(__xludf.DUMMYFUNCTION("""COMPUTED_VALUE"""),"User need to install the apk in their phone") -> User need to install the apk in their phone | F21: =IFERROR(__xludf.DUMMYFUNCTION("""COMPUTED_VALUE"""),"1. Open app 2. Signin using valid credentials 3. Subscribe and click on claim 4. Fill form with necessary information") -> 1. Open app 2. Signin using valid credentials 3. Subscribe and click on claim 4. Fill form with necessary information | G21: =IFERROR(__xludf.DUMMYFUNCTION("""COMPUTED_VALUE"""),"email : misak59277@foxroids.com pass : 123456abcde") -> email : misak59277@foxroids.com pass : 123456abcde | H21: =IFERROR(__xludf.DUMMYFUNCTION("""COMPUTED_VALUE"""),"After submitting all the questions, then by clicking on continue, body health question should appear") -> After submitting all the questions, then by clicking on continue, body health question should appear | I21: =IFERROR(__xludf.DUMMYFUNCTION("""COMPUTED_VALUE"""),"Failed to load body health questions ") -> Failed to load body health questions | J21: =IFERROR(__xludf.DUMMYFUNCTION("""COMPUTED_VALUE"""),"Fail") -> Fail | K21: =IFERROR(__xludf.DUMMYFUNCTION("""COMPUTED_VALUE"""),"High") -> High | L21: =IFERROR(__xludf.DUMMYFUNCTION("""COMPUTED_VALUE"""),"https://drive.google.com/file/d/1ql7xDdzIV0kFcbZyo_zAFJHrA8RN74KL/view?usp=drive_link") -> https://drive.google.com/file/d/1ql7xDdzIV0kFcbZyo_zAFJHrA8RN74KL/view?usp=drive_link | N21: =IFERROR(__xludf.DUMMYFUNCTION("""COMPUTED_VALUE"""),"Fahad") -> Fahad | O21: Solved
A22: BR-012 | B22: =IFERROR(__xludf.DUMMYFUNCTION("""COMPUTED_VALUE"""),"Message") -> Message | C22: =IFERROR(__xludf.DUMMYFUNCTION("""COMPUTED_VALUE"""),"Message Prifile Image") -> Message Prifile Image | D22: =IFERROR(__xludf.DUMMYFUNCTION("""COMPUTED_VALUE"""),"Validate that updated profile image is displayed in chat section") -> Validate that updated profile image is displayed in chat section | E22: =IFERROR(__xludf.DUMMYFUNCTION("""COMPUTED_VALUE"""),"User has already updated profile image successfully (visible in Profile section)") -> User has already updated profile image successfully (visible in Profile section) | F22: =IFERROR(__xludf.DUMMYFUNCTION("""COMPUTED_VALUE"""),"1) Open the app 2) Update profile image in Profile section (if not already) 3) Navigate to Chat page 4) Observe the displayed user image in chat messages") -> 1) Open the app 2) Update profile image in Profile section (if not already) 3) Navigate to Chat page 4) Observe the displayed user image in chat messages | H22: =IFERROR(__xludf.DUMMYFUNCTION("""COMPUTED_VALUE"""),"The chat page should display the user’s updated profile image instead of the default image") -> The chat page should display the user’s updated profile image instead of the default image | I22: =IFERROR(__xludf.DUMMYFUNCTION("""COMPUTED_VALUE"""),"The chat page still shows the default image even after updating the profile picture") -> The chat page still shows the default image even after updating the profile picture | J22: =IFERROR(__xludf.DUMMYFUNCTION("""COMPUTED_VALUE"""),"Fail") -> Fail | K22: =IFERROR(__xludf.DUMMYFUNCTION("""COMPUTED_VALUE"""),"Medium") -> Medium | L22: =IFERROR(__xludf.DUMMYFUNCTION("""COMPUTED_VALUE"""),"image in profile.jpg image in chat.jpg") -> image in profile.jpg image in chat.jpg | N22: =IFERROR(__xludf.DUMMYFUNCTION("""COMPUTED_VALUE"""),"Tahsin") -> Tahsin | O22: Solved
A23: BR-013 | B23: =IFERROR(__xludf.DUMMYFUNCTION("""COMPUTED_VALUE"""),"Message") -> Message | C23: =IFERROR(__xludf.DUMMYFUNCTION("""COMPUTED_VALUE"""),"Page") -> Page | D23: =IFERROR(__xludf.DUMMYFUNCTION("""COMPUTED_VALUE"""),"Validate that AI assistant responds properly in chat section") -> Validate that AI assistant responds properly in chat section | E23: =IFERROR(__xludf.DUMMYFUNCTION("""COMPUTED_VALUE"""),"User is logged in and on Chat page with stable internet connection") -> User is logged in and on Chat page with stable internet connection | F23: =IFERROR(__xludf.DUMMYFUNCTION("""COMPUTED_VALUE"""),"1) Open the app 2) Navigate to Chat page 3) Type a message to the AI assistant 4) Wait for a response") -> 1) Open the app 2) Navigate to Chat page 3) Type a message to the AI assistant 4) Wait for a response | G23: =IFERROR(__xludf.DUMMYFUNCTION("""COMPUTED_VALUE"""),"Message: “Hello”") -> Message: “Hello” | H23: =IFERROR(__xludf.DUMMYFUNCTION("""COMPUTED_VALUE"""),"The AI assistant should respond promptly with a relevant reply indicating it’s an automated AI system") -> The AI assistant should respond promptly with a relevant reply indicating it’s an automated AI system | I23: =IFERROR(__xludf.DUMMYFUNCTION("""COMPUTED_VALUE"""),"The chat shows no response or confusion whether it’s an AI or Admin panel") -> The chat shows no response or confusion whether it’s an AI or Admin panel | J23: =IFERROR(__xludf.DUMMYFUNCTION("""COMPUTED_VALUE"""),"Fail") -> Fail | K23: =IFERROR(__xludf.DUMMYFUNCTION("""COMPUTED_VALUE"""),"High") -> High | L23: =IFERROR(__xludf.DUMMYFUNCTION("""COMPUTED_VALUE"""),"message respone.jpg") -> message respone.jpg | N23: =IFERROR(__xludf.DUMMYFUNCTION("""COMPUTED_VALUE"""),"Tahsin") -> Tahsin | O23: Solved
A24: BR-014 | B24: =IFERROR(__xludf.DUMMYFUNCTION("""COMPUTED_VALUE"""),"Narration") -> Narration | C24: =IFERROR(__xludf.DUMMYFUNCTION("""COMPUTED_VALUE"""),"Narration") -> Narration | D24: =IFERROR(__xludf.DUMMYFUNCTION("""COMPUTED_VALUE"""),"Data mismatch") -> Data mismatch | E24: =IFERROR(__xludf.DUMMYFUNCTION("""COMPUTED_VALUE"""),"User need to install the apk in their phone") -> User need to install the apk in their phone | F24: =IFERROR(__xludf.DUMMYFUNCTION("""COMPUTED_VALUE"""),"1. Open app 2. Purchase subscription 3. Click on Claim now 4. Fillup form") -> 1. Open app 2. Purchase subscription 3. Click on Claim now 4. Fillup form | G24: =IFERROR(__xludf.DUMMYFUNCTION("""COMPUTED_VALUE"""),"email: deleri6454@haotuwu.com pass: 12345Abcdef@") -> email: deleri6454@haotuwu.com pass: 12345Abcdef@ | H24: =IFERROR(__xludf.DUMMYFUNCTION("""COMPUTED_VALUE"""),"Data should be accurate in the naration which was fetch from the form record") -> Data should be accurate in the naration which was fetch from the form record | I24: =IFERROR(__xludf.DUMMYFUNCTION("""COMPUTED_VALUE"""),"Data overwrite has been noticed.") -> Data overwrite has been noticed. | J24: =IFERROR(__xludf.DUMMYFUNCTION("""COMPUTED_VALUE"""),"Fail") -> Fail | K24: =IFERROR(__xludf.DUMMYFUNCTION("""COMPUTED_VALUE"""),"High") -> High | L24: =IFERROR(__xludf.DUMMYFUNCTION("""COMPUTED_VALUE"""),"https://drive.google.com/file/d/1ZPInnDyIXdDRacW3cZSTPQcngwBsqERk/view?usp=drive_link") -> https://drive.google.com/file/d/1ZPInnDyIXdDRacW3cZSTPQcngwBsqERk/view?usp=drive_link | M24: =IFERROR(__xludf.DUMMYFUNCTION("""COMPUTED_VALUE"""),"A rank might change during the service year.") -> A rank might change during the service year. | N24: =IFERROR(__xludf.DUMMYFUNCTION("""COMPUTED_VALUE"""),"Fahad") -> Fahad | O24: Unsolved | P24: Backend
A25: BR-015 | B25: =IFERROR(__xludf.DUMMYFUNCTION("""COMPUTED_VALUE"""),"Narration") -> Narration | C25: =IFERROR(__xludf.DUMMYFUNCTION("""COMPUTED_VALUE"""),"Narration") -> Narration | D25: =IFERROR(__xludf.DUMMYFUNCTION("""COMPUTED_VALUE"""),"Data missing in the narration") -> Data missing in the narration | E25: =IFERROR(__xludf.DUMMYFUNCTION("""COMPUTED_VALUE"""),"User need to install the apk in their phone") -> User need to install the apk in their phone | F25: =IFERROR(__xludf.DUMMYFUNCTION("""COMPUTED_VALUE"""),"1. Open app 2. Purchase subscription 3. Click on Claim now 4. Fillup form") -> 1. Open app 2. Purchase subscription 3. Click on Claim now 4. Fillup form | G25: =IFERROR(__xludf.DUMMYFUNCTION("""COMPUTED_VALUE"""),"email: deleri6454@haotuwu.com pass: 12345Abcdef@") -> email: deleri6454@haotuwu.com pass: 12345Abcdef@ | H25: =IFERROR(__xludf.DUMMYFUNCTION("""COMPUTED_VALUE"""),"All the data in the narration should match the form data.") -> All the data in the narration should match the form data. | I25: =IFERROR(__xludf.DUMMYFUNCTION("""COMPUTED_VALUE"""),"Some information is missing from the narration.") -> Some information is missing from the narration. | J25: =IFERROR(__xludf.DUMMYFUNCTION("""COMPUTED_VALUE"""),"Fail") -> Fail | K25: =IFERROR(__xludf.DUMMYFUNCTION("""COMPUTED_VALUE"""),"High") -> High | L25: =IFERROR(__xludf.DUMMYFUNCTION("""COMPUTED_VALUE"""),"https://drive.google.com/file/d/1T_ykRfbG70t1AaluRRxZf4OUtwAiIUBu/view?usp=drive_link") -> https://drive.google.com/file/d/1T_ykRfbG70t1AaluRRxZf4OUtwAiIUBu/view?usp=drive_link | N25: =IFERROR(__xludf.DUMMYFUNCTION("""COMPUTED_VALUE"""),"Fahad") -> Fahad | O25: Unsolved | P25: Backend
A26: BR-016 | B26: =IFERROR(__xludf.DUMMYFUNCTION("""COMPUTED_VALUE"""),"Narrative Page") -> Narrative Page | C26: =IFERROR(__xludf.DUMMYFUNCTION("""COMPUTED_VALUE"""),"Iconography/Functionality") -> Iconography/Functionality | D26: =IFERROR(__xludf.DUMMYFUNCTION("""COMPUTED_VALUE"""),"Verify the icon used for 'Copy Text' accurately reflects its clipboard functionality.") -> Verify the icon used for 'Copy Text' accurately reflects its clipboard functionality. | E26: =IFERROR(__xludf.DUMMYFUNCTION("""COMPUTED_VALUE"""),"A narrative has been successfully generated.") -> A narrative has been successfully generated. | F26: =IFERROR(__xludf.DUMMYFUNCTION("""COMPUTED_VALUE"""),"1. Tap the icon (currently a 'Download' icon). ") -> 1. Tap the icon (currently a 'Download' icon). | G26: =IFERROR(__xludf.DUMMYFUNCTION("""COMPUTED_VALUE"""),"N/A (Functional/UI Test)") -> N/A (Functional/UI Test) | H26: =IFERROR(__xludf.DUMMYFUNCTION("""COMPUTED_VALUE"""),"The icon displayed should be a standard 'Copy' icon instead of a 'Download' icon. ") -> The icon displayed should be a standard 'Copy' icon instead of a 'Download' icon. | I26: =IFERROR(__xludf.DUMMYFUNCTION("""COMPUTED_VALUE"""),"The page uses a 'Download' icon to initiate the 'Copy Text' function, leading to user confusion.") -> The page uses a 'Download' icon to initiate the 'Copy Text' function, leading to user confusion. | J26: =IFERROR(__xludf.DUMMYFUNCTION("""COMPUTED_VALUE"""),"Fail") -> Fail | K26: =IFERROR(__xludf.DUMMYFUNCTION("""COMPUTED_VALUE"""),"Medium") -> Medium | L26: =IFERROR(__xludf.DUMMYFUNCTION("""COMPUTED_VALUE"""),"copy test.mp4") -> copy test.mp4 | N26: =IFERROR(__xludf.DUMMYFUNCTION("""COMPUTED_VALUE"""),"Tahsin") -> Tahsin | O26: Solved
A27: BR-017 | B27: =IFERROR(__xludf.DUMMYFUNCTION("""COMPUTED_VALUE"""),"Narrative Page") -> Narrative Page | C27: =IFERROR(__xludf.DUMMYFUNCTION("""COMPUTED_VALUE"""),"Text Editor/Edit Narrative") -> Text Editor/Edit Narrative | D27: =IFERROR(__xludf.DUMMYFUNCTION("""COMPUTED_VALUE"""),"Verify cursor positioning via tap/click works correctly in the Narrative Edit screen.") -> Verify cursor positioning via tap/click works correctly in the Narrative Edit screen. | E27: =IFERROR(__xludf.DUMMYFUNCTION("""COMPUTED_VALUE"""),"A narrative has been successfully generated.") -> A narrative has been successfully generated. | F27: =IFERROR(__xludf.DUMMYFUNCTION("""COMPUTED_VALUE"""),"1. Navigate to the generated narrative screen. 2. Tap the 'Edit' icon (or button) to enter the editing mode. 3. Tap on a word of the narrative text. ") -> 1. Navigate to the generated narrative screen. 2. Tap the 'Edit' icon (or button) to enter the editing mode. 3. Tap on a word of the narrative text. | H27: =IFERROR(__xludf.DUMMYFUNCTION("""COMPUTED_VALUE"""),"Upon tapping any word in the narrative text, the cursor should instantly move to the tapped position, allowing for immediate text insertion or deletion.") -> Upon tapping any word in the narrative text, the cursor should instantly move to the tapped position, allowing for immediate text insertion or deletion. | I27: =IFERROR(__xludf.DUMMYFUNCTION("""COMPUTED_VALUE"""),"The cursor does not move to the tapped word; the user must manually scroll/slide the cursor using the pointer control handles to reach the desired word.") -> The cursor does not move to the tapped word; the user must manually scroll/slide the cursor using the pointer control handles to reach the desired word. | J27: =IFERROR(__xludf.DUMMYFUNCTION("""COMPUTED_VALUE"""),"Fail") -> Fail | K27: =IFERROR(__xludf.DUMMYFUNCTION("""COMPUTED_VALUE"""),"Medium") -> Medium | L27: =IFERROR(__xludf.DUMMYFUNCTION("""COMPUTED_VALUE"""),"cursor issue.mp4") -> cursor issue.mp4 | N27: =IFERROR(__xludf.DUMMYFUNCTION("""COMPUTED_VALUE"""),"Tahsin") -> Tahsin | O27: Solved
A28: BR-018 | B28: =IFERROR(__xludf.DUMMYFUNCTION("""COMPUTED_VALUE"""),"Profile") -> Profile | C28: =IFERROR(__xludf.DUMMYFUNCTION("""COMPUTED_VALUE"""),"Edit Profile") -> Edit Profile | D28: =IFERROR(__xludf.DUMMYFUNCTION("""COMPUTED_VALUE"""),"Validate that phone number field accepts only numeric input") -> Validate that phone number field accepts only numeric input | E28: =IFERROR(__xludf.DUMMYFUNCTION("""COMPUTED_VALUE"""),"User is logged in and on Edit Profile screen") -> User is logged in and on Edit Profile screen | F28: =IFERROR(__xludf.DUMMYFUNCTION("""COMPUTED_VALUE"""),"1) Open the app 2) Navigate to Profile section 3) Tap on Edit Profile 4) Tap on Phone Number field 5) Enter alphabets or special characters like “abc@#”") -> 1) Open the app 2) Navigate to Profile section 3) Tap on Edit Profile 4) Tap on Phone Number field 5) Enter alphabets or special characters like “abc@#” | G28: =IFERROR(__xludf.DUMMYFUNCTION("""COMPUTED_VALUE"""),"Phone Number: abc@#") -> Phone Number: abc@# | H28: =IFERROR(__xludf.DUMMYFUNCTION("""COMPUTED_VALUE"""),"The field should accept only numeric values (0–9) and reject alphabets or special characters") -> The field should accept only numeric values (0–9) and reject alphabets or special characters | I28: =IFERROR(__xludf.DUMMYFUNCTION("""COMPUTED_VALUE"""),"The field accepts characters and special symbols instead of restricting to numeric input") -> The field accepts characters and special symbols instead of restricting to numeric input | J28: =IFERROR(__xludf.DUMMYFUNCTION("""COMPUTED_VALUE"""),"Fail") -> Fail | K28: =IFERROR(__xludf.DUMMYFUNCTION("""COMPUTED_VALUE"""),"Medium") -> Medium | L28: =IFERROR(__xludf.DUMMYFUNCTION("""COMPUTED_VALUE"""),"Phone number.mp4") -> Phone number.mp4 | N28: =IFERROR(__xludf.DUMMYFUNCTION("""COMPUTED_VALUE"""),"Tahsin") -> Tahsin | O28: Unsolved
A29: BR-019 | B29: =IFERROR(__xludf.DUMMYFUNCTION("""COMPUTED_VALUE"""),"Profile") -> Profile | C29: =IFERROR(__xludf.DUMMYFUNCTION("""COMPUTED_VALUE"""),"Profile") -> Profile | D29: =IFERROR(__xludf.DUMMYFUNCTION("""COMPUTED_VALUE"""),"Profile picture automatically set.") -> Profile picture automatically set. | E29: =IFERROR(__xludf.DUMMYFUNCTION("""COMPUTED_VALUE"""),"User need to install the apk in their phone") -> User need to install the apk in their phone | F29: =IFERROR(__xludf.DUMMYFUNCTION("""COMPUTED_VALUE"""),"1. Open app 2. Signin using valid credentials 3. Goto Profile") -> 1. Open app 2. Signin using valid credentials 3. Goto Profile | G29: =IFERROR(__xludf.DUMMYFUNCTION("""COMPUTED_VALUE"""),"email : misak59277@foxroids.com pass : 123456abcde") -> email : misak59277@foxroids.com pass : 123456abcde | H29: =IFERROR(__xludf.DUMMYFUNCTION("""COMPUTED_VALUE"""),"A blank image should be displayed on the profile when a user creates a new account.") -> A blank image should be displayed on the profile when a user creates a new account. | I29: =IFERROR(__xludf.DUMMYFUNCTION("""COMPUTED_VALUE"""),"An automatic profile picture has been noticed, and it seems appropriate.") -> An automatic profile picture has been noticed, and it seems appropriate. | J29: =IFERROR(__xludf.DUMMYFUNCTION("""COMPUTED_VALUE"""),"Fail") -> Fail | K29: =IFERROR(__xludf.DUMMYFUNCTION("""COMPUTED_VALUE"""),"Medium") -> Medium | L29: =IFERROR(__xludf.DUMMYFUNCTION("""COMPUTED_VALUE"""),"https://drive.google.com/file/d/1lRM5FYW3Up-I7mwXq0VUVC6GF27kAvrp/view?usp=drive_link") -> https://drive.google.com/file/d/1lRM5FYW3Up-I7mwXq0VUVC6GF27kAvrp/view?usp=drive_link | N29: =IFERROR(__xludf.DUMMYFUNCTION("""COMPUTED_VALUE"""),"Fahad") -> Fahad | O29: Solved
A30: BR-020 | B30: =IFERROR(__xludf.DUMMYFUNCTION("""COMPUTED_VALUE"""),"Profile") -> Profile | C30: =IFERROR(__xludf.DUMMYFUNCTION("""COMPUTED_VALUE"""),"Profile") -> Profile | D30: =IFERROR(__xludf.DUMMYFUNCTION("""COMPUTED_VALUE"""),"Failed to update form information") -> Failed to update form information | E30: =IFERROR(__xludf.DUMMYFUNCTION("""COMPUTED_VALUE"""),"User need to install the apk in their phone") -> User need to install the apk in their phone | F30: =IFERROR(__xludf.DUMMYFUNCTION("""COMPUTED_VALUE"""),"1. Open app 2. Signin using valid credentials 3. Goto Profile") -> 1. Open app 2. Signin using valid credentials 3. Goto Profile | G30: =IFERROR(__xludf.DUMMYFUNCTION("""COMPUTED_VALUE"""),"email : misak59277@foxroids.com pass : 123456abcde") -> email : misak59277@foxroids.com pass : 123456abcde | H30: =IFERROR(__xludf.DUMMYFUNCTION("""COMPUTED_VALUE"""),"Users should be able to update their profiles without any issues.") -> Users should be able to update their profiles without any issues. | I30: =IFERROR(__xludf.DUMMYFUNCTION("""COMPUTED_VALUE"""),"An error from the backend has been noticed while updating profile information.") -> An error from the backend has been noticed while updating profile information. | J30: =IFERROR(__xludf.DUMMYFUNCTION("""COMPUTED_VALUE"""),"Fail") -> Fail | K30: =IFERROR(__xludf.DUMMYFUNCTION("""COMPUTED_VALUE"""),"High") -> High | L30: =IFERROR(__xludf.DUMMYFUNCTION("""COMPUTED_VALUE"""),"https://drive.google.com/file/d/1iP_bJ1pY2S2ztNFaUdlBMzO6pivTYK31/view?usp=drive_link") -> https://drive.google.com/file/d/1iP_bJ1pY2S2ztNFaUdlBMzO6pivTYK31/view?usp=drive_link | N30: =IFERROR(__xludf.DUMMYFUNCTION("""COMPUTED_VALUE"""),"Fahad") -> Fahad | O30: Solved
A31: BR-021 | B31: =IFERROR(__xludf.DUMMYFUNCTION("""COMPUTED_VALUE"""),"Profile") -> Profile | C31: =IFERROR(__xludf.DUMMYFUNCTION("""COMPUTED_VALUE"""),"Profile") -> Profile | D31: =IFERROR(__xludf.DUMMYFUNCTION("""COMPUTED_VALUE"""),"Failed to update profile picture") -> Failed to update profile picture | E31: =IFERROR(__xludf.DUMMYFUNCTION("""COMPUTED_VALUE"""),"User need to install the apk in their phone") -> User need to install the apk in their phone | F31: =IFERROR(__xludf.DUMMYFUNCTION("""COMPUTED_VALUE"""),"1. Open app 2. Goto profile 3. Select image for profile picture") -> 1. Open app 2. Goto profile 3. Select image for profile picture | G31: =IFERROR(__xludf.DUMMYFUNCTION("""COMPUTED_VALUE"""),"email: deleri6454@haotuwu.com pass: 12345Abcdef@") -> email: deleri6454@haotuwu.com pass: 12345Abcdef@ | H31: =IFERROR(__xludf.DUMMYFUNCTION("""COMPUTED_VALUE"""),"User should be able to update their profile picture") -> User should be able to update their profile picture | I31: =IFERROR(__xludf.DUMMYFUNCTION("""COMPUTED_VALUE"""),"Failed to update profile picture") -> Failed to update profile picture | J31: =IFERROR(__xludf.DUMMYFUNCTION("""COMPUTED_VALUE"""),"Fail") -> Fail | K31: =IFERROR(__xludf.DUMMYFUNCTION("""COMPUTED_VALUE"""),"High") -> High | L31: =IFERROR(__xludf.DUMMYFUNCTION("""COMPUTED_VALUE"""),"https://drive.google.com/file/d/1VIQjtXn7Qea_bnKM9izsTzcAZ6p8l3Dy/view?usp=drive_link") -> https://drive.google.com/file/d/1VIQjtXn7Qea_bnKM9izsTzcAZ6p8l3Dy/view?usp=drive_link | N31: =IFERROR(__xludf.DUMMYFUNCTION("""COMPUTED_VALUE"""),"Fahad") -> Fahad | O31: Solved
A32: BR-022 | B32: =IFERROR(__xludf.DUMMYFUNCTION("""COMPUTED_VALUE"""),"Registration") -> Registration | C32: =IFERROR(__xludf.DUMMYFUNCTION("""COMPUTED_VALUE"""),"Registration") -> Registration | D32: =IFERROR(__xludf.DUMMYFUNCTION("""COMPUTED_VALUE"""),"The password visibility icon is not dynamic; it remains fixed on a single option.") -> The password visibility icon is not dynamic; it remains fixed on a single option. | E32: =IFERROR(__xludf.DUMMYFUNCTION("""COMPUTED_VALUE"""),"User need to install the apk in their phone") -> User need to install the apk in their phone | F32: =IFERROR(__xludf.DUMMYFUNCTION("""COMPUTED_VALUE"""),"1. Open app 2. Click on Signup") -> 1. Open app 2. Click on Signup | G32: =IFERROR(__xludf.DUMMYFUNCTION("""COMPUTED_VALUE"""),"N/A") -> N/A | H32: =IFERROR(__xludf.DUMMYFUNCTION("""COMPUTED_VALUE"""),"The password visibility icon should update accordingly.") -> The password visibility icon should update accordingly. | I32: =IFERROR(__xludf.DUMMYFUNCTION("""COMPUTED_VALUE"""),"It's icon set to hide password option only") -> It's icon set to hide password option only | J32: =IFERROR(__xludf.DUMMYFUNCTION("""COMPUTED_VALUE"""),"Fail") -> Fail | K32: =IFERROR(__xludf.DUMMYFUNCTION("""COMPUTED_VALUE"""),"Low") -> Low | L32: =IFERROR(__xludf.DUMMYFUNCTION("""COMPUTED_VALUE"""),"https://drive.google.com/file/d/1Sk1eaL56DxGmBcusnsAxmiA18ygmic_4/view?usp=drive_link") -> https://drive.google.com/file/d/1Sk1eaL56DxGmBcusnsAxmiA18ygmic_4/view?usp=drive_link | N32: =IFERROR(__xludf.DUMMYFUNCTION("""COMPUTED_VALUE"""),"Fahad") -> Fahad | O32: Solved | P32: Same as BR-019
A33: BR-023 | B33: =IFERROR(__xludf.DUMMYFUNCTION("""COMPUTED_VALUE"""),"Registration") -> Registration | C33: =IFERROR(__xludf.DUMMYFUNCTION("""COMPUTED_VALUE"""),"Registration") -> Registration | D33: =IFERROR(__xludf.DUMMYFUNCTION("""COMPUTED_VALUE"""),"Email body contain user email not username") -> Email body contain user email not username | E33: =IFERROR(__xludf.DUMMYFUNCTION("""COMPUTED_VALUE"""),"User need to install the apk in their phone") -> User need to install the apk in their phone | F33: =IFERROR(__xludf.DUMMYFUNCTION("""COMPUTED_VALUE"""),"1. Open app 2. Click on Signup") -> 1. Open app 2. Click on Signup | G33: =IFERROR(__xludf.DUMMYFUNCTION("""COMPUTED_VALUE"""),"email : misak59277@foxroids.com pass : 123456abcdef") -> email : misak59277@foxroids.com pass : 123456abcdef | H33: =IFERROR(__xludf.DUMMYFUNCTION("""COMPUTED_VALUE"""),"In the main body, the user's name should be written instead of mentioning their primary address.") -> In the main body, the user's name should be written instead of mentioning their primary address. | I33: =IFERROR(__xludf.DUMMYFUNCTION("""COMPUTED_VALUE"""),"mentioning them by their email address") -> mentioning them by their email address | J33: =IFERROR(__xludf.DUMMYFUNCTION("""COMPUTED_VALUE"""),"Fail") -> Fail | K33: =IFERROR(__xludf.DUMMYFUNCTION("""COMPUTED_VALUE"""),"Medium") -> Medium | L33: =IFERROR(__xludf.DUMMYFUNCTION("""COMPUTED_VALUE"""),"https://drive.google.com/file/d/1gFAa4qdDuAUpQ4Sd-7yED0Otklc6UZam/view?usp=drive_link") -> https://drive.google.com/file/d/1gFAa4qdDuAUpQ4Sd-7yED0Otklc6UZam/view?usp=drive_link | N33: =IFERROR(__xludf.DUMMYFUNCTION("""COMPUTED_VALUE"""),"Fahad") -> Fahad | O33: Solved | P33: Same as BR-013
A34: BR-024 | B34: =IFERROR(__xludf.DUMMYFUNCTION("""COMPUTED_VALUE"""),"Registration") -> Registration | C34: =IFERROR(__xludf.DUMMYFUNCTION("""COMPUTED_VALUE"""),"Registration") -> Registration | D34: =IFERROR(__xludf.DUMMYFUNCTION("""COMPUTED_VALUE"""),"The email subject doesn't have an appropriate heading.") -> The email subject doesn't have an appropriate heading. | E34: =IFERROR(__xludf.DUMMYFUNCTION("""COMPUTED_VALUE"""),"User need to install the apk in their phone") -> User need to install the apk in their phone | F34: =IFERROR(__xludf.DUMMYFUNCTION("""COMPUTED_VALUE"""),"1. Open app 2. Click on Signup 3. Fillup necessary information and click next to get OTP") -> 1. Open app 2. Click on Signup 3. Fillup necessary information and click next to get OTP | G34: =IFERROR(__xludf.DUMMYFUNCTION("""COMPUTED_VALUE"""),"email : misak59277@foxroids.com pass : 123456abcdef") -> email : misak59277@foxroids.com pass : 123456abcdef | H34: =IFERROR(__xludf.DUMMYFUNCTION("""COMPUTED_VALUE"""),"Email subject name should be written properly") -> Email subject name should be written properly | I34: =IFERROR(__xludf.DUMMYFUNCTION("""COMPUTED_VALUE"""),"Simply state that an OTP has been received without specifying the reason for receiving it.") -> Simply state that an OTP has been received without specifying the reason for receiving it. | J34: =IFERROR(__xludf.DUMMYFUNCTION("""COMPUTED_VALUE"""),"Fail") -> Fail | K34: =IFERROR(__xludf.DUMMYFUNCTION("""COMPUTED_VALUE"""),"Medium") -> Medium | L34: =IFERROR(__xludf.DUMMYFUNCTION("""COMPUTED_VALUE"""),"https://drive.google.com/file/d/1VCzTvg_PIgpJa2oGxuA9W2J_oN9yPufZ/view?usp=drive_link") -> https://drive.google.com/file/d/1VCzTvg_PIgpJa2oGxuA9W2J_oN9yPufZ/view?usp=drive_link | M34: =IFERROR(__xludf.DUMMYFUNCTION("""COMPUTED_VALUE"""),"Mention it's VALR registration OTP code as OTP subject") -> Mention it's VALR registration OTP code as OTP subject | N34: =IFERROR(__xludf.DUMMYFUNCTION("""COMPUTED_VALUE"""),"Fahad") -> Fahad | O34: Solved
A35: BR-025 | B35: =IFERROR(__xludf.DUMMYFUNCTION("""COMPUTED_VALUE"""),"Registration") -> Registration | C35: =IFERROR(__xludf.DUMMYFUNCTION("""COMPUTED_VALUE"""),"Registration") -> Registration | D35: =IFERROR(__xludf.DUMMYFUNCTION("""COMPUTED_VALUE"""),"OTP submission error") -> OTP submission error | E35: =IFERROR(__xludf.DUMMYFUNCTION("""COMPUTED_VALUE"""),"User need to install the apk in their phone") -> User need to install the apk in their phone | F35: =IFERROR(__xludf.DUMMYFUNCTION("""COMPUTED_VALUE"""),"1. Open app 2. Click on Signup 3. Fillup necessary information and click next to get OTP") -> 1. Open app 2. Click on Signup 3. Fillup necessary information and click next to get OTP | G35: =IFERROR(__xludf.DUMMYFUNCTION("""COMPUTED_VALUE"""),"email : misak59277@foxroids.com pass : 123456abcdef") -> email : misak59277@foxroids.com pass : 123456abcdef | H35: =IFERROR(__xludf.DUMMYFUNCTION("""COMPUTED_VALUE"""),"user should be able to submit their OTP without any issue") -> user should be able to submit their OTP without any issue | I35: =IFERROR(__xludf.DUMMYFUNCTION("""COMPUTED_VALUE"""),"Failed to submit OTP , but user can submit it when they 2nd click on OTP box") -> Failed to submit OTP , but user can submit it when they 2nd click on OTP box | J35: =IFERROR(__xludf.DUMMYFUNCTION("""COMPUTED_VALUE"""),"Fail") -> Fail | K35: =IFERROR(__xludf.DUMMYFUNCTION("""COMPUTED_VALUE"""),"High") -> High | L35: =IFERROR(__xludf.DUMMYFUNCTION("""COMPUTED_VALUE"""),"https://drive.google.com/file/d/1000xgJujcIX7K8eQfPfwTdVThR6JRpqG/view?usp=drive_link") -> https://drive.google.com/file/d/1000xgJujcIX7K8eQfPfwTdVThR6JRpqG/view?usp=drive_link | M35: =IFERROR(__xludf.DUMMYFUNCTION("""COMPUTED_VALUE"""),"when click on one time, they can not submit it and after that, 2nd time click on OTP , user can write their OTP") -> when click on one time, they can not submit it and after that, 2nd time click on OTP , user can write their OTP | N35: =IFERROR(__xludf.DUMMYFUNCTION("""COMPUTED_VALUE"""),"Fahad") -> Fahad | O35: Solved
A36: BR-026 | B36: =IFERROR(__xludf.DUMMYFUNCTION("""COMPUTED_VALUE"""),"Registration") -> Registration | C36: =IFERROR(__xludf.DUMMYFUNCTION("""COMPUTED_VALUE"""),"Registration") -> Registration | D36: =IFERROR(__xludf.DUMMYFUNCTION("""COMPUTED_VALUE"""),"OTP expiration time is not added in the OTP page") -> OTP expiration time is not added in the OTP page | E36: =IFERROR(__xludf.DUMMYFUNCTION("""COMPUTED_VALUE"""),"User need to install the apk in their phone") -> User need to install the apk in their phone | F36: =IFERROR(__xludf.DUMMYFUNCTION("""COMPUTED_VALUE"""),"1. Open app 2. Click on Signup 3. Fillup necessary information and click next to get OTP") -> 1. Open app 2. Click on Signup 3. Fillup necessary information and click next to get OTP | G36: =IFERROR(__xludf.DUMMYFUNCTION("""COMPUTED_VALUE"""),"email : misak59277@foxroids.com pass : 123456abcdef") -> email : misak59277@foxroids.com pass : 123456abcdef | H36: =IFERROR(__xludf.DUMMYFUNCTION("""COMPUTED_VALUE"""),"OTP expiration count down time should be added in the OTP page") -> OTP expiration count down time should be added in the OTP page | I36: =IFERROR(__xludf.DUMMYFUNCTION("""COMPUTED_VALUE"""),"No countdown time has been noticed in the OTP page") -> No countdown time has been noticed in the OTP page | J36: =IFERROR(__xludf.DUMMYFUNCTION("""COMPUTED_VALUE"""),"Fail") -> Fail | K36: =IFERROR(__xludf.DUMMYFUNCTION("""COMPUTED_VALUE"""),"High") -> High | L36: =IFERROR(__xludf.DUMMYFUNCTION("""COMPUTED_VALUE"""),"https://drive.google.com/file/d/1gwFdvneV24O9Xekc1-CCCYnuBWBRji0n/view?usp=drive_link") -> https://drive.google.com/file/d/1gwFdvneV24O9Xekc1-CCCYnuBWBRji0n/view?usp=drive_link | N36: =IFERROR(__xludf.DUMMYFUNCTION("""COMPUTED_VALUE"""),"Fahad") -> Fahad | O36: Unsolved | P36: Backend
A37: BR-027 | B37: =IFERROR(__xludf.DUMMYFUNCTION("""COMPUTED_VALUE"""),"Registration") -> Registration | C37: =IFERROR(__xludf.DUMMYFUNCTION("""COMPUTED_VALUE"""),"Registration") -> Registration | D37: =IFERROR(__xludf.DUMMYFUNCTION("""COMPUTED_VALUE"""),"Overlay mixed aligned") -> Overlay mixed aligned | E37: =IFERROR(__xludf.DUMMYFUNCTION("""COMPUTED_VALUE"""),"User need to install the apk in their phone") -> User need to install the apk in their phone | F37: =IFERROR(__xludf.DUMMYFUNCTION("""COMPUTED_VALUE"""),"1. Open app 2. Click on Signup") -> 1. Open app 2. Click on Signup | G37: =IFERROR(__xludf.DUMMYFUNCTION("""COMPUTED_VALUE"""),"N/A") -> N/A | H37: =IFERROR(__xludf.DUMMYFUNCTION("""COMPUTED_VALUE"""),"No overlay should overlapped") -> No overlay should overlapped | I37: =IFERROR(__xludf.DUMMYFUNCTION("""COMPUTED_VALUE"""),"Overlapped has been noticed") -> Overlapped has been noticed | J37: =IFERROR(__xludf.DUMMYFUNCTION("""COMPUTED_VALUE"""),"Fail") -> Fail | K37: =IFERROR(__xludf.DUMMYFUNCTION("""COMPUTED_VALUE"""),"Low") -> Low | L37: =IFERROR(__xludf.DUMMYFUNCTION("""COMPUTED_VALUE"""),"https://drive.google.com/file/d/1k1Vdg_I-TyuwUJz23tc86AbiNzWi7dNw/view?usp=drive_link") -> https://drive.google.com/file/d/1k1Vdg_I-TyuwUJz23tc86AbiNzWi7dNw/view?usp=drive_link | N37: =IFERROR(__xludf.DUMMYFUNCTION("""COMPUTED_VALUE"""),"Fahad") -> Fahad
A38: BR-028 | B38: =IFERROR(__xludf.DUMMYFUNCTION("""COMPUTED_VALUE"""),"Registration") -> Registration | C38: =IFERROR(__xludf.DUMMYFUNCTION("""COMPUTED_VALUE"""),"Registration") -> Registration | D38: =IFERROR(__xludf.DUMMYFUNCTION("""COMPUTED_VALUE"""),"Strong password validation failed") -> Strong password validation failed | E38: =IFERROR(__xludf.DUMMYFUNCTION("""COMPUTED_VALUE"""),"User need to install the apk in their phone") -> User need to install the apk in their phone | F38: =IFERROR(__xludf.DUMMYFUNCTION("""COMPUTED_VALUE"""),"1. Open app 2. Click on Signup") -> 1. Open app 2. Click on Signup | G38: =IFERROR(__xludf.DUMMYFUNCTION("""COMPUTED_VALUE"""),"N/A") -> N/A | H38: =IFERROR(__xludf.DUMMYFUNCTION("""COMPUTED_VALUE"""),"Password should be validated and password indicator should be implemented") -> Password should be validated and password indicator should be implemented | I38: =IFERROR(__xludf.DUMMYFUNCTION("""COMPUTED_VALUE"""),"User can give poor level 8 characted password to create account") -> User can give poor level 8 characted password to create account | J38: =IFERROR(__xludf.DUMMYFUNCTION("""COMPUTED_VALUE"""),"Fail") -> Fail | K38: =IFERROR(__xludf.DUMMYFUNCTION("""COMPUTED_VALUE"""),"High") -> High | L38: =IFERROR(__xludf.DUMMYFUNCTION("""COMPUTED_VALUE"""),"https://drive.google.com/file/d/1tPoLrLk6gfDF0esxWgqf_pANwo7deJtS/view?usp=drive_link") -> https://drive.google.com/file/d/1tPoLrLk6gfDF0esxWgqf_pANwo7deJtS/view?usp=drive_link | N38: =IFERROR(__xludf.DUMMYFUNCTION("""COMPUTED_VALUE"""),"Fahad") -> Fahad
A39: BR-029 | B39: =IFERROR(__xludf.DUMMYFUNCTION("""COMPUTED_VALUE"""),"Registration") -> Registration | C39: =IFERROR(__xludf.DUMMYFUNCTION("""COMPUTED_VALUE"""),"Registration") -> Registration | D39: =IFERROR(__xludf.DUMMYFUNCTION("""COMPUTED_VALUE"""),"OTP digit can not be cancel when it is not fully inputed") -> OTP digit can not be cancel when it is not fully inputed | E39: =IFERROR(__xludf.DUMMYFUNCTION("""COMPUTED_VALUE"""),"User need to install the apk in their phone") -> User need to install the apk in their phone | F39: =IFERROR(__xludf.DUMMYFUNCTION("""COMPUTED_VALUE"""),"1. Open app 2. Click on Signup") -> 1. Open app 2. Click on Signup | G39: =IFERROR(__xludf.DUMMYFUNCTION("""COMPUTED_VALUE"""),"email : misak59277@foxroids.com pass : 123456abcdef") -> email : misak59277@foxroids.com pass : 123456abcdef | H39: =IFERROR(__xludf.DUMMYFUNCTION("""COMPUTED_VALUE"""),"Users can edit their incorrect OTP midway; they don't need to enter it completely again.") -> Users can edit their incorrect OTP midway; they don't need to enter it completely again. | I39: =IFERROR(__xludf.DUMMYFUNCTION("""COMPUTED_VALUE"""),"Unable to fix an incorrect OTP without fully entering it.") -> Unable to fix an incorrect OTP without fully entering it. | J39: =IFERROR(__xludf.DUMMYFUNCTION("""COMPUTED_VALUE"""),"Fail") -> Fail | K39: =IFERROR(__xludf.DUMMYFUNCTION("""COMPUTED_VALUE"""),"High") -> High | L39: =IFERROR(__xludf.DUMMYFUNCTION("""COMPUTED_VALUE"""),"https://drive.google.com/file/d/1YsR3cZ6babF8oE0BEzRWJcn7bFVOzL8-/view?usp=drive_link") -> https://drive.google.com/file/d/1YsR3cZ6babF8oE0BEzRWJcn7bFVOzL8-/view?usp=drive_link | N39: =IFERROR(__xludf.DUMMYFUNCTION("""COMPUTED_VALUE"""),"Fahad") -> Fahad
A40: BR-030 | B40: =IFERROR(__xludf.DUMMYFUNCTION("""COMPUTED_VALUE"""),"Registration") -> Registration | C40: =IFERROR(__xludf.DUMMYFUNCTION("""COMPUTED_VALUE"""),"Registration") -> Registration | D40: =IFERROR(__xludf.DUMMYFUNCTION("""COMPUTED_VALUE"""),"Validate that name field does not accept numbers or special characters") -> Validate that name field does not accept numbers or special characters | E40: =IFERROR(__xludf.DUMMYFUNCTION("""COMPUTED_VALUE"""),"User is on Registration screen") -> User is on Registration screen | F40: =IFERROR(__xludf.DUMMYFUNCTION("""COMPUTED_VALUE"""),"1) Open the app 2) Navigate to Registration page 3) Tap on Name field 4) Enter alphanumeric/special characters") -> 1) Open the app 2) Navigate to Registration page 3) Tap on Name field 4) Enter alphanumeric/special characters | G40: =IFERROR(__xludf.DUMMYFUNCTION("""COMPUTED_VALUE"""),"Name: 123 / John@#") -> Name: 123 / John@# | H40: =IFERROR(__xludf.DUMMYFUNCTION("""COMPUTED_VALUE"""),"The field should only allow alphabetic characters (A–Z, a–z) or Space and reject numbers or special characters") -> The field should only allow alphabetic characters (A–Z, a–z) or Space and reject numbers or special characters | I40: =IFERROR(__xludf.DUMMYFUNCTION("""COMPUTED_VALUE"""),"The field accepts numbers and special characters") -> The field accepts numbers and special characters | J40: =IFERROR(__xludf.DUMMYFUNCTION("""COMPUTED_VALUE"""),"Fail") -> Fail | K40: =IFERROR(__xludf.DUMMYFUNCTION("""COMPUTED_VALUE"""),"Medium") -> Medium | L40: =IFERROR(__xludf.DUMMYFUNCTION("""COMPUTED_VALUE"""),"Reg page.mp4") -> Reg page.mp4 | N40: =IFERROR(__xludf.DUMMYFUNCTION("""COMPUTED_VALUE"""),"Tahsin") -> Tahsin
A41: BR-031 | B41: =IFERROR(__xludf.DUMMYFUNCTION("""COMPUTED_VALUE"""),"Registration") -> Registration | C41: =IFERROR(__xludf.DUMMYFUNCTION("""COMPUTED_VALUE"""),"Registration") -> Registration | D41: =IFERROR(__xludf.DUMMYFUNCTION("""COMPUTED_VALUE"""),"Validate that password field enforces strong password rules") -> Validate that password field enforces strong password rules | E41: =IFERROR(__xludf.DUMMYFUNCTION("""COMPUTED_VALUE"""),"User is on Registration screen") -> User is on Registration screen | F41: =IFERROR(__xludf.DUMMYFUNCTION("""COMPUTED_VALUE"""),"1) Open the app 2) Navigate to Registration page 3) Tap on Password field 4) Enter password with only numbers like “12345678” 5) Attempt to submit the form") -> 1) Open the app 2) Navigate to Registration page 3) Tap on Password field 4) Enter password with only numbers like “12345678” 5) Attempt to submit the form | G41: =IFERROR(__xludf.DUMMYFUNCTION("""COMPUTED_VALUE"""),"Password: 12345678") -> Password: 12345678 | H41: =IFERROR(__xludf.DUMMYFUNCTION("""COMPUTED_VALUE"""),"The system should enforce strong password validation — requiring at least one uppercase letter, one number, and one special character (minimum 8 characters)") -> The system should enforce strong password validation — requiring at least one uppercase letter, one number, and one special character (minimum 8 characters) | I41: =IFERROR(__xludf.DUMMYFUNCTION("""COMPUTED_VALUE"""),"The field accepts weak passwords with only numbers (no uppercase, number, or special character)") -> The field accepts weak passwords with only numbers (no uppercase, number, or special character) | J41: =IFERROR(__xludf.DUMMYFUNCTION("""COMPUTED_VALUE"""),"Fail") -> Fail | K41: =IFERROR(__xludf.DUMMYFUNCTION("""COMPUTED_VALUE"""),"High") -> High | L41: =IFERROR(__xludf.DUMMYFUNCTION("""COMPUTED_VALUE"""),"Reg page.mp4") -> Reg page.mp4 | N41: =IFERROR(__xludf.DUMMYFUNCTION("""COMPUTED_VALUE"""),"Tahsin") -> Tahsin
A42: BR-032 | B42: =IFERROR(__xludf.DUMMYFUNCTION("""COMPUTED_VALUE"""),"Registration") -> Registration | C42: =IFERROR(__xludf.DUMMYFUNCTION("""COMPUTED_VALUE"""),"Registration") -> Registration | D42: =IFERROR(__xludf.DUMMYFUNCTION("""COMPUTED_VALUE"""),"Validate that password visibility toggle icon changes dynamically") -> Validate that password visibility toggle icon changes dynamically | E42: =IFERROR(__xludf.DUMMYFUNCTION("""COMPUTED_VALUE"""),"User is on Registration screen") -> User is on Registration screen | F42: =IFERROR(__xludf.DUMMYFUNCTION("""COMPUTED_VALUE"""),"1) Open the app 2) Navigate to Registration page 3) Tap on Password field 4) Tap on eye icon to toggle password visibility multiple times") -> 1) Open the app 2) Navigate to Registration page 3) Tap on Password field 4) Tap on eye icon to toggle password visibility multiple times | H42: =IFERROR(__xludf.DUMMYFUNCTION("""COMPUTED_VALUE"""),"The eye icon should change dynamically — show “open eye” when password is visible and “closed eye” when hidden") -> The eye icon should change dynamically — show “open eye” when password is visible and “closed eye” when hidden | I42: =IFERROR(__xludf.DUMMYFUNCTION("""COMPUTED_VALUE"""),"The icon remains the same (closed eye) regardless of visibility toggle") -> The icon remains the same (closed eye) regardless of visibility toggle | J42: =IFERROR(__xludf.DUMMYFUNCTION("""COMPUTED_VALUE"""),"Fail") -> Fail | K42: =IFERROR(__xludf.DUMMYFUNCTION("""COMPUTED_VALUE"""),"Low") -> Low | L42: =IFERROR(__xludf.DUMMYFUNCTION("""COMPUTED_VALUE"""),"https://jam.dev/c/6e192a78-56dc-4cd3-9d56-e6043e22abe0") -> https://jam.dev/c/6e192a78-56dc-4cd3-9d56-e6043e22abe0 | N42: =IFERROR(__xludf.DUMMYFUNCTION("""COMPUTED_VALUE"""),"Tahsin") -> Tahsin
...

Sheet Fahad
A2: Tester : | B2: Mohammed Fahad Faisal | E2: Severity | F2: Issues
A3: Project Name: | B3: VALR | E3: High | F3: =COUNTIF(Fahad!K8:K1004, "High") -> 13
A4: Developer: | B4: AI-Hunters | E4: Medium | F4: =COUNTIF(Fahad!K8:K1005, "Medium") -> 5
A5: OS: | B5: Windows 11 Pro Version:24H2 OS build:26100.4946 | E5: Low | F5: =COUNTIF(Tahsin!K13:K1008, "Low") -> 1
A6: Environment: | B6: Redmi Note 14 Xiomi Hyper OS (2.0.205.0) Android Version 15 AP3A.240905.015.A2
A8: Test ID | B8: Module | C8: Sub Module | D8: Test Case Description | E8: Preconditions | F8: Test Steps | G8: Test Data | H8: Expected Result | I8: Actual Result | J8: Status | K8: Severity | L8: Screen Shots | M8: Suggestion | N8: Feedback
