Workbook

Sheet Fahad
A1: Tester : | B1: Mohammed Fahad Faisal | E1: Severity | F1: Issues
A2: Project Name: | B2: CrewHub mobile app | E2: High | F2: =COUNTIF(Fahad!K8:K1003, "High") -> 28 | G2: Total Test Cases: | H2: =SUM(F2:F4) -> 42
A3: Developer: | B3: AI Thunder | E3: Medium | F3: =COUNTIF(Fahad!K8:K1004, "Medium") -> 11 | G3: Test Case Solved : | H3: =COUNTIF(N8:N2382, "Solved") -> 11
A4: OS: | B4: Windows 11 Pro Version:24H2 OS build:26100.4946 | E4: Low | F4: =COUNTIF(Fahad!K8:K1005, "Low") -> 3
A5: Environment: | B5: Brave 1.81.135 (Official Build) (64-bit) Chromium: 139.0.7258.127 | N5: Place solve if the issue resolves | \/ | O5: Mention which Stack solved the issue | \/
A7: Test ID | B7: Module | C7: Sub Module | D7: Test Case Description | E7: Preconditions | F7: Test Steps | G7: Test Data | H7: Expected Result | I7: Actual Result | J7: Status | K7: Severity | L7: Screen Shots | M7: Suggestion | N7: Feedback | O7: Stack | P7: Comment
A8: BR_001 | B8: Worker | C8: Mail | D8: Alignment issue in Mail body | E8: User need to install app on their mobile device | F8: 1. Open app 2. Register using necessary data | G8: Worker CREDENTIAL | H8: Alignment should be accurate in email body | I8: Alignment issue has been noticed | J8: Fail | K8: Low | L8: 001.png | N8: Solved
A10: BR_002 | B10: Worker | C10: Mail | D10: Mail is redirecting to localhost:3000, which isn’t accessible. | E10: User need to install app on their mobile device | F10: 1. Open app 2. Register using necessary data 3. Open mail body | G10: Worker CREDENTIAL | H10: Mail button redirect URL should be valid | I10: Redirecting to localhost port 3000 which is not accessible | J10: Fail | K10: Medium | L10: 002.png
A12: BR_003 | B12: Worker | C12: Certificate | D12: Failed to display Status in certificate | E12: User need to install app on their mobile device | F12: 1. Open app 2. Login using valid credentials 3. Goto Settings 4. Click on certificates | G12: Worker CREDENTIAL | H12: The certificate status should be properly displayed in the certificate list. | I12: Unable to display the certificate status | J12: Fail | K12: High | L12: 003.jpg | N12: Solved
A14: BR_004 | B14: Worker | C14: Profile | D14: Missing work experience data input in frontend | E14: User need to install app on their mobile device | F14: 1. Open app 2. Login using valid credentials 3. Goto Settings 4. Click on profile | G14: Worker CREDENTIAL | H14: App should include an input field as specified in the requirement. | I14: Experience field is missing in the app, even though it was part of the requirements. | J14: Fail | K14: High | L14: 004.jpg | N14: Solved
A16: BR_005 | B16: Worker | C16: Home | D16: Worker is available according to the calendar, but the display shows them as unavailable. | E16: User need to install app on their mobile device | F16: 1. Open app 2. Login using valid credentials 3. Goto Calender and set as available 4. Click on Home | G16: Worker CREDENTIAL | H16: Worker availability should be shown based on their calendar. | I16: Could not display the correct data | J16: Fail | K16: High | L16: 005.mp4 | N16: Solved
A18: BR_006 | B18: Worker | C18: Certificate | D18: Failed to display the notification for a certificate set to expire within one month. | E18: User need to install app on their mobile device | F18: 1. Open app 2. Login using valid credentials 3. Goto Certificate 4. Click on notification | G18: Worker CREDENTIAL | H18: Workers should receive push alerts 6 months, 3 months, and 1 month before cert expiry. | I18: Failed to receive push alert notification for certificate expiry. | J18: Fail | K18: High | L18: 006.mp4 | N18: Solved
A20: BR_007 | B20: Worker | C20: Home | D20: App keeps showing the network error message multiple times. | E20: User need to install app on their mobile device | F20: 1. Open app 2. Login using valid credentials 3. Close app and reopen again | G20: Worker CREDENTIAL | H20: Frontend should display the appropriate error message. | I20: A network error message appears at random times. | J20: Fail | K20: Medium | L20: 007.jpg | N20: Solved
A22: BR_008 | B22: Worker | C22: Certificate | D22: Unable to remove/update expired certificate | E22: User need to install app on their mobile device | F22: 1. Open app 2. Login using valid credentials 3. Goto Certificate | G22: Worker CREDENTIAL | H22: Users should be able to remove expired certificates or update them. | I22: Failed to replace/remove expire cert | J22: Fail | K22: High | L22: 008.jpg | N22: Solved
A24: BR_009 | B24: Worker | C24: Certificate | D24: Using "EXP." before the date doesn’t make sense when the field is already labeled for the expiration date. | E24: User need to install app on their mobile device | F24: 1. Open app 2. Login using valid credentials 3. Goto Certificate 4. Open Certificate | G24: Worker CREDENTIAL | H24: Only the date should be shown in the expiry section. | I24: "EXP." before the date isn’t relevant because the section is already for the expiration date. | J24: Fail | K24: Low | L24: 009.jpg | N24: Solved
A26: BR_010 | B26: Worker | C26: Certificate | D26: Should be the certificate issuer's name. | E26: User need to install app on their mobile device | F26: 1. Open app 2. Login using valid credentials 3. Goto Certificate 4. Open Certificate | G26: Worker CREDENTIAL | H26: Certificate data should be arranged according to the specified requirements. | I26: The issuer's name should go in the Last Name field. | J26: Fail | K26: Medium | L26: 010.jpg | N26: Solved
A28: BR_011 | B28: Worker | C28: Forget Password | D28: Login should be required after resetting the password. | E28: User need to install app on their mobile device | F28: 1. Open app 2. Open Login page 3. Click on Forget Password 4. reset password | G28: Worker CREDENTIAL | H28: User should be redirect to login page after they reset their password | I28: Failed to redirect, but a login popup appeared after it logged in automatically. | J28: Fail | K28: High | L28: 011.jpg
A30: BR_012 | B30: Recruiter | C30: Certificate | D30: Unable to download the worker certificate | E30: User need to install app on their mobile device | F30: 1. Open app 2. Login by recruiter credential 3. Download worker certificate | G30: Recruiter CREDENTIAL | H30: Recruiter should be able to download worker cert | I30: Failed to download worker cert | J30: Fail | K30: High | L30: 012.jpg | N30: Solved | P30: This feature wasn't mentioned by the client in the meeting | Q30: Was Mentioned in quotation and conversation
A32: BR_013 | B32: Recruiter | C32: Document | D32: Placeholder should be named as "Document Name" | E32: User need to install app on their mobile device | F32: 1. Open app 2. Login by recruiter credential 3. Goto Settings 4. Click on document | G32: Recruiter CREDENTIAL | H32: Recruiters should be able to submit different types of documents, so the placeholder name should reflect the document name. | I32: Placeholder name used as certificate name | J32: Fail | K32: Low | L32: 013.jpg
A34: BR_014 | B34: Recruiter | C34: Search | D34: Unable to search by category as mentioned in the requirement. | E34: User need to install app on their mobile device | F34: 1. Open app 2. Login by recruiter credential 3. Goto Search | G34: Recruiter CREDENTIAL | H34: Recruiters should be able to search for workers by trade or discipline, availability, and location as outlined in the requirements. | I34: A recruiter can search for a worker using their name or ID. | J34: Fail | K34: High | L34: 014.jpg | N34: Solved | P34: It's Already Working
A36: BR_015 | B36: Recruiter | C36: Search | D36: Random number appears on the worker's tag. | E36: User need to install app on their mobile device | F36: 1. Open app 2. Login by recruiter credential 3. Goto Search | G36: Recruiter CREDENTIAL | H36: The worker's tag should be displayed correctly on the search page. | I36: Random numbers are displayed on the worker's tag. | J36: Fail | K36: Medium | L36: 015.jpg
A38: BR_016 | B38: Worker | C38: Notification | D38: Failed to receive message notification | E38: User need to install app on their mobile device | F38: 1. Open app 2. Login using worker credentials 3. Goto notification / message | G38: Worker CREDENTIAL | H38: A message notification should appear when a worker logs in to the app or receives a message. | I38: Message notifications fail to appear when a worker logs in or is using the app. | J38: Fail | K38: High | L38: 016.jpg
A40: BR_017 | B40: Recruiter | C40: Login | D40: Failed to login using google login | E40: User need to install app on their mobile device | F40: 1. Open app 2. Login using google | G40: Recruiter CREDENTIAL | H40: Should be able to login with google login feature | I40: Failed to login using google login | J40: Fail | K40: High | L40: 017.jpg
A42: BR_018 | B42: Recruiter | C42: Login | D42: Remember me operation failed | E42: User need to install app on their mobile device | F42: 1. Open app 2. Goto Login Page | G42: Recruiter CREDENTIAL | H42: App should remember user credentials if they select the "remember me" option during login. | I42: The “Remember Me” option didn’t save the user credentials. | J42: Fail | K42: High | L42: 018.jpg
A44: BR_019 | B44: Recruiter | C44: OTP | D44: Clicking the back button closes the app instead of taking users to the login page. | E44: User need to install app on their mobile device | F44: 1. Open app 2. Goto Login Page 3. Click on forget password 4. provide email and goto OTP page | G44: Recruiter CREDENTIAL | H44: The back button should take the user to the home or login screen, and on the second click, it should either prompt them to quit the app or close it automatically. | I44: Close the app without prompting for confirmation | J44: Fail | K44: High | L44: 019.mp4
A46: BR_020 | B46: Worker | C46: Job Details | D46: Failed to display proper progress steps | E46: User need to install app on their mobile device | F46: 1. Open app 2. Login using worker credentials 3. Click on Jobs 4. Click on job details | G46: Worker CREDENTIAL | H46: Progress steps should properly displayed on workers job details | I46: Progress failed to show properly on the worker side. | J46: Fail | K46: High | L46: 020.jpg
A48: BR_021 | B48: Recruiter | C48: Job Details | D48: The progress mark is not set correctly in the recruiter dashboard. | E48: User need to install app on their mobile device | F48: 1. Open app 2. Goto Login Page 3. Click on job details | G48: Recruiter CREDENTIAL | H48: Progress steps should properly displayed on recruiter job details | I48: Progress failed to show properly on the worker side. | J48: Fail | K48: High | L48: 021.jpg
A50: BR_022 | B50: Worker | C50: Job Details | D50: Completed the job but still being asked to apply | E50: User need to install app on their mobile device | F50: 1. Open app 2. Login using worker credentials 3. Click on Jobs 4. Click on job details | G50: Worker CREDENTIAL | H50: Once a job is finished, it should be marked as complete and no longer available for applications. | I50: Can apply to expired job | J50: Fail | K50: High | L50: 022.jpg
A52: BR_023 | B52: Worker | C52: Job Details | D52: Unable to give a rating or review for a completed job from the worker's side. | E52: User need to install app on their mobile device | F52: 1. Open app 2. Login using worker credentials 3. Click on Jobs 4. Click on job details | G52: Worker CREDENTIAL | H52: Workers should be able to review(Food,Gym,Accommodation,Internet,Work environment) the job once it’s completed. | I52: Unable to review the job after it was completed on the worker's side. | J52: Fail | K52: High | L52: 023.jpg
A54: BR_024 | B54: Worker | C54: Job Details | D54: The 1-5 star rating is missing on the frontend. | E54: User need to install app on their mobile device | F54: 1. Open app 2. Login using worker credentials 3. Click on Jobs 4. Click on job details | G54: Worker CREDENTIAL | H54: Workers should be able to rate a job after completing it, and the rating should be displayed in the job details immediately. | I54: The rating system is missing from the job details once it’s completed. | J54: Fail | K54: High | L54: 024.jpg
A56: BR_025 | B56: Worker | C56: Job Details | D56: Unable to save job details once the job is completed. | E56: User need to install app on their mobile device | F56: 1. Open app 2. Login using worker credentials 3. Click on Jobs 4. Click on job details | G56: Worker CREDENTIAL | H56: Saved job should be displayed in save tag section | I56: Failed to display saved jobs | J56: Fail | K56: High | L56: 025.mp4
A58: BR_026 | B58: Worker | C58: Job Details | D58: Unable to comment on finished job | E58: User need to install app on their mobile device | F58: 1. Open app 2. Login using worker credentials 3. Click on Jobs 4. Click on job details | G58: Worker CREDENTIAL | H58: Workers should be able to leave a comment on a job after it’s finished, and it will be displayed in the job banner once approved by the admin. | I58: Missing comment section in job banner | J58: Fail | K58: High | L58: 026.jpg
... A90: BR_042 | B90: Worker | C90: Mail | D90: OTP alignment problem in the email body | E90: User need to install app on their mobile device | F90: 1. Open app 2. Register using necessary data 3. Open mail body | G90: Worker CREDENTIAL | H90: The alignment and design should be precise. | I90: An alignment issue has been spotted. | J90: Fail | K90: Medium | L90: 042.jpg
A92: BR_043
A94: BR_044
A96: BR_045
A98: BR_046
A100: BR_047
A102: BR_048

Sheet Tahsin
A2: Tester : | D2: Severity | E2: Issues
A3: Project Name: | D3: High | E3: =COUNTIF(K14:K897, "High") -> 0
A4: Project URL: | D4: Medium | E4: =COUNTIF(K14:K898, "Medium") -> 0
A5: Developer: | D5: Low | E5: =COUNTIF(K14:K899, "Low") -> 0
A6: OS:
A7: Environment | D7: Total Test Cases: | E7: =SUM(E3:E5) -> 0
D8: Test Case Solved :
A10: Test ID | B10: Module | C10: Sub Module | D10: Test Case Description | E10: Preconditions | F10: Test Steps | G10: Test Data | H10: Expected Result | I10: Actual Result | J10: Status | K10: Severity | L10: Screen Shots | M10: Suggestion | N10: Feedback | O10: Stack | P10: Comment

Sheet Summary Report
A1: Module | B1: Sub Module | C1: Test Case ID | D1: Bug Count | E1: Bug Rate % | F1: Bug Severity
A2: =IFERROR(__xludf.DUMMYFUNCTION("SORT( SPLIT( UNIQUE( FILTER('Main Report'!B11:B100 & ""♦"" & 'Main Report'!C11:C100, LEN('Main Report'!C11:C100)) ), ""♦"" ), 1, TRUE, 2, TRUE ) "),"Recruiter") -> Recruiter | B2: =IFERROR(__xludf.DUMMYFUNCTION("""COMPUTED_VALUE"""),"Applicant Details") -> Applicant Details | C2: =IFERROR(__xludf.DUMMYFUNCTION("TEXTJOIN("", "", TRUE, FILTER('Main Report'!A11:A100, ('Main Report'!B11:B100=A2) * ('Main Report'!C11:C100=B2) ) ) "),"BR-001") -> BR-001 | D2: =IFERROR(__xludf.DUMMYFUNCTION("COUNTA(UNIQUE(TRANSPOSE(SPLIT(C2, "", "")))) "),1.0) -> 1 | E2: =IF(D2="", "", TEXT((D2 / 'Main Report'!$E$7), "0.00%")) -> 2.38% | F2: =IFERROR(__xludf.DUMMYFUNCTION("IF(C2="""", """", TEXTJOIN("", "", TRUE, ""High: "" & COUNTIF(FILTER('Main Report'!K11:K100, ISNUMBER(MATCH('Main Report'!A11:A100, SPLIT(C2, "", ""), 0))), ""High"") & CHAR(10) & ""Medium: "" & COUNTIF(FILTER('Main Report'!K11:K100, ISNU"&"MBER(MATCH('Main Report'!A11:A100, SPLIT(C2, "", ""), 0))), ""Medium"") & CHAR(10) & ""Low: "" & COUNTIF(FILTER('Main Report'!K11:K100, ISNUMBER(MATCH('Main Report'!A11:A100, SPLIT(C2, "", ""), 0))), ""Low"") ) ) "),"High: 0 Medium: 1 Low: 0") -> High: 0 Medium: 1 Low: 0
A3: =IFERROR(__xludf.DUMMYFUNCTION("""COMPUTED_VALUE"""),"Recruiter") -> Recruiter | B3: =IFERROR(__xludf.DUMMYFUNCTION("""COMPUTED_VALUE"""),"Certificate") -> Certificate | C3: =IFERROR(__xludf.DUMMYFUNCTION("TEXTJOIN("", "", TRUE, FILTER('Main Report'!A12:A101, ('Main Report'!B12:B101=A3) * ('Main Report'!C12:C101=B3) ) ) "),"BR-002") -> BR-002 | D3: =IFERROR(__xludf.DUMMYFUNCTION("COUNTA(UNIQUE(TRANSPOSE(SPLIT(C3, "", "")))) "),1.0) -> 1 | E3: =IF(D3="", "", TEXT((D3 / 'Main Report'!$E$7), "0.00%")) -> 2.38% | F3: =IFERROR(__xludf.DUMMYFUNCTION("IF(C3="""", """", TEXTJOIN("", "", TRUE, ""High: "" & COUNTIF(FILTER('Main Report'!K12:K101, ISNUMBER(MATCH('Main Report'!A12:A101, SPLIT(C3, "", ""), 0))), ""High"") & CHAR(10) & ""Medium: "" & COUNTIF(FILTER('Main Report'!K12:K101, ISNU"&"MBER(MATCH('Main Report'!A12:A101, SPLIT(C3, "", ""), 0))), ""Medium"") & CHAR(10) & ""Low: "" & COUNTIF(FILTER('Main Report'!K12:K101, ISNUMBER(MATCH('Main Report'!A12:A101, SPLIT(C3, "", ""), 0))), ""Low"") ) ) "),"High: 1 Medium: 0 Low: 0") -> High: 1 Medium: 0 Low: 0
A4: =IFERROR(__xludf.DUMMYFUNCTION("""COMPUTED_VALUE"""),"Recruiter") -> Recruiter | B4: =IFERROR(__xludf.DUMMYFUNCTION("""COMPUTED_VALUE"""),"Chat") -> Chat | C4: =IFERROR(__xludf.DUMMYFUNCTION("TEXTJOIN("", "", TRUE, FILTER('Main Report'!A13:A102, ('Main Report'!B13:B102=A4) * ('Main Report'!C13:C102=B4) ) ) "),"BR-003") -> BR-003 | D4: =IFERROR(__xludf.DUMMYFUNCTION("COUNTA(UNIQUE(TRANSPOSE(SPLIT(C4, "", "")))) "),1.0) -> 1 | E4: =IF(D4="", "", TEXT((D4 / 'Main Report'!$E$7), "0.00%")) -> 2.38% | F4: =IFERROR(__xludf.DUMMYFUNCTION("IF(C4="""", """", TEXTJOIN("", "", TRUE, ""High: "" & COUNTIF(FILTER('Main Report'!K13:K102, ISNUMBER(MATCH('Main Report'!A13:A102, SPLIT(C4, "", ""), 0))), ""High"") & CHAR(10) & ""Medium: "" & COUNTIF(FILTER('Main Report'!K13:K102, ISNU"&"MBER(MATCH('Main Report'!A13:A102, SPLIT(C4, "", ""), 0))), ""Medium"") & CHAR(10) & ""Low: "" & COUNTIF(FILTER('Main Report'!K13:K102, ISNUMBER(MATCH('Main Report'!A13:A102, SPLIT(C4, "", ""), 0))), ""Low"") ) ) "),"High: 1 Medium: 0 Low: 0") -> High: 1 Medium: 0 Low: 0
A5: =IFERROR(__xludf.DUMMYFUNCTION("""COMPUTED_VALUE"""),"Recruiter") -> Recruiter | B5: =IFERROR(__xludf.DUMMYFUNCTION("""COMPUTED_VALUE"""),"Document") -> Document | C5: =IFERROR(__xludf.DUMMYFUNCTION("TEXTJOIN("", "", TRUE, FILTER('Main Report'!A14:A103, ('Main Report'!B14:B103=A5) * ('Main Report'!C14:C103=B5) ) ) "),"BR-004") -> BR-004 | D5: =IFERROR(__xludf.DUMMYFUNCTION("COUNTA(UNIQUE(TRANSPOSE(SPLIT(C5, "", "")))) "),1.0) -> 1 | E5: =IF(D5="", "", TEXT((D5 / 'Main Report'!$E$7), "0.00%")) -> 2.38% | F5: =IFERROR(__xludf.DUMMYFUNCTION("IF(C5="""", """", TEXTJOIN("", "", TRUE, ""High: "" & COUNTIF(FILTER('Main Report'!K14:K103, ISNUMBER(MATCH('Main Report'!A14:A103, SPLIT(C5, "", ""), 0))), ""High"") & CHAR(10) & ""Medium: "" & COUNTIF(FILTER('Main Report'!K14:K103, ISNU"&"MBER(MATCH('Main Report'!A14:A103, SPLIT(C5, "", ""), 0))), ""Medium"") & CHAR(10) & ""Low: "" & COUNTIF(FILTER('Main Report'!K14:K103, ISNUMBER(MATCH('Main Report'!A14:A103, SPLIT(C5, "", ""), 0))), ""Low"") ) ) "),"High: 0 Medium: 0 Low: 1") -> High: 0 Medium: 0 Low: 1
A6: =IFERROR(__xludf.DUMMYFUNCTION("""COMPUTED_VALUE"""),"Recruiter") -> Recruiter | B6: =IFERROR(__xludf.DUMMYFUNCTION("""COMPUTED_VALUE"""),"Forget Password") -> Forget Password | C6: =IFERROR(__xludf.DUMMYFUNCTION("TEXTJOIN("", "", TRUE, FILTER('Main Report'!A15:A104, ('Main Report'!B15:B104=A6) * ('Main Report'!C15:C104=B6) ) ) "),"BR-005, BR-006") -> BR-005, BR-006 | D6: =IFERROR(__xludf.DUMMYFUNCTION("COUNTA(UNIQUE(TRANSPOSE(SPLIT(C6, "", "")))) "),2.0) -> 2 | E6: =IF(D6="", "", TEXT((D6 / 'Main Report'!$E$7), "0.00%")) -> 4.76% | F6: =IFERROR(__xludf.DUMMYFUNCTION("IF(C6="""", """", TEXTJOIN("", "", TRUE, ""High: "" & COUNTIF(FILTER('Main Report'!K15:K104, ISNUMBER(MATCH('Main Report'!A15:A104, SPLIT(C6, "", ""), 0))), ""High"") & CHAR(10) & ""Medium: "" & COUNTIF(FILTER('Main Report'!K15:K104, ISNU"&"MBER(MATCH('Main Report'!A15:A104, SPLIT(C6, "", ""), 0))), ""Medium"") & CHAR(10) & ""Low: "" & COUNTIF(FILTER('Main Report'!K15:K104, ISNUMBER(MATCH('Main Report'!A15:A104, SPLIT(C6, "", ""), 0))), ""Low"") ) ) "),"High: 1 Medium: 1 Low: 0") -> High: 1 Medium: 1 Low: 0
A7: =IFERROR(__xludf.DUMMYFUNCTION("""COMPUTED_VALUE"""),"Recruiter") -> Recruiter | B7: =IFERROR(__xludf.DUMMYFUNCTION("""COMPUTED_VALUE"""),"Job Details") -> Job Details | C7: =IFERROR(__xludf.DUMMYFUNCTION("TEXTJOIN("", "", TRUE, FILTER('Main Report'!A16:A105, ('Main Report'!B16:B105=A7) * ('Main Report'!C16:C105=B7) ) ) "),"BR-007, BR-008, BR-009") -> BR-007, BR-008, BR-009 | D7: =IFERROR(__xludf.DUMMYFUNCTION("COUNTA(UNIQUE(TRANSPOSE(SPLIT(C7, "", "")))) "),3.0) -> 3 | E7: =IF(D7="", "", TEXT((D7 / 'Main Report'!$E$7), "0.00%")) -> 7.14% | F7: =IFERROR(__xludf.DUMMYFUNCTION("IF(C7="""", """", TEXTJOIN("", "", TRUE, ""High: "" & COUNTIF(FILTER('Main Report'!K16:K105, ISNUMBER(MATCH('Main Report'!A16:A105, SPLIT(C7, "", ""), 0))), ""High"") & CHAR(10) & ""Medium: "" & COUNTIF(FILTER('Main Report'!K16:K105, ISNU"&"MBER(MATCH('Main Report'!A16:A105, SPLIT(C7, "", ""), 0))), ""Medium"") & CHAR(10) & ""Low: "" & COUNTIF(FILTER('Main Report'!K16:K105, ISNUMBER(MATCH('Main Report'!A16:A105, SPLIT(C7, "", ""), 0))), ""Low"") ) ) "),"High: 3 Medium: 0 Low: 0") -> High: 3 Medium: 0 Low: 0
A8: =IFERROR(__xludf.DUMMYFUNCTION("""COMPUTED_VALUE"""),"Recruiter") -> Recruiter | B8: =IFERROR(__xludf.DUMMYFUNCTION("""COMPUTED_VALUE"""),"Login") -> Login | C8: =IFERROR(__xludf.DUMMYFUNCTION("TEXTJOIN("", "", TRUE, FILTER('Main Report'!A17:A106, ('Main Report'!B17:B106=A8) * ('Main Report'!C17:C106=B8) ) ) "),"BR-010, BR-011, BR-012") -> BR-010, BR-011, BR-012 | D8: =IFERROR(__xludf.DUMMYFUNCTION("COUNTA(UNIQUE(TRANSPOSE(SPLIT(C8, "", "")))) "),3.0) -> 3 | E8: =IF(D8="", "", TEXT((D8 / 'Main Report'!$E$7), "0.00%")) -> 7.14% | F8: =IFERROR(__xludf.DUMMYFUNCTION("IF(C8="""", """", TEXTJOIN("", "", TRUE, ""High: "" & COUNTIF(FILTER('Main Report'!K17:K106, ISNUMBER(MATCH('Main Report'!A17:A106, SPLIT(C8, "", ""), 0))), ""High"") & CHAR(10) & ""Medium: "" & COUNTIF(FILTER('Main Report'!K17:K106, ISNU"&"MBER(MATCH('Main Report'!A17:A106, SPLIT(C8, "", ""), 0))), ""Medium"") & CHAR(10) & ""Low: "" & COUNTIF(FILTER('Main Report'!K17:K106, ISNUMBER(MATCH('Main Report'!A17:A106, SPLIT(C8, "", ""), 0))), ""Low"") ) ) "),"High: 2 Medium: 1 Low: 0") -> High: 2 Medium: 1 Low: 0
A9: =IFERROR(__xludf.DUMMYFUNCTION("""COMPUTED_VALUE"""),"Recruiter") -> Recruiter | B9: =IFERROR(__xludf.DUMMYFUNCTION("""COMPUTED_VALUE"""),"OTP") -> OTP | C9: =IFERROR(__xludf.DUMMYFUNCTION("TEXTJOIN("", "", TRUE, FILTER('Main Report'!A18:A107, ('Main Report'!B18:B107=A9) * ('Main Report'!C18:C107=B9) ) ) "),"BR-013") -> BR-013 | D9: =IFERROR(__xludf.DUMMYFUNCTION("COUNTA(UNIQUE(TRANSPOSE(SPLIT(C9, "", "")))) "),1.0) -> 1 | E9: =IF(D9="", "", TEXT((D9 / 'Main Report'!$E$7), "0.00%")) -> 2.38% | F9: =IFERROR(__xludf.DUMMYFUNCTION("IF(C9="""", """", TEXTJOIN("", "", TRUE, ""High: "" & COUNTIF(FILTER('Main Report'!K18:K107, ISNUMBER(MATCH('Main Report'!A18:A107, SPLIT(C9, "", ""), 0))), ""High"") & CHAR(10) & ""Medium: "" & COUNTIF(FILTER('Main Report'!K18:K107, ISNU"&"MBER(MATCH('Main Report'!A18:A107, SPLIT(C9, "", ""), 0))), ""Medium"") & CHAR(10) & ""Low: "" & COUNTIF(FILTER('Main Report'!K18:K107, ISNUMBER(MATCH('Main Report'!A18:A107, SPLIT(C9, "", ""), 0))), ""Low"") ) ) "),"High: 1 Medium: 0 Low: 0") -> High: 1 Medium: 0 Low: 0
A10: =IFERROR(__xludf.DUMMYFUNCTION("""COMPUTED_VALUE"""),"Recruiter") -> Recruiter | B10: =IFERROR(__xludf.DUMMYFUNCTION("""COMPUTED_VALUE"""),"Search") -> Search | C10: =IFERROR(__xludf.DUMMYFUNCTION("TEXTJOIN("", "", TRUE, FILTER('Main Report'!A19:A108, ('Main Report'!B19:B108=A10) * ('Main Report'!C19:C108=B10) ) ) "),"BR-014, BR-015") -> BR-014, BR-015 | D10: =IFERROR(__xludf.DUMMYFUNCTION("COUNTA(UNIQUE(TRANSPOSE(SPLIT(C10, "", "")))) "),2.0) -> 2 | E10: =IF(D10="", "", TEXT((D10 / 'Main Report'!$E$7), "0.00%")) -> 4.76% | F10: =IFERROR(__xludf.DUMMYFUNCTION("IF(C10="""", """", TEXTJOIN("", "", TRUE, ""High: "" & COUNTIF(FILTER('Main Report'!K19:K108, ISNUMBER(MATCH('Main Report'!A19:A108, SPLIT(C10, "", ""), 0))), ""High"") & CHAR(10) & ""Medium: "" & COUNTIF(FILTER('Main Report'!K19:K108, IS"&"NUMBER(MATCH('Main Report'!A19:A108, SPLIT(C10, "", ""), 0))), ""Medium"") & CHAR(10) & ""Low: "" & COUNTIF(FILTER('Main Report'!K19:K108, ISNUMBER(MATCH('Main Report'!A19:A108, SPLIT(C10, "", ""), 0))), ""Low"") ) ) "),"High: 1 Medium: 1 Low: 0") -> High: 1 Medium: 1 Low: 0
A11: =IFERROR(__xludf.DUMMYFUNCTION("""COMPUTED_VALUE"""),"Worker") -> Worker | B11: =IFERROR(__xludf.DUMMYFUNCTION("""COMPUTED_VALUE"""),"Certificate") -> Certificate | C11: =IFERROR(__xludf.DUMMYFUNCTION("TEXTJOIN("", "", TRUE, FILTER('Main Report'!A20:A109, ('Main Report'!B20:B109=A11) * ('Main Report'!C20:C109=B11) ) ) "),"BR-016, BR-017, BR-018, BR-019, BR-020, BR-021") -> BR-016, BR-017, BR-018, BR-019, BR-020, BR-021 | D11: =IFERROR(__xludf.DUMMYFUNCTION("COUNTA(UNIQUE(TRANSPOSE(SPLIT(C11, "", "")))) "),6.0) -> 6 | E11: =IF(D11="", "", TEXT((D11 / 'Main Report'!$E$7), "0.00%")) -> 14.29% | F11: =IFERROR(__xludf.DUMMYFUNCTION("IF(C11="""", """", TEXTJOIN("", "", TRUE, ""High: "" & COUNTIF(FILTER('Main Report'!K20:K109, ISNUMBER(MATCH('Main Report'!A20:A109, SPLIT(C11, "", ""), 0))), ""High"") & CHAR(10) & ""Medium: "" & COUNTIF(FILTER('Main Report'!K20:K109, IS"&"NUMBER(MATCH('Main Report'!A20:A109, SPLIT(C11, "", ""), 0))), ""Medium"") & CHAR(10) & ""Low: "" & COUNTIF(FILTER('Main Report'!K20:K109, ISNUMBER(MATCH('Main Report'!A20:A109, SPLIT(C11, "", ""), 0))), ""Low"") ) ) "),"High: 4 Medium: 1 Low: 1") -> High: 4 Medium: 1 Low: 1
A12: =IFERROR(__xludf.DUMMYFUNCTION("""COMPUTED_VALUE"""),"Worker") -> Worker | B12: =IFERROR(__xludf.DUMMYFUNCTION("""COMPUTED_VALUE"""),"Forget Password") -> Forget Password | C12: =IFERROR(__xludf.DUMMYFUNCTION("TEXTJOIN("", "", TRUE, FILTER('Main Report'!A21:A110, ('Main Report'!B21:B110=A12) * ('Main Report'!C21:C110=B12) ) ) "),"BR-022") -> BR-022 | D12: =IFERROR(__xludf.DUMMYFUNCTION("COUNTA(UNIQUE(TRANSPOSE(SPLIT(C12, "", "")))) "),1.0) -> 1 | E12: =IF(D12="", "", TEXT((D12 / 'Main Report'!$E$7), "0.00%")) -> 2.38% | F12: =IFERROR(__xludf.DUMMYFUNCTION("IF(C12="""", """", TEXTJOIN("", "", TRUE, ""High: "" & COUNTIF(FILTER('Main Report'!K21:K110, ISNUMBER(MATCH('Main Report'!A21:A110, SPLIT(C12, "", ""), 0))), ""High"") & CHAR(10) & ""Medium: "" & COUNTIF(FILTER('Main Report'!K21:K110, IS"&"NUMBER(MATCH('Main Report'!A21:A110, SPLIT(C12, "", ""), 0))), ""Medium"") & CHAR(10) & ""Low: "" & COUNTIF(FILTER('Main Report'!K21:K110, ISNUMBER(MATCH('Main Report'!A21:A110, SPLIT(C12, "", ""), 0))), ""Low"") ) ) "),"High: 1 Medium: 0 Low: 0") -> High: 1 Medium: 0 Low: 0
A13: =IFERROR(__xludf.DUMMYFUNCTION("""COMPUTED_VALUE"""),"Worker") -> Worker | B13: =IFERROR(__xludf.DUMMYFUNCTION("""COMPUTED_VALUE"""),"Home") -> Home | C13: =IFERROR(__xludf.DUMMYFUNCTION("TEXTJOIN("", "", TRUE, FILTER('Main Report'!A22:A111, ('Main Report'!B22:B111=A13) * ('Main Report'!C22:C111=B13) ) ) "),"BR-023, BR-024, BR-025") -> BR-023, BR-024, BR-025 | D13: =IFERROR(__xludf.DUMMYFUNCTION("COUNTA(UNIQUE(TRANSPOSE(SPLIT(C13, "", "")))) "),3.0) -> 3 | E13: =IF(D13="", "", TEXT((D13 / 'Main Report'!$E$7), "0.00%")) -> 7.14% | F13: =IFERROR(__xludf.DUMMYFUNCTION("IF(C13="""", """", TEXTJOIN("", "", TRUE, ""High: "" & COUNTIF(FILTER('Main Report'!K22:K111, ISNUMBER(MATCH('Main Report'!A22:A111, SPLIT(C13, "", ""), 0))), ""High"") & CHAR(10) & ""Medium: "" & COUNTIF(FILTER('Main Report'!K22:K111, IS"&"NUMBER(MATCH('Main Report'!A22:A111, SPLIT(C13, "", ""), 0))), ""Medium"") & CHAR(10) & ""Low: "" & COUNTIF(FILTER('Main Report'!K22:K111, ISNUMBER(MATCH('Main Report'!A22:A111, SPLIT(C13, "", ""), 0))), ""Low"") ) ) "),"High: 2 Medium: 1 Low: 0") -> High: 2 Medium: 1 Low: 0
A14: =IFERROR(__xludf.DUMMYFUNCTION("""COMPUTED_VALUE"""),"Worker") -> Worker | B14: =IFERROR(__xludf.DUMMYFUNCTION("""COMPUTED_VALUE"""),"Job Details") -> Job Details | C14: =IFERROR(__xludf.DUMMYFUNCTION("TEXTJOIN("", "", TRUE, FILTER('Main Report'!A23:A112, ('Main Report'!B23:B112=A14) * ('Main Report'!C23:C112=B14) ) ) "),"BR-026, BR-027, BR-028, BR-029, BR-030, BR-031, BR-032, BR-033, BR-034, BR-035") -> BR-026, BR-027, BR-028, BR-029, BR-030, BR-031, BR-032, BR-033, BR-034, BR-035 | D14: =IFERROR(__xludf.DUMMYFUNCTION("COUNTA(UNIQUE(TRANSPOSE(SPLIT(C14, "", "")))) "),10.0) -> 10 | E14: =IF(D14="", "", TEXT((D14 / 'Main Report'!$E$7), "0.00%")) -> 23.81% | F14: =IFERROR(__xludf.DUMMYFUNCTION("IF(C14="""", """", TEXTJOIN("", "", TRUE, ""High: "" & COUNTIF(FILTER('Main Report'!K23:K112, ISNUMBER(MATCH('Main Report'!A23:A112, SPLIT(C14, "", ""), 0))), ""High"") & CHAR(10) & ""Medium: "" & COUNTIF(FILTER('Main Report'!K23:K112, IS"&"NUMBER(MATCH('Main Report'!A23:A112, SPLIT(C14, "", ""), 0))), ""Medium"") & CHAR(10) & ""Low: "" & COUNTIF(FILTER('Main Report'!K23:K112, ISNUMBER(MATCH('Main Report'!A23:A112, SPLIT(C14, "", ""), 0))), ""Low"") ) ) "),"High: 9 Medium: 1 Low: 0") -> High: 9 Medium: 1 Low: 0
A15: =IFERROR(__xludf.DUMMYFUNCTION("""COMPUTED_VALUE"""),"Worker") -> Worker | B15: =IFERROR(__xludf.DUMMYFUNCTION("""COMPUTED_VALUE"""),"Mail") -> Mail | C15: =IFERROR(__xludf.DUMMYFUNCTION("TEXTJOIN("", "", TRUE, FILTER('Main Report'!A24:A113, ('Main Report'!B24:B113=A15) * ('Main Report'!C24:C113=B15) ) ) "),"BR-036, BR-037, BR-038") -> BR-036, BR-037, BR-038 | D15: =IFERROR(__xludf.DUMMYFUNCTION("COUNTA(UNIQUE(TRANSPOSE(SPLIT(C15, "", "")))) "),3.0) -> 3 | E15: =IF(D15="", "", TEXT((D15 / 'Main Report'!$E$7), "0.00%")) -> 7.14% | F15: =IFERROR(__xludf.DUMMYFUNCTION("IF(C15="""", """", TEXTJOIN("", "", TRUE, ""High: "" & COUNTIF(FILTER('Main Report'!K24:K113, ISNUMBER(MATCH('Main Report'!A24:A113, SPLIT(C15, "", ""), 0))), ""High"") & CHAR(10) & ""Medium: "" & COUNTIF(FILTER('Main Report'!K24:K113, IS"&"NUMBER(MATCH('Main Report'!A24:A113, SPLIT(C15, "", ""), 0))), ""Medium"") & CHAR(10) & ""Low: "" & COUNTIF(FILTER('Main Report'!K24:K113, ISNUMBER(MATCH('Main Report'!A24:A113, SPLIT(C15, "", ""), 0))), ""Low"") ) ) "),"High: 0 Medium: 2 Low: 1") -> High: 0 Medium: 2 Low: 1
A16: =IFERROR(__xludf.DUMMYFUNCTION("""COMPUTED_VALUE"""),"Worker") -> Worker | B16: =IFERROR(__xludf.DUMMYFUNCTION("""COMPUTED_VALUE"""),"Notification") -> Notification | C16: =IFERROR(__xludf.DUMMYFUNCTION("TEXTJOIN("", "", TRUE, FILTER('Main Report'!A25:A114, ('Main Report'!B25:B114=A16) * ('Main Report'!C25:C114=B16) ) ) "),"BR-039, BR-040, BR-041") -> BR-039, BR-040, BR-041 | D16: =IFERROR(__xludf.DUMMYFUNCTION("COUNTA(UNIQUE(TRANSPOSE(SPLIT(C16, "", "")))) "),3.0) -> 3 | E16: =IF(D16="", "", TEXT((D16 / 'Main Report'!$E$7), "0.00%")) -> 7.14% | F16: =IFERROR(__xludf.DUMMYFUNCTION("IF(C16="""", """", TEXTJOIN("", "", TRUE, ""High: "" & COUNTIF(FILTER('Main Report'!K25:K114, ISNUMBER(MATCH('Main Report'!A25:A114, SPLIT(C16, "", ""), 0))), ""High"") & CHAR(10) & ""Medium: "" & COUNTIF(FILTER('Main Report'!K25:K114, IS"&"NUMBER(MATCH('Main Report'!A25:A114, SPLIT(C16, "", ""), 0))), ""Medium"") & CHAR(10) & ""Low: "" & COUNTIF(FILTER('Main Report'!K25:K114, ISNUMBER(MATCH('Main Report'!A25:A114, SPLIT(C16, "", ""), 0))), ""Low"") ) ) "),"High: 1 Medium: 2 Low: 0") -> High: 1 Medium: 2 Low: 0
A17: =IFERROR(__xludf.DUMMYFUNCTION("""COMPUTED_VALUE"""),"Worker") -> Worker | B17: =IFERROR(__xludf.DUMMYFUNCTION("""COMPUTED_VALUE"""),"Profile") -> Profile | C17: =IFERROR(__xludf.DUMMYFUNCTION("TEXTJOIN("", "", TRUE, FILTER('Main Report'!A26:A115, ('Main Report'!B26:B115=A17) * ('Main Report'!C26:C115=B17) ) ) "),"BR-042") -> BR-042 | D17: =IFERROR(__xludf.DUMMYFUNCTION("COUNTA(UNIQUE(TRANSPOSE(SPLIT(C17, "", "")))) "),1.0) -> 1 | E17: =IF(D17="", "", TEXT((D17 / 'Main Report'!$E$7), "0.00%")) -> 2.38% | F17: =IFERROR(__xludf.DUMMYFUNCTION("IF(C17="""", """", TEXTJOIN("", "", TRUE, ""High: "" & COUNTIF(FILTER('Main Report'!K26:K115, ISNUMBER(MATCH('Main Report'!A26:A115, SPLIT(C17, "", ""), 0))), ""High"") & CHAR(10) & ""Medium: "" & COUNTIF(FILTER('Main Report'!K26:K115, IS"&"NUMBER(MATCH('Main Report'!A26:A115, SPLIT(C17, "", ""), 0))), ""Medium"") & CHAR(10) & ""Low: "" & COUNTIF(FILTER('Main Report'!K26:K115, ISNUMBER(MATCH('Main Report'!A26:A115, SPLIT(C17, "", ""), 0))), ""Low"") ) ) "),"High: 1 Medium: 0 Low: 0") -> High: 1 Medium: 0 Low: 0
C18: =IFERROR(__xludf.DUMMYFUNCTION("TEXTJOIN("", "", TRUE, FILTER('Main Report'!A27:A116, ('Main Report'!B27:B116=A18) * ('Main Report'!C27:C116=B18) ) ) "),"") | E18: =IF(D18="", "", TEXT((D18 / 'Main Report'!$E$7), "0.00%")) | F18: =IFERROR(__xludf.DUMMYFUNCTION("IF(C18="""", """", TEXTJOIN("", "", TRUE, ""High: "" & COUNTIF(FILTER('Main Report'!K27:K116, ISNUMBER(MATCH('Main Report'!A27:A116, SPLIT(C18, "", ""), 0))), ""High"") & CHAR(10) & ""Medium: "" & COUNTIF(FILTER('Main Report'!K27:K116, IS"&"NUMBER(MATCH('Main Report'!A27:A116, SPLIT(C18, "", ""), 0))), ""Medium"") & CHAR(10) & ""Low: "" & COUNTIF(FILTER('Main Report'!K27:K116, ISNUMBER(MATCH('Main Report'!A27:A116, SPLIT(C18, "", ""), 0))), ""Low"") ) ) "),"")
C19: =IFERROR(__xludf.DUMMYFUNCTION("TEXTJOIN("", "", TRUE, FILTER('Main Report'!A28:A117, ('Main Report'!B28:B117=A19) * ('Main Report'!C28:C117=B19) ) ) "),"") | E19: =IF(D19="", "", TEXT((D19 / 'Main Report'!$E$7), "0.00%")) | F19: =IFERROR(__xludf.DUMMYFUNCTION("IF(C19="""", """", TEXTJOIN("", "", TRUE, ""High: "" & COUNTIF(FILTER('Main Report'!K28:K117, ISNUMBER(MATCH('Main Report'!A28:A117, SPLIT(C19, "", ""), 0))), ""High"") & CHAR(10) & ""Medium: "" & COUNTIF(FILTER('Main Report'!K28:K117, IS"&"NUMBER(MATCH('Main Report'!A28:A117, SPLIT(C19, "", ""), 0))), ""Medium"") & CHAR(10) & ""Low: "" & COUNTIF(FILTER('Main Report'!K28:K117, ISNUMBER(MATCH('Main Report'!A28:A117, SPLIT(C19, "", ""), 0))), ""Low"") ) ) "),"")
C20: =IFERROR(__xludf.DUMMYFUNCTION("TEXTJOIN("", "", TRUE, FILTER('Main Report'!A29:A118, ('Main Report'!B29:B118=A20) * ('Main Report'!C29:C118=B20) ) ) "),"") | E20: =IF(D20="", "", TEXT((D20 / 'Main Report'!$E$7), "0.00%")) | F20: =IFERROR(__xludf.DUMMYFUNCTION("IF(C20="""", """", TEXTJOIN("", "", TRUE, ""High: "" & COUNTIF(FILTER('Main Report'!K29:K118, ISNUMBER(MATCH('Main Report'!A29:A118, SPLIT(C20, "", ""), 0))), ""High"") & CHAR(10) & ""Medium: "" & COUNTIF(FILTER('Main Report'!K29:K118, IS"&"NUMBER(MATCH('Main Report'!A29:A118, SPLIT(C20, "", ""), 0))), ""Medium"") & CHAR(10) & ""Low: "" & COUNTIF(FILTER('Main Report'!K29:K118, ISNUMBER(MATCH('Main Report'!A29:A118, SPLIT(C20, "", ""), 0))), ""Low"") ) ) "),"")
C21: =IFERROR(__xludf.DUMMYFUNCTION("TEXTJOIN("", "", TRUE, FILTER('Main Report'!A30:A119, ('Main Report'!B30:B119=A21) * ('Main Report'!C30:C119=B21) ) ) "),"") | E21: =IF(D21="", "", TEXT((D21 / 'Main Report'!$E$7), "0.00%")) | F21: =IFERROR(__xludf.DUMMYFUNCTION("IF(C21="""", """", TEXTJOIN("", "", TRUE, ""High: "" & COUNTIF(FILTER('Main Report'!K30:K119, ISNUMBER(MATCH('Main Report'!A30:A119, SPLIT(C21, "", ""), 0))), ""High"") & CHAR(10) & ""Medium: "" & COUNTIF(FILTER('Main Report'!K30:K119, IS"&"NUMBER(MATCH('Main Report'!A30:A119, SPLIT(C21, "", ""), 0))), ""Medium"") & CHAR(10) & ""Low: "" & COUNTIF(FILTER('Main Report'!K30:K119, ISNUMBER(MATCH('Main Report'!A30:A119, SPLIT(C21, "", ""), 0))), ""Low"") ) ) "),"")

Sheet Main Report
A2: Tester : | B2: Mohammed Fahad Faisal | D2: Severity | E2: Issues
A3: Project Name: | B3: CrewHub | D3: High | E3: =COUNTIF(Tahsin!K14:K897, "High") + COUNTIF(Fahad!K8:K1004, "High") -> 28
A4: Project URL: | D4: Medium | E4: =COUNTIF(Tahsin!K14:K898, "Medium") + COUNTIF(Fahad!K8:K1005, "Medium") -> 11
A5: Developer: | B5: AI Thunder | D5: Low | E5: =COUNTIF(Fahad!K8:K1006, "Low") + COUNTIF(Tahsin!K14:K901, "Low") -> 3
A6: OS:
A7: Environment | D7: Total Test Cases: | E7: =SUM(E3:E5) -> 42
D8: Test Case Solved : | E8: =COUNTIF(N11:N2387, "Solved") -> 11
A10: Test Case ID | B10: Module | C10: Sub Module | D10: Test Case Description | E10: Preconditions | F10: Test Steps | G10: Test Data | H10: Expected Result | I10: Actual Result | J10: Status | K10: Severity | L10: Screen Shots | M10: Suggestion | N10: Feedback | O10: Stack | P10: Comment | Q10: Tester
A11: {=IF((LEN(B11:B100)+LEN(C11:C100))>0, "BR-" & TEXT(ROW(B11:B100)-ROW(B11)+1,"000"), "")} -> BR-001 | B11: =IFERROR(__xludf.DUMMYFUNCTION("QUERY( { ARRAYFORMULA({ TRIM(Fahad!B8:B2383), Fahad!C8:P2383, IF(LEN(Fahad!B8:B2383), ""Fahad"", """") }); ARRAYFORMULA({ TRIM(Tahsin!B15:B2383), Tahsin!C15:P2383, IF(LEN(Tahsin!B15:B2383), ""Tahsin"","&" """") }) }, ""SELECT * WHERE Col1 IS NOT NULL ORDER BY Col1 ASC, Col2 ASC"", 0 )"),"Recruiter") -> Recruiter | C11: =IFERROR(__xludf.DUMMYFUNCTION("""COMPUTED_VALUE"""),"Applicant Details") -> Applicant Details | D11: =IFERROR(__xludf.DUMMYFUNCTION("""COMPUTED_VALUE"""),"All applicant certificate expiry dates are shown in red, which can be confusing for recruiters, especially since the Figma design specifies that three colors should be used.") -> All applicant certificate expiry dates are shown in red, which can be confusing for recruiters, especially since the Figma design specifies that three colors should be used. | E11: =IFERROR(__xludf.DUMMYFUNCTION("""COMPUTED_VALUE"""),"User need to install app on their mobile device") -> User need to install app on their mobile device | F11: =IFERROR(__xludf.DUMMYFUNCTION("""COMPUTED_VALUE"""),"1. Open app 2. Goto Login Page 3. Click on job details 4. Click on applicant details") -> 1. Open app 2. Goto Login Page 3. Click on job details 4. Click on applicant details | G11: =IFERROR(__xludf.DUMMYFUNCTION("""COMPUTED_VALUE"""),"Recruiter CREDENTIAL") -> Recruiter CREDENTIAL | H11: =IFERROR(__xludf.DUMMYFUNCTION("""COMPUTED_VALUE"""),"According to the Figma design, there should be three colors (Green, Amber, Red) for certificates in the categories Up to Date, Expire Soon, and Expired.") -> According to the Figma design, there should be three colors (Green, Amber, Red) for certificates in the categories Up to Date, Expire Soon, and Expired. | I11: =IFERROR(__xludf.DUMMYFUNCTION("""COMPUTED_VALUE"""),"All are marked in red, which can cause confusion between expired and up-to-date certificates.") -> All are marked in red, which can cause confusion between expired and up-to-date certificates. | J11: =IFERROR(__xludf.DUMMYFUNCTION("""COMPUTED_VALUE"""),"Fail") -> Fail | K11: =IFERROR(__xludf.DUMMYFUNCTION("""COMPUTED_VALUE"""),"Medium") -> Medium | L11: =IFERROR(__xludf.DUMMYFUNCTION("""COMPUTED_VALUE"""),"033.jpg") -> 033.jpg | Q11: =IFERROR(__xludf.DUMMYFUNCTION("""COMPUTED_VALUE"""),"Fahad") -> Fahad
A12: BR-002 | B12: =IFERROR(__xludf.DUMMYFUNCTION("""COMPUTED_VALUE"""),"Recruiter") -> Recruiter | C12: =IFERROR(__xludf.DUMMYFUNCTION("""COMPUTED_VALUE"""),"Certificate") -> Certificate | D12: =IFERROR(__xludf.DUMMYFUNCTION("""COMPUTED_VALUE"""),"Unable to download the worker certificate") -> Unable to download the worker certificate | E12: =IFERROR(__xludf.DUMMYFUNCTION("""COMPUTED_VALUE"""),"User need to install app on their mobile device") -> User need to install app on their mobile device | F12: =IFERROR(__xludf.DUMMYFUNCTION("""COMPUTED_VALUE"""),"1. Open app 2. Login by recruiter credential 3. Download worker certificate") -> 1. Open app 2. Login by recruiter credential 3. Download worker certificate | G12: =IFERROR(__xludf.DUMMYFUNCTION("""COMPUTED_VALUE"""),"Recruiter CREDENTIAL") -> Recruiter CREDENTIAL | H12: =IFERROR(__xludf.DUMMYFUNCTION("""COMPUTED_VALUE"""),"Recruiter should be able to download worker cert") -> Recruiter should be able to download worker cert | I12: =IFERROR(__xludf.DUMMYFUNCTION("""COMPUTED_VALUE"""),"Failed to download worker cert") -> Failed to download worker cert | J12: =IFERROR(__xludf.DUMMYFUNCTION("""COMPUTED_VALUE"""),"Fail") -> Fail | K12: =IFERROR(__xludf.DUMMYFUNCTION("""COMPUTED_VALUE"""),"High") -> High | L12: =IFERROR(__xludf.DUMMYFUNCTION("""COMPUTED_VALUE"""),"012.jpg") -> 012.jpg | N12: =IFERROR(__xludf.DUMMYFUNCTION("""COMPUTED_VALUE"""),"Solved") -> Solved | P12: =IFERROR(__xludf.DUMMYFUNCTION("""COMPUTED_VALUE"""),"This feature wasn't mentioned by the client in the meeting") -> This feature wasn't mentioned by the client in the meeting | Q12: =IFERROR(__xludf.DUMMYFUNCTION("""COMPUTED_VALUE"""),"Fahad") -> Fahad
A13: BR-003 | B13: =IFERROR(__xludf.DUMMYFUNCTION("""COMPUTED_VALUE"""),"Recruiter") -> Recruiter | C13: =IFERROR(__xludf.DUMMYFUNCTION("""COMPUTED_VALUE"""),"Chat") -> Chat | D13: =IFERROR(__xludf.DUMMYFUNCTION("""COMPUTED_VALUE"""),"Should display last message time") -> Should display last message time | E13: =IFERROR(__xludf.DUMMYFUNCTION("""COMPUTED_VALUE"""),"User need to install app on their mobile device") -> User need to install app on their mobile device | F13: =IFERROR(__xludf.DUMMYFUNCTION("""COMPUTED_VALUE"""),"1. Open app 2. Goto Login Page 3. Click on Chat") -> 1. Open app 2. Goto Login Page 3. Click on Chat | G13: =IFERROR(__xludf.DUMMYFUNCTION("""COMPUTED_VALUE"""),"Recruiter CREDENTIAL") -> Recruiter CREDENTIAL | H13: =IFERROR(__xludf.DUMMYFUNCTION("""COMPUTED_VALUE"""),"The message time should be shown in the message bar on the right side.") -> The message time should be shown in the message bar on the right side. | I13: =IFERROR(__xludf.DUMMYFUNCTION("""COMPUTED_VALUE"""),"Unable to show the message time on the message bar.") -> Unable to show the message time on the message bar. | J13: =IFERROR(__xludf.DUMMYFUNCTION("""COMPUTED_VALUE"""),"Fail") -> Fail | K13: =IFERROR(__xludf.DUMMYFUNCTION("""COMPUTED_VALUE"""),"High") -> High | L13: =IFERROR(__xludf.DUMMYFUNCTION("""COMPUTED_VALUE"""),"030.jpg") -> 030.jpg | Q13: =IFERROR(__xludf.DUMMYFUNCTION("""COMPUTED_VALUE"""),"Fahad") -> Fahad
A14: BR-004 | B14: =IFERROR(__xludf.DUMMYFUNCTION("""COMPUTED_VALUE"""),"Recruiter") -> Recruiter | C14: =IFERROR(__xludf.DUMMYFUNCTION("""COMPUTED_VALUE"""),"Document") -> Document | D14: =IFERROR(__xludf.DUMMYFUNCTION("""COMPUTED_VALUE"""),"Placeholder should be named as ""Document Name""") -> Placeholder should be named as "Document Name" | E14: =IFERROR(__xludf.DUMMYFUNCTION("""COMPUTED_VALUE"""),"User need to install app on their mobile device") -> User need to install app on their mobile device | F14: =IFERROR(__xludf.DUMMYFUNCTION("""COMPUTED_VALUE"""),"1. Open app 2. Login by recruiter credential 3. Goto Settings 4. Click on document") -> 1. Open app 2. Login by recruiter credential 3. Goto Settings 4. Click on document | G14: =IFERROR(__xludf.DUMMYFUNCTION("""COMPUTED_VALUE"""),"Recruiter CREDENTIAL") -> Recruiter CREDENTIAL | H14: =IFERROR(__xludf.DUMMYFUNCTION("""COMPUTED_VALUE"""),"Recruiters should be able to submit different types of documents, so the placeholder name should reflect the document name.") -> Recruiters should be able to submit different types of documents, so the placeholder name should reflect the document name. | I14: =IFERROR(__xludf.DUMMYFUNCTION("""COMPUTED_VALUE"""),"Placeholder name used as certificate name") -> Placeholder name used as certificate name | J14: =IFERROR(__xludf.DUMMYFUNCTION("""COMPUTED_VALUE"""),"Fail") -> Fail | K14: =IFERROR(__xludf.DUMMYFUNCTION("""COMPUTED_VALUE"""),"Low") -> Low | L14: =IFERROR(__xludf.DUMMYFUNCTION("""COMPUTED_VALUE"""),"013.jpg") -> 013.jpg | Q14: =IFERROR(__xludf.DUMMYFUNCTION("""COMPUTED_VALUE"""),"Fahad") -> Fahad
A15: BR-005 | B15: =IFERROR(__xludf.DUMMYFUNCTION("""COMPUTED_VALUE"""),"Recruiter") -> Recruiter | C15: =IFERROR(__xludf.DUMMYFUNCTION("""COMPUTED_VALUE"""),"Forget Password") -> Forget Password | D15: =IFERROR(__xludf.DUMMYFUNCTION("""COMPUTED_VALUE"""),"Received OTP, but it showed as invalid.") -> Received OTP, but it showed as invalid. | E15: =IFERROR(__xludf.DUMMYFUNCTION("""COMPUTED_VALUE"""),"User need to install app on their mobile device") -> User need to install app on their mobile device | F15: =IFERROR(__xludf.DUMMYFUNCTION("""COMPUTED_VALUE"""),"1. Open app 2. Goto Login Page 3. Click on forget password") -> 1. Open app 2. Goto Login Page 3. Click on forget password | G15: =IFERROR(__xludf.DUMMYFUNCTION("""COMPUTED_VALUE"""),"Recruiter CREDENTIAL") -> Recruiter CREDENTIAL | H15: =IFERROR(__xludf.DUMMYFUNCTION("""COMPUTED_VALUE"""),"The user should be able to receive an OTP and submit it for verification.") -> The user should be able to receive an OTP and submit it for verification. | I15: =IFERROR(__xludf.DUMMYFUNCTION("""COMPUTED_VALUE"""),"Unable to submit the OTP after receiving it via email.") -> Unable to submit the OTP after receiving it via email. | J15: =IFERROR(__xludf.DUMMYFUNCTION("""COMPUTED_VALUE"""),"Fail") -> Fail | K15: =IFERROR(__xludf.DUMMYFUNCTION("""COMPUTED_VALUE"""),"High") -> High | L15: =IFERROR(__xludf.DUMMYFUNCTION("""COMPUTED_VALUE"""),"040.png") -> 040.png | Q15: =IFERROR(__xludf.DUMMYFUNCTION("""COMPUTED_VALUE"""),"Fahad") -> Fahad
A16: BR-006 | B16: =IFERROR(__xludf.DUMMYFUNCTION("""COMPUTED_VALUE"""),"Recruiter") -> Recruiter | C16: =IFERROR(__xludf.DUMMYFUNCTION("""COMPUTED_VALUE"""),"Forget Password") -> Forget Password | D16: =IFERROR(__xludf.DUMMYFUNCTION("""COMPUTED_VALUE"""),"Can't navigate to the login page from the OTP submission page.") -> Can't navigate to the login page from the OTP submission page. | E16: =IFERROR(__xludf.DUMMYFUNCTION("""COMPUTED_VALUE"""),"User need to install app on their mobile device") -> User need to install app on their mobile device | F16: =IFERROR(__xludf.DUMMYFUNCTION("""COMPUTED_VALUE"""),"1. Open app 2. Goto Login Page 3. Click on forget password") -> 1. Open app 2. Goto Login Page 3. Click on forget password | G16: =IFERROR(__xludf.DUMMYFUNCTION("""COMPUTED_VALUE"""),"Recruiter CREDENTIAL") -> Recruiter CREDENTIAL | H16: =IFERROR(__xludf.DUMMYFUNCTION("""COMPUTED_VALUE"""),"Users should be able to backtrack.") -> Users should be able to backtrack. | I16: =IFERROR(__xludf.DUMMYFUNCTION("""COMPUTED_VALUE"""),"Failed to backtrack and navigate to the desired page.") -> Failed to backtrack and navigate to the desired page. | J16: =IFERROR(__xludf.DUMMYFUNCTION("""COMPUTED_VALUE"""),"Fail") -> Fail | K16: =IFERROR(__xludf.DUMMYFUNCTION("""COMPUTED_VALUE"""),"Medium") -> Medium | L16: =IFERROR(__xludf.DUMMYFUNCTION("""COMPUTED_VALUE"""),"041.mp4") -> 041.mp4 | Q16: =IFERROR(__xludf.DUMMYFUNCTION("""COMPUTED_VALUE"""),"Fahad") -> Fahad
A17: BR-007 | B17: =IFERROR(__xludf.DUMMYFUNCTION("""COMPUTED_VALUE"""),"Recruiter") -> Recruiter | C17: =IFERROR(__xludf.DUMMYFUNCTION("""COMPUTED_VALUE"""),"Job Details") -> Job Details | D17: =IFERROR(__xludf.DUMMYFUNCTION("""COMPUTED_VALUE"""),"The progress mark is not set correctly in the recruiter dashboard.") -> The progress mark is not set correctly in the recruiter dashboard. | E17: =IFERROR(__xludf.DUMMYFUNCTION("""COMPUTED_VALUE"""),"User need to install app on their mobile device") -> User need to install app on their mobile device | F17: =IFERROR(__xludf.DUMMYFUNCTION("""COMPUTED_VALUE"""),"1. Open app 2. Goto Login Page 3. Click on job details") -> 1. Open app 2. Goto Login Page 3. Click on job details | G17: =IFERROR(__xludf.DUMMYFUNCTION("""COMPUTED_VALUE"""),"Recruiter CREDENTIAL") -> Recruiter CREDENTIAL | H17: =IFERROR(__xludf.DUMMYFUNCTION("""COMPUTED_VALUE"""),"Progress steps should properly displayed on recruiter job details") -> Progress steps should properly displayed on recruiter job details | I17: =IFERROR(__xludf.DUMMYFUNCTION("""COMPUTED_VALUE"""),"Progress failed to show properly on the worker side.") -> Progress failed to show properly on the worker side. | J17: =IFERROR(__xludf.DUMMYFUNCTION("""COMPUTED_VALUE"""),"Fail") -> Fail | K17: =IFERROR(__xludf.DUMMYFUNCTION("""COMPUTED_VALUE"""),"High") -> High | L17: =IFERROR(__xludf.DUMMYFUNCTION("""COMPUTED_VALUE"""),"021.jpg") -> 021.jpg | Q17: =IFERROR(__xludf.DUMMYFUNCTION("""COMPUTED_VALUE"""),"Fahad") -> Fahad
A18: BR-008 | B18: =IFERROR(__xludf.DUMMYFUNCTION("""COMPUTED_VALUE"""),"Recruiter") -> Recruiter | C18: =IFERROR(__xludf.DUMMYFUNCTION("""COMPUTED_VALUE"""),"Job Details") -> Job Details | D18: =IFERROR(__xludf.DUMMYFUNCTION("""COMPUTED_VALUE"""),"Location picker needs to be integrated.") -> Location picker needs to be integrated. | E18: =IFERROR(__xludf.DUMMYFUNCTION("""COMPUTED_VALUE"""),"User need to install app on their mobile device") -> User need to install app on their mobile device | F18: =IFERROR(__xludf.DUMMYFUNCTION("""COMPUTED_VALUE"""),"1. Open app 2. Goto Login Page 3. Click on job details") -> 1. Open app 2. Goto Login Page 3. Click on job details | G18: =IFERROR(__xludf.DUMMYFUNCTION("""COMPUTED_VALUE"""),"Recruiter CREDENTIAL") -> Recruiter CREDENTIAL | H18: =IFERROR(__xludf.DUMMYFUNCTION("""COMPUTED_VALUE"""),"Location picker should be integrated into the location input.") -> Location picker should be integrated into the location input. | I18: =IFERROR(__xludf.DUMMYFUNCTION("""COMPUTED_VALUE"""),"The absence of a location picker in the job section can cause confusion about the exact workplace.") -> The absence of a location picker in the job section can cause confusion about the exact workplace. | J18: =IFERROR(__xludf.DUMMYFUNCTION("""COMPUTED_VALUE"""),"Fail") -> Fail | K18: =IFERROR(__xludf.DUMMYFUNCTION("""COMPUTED_VALUE"""),"High") -> High | L18: =IFERROR(__xludf.DUMMYFUNCTION("""COMPUTED_VALUE"""),"029.jpg") -> 029.jpg | Q18: =IFERROR(__xludf.DUMMYFUNCTION("""COMPUTED_VALUE"""),"Fahad") -> Fahad
A19: BR-009 | B19: =IFERROR(__xludf.DUMMYFUNCTION("""COMPUTED_VALUE"""),"Recruiter") -> Recruiter | C19: =IFERROR(__xludf.DUMMYFUNCTION("""COMPUTED_VALUE"""),"Job Details") -> Job Details | D19: =IFERROR(__xludf.DUMMYFUNCTION("""COMPUTED_VALUE"""),"Certificate list is not integrated into the job details.") -> Certificate list is not integrated into the job details. | E19: =IFERROR(__xludf.DUMMYFUNCTION("""COMPUTED_VALUE"""),"User need to install app on their mobile device") -> User need to install app on their mobile device | F19: =IFERROR(__xludf.DUMMYFUNCTION("""COMPUTED_VALUE"""),"1. Open app 2. Goto Login Page 3. Click on job details") -> 1. Open app 2. Goto Login Page 3. Click on job details | G19: =IFERROR(__xludf.DUMMYFUNCTION("""COMPUTED_VALUE"""),"Recruiter CREDENTIAL") -> Recruiter CREDENTIAL | H19: =IFERROR(__xludf.DUMMYFUNCTION("""COMPUTED_VALUE"""),"The required cert input field should integrate a cert list that displays cert names in a dropdown or search format.") -> The required cert input field should integrate a cert list that displays cert names in a dropdown or search format. | I19: =IFERROR(__xludf.DUMMYFUNCTION("""COMPUTED_VALUE"""),"Missing certificate data in the required field can lead to workers not applying for a job due to a certificate mismatch.") -> Missing certificate data in the required field can lead to workers not applying for a job due to a certificate mismatch. | J19: =IFERROR(__xludf.DUMMYFUNCTION("""COMPUTED_VALUE"""),"Fail") -> Fail | K19: =IFERROR(__xludf.DUMMYFUNCTION("""COMPUTED_VALUE"""),"High") -> High | L19: =IFERROR(__xludf.DUMMYFUNCTION("""COMPUTED_VALUE"""),"031.jpg") -> 031.jpg | Q19: =IFERROR(__xludf.DUMMYFUNCTION("""COMPUTED_VALUE"""),"Fahad") -> Fahad
A20: BR-010 | B20: =IFERROR(__xludf.DUMMYFUNCTION("""COMPUTED_VALUE"""),"Recruiter") -> Recruiter | C20: =IFERROR(__xludf.DUMMYFUNCTION("""COMPUTED_VALUE"""),"Login") -> Login | D20: =IFERROR(__xludf.DUMMYFUNCTION("""COMPUTED_VALUE"""),"Failed to login using google login") -> Failed to login using google login | E20: =IFERROR(__xludf.DUMMYFUNCTION("""COMPUTED_VALUE"""),"User need to install app on their mobile device") -> User need to install app on their mobile device | F20: =IFERROR(__xludf.DUMMYFUNCTION("""COMPUTED_VALUE"""),"1. Open app 2. Login using google ") -> 1. Open app 2. Login using google | G20: =IFERROR(__xludf.DUMMYFUNCTION("""COMPUTED_VALUE"""),"Recruiter CREDENTIAL") -> Recruiter CREDENTIAL | H20: =IFERROR(__xludf.DUMMYFUNCTION("""COMPUTED_VALUE"""),"Should be able to login with google login feature") -> Should be able to login with google login feature | I20: =IFERROR(__xludf.DUMMYFUNCTION("""COMPUTED_VALUE"""),"Failed to login using google login") -> Failed to login using google login | J20: =IFERROR(__xludf.DUMMYFUNCTION("""COMPUTED_VALUE"""),"Fail") -> Fail | K20: =IFERROR(__xludf.DUMMYFUNCTION("""COMPUTED_VALUE"""),"High") -> High | L20: =IFERROR(__xludf.DUMMYFUNCTION("""COMPUTED_VALUE"""),"017.jpg") -> 017.jpg | Q20: =IFERROR(__xludf.DUMMYFUNCTION("""COMPUTED_VALUE"""),"Fahad") -> Fahad
A21: BR-011 | B21: =IFERROR(__xludf.DUMMYFUNCTION("""COMPUTED_VALUE"""),"Recruiter") -> Recruiter | C21: =IFERROR(__xludf.DUMMYFUNCTION("""COMPUTED_VALUE"""),"Login") -> Login | D21: =IFERROR(__xludf.DUMMYFUNCTION("""COMPUTED_VALUE"""),"Remember me operation failed") -> Remember me operation failed | E21: =IFERROR(__xludf.DUMMYFUNCTION("""COMPUTED_VALUE"""),"User need to install app on their mobile device") -> User need to install app on their mobile device | F21: =IFERROR(__xludf.DUMMYFUNCTION("""COMPUTED_VALUE"""),"1. Open app 2. Goto Login Page") -> 1. Open app 2. Goto Login Page | G21: =IFERROR(__xludf.DUMMYFUNCTION("""COMPUTED_VALUE"""),"Recruiter CREDENTIAL") -> Recruiter CREDENTIAL | H21: =IFERROR(__xludf.DUMMYFUNCTION("""COMPUTED_VALUE"""),"App should remember user credentials if they select the ""remember me"" option during login.") -> App should remember user credentials if they select the "remember me" option during login. | I21: =IFERROR(__xludf.DUMMYFUNCTION("""COMPUTED_VALUE"""),"The “Remember Me” option didn’t save the user credentials.") -> The “Remember Me” option didn’t save the user credentials. | J21: =IFERROR(__xludf.DUMMYFUNCTION("""COMPUTED_VALUE"""),"Fail") -> Fail | K21: =IFERROR(__xludf.DUMMYFUNCTION("""COMPUTED_VALUE"""),"High") -> High | L21: =IFERROR(__xludf.DUMMYFUNCTION("""COMPUTED_VALUE"""),"018.jpg") -> 018.jpg | Q21: =IFERROR(__xludf.DUMMYFUNCTION("""COMPUTED_VALUE"""),"Fahad") -> Fahad
A22: BR-012 | B22: =IFERROR(__xludf.DUMMYFUNCTION("""COMPUTED_VALUE"""),"Recruiter") -> Recruiter | C22: =IFERROR(__xludf.DUMMYFUNCTION("""COMPUTED_VALUE"""),"Login") -> Login | D22: =IFERROR(__xludf.DUMMYFUNCTION("""COMPUTED_VALUE"""),"Need to set up Apple Sign-In.") -> Need to set up Apple Sign-In. | E22: =IFERROR(__xludf.DUMMYFUNCTION("""COMPUTED_VALUE"""),"User need to install app on their mobile device") -> User need to install app on their mobile device | F22: =IFERROR(__xludf.DUMMYFUNCTION("""COMPUTED_VALUE"""),"1. Open app 2. Goto Login Page") -> 1. Open app 2. Goto Login Page | G22: =IFERROR(__xludf.DUMMYFUNCTION("""COMPUTED_VALUE"""),"N/A") -> N/A | H22: =IFERROR(__xludf.DUMMYFUNCTION("""COMPUTED_VALUE"""),"The app should include Apple login integration.") -> The app should include Apple login integration. | I22: =IFERROR(__xludf.DUMMYFUNCTION("""COMPUTED_VALUE"""),"Missing apple login") -> Missing apple login | J22: =IFERROR(__xludf.DUMMYFUNCTION("""COMPUTED_VALUE"""),"Fail") -> Fail | K22: =IFERROR(__xludf.DUMMYFUNCTION("""COMPUTED_VALUE"""),"Medium") -> Medium | L22: =IFERROR(__xludf.DUMMYFUNCTION("""COMPUTED_VALUE"""),"037.jpg") -> 037.jpg | Q22: =IFERROR(__xludf.DUMMYFUNCTION("""COMPUTED_VALUE"""),"Fahad") -> Fahad
A23: BR-013 | B23: =IFERROR(__xludf.DUMMYFUNCTION("""COMPUTED_VALUE"""),"Recruiter") -> Recruiter | C23: =IFERROR(__xludf.DUMMYFUNCTION("""COMPUTED_VALUE"""),"OTP") -> OTP | D23: =IFERROR(__xludf.DUMMYFUNCTION("""COMPUTED_VALUE"""),"Clicking the back button closes the app instead of taking users to the login page.") -> Clicking the back button closes the app instead of taking users to the login page. | E23: =IFERROR(__xludf.DUMMYFUNCTION("""COMPUTED_VALUE"""),"User need to install app on their mobile device") -> User need to install app on their mobile device | F23: =IFERROR(__xludf.DUMMYFUNCTION("""COMPUTED_VALUE"""),"1. Open app 2. Goto Login Page 3. Click on forget password 4. provide email and goto OTP page") -> 1. Open app 2. Goto Login Page 3. Click on forget password 4. provide email and goto OTP page | G23: =IFERROR(__xludf.DUMMYFUNCTION("""COMPUTED_VALUE"""),"Recruiter CREDENTIAL") -> Recruiter CREDENTIAL | H23: =IFERROR(__xludf.DUMMYFUNCTION("""COMPUTED_VALUE"""),"The back button should take the user to the home or login screen, and on the second click, it should either prompt them to quit the app or close it automatically.") -> The back button should take the user to the home or login screen, and on the second click, it should either prompt them to quit the app or close it automatically. | I23: =IFERROR(__xludf.DUMMYFUNCTION("""COMPUTED_VALUE"""),"Close the app without prompting for confirmation") -> Close the app without prompting for confirmation | J23: =IFERROR(__xludf.DUMMYFUNCTION("""COMPUTED_VALUE"""),"Fail") -> Fail | K23: =IFERROR(__xludf.DUMMYFUNCTION("""COMPUTED_VALUE"""),"High") -> High | L23: =IFERROR(__xludf.DUMMYFUNCTION("""COMPUTED_VALUE"""),"019.mp4") -> 019.mp4 | Q23: =IFERROR(__xludf.DUMMYFUNCTION("""COMPUTED_VALUE"""),"Fahad") -> Fahad
A24: BR-014 | B24: =IFERROR(__xludf.DUMMYFUNCTION("""COMPUTED_VALUE"""),"Recruiter") -> Recruiter | C24: =IFERROR(__xludf.DUMMYFUNCTION("""COMPUTED_VALUE"""),"Search") -> Search | D24: =IFERROR(__xludf.DUMMYFUNCTION("""COMPUTED_VALUE"""),"Unable to search by category as mentioned in the requirement.") -> Unable to search by category as mentioned in the requirement. | E24: =IFERROR(__xludf.DUMMYFUNCTION("""COMPUTED_VALUE"""),"User need to install app on their mobile device") -> User need to install app on their mobile device | F24: =IFERROR(__xludf.DUMMYFUNCTION("""COMPUTED_VALUE"""),"1. Open app 2. Login by recruiter credential 3. Goto Search") -> 1. Open app 2. Login by recruiter credential 3. Goto Search | G24: =IFERROR(__xludf.DUMMYFUNCTION("""COMPUTED_VALUE"""),"Recruiter CREDENTIAL") -> Recruiter CREDENTIAL | H24: =IFERROR(__xludf.DUMMYFUNCTION("""COMPUTED_VALUE"""),"Recruiters should be able to search for workers by trade or discipline, availability, and location as outlined in the requirements.") -> Recruiters should be able to search for workers by trade or discipline, availability, and location as outlined in the requirements. | I24: =IFERROR(__xludf.DUMMYFUNCTION("""COMPUTED_VALUE"""),"A recruiter can search for a worker using their name or ID.") -> A recruiter can search for a worker using their name or ID. | J24: =IFERROR(__xludf.DUMMYFUNCTION("""COMPUTED_VALUE"""),"Fail") -> Fail | K24: =IFERROR(__xludf.DUMMYFUNCTION("""COMPUTED_VALUE"""),"High") -> High | L24: =IFERROR(__xludf.DUMMYFUNCTION("""COMPUTED_VALUE"""),"014.jpg") -> 014.jpg | N24: =IFERROR(__xludf.DUMMYFUNCTION("""COMPUTED_VALUE"""),"Solved") -> Solved | P24: =IFERROR(__xludf.DUMMYFUNCTION("""COMPUTED_VALUE"""),"It's Already Working") -> It's Already Working | Q24: =IFERROR(__xludf.DUMMYFUNCTION("""COMPUTED_VALUE"""),"Fahad") -> Fahad
A25: BR-015 | B25: =IFERROR(__xludf.DUMMYFUNCTION("""COMPUTED_VALUE"""),"Recruiter") -> Recruiter | C25: =IFERROR(__xludf.DUMMYFUNCTION("""COMPUTED_VALUE"""),"Search") -> Search | D25: =IFERROR(__xludf.DUMMYFUNCTION("""COMPUTED_VALUE"""),"Random number appears on the worker's tag.") -> Random number appears on the worker's tag. | E25: =IFERROR(__xludf.DUMMYFUNCTION("""COMPUTED_VALUE"""),"User need to install app on their mobile device") -> User need to install app on their mobile device | F25: =IFERROR(__xludf.DUMMYFUNCTION("""COMPUTED_VALUE"""),"1. Open app 2. Login by recruiter credential 3. Goto Search") -> 1. Open app 2. Login by recruiter credential 3. Goto Search | G25: =IFERROR(__xludf.DUMMYFUNCTION("""COMPUTED_VALUE"""),"Recruiter CREDENTIAL") -> Recruiter CREDENTIAL | H25: =IFERROR(__xludf.DUMMYFUNCTION("""COMPUTED_VALUE"""),"The worker's tag should be displayed correctly on the search page.") -> The worker's tag should be displayed correctly on the search page. | I25: =IFERROR(__xludf.DUMMYFUNCTION("""COMPUTED_VALUE"""),"Random numbers are displayed on the worker's tag.") -> Random numbers are displayed on the worker's tag. | J25: =IFERROR(__xludf.DUMMYFUNCTION("""COMPUTED_VALUE"""),"Fail") -> Fail | K25: =IFERROR(__xludf.DUMMYFUNCTION("""COMPUTED_VALUE"""),"Medium") -> Medium | L25: =IFERROR(__xludf.DUMMYFUNCTION("""COMPUTED_VALUE"""),"015.jpg") -> 015.jpg | Q25: =IFERROR(__xludf.DUMMYFUNCTION("""COMPUTED_VALUE"""),"Fahad") -> Fahad
