Workbook

Sheet Main Report
A2: Tester : | B2: Mohammed Fahad Faisal | D2: Severity | E2: Issues
A3: Project Name: | D3: High | E3: =COUNTIF(Tahsin!K14:K1005, "High") + COUNTIF(Fahad!K8:K1004, "High") -> 22
A4: Project URL: | D4: Medium | E4: =COUNTIF(Tahsin!K14:K1006, "Medium") + COUNTIF(Fahad!K8:K1005, "Medium") -> 17
A5: Developer: | D5: Low | E5: =COUNTIF(Fahad!K8:K1006, "Low") + COUNTIF(Tahsin!K14:K1009, "Low") -> 1
A6: OS:
A7: Environment | D7: Total Test Cases: | E7: =SUM(E3:E5) -> 40 | O7: Place solve if the issue resolves I V | P7: Mention which Stack solved the issue I V
D8: Test Case Solved : | E8: =COUNTIF(O11:O1003, "Solved") -> 0
A10: Test Case ID | B10: Module | C10: Sub Module | D10: Test Case Description | E10: Preconditions | F10: Test Steps | G10: Test Data | H10: Expected Result | I10: Actual Result | J10: Status | K10: Severity | L10: Screen Shots | M10: Suggestion | N10: Tester | O10: Feedback | P10: Stack | Q10: Comment
A11: {=IF((LEN(B11:B1000)+LEN(C11:C1000))>0, "BR-" & TEXT(ROW(B11:B1000)-ROW(B11)+1,"000"), "")} -> BR-001 | B11: =IFERROR(__xludf.DUMMYFUNCTION("QUERY( { ARRAYFORMULA({TRIM(Fahad!B8:B999), Fahad!C8:M999, IF(LEN(Fahad!B8:B999), ""Fahad"", """")}); ARRAYFORMULA({TRIM(Tahsin!B15:B999), Tahsin!C15:M999, IF(LEN(Tahsin!B15:B999), ""Tahsin"", """")}) }, ""SELECT * WHERE Col1 IS NOT NULL ORD"&"ER BY Col1 ASC, Col2 ASC"", 0 ) "),"Account") -> Account | C11: =IFERROR(__xludf.DUMMYFUNCTION("""COMPUTED_VALUE"""),"Account") -> Account | D11: =IFERROR(__xludf.DUMMYFUNCTION("""COMPUTED_VALUE"""),"Different from UI") -> Different from UI | E11: =IFERROR(__xludf.DUMMYFUNCTION("""COMPUTED_VALUE"""),"User need to install the app in their android device") -> User need to install the app in their android device | F11: =IFERROR(__xludf.DUMMYFUNCTION("""COMPUTED_VALUE"""),"1. Open app 2. Sign-in using valid credential 3. Select driver role 4. Click on Account") -> 1. Open app 2. Sign-in using valid credential 3. Select driver role 4. Click on Account | G11: =IFERROR(__xludf.DUMMYFUNCTION("""COMPUTED_VALUE"""),"Driver Credentials") -> Driver Credentials | H11: =IFERROR(__xludf.DUMMYFUNCTION("""COMPUTED_VALUE"""),"The design and alignments should be as accurate as in Figma.") -> The design and alignments should be as accurate as in Figma. | I11: =IFERROR(__xludf.DUMMYFUNCTION("""COMPUTED_VALUE"""),"Noticed a different design implementation in the app.") -> Noticed a different design implementation in the app. | J11: =IFERROR(__xludf.DUMMYFUNCTION("""COMPUTED_VALUE"""),"Fail") -> Fail | K11: =IFERROR(__xludf.DUMMYFUNCTION("""COMPUTED_VALUE"""),"Medium") -> Medium | L11: =IFERROR(__xludf.DUMMYFUNCTION("""COMPUTED_VALUE"""),"031.png") -> 031.png | N11: =IFERROR(__xludf.DUMMYFUNCTION("""COMPUTED_VALUE"""),"Fahad") -> Fahad
A12: BR-002 | B12: =IFERROR(__xludf.DUMMYFUNCTION("""COMPUTED_VALUE"""),"Account") -> Account | C12: =IFERROR(__xludf.DUMMYFUNCTION("""COMPUTED_VALUE"""),"Account") -> Account | D12: =IFERROR(__xludf.DUMMYFUNCTION("""COMPUTED_VALUE"""),"Flow broken. Unable to add wallet card in app") -> Flow broken. Unable to add wallet card in app | E12: =IFERROR(__xludf.DUMMYFUNCTION("""COMPUTED_VALUE"""),"User need to install the app in their android device") -> User need to install the app in their android device | F12: =IFERROR(__xludf.DUMMYFUNCTION("""COMPUTED_VALUE"""),"1. Open app 2. Sign-in using valid credential 3. Select driver role 4. Click on Account") -> 1. Open app 2. Sign-in using valid credential 3. Select driver role 4. Click on Account | G12: =IFERROR(__xludf.DUMMYFUNCTION("""COMPUTED_VALUE"""),"Driver Credentials") -> Driver Credentials | H12: =IFERROR(__xludf.DUMMYFUNCTION("""COMPUTED_VALUE"""),"The flow should be accurate according to the Figma design.") -> The flow should be accurate according to the Figma design. | I12: =IFERROR(__xludf.DUMMYFUNCTION("""COMPUTED_VALUE"""),"The app is missing a feature that allows adding a wallet card to the driver profile.") -> The app is missing a feature that allows adding a wallet card to the driver profile. | J12: =IFERROR(__xludf.DUMMYFUNCTION("""COMPUTED_VALUE"""),"Fail") -> Fail | K12: =IFERROR(__xludf.DUMMYFUNCTION("""COMPUTED_VALUE"""),"High") -> High | L12: =IFERROR(__xludf.DUMMYFUNCTION("""COMPUTED_VALUE"""),"032.png") -> 032.png | N12: =IFERROR(__xludf.DUMMYFUNCTION("""COMPUTED_VALUE"""),"Fahad") -> Fahad
A13: BR-003 | B13: =IFERROR(__xludf.DUMMYFUNCTION("""COMPUTED_VALUE"""),"Account") -> Account | C13: =IFERROR(__xludf.DUMMYFUNCTION("""COMPUTED_VALUE"""),"Account") -> Account | D13: =IFERROR(__xludf.DUMMYFUNCTION("""COMPUTED_VALUE"""),"Missing email input field in app") -> Missing email input field in app | E13: =IFERROR(__xludf.DUMMYFUNCTION("""COMPUTED_VALUE"""),"User need to install the app in their android device") -> User need to install the app in their android device | F13: =IFERROR(__xludf.DUMMYFUNCTION("""COMPUTED_VALUE"""),"1. Open app 2. Sign-in using valid credential 3. Select driver role 4. Click on Account") -> 1. Open app 2. Sign-in using valid credential 3. Select driver role 4. Click on Account | G13: =IFERROR(__xludf.DUMMYFUNCTION("""COMPUTED_VALUE"""),"Driver Credentials") -> Driver Credentials | H13: =IFERROR(__xludf.DUMMYFUNCTION("""COMPUTED_VALUE"""),"The input field should be positioned precisely as shown in the Figma design.") -> The input field should be positioned precisely as shown in the Figma design. | I13: =IFERROR(__xludf.DUMMYFUNCTION("""COMPUTED_VALUE"""),"Missing input field in app") -> Missing input field in app | J13: =IFERROR(__xludf.DUMMYFUNCTION("""COMPUTED_VALUE"""),"Fail") -> Fail | K13: =IFERROR(__xludf.DUMMYFUNCTION("""COMPUTED_VALUE"""),"High") -> High | L13: =IFERROR(__xludf.DUMMYFUNCTION("""COMPUTED_VALUE"""),"033.png") -> 033.png | N13: =IFERROR(__xludf.DUMMYFUNCTION("""COMPUTED_VALUE"""),"Fahad") -> Fahad
A14: BR-004 | B14: =IFERROR(__xludf.DUMMYFUNCTION("""COMPUTED_VALUE"""),"Account") -> Account | C14: =IFERROR(__xludf.DUMMYFUNCTION("""COMPUTED_VALUE"""),"Account") -> Account | D14: =IFERROR(__xludf.DUMMYFUNCTION("""COMPUTED_VALUE"""),"Missing update password field in app") -> Missing update password field in app | E14: =IFERROR(__xludf.DUMMYFUNCTION("""COMPUTED_VALUE"""),"User need to install the app in their android device") -> User need to install the app in their android device | F14: =IFERROR(__xludf.DUMMYFUNCTION("""COMPUTED_VALUE"""),"1. Open app 2. Sign-in using valid credential 3. Select driver role 4. Click on Account") -> 1. Open app 2. Sign-in using valid credential 3. Select driver role 4. Click on Account | G14: =IFERROR(__xludf.DUMMYFUNCTION("""COMPUTED_VALUE"""),"Driver Credentials") -> Driver Credentials | H14: =IFERROR(__xludf.DUMMYFUNCTION("""COMPUTED_VALUE"""),"Features and functionalities should be implemented correctly.") -> Features and functionalities should be implemented correctly. | I14: =IFERROR(__xludf.DUMMYFUNCTION("""COMPUTED_VALUE"""),"Missing feature noticed") -> Missing feature noticed | J14: =IFERROR(__xludf.DUMMYFUNCTION("""COMPUTED_VALUE"""),"Fail") -> Fail | K14: =IFERROR(__xludf.DUMMYFUNCTION("""COMPUTED_VALUE"""),"High") -> High | L14: =IFERROR(__xludf.DUMMYFUNCTION("""COMPUTED_VALUE"""),"034.png") -> 034.png | N14: =IFERROR(__xludf.DUMMYFUNCTION("""COMPUTED_VALUE"""),"Fahad") -> Fahad
A15: BR-005 | B15: =IFERROR(__xludf.DUMMYFUNCTION("""COMPUTED_VALUE"""),"Account") -> Account | C15: =IFERROR(__xludf.DUMMYFUNCTION("""COMPUTED_VALUE"""),"Account") -> Account | D15: =IFERROR(__xludf.DUMMYFUNCTION("""COMPUTED_VALUE"""),"Button is not functional") -> Button is not functional | E15: =IFERROR(__xludf.DUMMYFUNCTION("""COMPUTED_VALUE"""),"User need to install the app in their android device") -> User need to install the app in their android device | F15: =IFERROR(__xludf.DUMMYFUNCTION("""COMPUTED_VALUE"""),"1. Open app 2. Sign-in using valid credential 3. Select driver role 4. Click on Account") -> 1. Open app 2. Sign-in using valid credential 3. Select driver role 4. Click on Account | G15: =IFERROR(__xludf.DUMMYFUNCTION("""COMPUTED_VALUE"""),"Driver Credentials") -> Driver Credentials | H15: =IFERROR(__xludf.DUMMYFUNCTION("""COMPUTED_VALUE"""),"Features and functionalities should be implemented correctly.") -> Features and functionalities should be implemented correctly. | I15: =IFERROR(__xludf.DUMMYFUNCTION("""COMPUTED_VALUE"""),"Missing feature noticed") -> Missing feature noticed | J15: =IFERROR(__xludf.DUMMYFUNCTION("""COMPUTED_VALUE"""),"Fail") -> Fail | K15: =IFERROR(__xludf.DUMMYFUNCTION("""COMPUTED_VALUE"""),"High") -> High | L15: =IFERROR(__xludf.DUMMYFUNCTION("""COMPUTED_VALUE"""),"035.png") -> 035.png | N15: =IFERROR(__xludf.DUMMYFUNCTION("""COMPUTED_VALUE"""),"Fahad") -> Fahad
A16: BR-006 | B16: =IFERROR(__xludf.DUMMYFUNCTION("""COMPUTED_VALUE"""),"Account") -> Account | C16: =IFERROR(__xludf.DUMMYFUNCTION("""COMPUTED_VALUE"""),"Account") -> Account | D16: =IFERROR(__xludf.DUMMYFUNCTION("""COMPUTED_VALUE"""),"Missing privacy and data ") -> Missing privacy and data | E16: =IFERROR(__xludf.DUMMYFUNCTION("""COMPUTED_VALUE"""),"User need to install the app in their android device") -> User need to install the app in their android device | F16: =IFERROR(__xludf.DUMMYFUNCTION("""COMPUTED_VALUE"""),"1. Open app 2. Sign-in using valid credential 3. Select driver role 4. Click on Account") -> 1. Open app 2. Sign-in using valid credential 3. Select driver role 4. Click on Account | G16: =IFERROR(__xludf.DUMMYFUNCTION("""COMPUTED_VALUE"""),"Driver Credentials") -> Driver Credentials | H16: =IFERROR(__xludf.DUMMYFUNCTION("""COMPUTED_VALUE"""),"Page data should be positioned perfectly.") -> Page data should be positioned perfectly. | I16: =IFERROR(__xludf.DUMMYFUNCTION("""COMPUTED_VALUE"""),"Missing content on privacy and data ") -> Missing content on privacy and data | J16: =IFERROR(__xludf.DUMMYFUNCTION("""COMPUTED_VALUE"""),"Fail") -> Fail | K16: =IFERROR(__xludf.DUMMYFUNCTION("""COMPUTED_VALUE"""),"Low") -> Low | L16: =IFERROR(__xludf.DUMMYFUNCTION("""COMPUTED_VALUE"""),"036.png") -> 036.png | N16: =IFERROR(__xludf.DUMMYFUNCTION("""COMPUTED_VALUE"""),"Fahad") -> Fahad
A17: BR-007 | B17: =IFERROR(__xludf.DUMMYFUNCTION("""COMPUTED_VALUE"""),"Account") -> Account | C17: =IFERROR(__xludf.DUMMYFUNCTION("""COMPUTED_VALUE"""),"Account") -> Account | D17: =IFERROR(__xludf.DUMMYFUNCTION("""COMPUTED_VALUE"""),"About us page missing in app") -> About us page missing in app | E17: =IFERROR(__xludf.DUMMYFUNCTION("""COMPUTED_VALUE"""),"User need to install the app in their android device") -> User need to install the app in their android device | F17: =IFERROR(__xludf.DUMMYFUNCTION("""COMPUTED_VALUE"""),"1. Open app 2. Sign-in using valid credential 3. Select driver role 4. Click on Account") -> 1. Open app 2. Sign-in using valid credential 3. Select driver role 4. Click on Account | G17: =IFERROR(__xludf.DUMMYFUNCTION("""COMPUTED_VALUE"""),"Driver Credentials") -> Driver Credentials | H17: =IFERROR(__xludf.DUMMYFUNCTION("""COMPUTED_VALUE"""),"The feature and page should be positioned in the ideal spot.") -> The feature and page should be positioned in the ideal spot. | I17: =IFERROR(__xludf.DUMMYFUNCTION("""COMPUTED_VALUE"""),"Page missing also option missing in account") -> Page missing also option missing in account | J17: =IFERROR(__xludf.DUMMYFUNCTION("""COMPUTED_VALUE"""),"Fail") -> Fail | K17: =IFERROR(__xludf.DUMMYFUNCTION("""COMPUTED_VALUE"""),"High") -> High | L17: =IFERROR(__xludf.DUMMYFUNCTION("""COMPUTED_VALUE"""),"037.png") -> 037.png | N17: =IFERROR(__xludf.DUMMYFUNCTION("""COMPUTED_VALUE"""),"Fahad") -> Fahad
A18: BR-008 | B18: =IFERROR(__xludf.DUMMYFUNCTION("""COMPUTED_VALUE"""),"Account") -> Account | C18: =IFERROR(__xludf.DUMMYFUNCTION("""COMPUTED_VALUE"""),"Account") -> Account | D18: =IFERROR(__xludf.DUMMYFUNCTION("""COMPUTED_VALUE"""),"Vehicle update missing from account") -> Vehicle update missing from account | E18: =IFERROR(__xludf.DUMMYFUNCTION("""COMPUTED_VALUE"""),"User need to install the app in their android device") -> User need to install the app in their android device | F18: =IFERROR(__xludf.DUMMYFUNCTION("""COMPUTED_VALUE"""),"1. Open app 2. Sign-in using valid credential 3. Select driver role 4. Click on Account") -> 1. Open app 2. Sign-in using valid credential 3. Select driver role 4. Click on Account | G18: =IFERROR(__xludf.DUMMYFUNCTION("""COMPUTED_VALUE"""),"Driver Credentials") -> Driver Credentials | H18: =IFERROR(__xludf.DUMMYFUNCTION("""COMPUTED_VALUE"""),"The feature and page should be positioned in the ideal spot.") -> The feature and page should be positioned in the ideal spot. | I18: =IFERROR(__xludf.DUMMYFUNCTION("""COMPUTED_VALUE"""),"Page missing also option missing in account") -> Page missing also option missing in account | J18: =IFERROR(__xludf.DUMMYFUNCTION("""COMPUTED_VALUE"""),"Fail") -> Fail | K18: =IFERROR(__xludf.DUMMYFUNCTION("""COMPUTED_VALUE"""),"High") -> High | L18: =IFERROR(__xludf.DUMMYFUNCTION("""COMPUTED_VALUE"""),"038.png") -> 038.png | N18: =IFERROR(__xludf.DUMMYFUNCTION("""COMPUTED_VALUE"""),"Fahad") -> Fahad
A19: BR-009 | B19: =IFERROR(__xludf.DUMMYFUNCTION("""COMPUTED_VALUE"""),"Forget Password") -> Forget Password | C19: =IFERROR(__xludf.DUMMYFUNCTION("""COMPUTED_VALUE"""),"Forget Password") -> Forget Password | D19: =IFERROR(__xludf.DUMMYFUNCTION("""COMPUTED_VALUE"""),"Wrong error in wrong place") -> Wrong error in wrong place | E19: =IFERROR(__xludf.DUMMYFUNCTION("""COMPUTED_VALUE"""),"User need to install the app in their android device") -> User need to install the app in their android device | F19: =IFERROR(__xludf.DUMMYFUNCTION("""COMPUTED_VALUE"""),"1. Open app 2. Click on sign-in 3. Click on Forget Password") -> 1. Open app 2. Click on sign-in 3. Click on Forget Password | G19: =IFERROR(__xludf.DUMMYFUNCTION("""COMPUTED_VALUE"""),"User Credential") -> User Credential | H19: =IFERROR(__xludf.DUMMYFUNCTION("""COMPUTED_VALUE"""),"Error should be displayed in right place") -> Error should be displayed in right place | I19: =IFERROR(__xludf.DUMMYFUNCTION("""COMPUTED_VALUE"""),"wrong error in wrong place") -> wrong error in wrong place | J19: =IFERROR(__xludf.DUMMYFUNCTION("""COMPUTED_VALUE"""),"Fail") -> Fail | K19: =IFERROR(__xludf.DUMMYFUNCTION("""COMPUTED_VALUE"""),"Medium") -> Medium | L19: =IFERROR(__xludf.DUMMYFUNCTION("""COMPUTED_VALUE"""),"005.png") -> 005.png | N19: =IFERROR(__xludf.DUMMYFUNCTION("""COMPUTED_VALUE"""),"Fahad") -> Fahad
A20: BR-010 | B20: =IFERROR(__xludf.DUMMYFUNCTION("""COMPUTED_VALUE"""),"History") -> History | C20: =IFERROR(__xludf.DUMMYFUNCTION("""COMPUTED_VALUE"""),"History") -> History | D20: =IFERROR(__xludf.DUMMYFUNCTION("""COMPUTED_VALUE"""),"Different from UI") -> Different from UI | E20: =IFERROR(__xludf.DUMMYFUNCTION("""COMPUTED_VALUE"""),"User need to install the app in their android device") -> User need to install the app in their android device | F20: =IFERROR(__xludf.DUMMYFUNCTION("""COMPUTED_VALUE"""),"1. Open app 2. Sign-in using valid credential 3. Select user role 4. Click on History") -> 1. Open app 2. Sign-in using valid credential 3. Select user role 4. Click on History | G20: =IFERROR(__xludf.DUMMYFUNCTION("""COMPUTED_VALUE"""),"User Credential") -> User Credential | H20: =IFERROR(__xludf.DUMMYFUNCTION("""COMPUTED_VALUE"""),"The design and alignments should be as accurate as in Figma.") -> The design and alignments should be as accurate as in Figma. | I20: =IFERROR(__xludf.DUMMYFUNCTION("""COMPUTED_VALUE"""),"Noticed a different design implementation in the app.") -> Noticed a different design implementation in the app. | J20: =IFERROR(__xludf.DUMMYFUNCTION("""COMPUTED_VALUE"""),"Fail") -> Fail | K20: =IFERROR(__xludf.DUMMYFUNCTION("""COMPUTED_VALUE"""),"Medium") -> Medium | L20: =IFERROR(__xludf.DUMMYFUNCTION("""COMPUTED_VALUE"""),"040.png") -> 040.png | N20: =IFERROR(__xludf.DUMMYFUNCTION("""COMPUTED_VALUE"""),"Fahad") -> Fahad
A21: BR-011 | B21: =IFERROR(__xludf.DUMMYFUNCTION("""COMPUTED_VALUE"""),"Home") -> Home | C21: =IFERROR(__xludf.DUMMYFUNCTION("""COMPUTED_VALUE"""),"Quick Booking") -> Quick Booking | D21: =IFERROR(__xludf.DUMMYFUNCTION("""COMPUTED_VALUE"""),"Feature missing in app") -> Feature missing in app | E21: =IFERROR(__xludf.DUMMYFUNCTION("""COMPUTED_VALUE"""),"User need to install the app in their android device") -> User need to install the app in their android device | F21: =IFERROR(__xludf.DUMMYFUNCTION("""COMPUTED_VALUE"""),"1. Open app 2. Sign-in using valid credential 3. Select user role") -> 1. Open app 2. Sign-in using valid credential 3. Select user role | G21: =IFERROR(__xludf.DUMMYFUNCTION("""COMPUTED_VALUE"""),"User Credential") -> User Credential | H21: =IFERROR(__xludf.DUMMYFUNCTION("""COMPUTED_VALUE"""),"Features and functionalities should be implemented correctly.") -> Features and functionalities should be implemented correctly. | I21: =IFERROR(__xludf.DUMMYFUNCTION("""COMPUTED_VALUE"""),"Missing feature noticed") -> Missing feature noticed | J21: =IFERROR(__xludf.DUMMYFUNCTION("""COMPUTED_VALUE"""),"Fail") -> Fail | K21: =IFERROR(__xludf.DUMMYFUNCTION("""COMPUTED_VALUE"""),"High") -> High | L21: =IFERROR(__xludf.DUMMYFUNCTION("""COMPUTED_VALUE"""),"019.png") -> 019.png | N21: =IFERROR(__xludf.DUMMYFUNCTION("""COMPUTED_VALUE"""),"Fahad") -> Fahad
A22: BR-012 | B22: =IFERROR(__xludf.DUMMYFUNCTION("""COMPUTED_VALUE"""),"Home") -> Home | C22: =IFERROR(__xludf.DUMMYFUNCTION("""COMPUTED_VALUE"""),"Quick Booking") -> Quick Booking | D22: =IFERROR(__xludf.DUMMYFUNCTION("""COMPUTED_VALUE"""),"Missing option to set location on the map") -> Missing option to set location on the map | E22: =IFERROR(__xludf.DUMMYFUNCTION("""COMPUTED_VALUE"""),"User need to install the app in their android device") -> User need to install the app in their android device | F22: =IFERROR(__xludf.DUMMYFUNCTION("""COMPUTED_VALUE"""),"1. Open app 2. Sign-in using valid credential 3. Select user role") -> 1. Open app 2. Sign-in using valid credential 3. Select user role | G22: =IFERROR(__xludf.DUMMYFUNCTION("""COMPUTED_VALUE"""),"User Credential") -> User Credential | H22: =IFERROR(__xludf.DUMMYFUNCTION("""COMPUTED_VALUE"""),"Features and functionalities should be implemented correctly.") -> Features and functionalities should be implemented correctly. | I22: =IFERROR(__xludf.DUMMYFUNCTION("""COMPUTED_VALUE"""),"Missing feature noticed") -> Missing feature noticed | J22: =IFERROR(__xludf.DUMMYFUNCTION("""COMPUTED_VALUE"""),"Fail") -> Fail | K22: =IFERROR(__xludf.DUMMYFUNCTION("""COMPUTED_VALUE"""),"High") -> High | L22: =IFERROR(__xludf.DUMMYFUNCTION("""COMPUTED_VALUE"""),"020.png") -> 020.png | N22: =IFERROR(__xludf.DUMMYFUNCTION("""COMPUTED_VALUE"""),"Fahad") -> Fahad
A23: BR-013 | B23: =IFERROR(__xludf.DUMMYFUNCTION("""COMPUTED_VALUE"""),"Home") -> Home | C23: =IFERROR(__xludf.DUMMYFUNCTION("""COMPUTED_VALUE"""),"Quick Booking") -> Quick Booking | D23: =IFERROR(__xludf.DUMMYFUNCTION("""COMPUTED_VALUE"""),"The map on the top bar is missing in the app.") -> The map on the top bar is missing in the app. | E23: =IFERROR(__xludf.DUMMYFUNCTION("""COMPUTED_VALUE"""),"User need to install the app in their android device") -> User need to install the app in their android device | F23: =IFERROR(__xludf.DUMMYFUNCTION("""COMPUTED_VALUE"""),"1. Open app 2. Sign-in using valid credential 3. Select user role") -> 1. Open app 2. Sign-in using valid credential 3. Select user role | G23: =IFERROR(__xludf.DUMMYFUNCTION("""COMPUTED_VALUE"""),"User Credential") -> User Credential | H23: =IFERROR(__xludf.DUMMYFUNCTION("""COMPUTED_VALUE"""),"The design and alignments should be as accurate as in Figma.") -> The design and alignments should be as accurate as in Figma. | I23: =IFERROR(__xludf.DUMMYFUNCTION("""COMPUTED_VALUE"""),"Noticed a different design implementation in the app.") -> Noticed a different design implementation in the app. | J23: =IFERROR(__xludf.DUMMYFUNCTION("""COMPUTED_VALUE"""),"Fail") -> Fail | K23: =IFERROR(__xludf.DUMMYFUNCTION("""COMPUTED_VALUE"""),"Medium") -> Medium | L23: =IFERROR(__xludf.DUMMYFUNCTION("""COMPUTED_VALUE"""),"021.png") -> 021.png | N23: =IFERROR(__xludf.DUMMYFUNCTION("""COMPUTED_VALUE"""),"Fahad") -> Fahad
A24: BR-014 | B24: =IFERROR(__xludf.DUMMYFUNCTION("""COMPUTED_VALUE"""),"Home") -> Home | C24: =IFERROR(__xludf.DUMMYFUNCTION("""COMPUTED_VALUE"""),"Quick Booking") -> Quick Booking | D24: =IFERROR(__xludf.DUMMYFUNCTION("""COMPUTED_VALUE"""),"The multi-stop feature hasn’t been added to the app yet.") -> The multi-stop feature hasn’t been added to the app yet. | E24: =IFERROR(__xludf.DUMMYFUNCTION("""COMPUTED_VALUE"""),"User need to install the app in their android device") -> User need to install the app in their android device | F24: =IFERROR(__xludf.DUMMYFUNCTION("""COMPUTED_VALUE"""),"1. Open app 2. Sign-in using valid credential 3. Select user role") -> 1. Open app 2. Sign-in using valid credential 3. Select user role | G24: =IFERROR(__xludf.DUMMYFUNCTION("""COMPUTED_VALUE"""),"User Credential") -> User Credential | H24: =IFERROR(__xludf.DUMMYFUNCTION("""COMPUTED_VALUE"""),"Features and functionalities should be implemented correctly.") -> Features and functionalities should be implemented correctly. | I24: =IFERROR(__xludf.DUMMYFUNCTION("""COMPUTED_VALUE"""),"Missing feature noticed") -> Missing feature noticed | J24: =IFERROR(__xludf.DUMMYFUNCTION("""COMPUTED_VALUE"""),"Fail") -> Fail | K24: =IFERROR(__xludf.DUMMYFUNCTION("""COMPUTED_VALUE"""),"High") -> High | L24: =IFERROR(__xludf.DUMMYFUNCTION("""COMPUTED_VALUE"""),"022.png") -> 022.png | N24: =IFERROR(__xludf.DUMMYFUNCTION("""COMPUTED_VALUE"""),"Fahad") -> Fahad
A25: BR-015 | B25: =IFERROR(__xludf.DUMMYFUNCTION("""COMPUTED_VALUE"""),"Home") -> Home | C25: =IFERROR(__xludf.DUMMYFUNCTION("""COMPUTED_VALUE"""),"Quick Booking") -> Quick Booking | D25: =IFERROR(__xludf.DUMMYFUNCTION("""COMPUTED_VALUE"""),"The app doesn’t have a feature to set pickup and drop-off times.") -> The app doesn’t have a feature to set pickup and drop-off times. | E25: =IFERROR(__xludf.DUMMYFUNCTION("""COMPUTED_VALUE"""),"User need to install the app in their android device") -> User need to install the app in their android device | F25: =IFERROR(__xludf.DUMMYFUNCTION("""COMPUTED_VALUE"""),"1. Open app 2. Sign-in using valid credential 3. Select user role") -> 1. Open app 2. Sign-in using valid credential 3. Select user role | G25: =IFERROR(__xludf.DUMMYFUNCTION("""COMPUTED_VALUE"""),"User Credential") -> User Credential | H25: =IFERROR(__xludf.DUMMYFUNCTION("""COMPUTED_VALUE"""),"Features and functionalities should be implemented correctly.") -> Features and functionalities should be implemented correctly. | I25: =IFERROR(__xludf.DUMMYFUNCTION("""COMPUTED_VALUE"""),"Missing feature noticed") -> Missing feature noticed | J25: =IFERROR(__xludf.DUMMYFUNCTION("""COMPUTED_VALUE"""),"Fail") -> Fail | K25: =IFERROR(__xludf.DUMMYFUNCTION("""COMPUTED_VALUE"""),"High") -> High | L25: =IFERROR(__xludf.DUMMYFUNCTION("""COMPUTED_VALUE"""),"023.png") -> 023.png | N25: =IFERROR(__xludf.DUMMYFUNCTION("""COMPUTED_VALUE"""),"Fahad") -> Fahad
A26: BR-016 | B26: =IFERROR(__xludf.DUMMYFUNCTION("""COMPUTED_VALUE"""),"Home") -> Home | C26: =IFERROR(__xludf.DUMMYFUNCTION("""COMPUTED_VALUE"""),"Quick Booking") -> Quick Booking | D26: =IFERROR(__xludf.DUMMYFUNCTION("""COMPUTED_VALUE"""),"User profile icon set as default") -> User profile icon set as default | E26: =IFERROR(__xludf.DUMMYFUNCTION("""COMPUTED_VALUE"""),"User need to install the app in their android device") -> User need to install the app in their android device | F26: =IFERROR(__xludf.DUMMYFUNCTION("""COMPUTED_VALUE"""),"1. Open app 2. Sign-in using valid credential 3. Select user role") -> 1. Open app 2. Sign-in using valid credential 3. Select user role | G26: =IFERROR(__xludf.DUMMYFUNCTION("""COMPUTED_VALUE"""),"User Credential") -> User Credential | H26: =IFERROR(__xludf.DUMMYFUNCTION("""COMPUTED_VALUE"""),"Features and functionalities should be implemented correctly.") -> Features and functionalities should be implemented correctly. | I26: =IFERROR(__xludf.DUMMYFUNCTION("""COMPUTED_VALUE"""),"Missing feature noticed") -> Missing feature noticed | J26: =IFERROR(__xludf.DUMMYFUNCTION("""COMPUTED_VALUE"""),"Fail") -> Fail | K26: =IFERROR(__xludf.DUMMYFUNCTION("""COMPUTED_VALUE"""),"Medium") -> Medium | L26: =IFERROR(__xludf.DUMMYFUNCTION("""COMPUTED_VALUE"""),"024.png") -> 024.png | N26: =IFERROR(__xludf.DUMMYFUNCTION("""COMPUTED_VALUE"""),"Fahad") -> Fahad
A27: BR-017 | B27: =IFERROR(__xludf.DUMMYFUNCTION("""COMPUTED_VALUE"""),"Home") -> Home | C27: =IFERROR(__xludf.DUMMYFUNCTION("""COMPUTED_VALUE"""),"Quick Booking") -> Quick Booking | D27: =IFERROR(__xludf.DUMMYFUNCTION("""COMPUTED_VALUE"""),"View current location feature missing in app") -> View current location feature missing in app | E27: =IFERROR(__xludf.DUMMYFUNCTION("""COMPUTED_VALUE"""),"User need to install the app in their android device") -> User need to install the app in their android device | F27: =IFERROR(__xludf.DUMMYFUNCTION("""COMPUTED_VALUE"""),"1. Open app 2. Sign-in using valid credential 3. Select user role") -> 1. Open app 2. Sign-in using valid credential 3. Select user role | G27: =IFERROR(__xludf.DUMMYFUNCTION("""COMPUTED_VALUE"""),"User Credential") -> User Credential | H27: =IFERROR(__xludf.DUMMYFUNCTION("""COMPUTED_VALUE"""),"The map should include a show current location feature because it’s a basic necessity.") -> The map should include a show current location feature because it’s a basic necessity. | I27: =IFERROR(__xludf.DUMMYFUNCTION("""COMPUTED_VALUE"""),"Current location view is missing in app") -> Current location view is missing in app | J27: =IFERROR(__xludf.DUMMYFUNCTION("""COMPUTED_VALUE"""),"Fail") -> Fail | K27: =IFERROR(__xludf.DUMMYFUNCTION("""COMPUTED_VALUE"""),"High") -> High | L27: =IFERROR(__xludf.DUMMYFUNCTION("""COMPUTED_VALUE"""),"025.png") -> 025.png | N27: =IFERROR(__xludf.DUMMYFUNCTION("""COMPUTED_VALUE"""),"Fahad") -> Fahad
A28: BR-018 | B28: =IFERROR(__xludf.DUMMYFUNCTION("""COMPUTED_VALUE"""),"Home") -> Home | C28: =IFERROR(__xludf.DUMMYFUNCTION("""COMPUTED_VALUE"""),"Quick Booking") -> Quick Booking | D28: =IFERROR(__xludf.DUMMYFUNCTION("""COMPUTED_VALUE"""),"Car list displayed at the pickup spot") -> Car list displayed at the pickup spot | E28: =IFERROR(__xludf.DUMMYFUNCTION("""COMPUTED_VALUE"""),"User need to install the app in their android device") -> User need to install the app in their android device | F28: =IFERROR(__xludf.DUMMYFUNCTION("""COMPUTED_VALUE"""),"1. Open app 2. Sign-in using valid credential 3. Select user role") -> 1. Open app 2. Sign-in using valid credential 3. Select user role | G28: =IFERROR(__xludf.DUMMYFUNCTION("""COMPUTED_VALUE"""),"User Credential") -> User Credential | H28: =IFERROR(__xludf.DUMMYFUNCTION("""COMPUTED_VALUE"""),"Features and functionalities should be implemented correctly.") -> Features and functionalities should be implemented correctly. | I28: =IFERROR(__xludf.DUMMYFUNCTION("""COMPUTED_VALUE"""),"Missing feature noticed") -> Missing feature noticed | J28: =IFERROR(__xludf.DUMMYFUNCTION("""COMPUTED_VALUE"""),"Fail") -> Fail | K28: =IFERROR(__xludf.DUMMYFUNCTION("""COMPUTED_VALUE"""),"High") -> High | L28: =IFERROR(__xludf.DUMMYFUNCTION("""COMPUTED_VALUE"""),"026.png") -> 026.png | N28: =IFERROR(__xludf.DUMMYFUNCTION("""COMPUTED_VALUE"""),"Fahad") -> Fahad
A29: BR-019 | B29: =IFERROR(__xludf.DUMMYFUNCTION("""COMPUTED_VALUE"""),"Landing screen") -> Landing screen | C29: =IFERROR(__xludf.DUMMYFUNCTION("""COMPUTED_VALUE"""),"Home") -> Home | D29: =IFERROR(__xludf.DUMMYFUNCTION("""COMPUTED_VALUE"""),"The UI was implemented in a different way.") -> The UI was implemented in a different way. | E29: =IFERROR(__xludf.DUMMYFUNCTION("""COMPUTED_VALUE"""),"User need to install the app in their android device") -> User need to install the app in their android device | F29: =IFERROR(__xludf.DUMMYFUNCTION("""COMPUTED_VALUE"""),"1. Open app 2. Sign-in using valid credential 3. Select user role") -> 1. Open app 2. Sign-in using valid credential 3. Select user role | G29: =IFERROR(__xludf.DUMMYFUNCTION("""COMPUTED_VALUE"""),"User Credential") -> User Credential | H29: =IFERROR(__xludf.DUMMYFUNCTION("""COMPUTED_VALUE"""),"The design and alignments should be as accurate as in Figma.") -> The design and alignments should be as accurate as in Figma. | I29: =IFERROR(__xludf.DUMMYFUNCTION("""COMPUTED_VALUE"""),"Noticed a different design implementation in the app.") -> Noticed a different design implementation in the app. | J29: =IFERROR(__xludf.DUMMYFUNCTION("""COMPUTED_VALUE"""),"Fail") -> Fail | K29: =IFERROR(__xludf.DUMMYFUNCTION("""COMPUTED_VALUE"""),"High") -> High | L29: =IFERROR(__xludf.DUMMYFUNCTION("""COMPUTED_VALUE"""),"015.png") -> 015.png | N29: =IFERROR(__xludf.DUMMYFUNCTION("""COMPUTED_VALUE"""),"Fahad") -> Fahad
A30: BR-020 | B30: =IFERROR(__xludf.DUMMYFUNCTION("""COMPUTED_VALUE"""),"Landing screen") -> Landing screen | C30: =IFERROR(__xludf.DUMMYFUNCTION("""COMPUTED_VALUE"""),"Home") -> Home | D30: =IFERROR(__xludf.DUMMYFUNCTION("""COMPUTED_VALUE"""),"Figma set as 3D but implemented as 2D") -> Figma set as 3D but implemented as 2D | E30: =IFERROR(__xludf.DUMMYFUNCTION("""COMPUTED_VALUE"""),"User need to install the app in their android device") -> User need to install the app in their android device | F30: =IFERROR(__xludf.DUMMYFUNCTION("""COMPUTED_VALUE"""),"1. Open app 2. Sign-in using valid credential 3. Select user role") -> 1. Open app 2. Sign-in using valid credential 3. Select user role | G30: =IFERROR(__xludf.DUMMYFUNCTION("""COMPUTED_VALUE"""),"User Credential") -> User Credential | H30: =IFERROR(__xludf.DUMMYFUNCTION("""COMPUTED_VALUE"""),"The design and alignments should be as accurate as in Figma.") -> The design and alignments should be as accurate as in Figma. | I30: =IFERROR(__xludf.DUMMYFUNCTION("""COMPUTED_VALUE"""),"Noticed a different design implementation in the app.") -> Noticed a different design implementation in the app. | J30: =IFERROR(__xludf.DUMMYFUNCTION("""COMPUTED_VALUE"""),"Fail") -> Fail | K30: =IFERROR(__xludf.DUMMYFUNCTION("""COMPUTED_VALUE"""),"Medium") -> Medium | L30: =IFERROR(__xludf.DUMMYFUNCTION("""COMPUTED_VALUE"""),"016.png") -> 016.png | N30: =IFERROR(__xludf.DUMMYFUNCTION("""COMPUTED_VALUE"""),"Fahad") -> Fahad
A31: BR-021 | B31: =IFERROR(__xludf.DUMMYFUNCTION("""COMPUTED_VALUE"""),"Landing screen") -> Landing screen | C31: =IFERROR(__xludf.DUMMYFUNCTION("""COMPUTED_VALUE"""),"Home") -> Home | D31: =IFERROR(__xludf.DUMMYFUNCTION("""COMPUTED_VALUE"""),"The app has a top-notch blend in its design, but within the app itself, it doesn’t quite blend in.") -> The app has a top-notch blend in its design, but within the app itself, it doesn’t quite blend in. | E31: =IFERROR(__xludf.DUMMYFUNCTION("""COMPUTED_VALUE"""),"User need to install the app in their android device") -> User need to install the app in their android device | F31: =IFERROR(__xludf.DUMMYFUNCTION("""COMPUTED_VALUE"""),"1. Open app 2. Sign-in using valid credential 3. Select user role") -> 1. Open app 2. Sign-in using valid credential 3. Select user role | G31: =IFERROR(__xludf.DUMMYFUNCTION("""COMPUTED_VALUE"""),"User Credential") -> User Credential | H31: =IFERROR(__xludf.DUMMYFUNCTION("""COMPUTED_VALUE"""),"The design and alignments should be as accurate as in Figma.") -> The design and alignments should be as accurate as in Figma. | I31: =IFERROR(__xludf.DUMMYFUNCTION("""COMPUTED_VALUE"""),"Noticed a different design implementation in the app.") -> Noticed a different design implementation in the app. | J31: =IFERROR(__xludf.DUMMYFUNCTION("""COMPUTED_VALUE"""),"Fail") -> Fail | K31: =IFERROR(__xludf.DUMMYFUNCTION("""COMPUTED_VALUE"""),"Medium") -> Medium | L31: =IFERROR(__xludf.DUMMYFUNCTION("""COMPUTED_VALUE"""),"017.png") -> 017.png | N31: =IFERROR(__xludf.DUMMYFUNCTION("""COMPUTED_VALUE"""),"Fahad") -> Fahad
A32: BR-022 | B32: =IFERROR(__xludf.DUMMYFUNCTION("""COMPUTED_VALUE"""),"Landing screen") -> Landing screen | C32: =IFERROR(__xludf.DUMMYFUNCTION("""COMPUTED_VALUE"""),"Home") -> Home | D32: =IFERROR(__xludf.DUMMYFUNCTION("""COMPUTED_VALUE"""),"The UI and implementation are different.") -> The UI and implementation are different. | E32: =IFERROR(__xludf.DUMMYFUNCTION("""COMPUTED_VALUE"""),"User need to install the app in their android device") -> User need to install the app in their android device | F32: =IFERROR(__xludf.DUMMYFUNCTION("""COMPUTED_VALUE"""),"1. Open app 2. Sign-in using valid credential 3. Select user role") -> 1. Open app 2. Sign-in using valid credential 3. Select user role | G32: =IFERROR(__xludf.DUMMYFUNCTION("""COMPUTED_VALUE"""),"User Credential") -> User Credential | H32: =IFERROR(__xludf.DUMMYFUNCTION("""COMPUTED_VALUE"""),"The design and alignments should be as accurate as in Figma.") -> The design and alignments should be as accurate as in Figma. | I32: =IFERROR(__xludf.DUMMYFUNCTION("""COMPUTED_VALUE"""),"Noticed a different design implementation in the app.") -> Noticed a different design implementation in the app. | J32: =IFERROR(__xludf.DUMMYFUNCTION("""COMPUTED_VALUE"""),"Fail") -> Fail | K32: =IFERROR(__xludf.DUMMYFUNCTION("""COMPUTED_VALUE"""),"Medium") -> Medium | L32: =IFERROR(__xludf.DUMMYFUNCTION("""COMPUTED_VALUE"""),"018.png") -> 018.png | N32: =IFERROR(__xludf.DUMMYFUNCTION("""COMPUTED_VALUE"""),"Fahad") -> Fahad
A33: BR-023 | B33: =IFERROR(__xludf.DUMMYFUNCTION("""COMPUTED_VALUE"""),"Landing screen") -> Landing screen | C33: =IFERROR(__xludf.DUMMYFUNCTION("""COMPUTED_VALUE"""),"Home") -> Home | D33: =IFERROR(__xludf.DUMMYFUNCTION("""COMPUTED_VALUE"""),"The profile name doesn’t update automatically.") -> The profile name doesn’t update automatically. | E33: =IFERROR(__xludf.DUMMYFUNCTION("""COMPUTED_VALUE"""),"User need to install the app in their android device") -> User need to install the app in their android device | F33: =IFERROR(__xludf.DUMMYFUNCTION("""COMPUTED_VALUE"""),"1. Open app 2. Sign-in using valid credential 3. Select user role") -> 1. Open app 2. Sign-in using valid credential 3. Select user role | G33: =IFERROR(__xludf.DUMMYFUNCTION("""COMPUTED_VALUE"""),"User Credential") -> User Credential | H33: =IFERROR(__xludf.DUMMYFUNCTION("""COMPUTED_VALUE"""),"The profile should automatically update after switching roles.") -> The profile should automatically update after switching roles. | I33: =IFERROR(__xludf.DUMMYFUNCTION("""COMPUTED_VALUE"""),"The profile does not update dynamically.") -> The profile does not update dynamically. | J33: =IFERROR(__xludf.DUMMYFUNCTION("""COMPUTED_VALUE"""),"Fail") -> Fail | K33: =IFERROR(__xludf.DUMMYFUNCTION("""COMPUTED_VALUE"""),"Medium") -> Medium | L33: =IFERROR(__xludf.DUMMYFUNCTION("""COMPUTED_VALUE"""),"028.mp4") -> 028.mp4 | N33: =IFERROR(__xludf.DUMMYFUNCTION("""COMPUTED_VALUE"""),"Fahad") -> Fahad
A34: BR-024 | B34: =IFERROR(__xludf.DUMMYFUNCTION("""COMPUTED_VALUE"""),"Landing screen") -> Landing screen | C34: =IFERROR(__xludf.DUMMYFUNCTION("""COMPUTED_VALUE"""),"Home") -> Home | D34: =IFERROR(__xludf.DUMMYFUNCTION("""COMPUTED_VALUE"""),"Clicking on the profile doesn’t navigate the user to the profile screen.") -> Clicking on the profile doesn’t navigate the user to the profile screen. | E34: =IFERROR(__xludf.DUMMYFUNCTION("""COMPUTED_VALUE"""),"User need to install the app in their android device") -> User need to install the app in their android device | F34: =IFERROR(__xludf.DUMMYFUNCTION("""COMPUTED_VALUE"""),"1. Open app 2. Sign-in using valid credential 3. Select user role") -> 1. Open app 2. Sign-in using valid credential 3. Select user role | G34: =IFERROR(__xludf.DUMMYFUNCTION("""COMPUTED_VALUE"""),"User Credential") -> User Credential | H34: =IFERROR(__xludf.DUMMYFUNCTION("""COMPUTED_VALUE"""),"Features and functionalities should be implemented correctly.") -> Features and functionalities should be implemented correctly. | I34: =IFERROR(__xludf.DUMMYFUNCTION("""COMPUTED_VALUE"""),"Missing feature noticed") -> Missing feature noticed | J34: =IFERROR(__xludf.DUMMYFUNCTION("""COMPUTED_VALUE"""),"Fail") -> Fail | K34: =IFERROR(__xludf.DUMMYFUNCTION("""COMPUTED_VALUE"""),"High") -> High | L34: =IFERROR(__xludf.DUMMYFUNCTION("""COMPUTED_VALUE"""),"029.png") -> 029.png | N34: =IFERROR(__xludf.DUMMYFUNCTION("""COMPUTED_VALUE"""),"Fahad") -> Fahad
A35: BR-025 | B35: =IFERROR(__xludf.DUMMYFUNCTION("""COMPUTED_VALUE"""),"Landing screen") -> Landing screen | C35: =IFERROR(__xludf.DUMMYFUNCTION("""COMPUTED_VALUE"""),"Home") -> Home | D35: =IFERROR(__xludf.DUMMYFUNCTION("""COMPUTED_VALUE"""),"Not functional") -> Not functional | E35: =IFERROR(__xludf.DUMMYFUNCTION("""COMPUTED_VALUE"""),"User need to install the app in their android device") -> User need to install the app in their android device | F35: =IFERROR(__xludf.DUMMYFUNCTION("""COMPUTED_VALUE"""),"1. Open app 2. Sign-in using valid credential 3. Select user role") -> 1. Open app 2. Sign-in using valid credential 3. Select user role | G35: =IFERROR(__xludf.DUMMYFUNCTION("""COMPUTED_VALUE"""),"User Credential") -> User Credential | H35: =IFERROR(__xludf.DUMMYFUNCTION("""COMPUTED_VALUE"""),"Features and functionalities should be implemented correctly.") -> Features and functionalities should be implemented correctly. | I35: =IFERROR(__xludf.DUMMYFUNCTION("""COMPUTED_VALUE"""),"Missing feature noticed") -> Missing feature noticed | J35: =IFERROR(__xludf.DUMMYFUNCTION("""COMPUTED_VALUE"""),"Fail") -> Fail | K35: =IFERROR(__xludf.DUMMYFUNCTION("""COMPUTED_VALUE"""),"High") -> High | L35: =IFERROR(__xludf.DUMMYFUNCTION("""COMPUTED_VALUE"""),"030.png") -> 030.png | N35: =IFERROR(__xludf.DUMMYFUNCTION("""COMPUTED_VALUE"""),"Fahad") -> Fahad
A36: BR-026 | B36: =IFERROR(__xludf.DUMMYFUNCTION("""COMPUTED_VALUE"""),"Landing screen") -> Landing screen | C36: =IFERROR(__xludf.DUMMYFUNCTION("""COMPUTED_VALUE"""),"Home") -> Home | D36: =IFERROR(__xludf.DUMMYFUNCTION("""COMPUTED_VALUE"""),"Users UI set as Drivers UI") -> Users UI set as Drivers UI | E36: =IFERROR(__xludf.DUMMYFUNCTION("""COMPUTED_VALUE"""),"User need to install the app in their android device") -> User need to install the app in their android device | F36: =IFERROR(__xludf.DUMMYFUNCTION("""COMPUTED_VALUE"""),"1. Open app 2. Sign-in using valid credential 3. Select driver role") -> 1. Open app 2. Sign-in using valid credential 3. Select driver role | G36: =IFERROR(__xludf.DUMMYFUNCTION("""COMPUTED_VALUE"""),"Driver Credentials") -> Driver Credentials | H36: =IFERROR(__xludf.DUMMYFUNCTION("""COMPUTED_VALUE"""),"The UI should be designed to adapt to different user roles.") -> The UI should be designed to adapt to different user roles. | I36: =IFERROR(__xludf.DUMMYFUNCTION("""COMPUTED_VALUE"""),"Users UI is integrated in drivers UI") -> Users UI is integrated in drivers UI | J36: =IFERROR(__xludf.DUMMYFUNCTION("""COMPUTED_VALUE"""),"Fail") -> Fail | K36: =IFERROR(__xludf.DUMMYFUNCTION("""COMPUTED_VALUE"""),"Medium") -> Medium | L36: =IFERROR(__xludf.DUMMYFUNCTION("""COMPUTED_VALUE"""),"039.png") -> 039.png | N36: =IFERROR(__xludf.DUMMYFUNCTION("""COMPUTED_VALUE"""),"Fahad") -> Fahad
A37: BR-027 | B37: =IFERROR(__xludf.DUMMYFUNCTION("""COMPUTED_VALUE"""),"OTP") -> OTP | C37: =IFERROR(__xludf.DUMMYFUNCTION("""COMPUTED_VALUE"""),"OTP") -> OTP | D37: =IFERROR(__xludf.DUMMYFUNCTION("""COMPUTED_VALUE"""),"Failed to receive OTP in the entered email.") -> Failed to receive OTP in the entered email. | E37: =IFERROR(__xludf.DUMMYFUNCTION("""COMPUTED_VALUE"""),"User need to install the app in their android device") -> User need to install the app in their android device | F37: =IFERROR(__xludf.DUMMYFUNCTION("""COMPUTED_VALUE"""),"1. Open app 2. Click on sign-up") -> 1. Open app 2. Click on sign-up | G37: =IFERROR(__xludf.DUMMYFUNCTION("""COMPUTED_VALUE"""),"User Credential") -> User Credential | H37: =IFERROR(__xludf.DUMMYFUNCTION("""COMPUTED_VALUE"""),"The user should get an OTP for email verification.") -> The user should get an OTP for email verification. | I37: =IFERROR(__xludf.DUMMYFUNCTION("""COMPUTED_VALUE"""),"Did not receive the OTP in the registered email address.") -> Did not receive the OTP in the registered email address. | J37: =IFERROR(__xludf.DUMMYFUNCTION("""COMPUTED_VALUE"""),"Fail") -> Fail | K37: =IFERROR(__xludf.DUMMYFUNCTION("""COMPUTED_VALUE"""),"High") -> High | L37: =IFERROR(__xludf.DUMMYFUNCTION("""COMPUTED_VALUE"""),"003.png") -> 003.png | N37: =IFERROR(__xludf.DUMMYFUNCTION("""COMPUTED_VALUE"""),"Fahad") -> Fahad
A38: BR-028 | B38: =IFERROR(__xludf.DUMMYFUNCTION("""COMPUTED_VALUE"""),"OTP") -> OTP | C38: =IFERROR(__xludf.DUMMYFUNCTION("""COMPUTED_VALUE"""),"OTP") -> OTP | D38: =IFERROR(__xludf.DUMMYFUNCTION("""COMPUTED_VALUE"""),"The app name in the OTP is incorrect.") -> The app name in the OTP is incorrect. | E38: =IFERROR(__xludf.DUMMYFUNCTION("""COMPUTED_VALUE"""),"User need to install the app in their android device") -> User need to install the app in their android device | F38: =IFERROR(__xludf.DUMMYFUNCTION("""COMPUTED_VALUE"""),"1. Open app 2. Click on sign-in 3. Click on Forget Password 4. Open mail") -> 1. Open app 2. Click on sign-in 3. Click on Forget Password 4. Open mail | G38: =IFERROR(__xludf.DUMMYFUNCTION("""COMPUTED_VALUE"""),"User Credential") -> User Credential | H38: =IFERROR(__xludf.DUMMYFUNCTION("""COMPUTED_VALUE"""),"The app name in the OTP should be correct.") -> The app name in the OTP should be correct. | I38: =IFERROR(__xludf.DUMMYFUNCTION("""COMPUTED_VALUE"""),"The mail title shows the wrong app name.") -> The mail title shows the wrong app name. | J38: =IFERROR(__xludf.DUMMYFUNCTION("""COMPUTED_VALUE"""),"Fail") -> Fail | K38: =IFERROR(__xludf.DUMMYFUNCTION("""COMPUTED_VALUE"""),"Medium") -> Medium | L38: =IFERROR(__xludf.DUMMYFUNCTION("""COMPUTED_VALUE"""),"006.png") -> 006.png | N38: =IFERROR(__xludf.DUMMYFUNCTION("""COMPUTED_VALUE"""),"Fahad") -> Fahad
A39: BR-029 | B39: =IFERROR(__xludf.DUMMYFUNCTION("""COMPUTED_VALUE"""),"OTP") -> OTP | C39: =IFERROR(__xludf.DUMMYFUNCTION("""COMPUTED_VALUE"""),"OTP") -> OTP | D39: =IFERROR(__xludf.DUMMYFUNCTION("""COMPUTED_VALUE"""),"support mail is not aligned with app name") -> support mail is not aligned with app name | E39: =IFERROR(__xludf.DUMMYFUNCTION("""COMPUTED_VALUE"""),"User need to install the app in their android device") -> User need to install the app in their android device | F39: =IFERROR(__xludf.DUMMYFUNCTION("""COMPUTED_VALUE"""),"1. Open app 2. Click on sign-in 3. Click on Forget Password 4. Open mail") -> 1. Open app 2. Click on sign-in 3. Click on Forget Password 4. Open mail | G39: =IFERROR(__xludf.DUMMYFUNCTION("""COMPUTED_VALUE"""),"User Credential") -> User Credential | H39: =IFERROR(__xludf.DUMMYFUNCTION("""COMPUTED_VALUE"""),"The support email should match the app name.") -> The support email should match the app name. | I39: =IFERROR(__xludf.DUMMYFUNCTION("""COMPUTED_VALUE"""),"Noticed difference of app name and support mail") -> Noticed difference of app name and support mail | J39: =IFERROR(__xludf.DUMMYFUNCTION("""COMPUTED_VALUE"""),"Fail") -> Fail | K39: =IFERROR(__xludf.DUMMYFUNCTION("""COMPUTED_VALUE"""),"Medium") -> Medium | L39: =IFERROR(__xludf.DUMMYFUNCTION("""COMPUTED_VALUE"""),"007.png") -> 007.png | N39: =IFERROR(__xludf.DUMMYFUNCTION("""COMPUTED_VALUE"""),"Fahad") -> Fahad
A40: BR-030 | B40: =IFERROR(__xludf.DUMMYFUNCTION("""COMPUTED_VALUE"""),"OTP") -> OTP | C40: =IFERROR(__xludf.DUMMYFUNCTION("""COMPUTED_VALUE"""),"OTP") -> OTP | D40: =IFERROR(__xludf.DUMMYFUNCTION("""COMPUTED_VALUE"""),"The OTP code in the email body is missing.") -> The OTP code in the email body is missing. | E40: =IFERROR(__xludf.DUMMYFUNCTION("""COMPUTED_VALUE"""),"User need to install the app in their android device") -> User need to install the app in their android device | F40: =IFERROR(__xludf.DUMMYFUNCTION("""COMPUTED_VALUE"""),"1. Open app 2. Click on sign-in 3. Click on Forget Password 4. Open mail") -> 1. Open app 2. Click on sign-in 3. Click on Forget Password 4. Open mail | G40: =IFERROR(__xludf.DUMMYFUNCTION("""COMPUTED_VALUE"""),"User Credential") -> User Credential | H40: =IFERROR(__xludf.DUMMYFUNCTION("""COMPUTED_VALUE"""),"Email body should contain User name , OTP code, time and date ") -> Email body should contain User name , OTP code, time and date | I40: =IFERROR(__xludf.DUMMYFUNCTION("""COMPUTED_VALUE"""),"Blank email body has been noticed") -> Blank email body has been noticed | J40: =IFERROR(__xludf.DUMMYFUNCTION("""COMPUTED_VALUE"""),"Fail") -> Fail | K40: =IFERROR(__xludf.DUMMYFUNCTION("""COMPUTED_VALUE"""),"High") -> High | L40: =IFERROR(__xludf.DUMMYFUNCTION("""COMPUTED_VALUE"""),"008.png") -> 008.png | N40: =IFERROR(__xludf.DUMMYFUNCTION("""COMPUTED_VALUE"""),"Fahad") -> Fahad
A41: BR-031 | B41: =IFERROR(__xludf.DUMMYFUNCTION("""COMPUTED_VALUE"""),"Sign-up") -> Sign-up | C41: =IFERROR(__xludf.DUMMYFUNCTION("""COMPUTED_VALUE"""),"Sign-up") -> Sign-up | D41: =IFERROR(__xludf.DUMMYFUNCTION("""COMPUTED_VALUE"""),"Failed to create account") -> Failed to create account | E41: =IFERROR(__xludf.DUMMYFUNCTION("""COMPUTED_VALUE"""),"User need to install the app in their android device") -> User need to install the app in their android device | F41: =IFERROR(__xludf.DUMMYFUNCTION("""COMPUTED_VALUE"""),"1. Open app 2. Click on sign-up") -> 1. Open app 2. Click on sign-up | G41: =IFERROR(__xludf.DUMMYFUNCTION("""COMPUTED_VALUE"""),"N/A") -> N/A | H41: =IFERROR(__xludf.DUMMYFUNCTION("""COMPUTED_VALUE"""),"Users should be able to sign up without encountering any problems.") -> Users should be able to sign up without encountering any problems. | I41: =IFERROR(__xludf.DUMMYFUNCTION("""COMPUTED_VALUE"""),"Failed to signup") -> Failed to signup | J41: =IFERROR(__xludf.DUMMYFUNCTION("""COMPUTED_VALUE"""),"Fail") -> Fail | K41: =IFERROR(__xludf.DUMMYFUNCTION("""COMPUTED_VALUE"""),"High") -> High | L41: =IFERROR(__xludf.DUMMYFUNCTION("""COMPUTED_VALUE"""),"001.png") -> 001.png | N41: =IFERROR(__xludf.DUMMYFUNCTION("""COMPUTED_VALUE"""),"Fahad") -> Fahad
A42: BR-032 | B42: =IFERROR(__xludf.DUMMYFUNCTION("""COMPUTED_VALUE"""),"Sign-up") -> Sign-up | C42: =IFERROR(__xludf.DUMMYFUNCTION("""COMPUTED_VALUE"""),"Sign-up") -> Sign-up | D42: =IFERROR(__xludf.DUMMYFUNCTION("""COMPUTED_VALUE"""),"Failed to create account") -> Failed to create account | E42: =IFERROR(__xludf.DUMMYFUNCTION("""COMPUTED_VALUE"""),"User need to install the app in their android device") -> User need to install the app in their android device | F42: =IFERROR(__xludf.DUMMYFUNCTION("""COMPUTED_VALUE"""),"1. Open app 2. Click on sign-up") -> 1. Open app 2. Click on sign-up | G42: =IFERROR(__xludf.DUMMYFUNCTION("""COMPUTED_VALUE"""),"N/A") -> N/A | H42: =IFERROR(__xludf.DUMMYFUNCTION("""COMPUTED_VALUE"""),"Users should be able to sign up without encountering any problems.") -> Users should be able to sign up without encountering any problems. | I42: =IFERROR(__xludf.DUMMYFUNCTION("""COMPUTED_VALUE"""),"Failed to signup") -> Failed to signup | J42: =IFERROR(__xludf.DUMMYFUNCTION("""COMPUTED_VALUE"""),"Fail") -> Fail | K42: =IFERROR(__xludf.DUMMYFUNCTION("""COMPUTED_VALUE"""),"High") -> High | L42: =IFERROR(__xludf.DUMMYFUNCTION("""COMPUTED_VALUE"""),"002.png") -> 002.png | N42: =IFERROR(__xludf.DUMMYFUNCTION("""COMPUTED_VALUE"""),"Fahad") -> Fahad
...

Sheet Fahad
A1: Tester : | B1: Mohammed Fahad Faisal | F1: Email | G1: user@gmail.com | H1: driver@gmail.com
A2: Project Name: | B2: Ryde Islands | F2: Pass | G2: user*user* | H2: driver*driver*
A3: Developer: | B3: AI Thunder
A4: OS: | B4: Windows 11 Pro Version:24H2 OS build:26100.4946
A5: Environment: | B5: realme C63 model : RMX3939 Android Version : 15 Dimention : (6.59 x 3.02 x 0.30)in
A7: Test ID | B7: Module | C7: Sub Module | D7: Test Case Description | E7: Preconditions | F7: Test Steps | G7: Test Data | H7: Expected Result | I7: Actual Result | J7: Status | K7: Severity | L7: Screen Shots | M7: Suggestion | N7: Feedback
A8: BR_001 | B8: Sign-up | C8: Sign-up | D8: Failed to create account | E8: User need to install the app in their android device | F8: 1. Open app 2. Click on sign-up | G8: N/A | H8: Users should be able to sign up without encountering any problems. | I8: Failed to signup | J8: Fail | K8: High | L8: 001.png
A10: BR_002 | B10: Sign-up | C10: Sign-up | D10: Failed to create account | E10: User need to install the app in their android device | F10: 1. Open app 2. Click on sign-up | G10: N/A | H10: Users should be able to sign up without encountering any problems. | I10: Failed to signup | J10: Fail | K10: High | L10: 002.png
A12: BR_003 | B12: OTP | C12: OTP | D12: Failed to receive OTP in the entered email. | E12: User need to install the app in their android device | F12: 1. Open app 2. Click on sign-up | G12: User Credential | H12: The user should get an OTP for email verification. | I12: Did not receive the OTP in the registered email address. | J12: Fail | K12: High | L12: 003.png
A14: BR_004 | B14: Sign-up | C14: Sign-up | D14: The "Remember Me" button isn’t working. | E14: User need to install the app in their android device | F14: 1. Open app 2. Click on sign-up | G14: User Credential | H14: Remember button should be functional | I14: Not working button. Unable to click | J14: Fail | K14: Medium | L14: 004.png
A16: BR_005 | B16: Forget Password | C16: Forget Password | D16: Wrong error in wrong place | E16: User need to install the app in their android device | F16: 1. Open app 2. Click on sign-in 3. Click on Forget Password | G16: User Credential | H16: Error should be displayed in right place | I16: wrong error in wrong place | J16: Fail | K16: Medium | L16: 005.png
A18: BR_006 | B18: OTP | C18: OTP | D18: The app name in the OTP is incorrect. | E18: User need to install the app in their android device | F18: 1. Open app 2. Click on sign-in 3. Click on Forget Password 4. Open mail | G18: User Credential | H18: The app name in the OTP should be correct. | I18: The mail title shows the wrong app name. | J18: Fail | K18: Medium | L18: 006.png
A20: BR_007 | B20: OTP | C20: OTP | D20: support mail is not aligned with app name | E20: User need to install the app in their android device | F20: 1. Open app 2. Click on sign-in 3. Click on Forget Password 4. Open mail | G20: User Credential | H20: The support email should match the app name. | I20: Noticed difference of app name and support mail | J20: Fail | K20: Medium | L20: 007.png
A22: BR_008 | B22: OTP | C22: OTP | D22: The OTP code in the email body is missing. | E22: User need to install the app in their android device | F22: 1. Open app 2. Click on sign-in 3. Click on Forget Password 4. Open mail | G22: User Credential | H22: Email body should contain User name , OTP code, time and date | I22: Blank email body has been noticed | J22: Fail | K22: High | L22: 008.png
A24: BR_009 | B24: Vehicle Information | C24: Vehicle Information | D24: Design Alignment issue | E24: User need to install the app in their android device | F24: 1. Open app 2. Sign-in using valid credential 3. Select driver role | G24: Driver Credentials | H24: Alignment and design should be as same as figma | I24: Different design has been noticed | J24: Fail | K24: Medium | L24: 009.png
A26: BR_010 | B26: Vehicle Information | C26: Vehicle Information | D26: Different UI has been noticed | E26: User need to install the app in their android device | F26: 1. Open app 2. Sign-in using valid credential 3. Select driver role | G26: Driver Credentials | H26: Alignment and design should be as same as figma | I26: Different design has been noticed | J26: Fail | K26: Medium | L26: 010.png
A28: BR_011 | B28: Vehicle Information | C28: Vehicle Information | D28: The error toast still shows up even after all input fields are filled. | E28: User need to install the app in their android device | F28: 1. Open app 2. Sign-in using valid credential 3. Select driver role | G28: Driver Credentials | H28: Error should only be visible when it's required | I28: The error keeps appearing even when it’s not needed. | J28: Fail | K28: Medium | L28: 011.png
A30: BR_012 | B30: Vehicle Information | C30: Vehicle Information | D30: Submission failed after loading time | E30: User need to install the app in their android device | F30: 1. Open app 2. Sign-in using valid credential 3. Select driver role | G30: Driver Credentials | H30: Vehicle information submission should be completed smoothly and without any problems. | I30: The submission failed after loading for 2 minutes. | J30: Fail | K30: High | L30: 012.png
... A86: BR_040 | B86: History | C86: History | D86: Different from UI | E86: User need to install the app in their android device | F86: 1. Open app 2. Sign-in using valid credential 3. Select user role 4. Click on History | G86: User Credential | H86: The design and alignments should be as accurate as in Figma. | I86: Noticed a different design implementation in the app. | J86: Fail | K86: Medium | L86: 040.png
A88: BR_041
A90: BR_042
A92: BR_043
A94: BR_044
A96: BR_045
A98: BR_046
A100: BR_047
A102: BR_048
A104: BR_049
A106: BR_050

Sheet Tahsin
A2: Tester : | D2: Severity | E2: Issues
A3: Project Name: | D3: High | E3: =COUNTIF(K14:K1005, "High") -> 0
A4: Project URL: | D4: Medium | E4: =COUNTIF(K14:K1006, "Medium") -> 0
A5: Developer: | D5: Low | E5: =COUNTIF(K14:K1007, "Low") -> 0
A6: OS:
A7: Environment | D7: Total Test Cases: | E7: =SUM(E3:E5) -> 0
D8: Test Case Solved :
A14: Test Case ID | B14: Module | C14: Sub Module | D14: Test Case Description | E14: Preconditions | F14: Test Steps | G14: Test Data | H14: Expected Result | I14: Actual Result | J14: Status | K14: Severity | L14: Screen Shots | M14: Suggestion | N14: Feedback

Sheet Summary Report
A1: Module | B1: Sub Module | C1: Test Case ID | D1: Bug Count | E1: Bug Rate % | F1: Bug Severity
A2: =IFERROR(__xludf.DUMMYFUNCTION("SORT( SPLIT( UNIQUE( FILTER('Main Report'!B11:B1000 & ""♦"" & 'Main Report'!C11:C1000, LEN('Main Report'!C11:C1000)) ), ""♦"" ), 1, TRUE, 2, TRUE ) "),"Account") -> Account | B2: =IFERROR(__xludf.DUMMYFUNCTION("""COMPUTED_VALUE"""),"Account") -> Account | C2: =IFERROR(__xludf.DUMMYFUNCTION("TEXTJOIN("", "", TRUE, FILTER('Main Report'!A11:A1000, ('Main Report'!B11:B1000=A2) * ('Main Report'!C11:C1000=B2) ) ) "),"BR-001, BR-002, BR-003, BR-004, BR-005, BR-006, BR-007, BR-008") -> BR-001, BR-002, BR-003, BR-004, BR-005, BR-006, BR-007, BR-008 | D2: =IFERROR(__xludf.DUMMYFUNCTION("COUNTA(UNIQUE(TRANSPOSE(SPLIT(C2, "", "")))) "),8.0) -> 8 | E2: =IF(D2="", "", TEXT((D2 / 'Main Report'!$E$7), "0.00%")) -> 20.00% | F2: =IFERROR(__xludf.DUMMYFUNCTION("IF(C2="""", """", TEXTJOIN("", "", TRUE, ""High: "" & COUNTIF(FILTER('Main Report'!K11:K1000, ISNUMBER(MATCH('Main Report'!A11:A1000, SPLIT(C2, "", ""), 0))), ""High"") & CHAR(10) & ""Medium: "" & COUNTIF(FILTER('Main Report'!K11:K1000, I"&"SNUMBER(MATCH('Main Report'!A11:A1000, SPLIT(C2, "", ""), 0))), ""Medium"") & CHAR(10) & ""Low: "" & COUNTIF(FILTER('Main Report'!K11:K1000, ISNUMBER(MATCH('Main Report'!A11:A1000, SPLIT(C2, "", ""), 0))), ""Low"") ) ) "),"High: 6 Medium: 1 Low: 1") -> High: 6 Medium: 1 Low: 1
A3: =IFERROR(__xludf.DUMMYFUNCTION("""COMPUTED_VALUE"""),"Forget Password") -> Forget Password | B3: =IFERROR(__xludf.DUMMYFUNCTION("""COMPUTED_VALUE"""),"Forget Password") -> Forget Password | C3: =IFERROR(__xludf.DUMMYFUNCTION("TEXTJOIN("", "", TRUE, FILTER('Main Report'!A12:A1001, ('Main Report'!B12:B1001=A3) * ('Main Report'!C12:C1001=B3) ) ) "),"BR-009") -> BR-009 | D3: =IFERROR(__xludf.DUMMYFUNCTION("COUNTA(UNIQUE(TRANSPOSE(SPLIT(C3, "", "")))) "),1.0) -> 1 | E3: =IF(D3="", "", TEXT((D3 / 'Main Report'!$E$7), "0.00%")) -> 2.50% | F3: =IFERROR(__xludf.DUMMYFUNCTION("IF(C3="""", """", TEXTJOIN("", "", TRUE, ""High: "" & COUNTIF(FILTER('Main Report'!K12:K1001, ISNUMBER(MATCH('Main Report'!A12:A1001, SPLIT(C3, "", ""), 0))), ""High"") & CHAR(10) & ""Medium: "" & COUNTIF(FILTER('Main Report'!K12:K1001, I"&"SNUMBER(MATCH('Main Report'!A12:A1001, SPLIT(C3, "", ""), 0))), ""Medium"") & CHAR(10) & ""Low: "" & COUNTIF(FILTER('Main Report'!K12:K1001, ISNUMBER(MATCH('Main Report'!A12:A1001, SPLIT(C3, "", ""), 0))), ""Low"") ) ) "),"High: 0 Medium: 1 Low: 0") -> High: 0 Medium: 1 Low: 0
A4: =IFERROR(__xludf.DUMMYFUNCTION("""COMPUTED_VALUE"""),"History") -> History | B4: =IFERROR(__xludf.DUMMYFUNCTION("""COMPUTED_VALUE"""),"History") -> History | C4: =IFERROR(__xludf.DUMMYFUNCTION("TEXTJOIN("", "", TRUE, FILTER('Main Report'!A13:A1002, ('Main Report'!B13:B1002=A4) * ('Main Report'!C13:C1002=B4) ) ) "),"BR-010") -> BR-010 | D4: =IFERROR(__xludf.DUMMYFUNCTION("COUNTA(UNIQUE(TRANSPOSE(SPLIT(C4, "", "")))) "),1.0) -> 1 | E4: =IF(D4="", "", TEXT((D4 / 'Main Report'!$E$7), "0.00%")) -> 2.50% | F4: =IFERROR(__xludf.DUMMYFUNCTION("IF(C4="""", """", TEXTJOIN("", "", TRUE, ""High: "" & COUNTIF(FILTER('Main Report'!K13:K1002, ISNUMBER(MATCH('Main Report'!A13:A1002, SPLIT(C4, "", ""), 0))), ""High"") & CHAR(10) & ""Medium: "" & COUNTIF(FILTER('Main Report'!K13:K1002, I"&"SNUMBER(MATCH('Main Report'!A13:A1002, SPLIT(C4, "", ""), 0))), ""Medium"") & CHAR(10) & ""Low: "" & COUNTIF(FILTER('Main Report'!K13:K1002, ISNUMBER(MATCH('Main Report'!A13:A1002, SPLIT(C4, "", ""), 0))), ""Low"") ) ) "),"High: 0 Medium: 1 Low: 0") -> High: 0 Medium: 1 Low: 0
A5: =IFERROR(__xludf.DUMMYFUNCTION("""COMPUTED_VALUE"""),"Home") -> Home | B5: =IFERROR(__xludf.DUMMYFUNCTION("""COMPUTED_VALUE"""),"Quick Booking") -> Quick Booking | C5: =IFERROR(__xludf.DUMMYFUNCTION("TEXTJOIN("", "", TRUE, FILTER('Main Report'!A14:A1003, ('Main Report'!B14:B1003=A5) * ('Main Report'!C14:C1003=B5) ) ) "),"BR-011, BR-012, BR-013, BR-014, BR-015, BR-016, BR-017, BR-018") -> BR-011, BR-012, BR-013, BR-014, BR-015, BR-016, BR-017, BR-018 | D5: =IFERROR(__xludf.DUMMYFUNCTION("COUNTA(UNIQUE(TRANSPOSE(SPLIT(C5, "", "")))) "),8.0) -> 8 | E5: =IF(D5="", "", TEXT((D5 / 'Main Report'!$E$7), "0.00%")) -> 20.00% | F5: =IFERROR(__xludf.DUMMYFUNCTION("IF(C5="""", """", TEXTJOIN("", "", TRUE, ""High: "" & COUNTIF(FILTER('Main Report'!K14:K1003, ISNUMBER(MATCH('Main Report'!A14:A1003, SPLIT(C5, "", ""), 0))), ""High"") & CHAR(10) & ""Medium: "" & COUNTIF(FILTER('Main Report'!K14:K1003, I"&"SNUMBER(MATCH('Main Report'!A14:A1003, SPLIT(C5, "", ""), 0))), ""Medium"") & CHAR(10) & ""Low: "" & COUNTIF(FILTER('Main Report'!K14:K1003, ISNUMBER(MATCH('Main Report'!A14:A1003, SPLIT(C5, "", ""), 0))), ""Low"") ) ) "),"High: 6 Medium: 2 Low: 0") -> High: 6 Medium: 2 Low: 0
A6: =IFERROR(__xludf.DUMMYFUNCTION("""COMPUTED_VALUE"""),"Landing screen") -> Landing screen | B6: =IFERROR(__xludf.DUMMYFUNCTION("""COMPUTED_VALUE"""),"Home") -> Home | C6: =IFERROR(__xludf.DUMMYFUNCTION("TEXTJOIN("", "", TRUE, FILTER('Main Report'!A15:A104, ('Main Report'!B15:B104=A6) * ('Main Report'!C15:C104=B6) ) ) "),"BR-019, BR-020, BR-021, BR-022, BR-023, BR-024, BR-025, BR-026") -> BR-019, BR-020, BR-021, BR-022, BR-023, BR-024, BR-025, BR-026 | D6: =IFERROR(__xludf.DUMMYFUNCTION("COUNTA(UNIQUE(TRANSPOSE(SPLIT(C6, "", "")))) "),8.0) -> 8 | E6: =IF(D6="", "", TEXT((D6 / 'Main Report'!$E$7), "0.00%")) -> 20.00% | F6: =IFERROR(__xludf.DUMMYFUNCTION("IF(C6="""", """", TEXTJOIN("", "", TRUE, ""High: "" & COUNTIF(FILTER('Main Report'!K15:K104, ISNUMBER(MATCH('Main Report'!A15:A104, SPLIT(C6, "", ""), 0))), ""High"") & CHAR(10) & ""Medium: "" & COUNTIF(FILTER('Main Report'!K15:K104, ISNU"&"MBER(MATCH('Main Report'!A15:A104, SPLIT(C6, "", ""), 0))), ""Medium"") & CHAR(10) & ""Low: "" & COUNTIF(FILTER('Main Report'!K15:K104, ISNUMBER(MATCH('Main Report'!A15:A104, SPLIT(C6, "", ""), 0))), ""Low"") ) ) "),"High: 3 Medium: 5 Low: 0") -> High: 3 Medium: 5 Low: 0
