Workbook

Sheet Fahad
A1: Tester : | B1: Mohammed Fahad Faisal
A2: Project Name: | B2: Jensa Group
A3: Developer: | B3: AI Venture
A4: OS: | B4: Windows 11 Pro Version:24H2 OS build:26100.4946
A5: Environment: | B5: Brave 1.81.135 (Official Build) (64-bit) Chromium: 139.0.7258.127 | N5: Place solve if the issue resolves | \/ | O5: Mention which Stack solved the issue | \/
A7: Test ID | B7: Module | C7: Sub Module | D7: Test Case Description | E7: Preconditions | F7: Test Steps | G7: Test Data | H7: Expected Result | I7: Actual Result | J7: Status | K7: Severity | L7: Screen Shots | M7: Suggestion | N7: Feedback | O7: Stack | P7: Comment
A8: BR_001 | B8: Login | C8: Login | D8: Strong password indicator needs to be implemented. | E8: User needs to access the login portal using a web browser. | F8: 1. Open browser 2. Login with admin credentials | G8: ADMIN Credentials | H8: Strong password indicator should be displayed while entering a password. | I8: Login page is missing a password field indicator. | J8: Fail | K8: Medium | L8: 001.png
A10: BR_002 | B10: Home | C10: Dashboard | D10: not connected to the route | E10: User needs to access the login portal using a web browser. | F10: 1. Open browser 2. Login with admin credentials | G10: ADMIN Credentials | H10: Clicking on the banners should redirect to the actual page. | I10: Static feature has been detected. | J10: Fail | K10: High | L10: 002.png
A12: BR_003 | B12: Home | C12: Dashboard | D12: Search module isn’t working. | E12: User needs to access the login portal using a web browser. | F12: 1. Open browser 2. Login with admin credentials | G12: ADMIN Credentials | H12: Search module should be functional | I12: Search module has been found to be non-functional. | J12: Fail | K12: High | L12: 003.png
A14: BR_004 | B14: Home | C14: Dashboard | D14: Clicking on a username should take the user to their profile. | E14: User needs to access the login portal using a web browser. | F14: 1. Open browser 2. Login with admin credentials | G14: ADMIN Credentials | H14: Click on user name on dashboard should redirect to user to profile section | I14: Stay in place after clicking on the username. | J14: Fail | K14: High | L14: 004.png
A16: BR_005 | B16: Home | C16: Dashboard | D16: Section title differs from Figma. | E16: User needs to access the login portal using a web browser. | F16: 1. Open browser 2. Login with admin credentials | G16: ADMIN Credentials | H16: Design and alignment should be exactly the same as in Figma. | I16: Section differs from Figma. | J16: Fail | K16: Low | L16: 005.png
A18: BR_006 | B18: Home | C18: Dashboard | D18: Content design mismatch from Figma | E18: User needs to access the login portal using a web browser. | F18: 1. Open browser 2. Login with admin credentials | G18: ADMIN Credentials | H18: Design and alignment should be exactly the same as in Figma. | I18: Section differs from Figma. | J18: Fail | K18: Medium | L18: 006.png
A20: BR_007 | B20: Home | C20: Dashboard | D20: Showing a number instead of theassigned persons name. | E20: User needs to access the login portal using a web browser. | F20: 1. Open browser 2. Login with admin credentials | G20: ADMIN Credentials | H20: Assigned persons name should be displayed accurately in the Upcoming Tasks Today section | I20: Missing assigned persons name in Upcoming Tasks Today section | J20: Fail | K20: High | L20: 007.png
A22: BR_008 | B22: Home | C22: Dashboard | D22: Failed to view attached media | E22: User needs to access the login portal using a web browser. | F22: 1. Open browser 2. Login with admin credentials | G22: ADMIN Credentials | H22: Media data should load perfectly. | I22: Failed to load media data. | J22: Fail | K22: High | L22: 008.png
A24: BR_009 | B24: Home | C24: Buildings | D24: Should be highlighted when the user is in the buildings section. | E24: User needs to access the login portal using a web browser. | F24: 1. Open browser 2. Login with admin credentials 3. Goto Buildings section | G24: ADMIN Credentials | H24: Option should be highlighted when the user is within the segment. | I24: =IFERROR(__xludf.DUMMYFUNCTION("AI(""Fill an appropriate value for this cell based on the table context"")"),"Not highlighted when the user is in the buildings section.") -> Not highlighted when the user is in the buildings section. | J24: Fail | K24: Medium | L24: 009.png
A26: BR_010 | B26: Home | C26: Buildings | D26: Missing edit details for flat | E26: User needs to access the login portal using a web browser. | F26: 1. Open browser 2. Login with admin credentials 3. Goto Buildings section | G26: ADMIN Credentials | H26: Design and feature implementation should match the Figma exactly. | I26: "Edit Details" option is missing from the frontend. | J26: Fail | K26: High | L26: 010.png
A28: BR_011 | B28: Home | C28: Buildings | D28: UI layout differs from Figma | E28: User needs to access the login portal using a web browser. | F28: 1. Open browser 2. Login with admin credentials 3. Goto Buildings section | G28: ADMIN Credentials | H28: UI layout should match the Figma design to ensure client satisfaction. | I28: Different UI implementation has been found. | J28: Fail | K28: Medium | L28: 011.png
A30: BR_012 | B30: Home | C30: Buildings | D30: layout design issue | E30: User needs to access the login portal using a web browser. | F30: 1. Open browser 2. Login with admin credentials 3. Goto Buildings section | G30: ADMIN Credentials | H30: UI layout should match the Figma design to ensure client satisfaction. | I30: Different UI implementation has been found. | J30: Fail | K30: Medium | L30: 012.png
A32: BR_013 | B32: Home | C32: Maintenance | D32: Status filter option is missing. | E32: User needs to access the login portal using a web browser. | F32: 1. Open browser 2. Login with admin credentials 3. Goto Maintenance section | G32: ADMIN Credentials | H32: Design and feature implementation should match the Figma exactly. | I32: "Edit Details" option is missing on frontend. | J32: Fail | K32: High | L32: 013.png
A34: BR_014 | B34: Home | C34: Maintenance | D34: View option is missing from the action segment. | E34: User needs to access the login portal using a web browser. | F34: 1. Open browser 2. Login with admin credentials 3. Goto Maintenance section | G34: ADMIN Credentials | H34: Design and feature implementation should match the Figma exactly. | I34: "view" option is missing on frontend. | J34: Fail | K34: High | L34: 014.png
A36: BR_015 | B36: Home | C36: User Management | D36: Design layout differs from Figma. | E36: User needs to access the login portal using a web browser. | F36: 1. Open browser 2. Login with admin credentials 3. Goto User management section 4. Click on mini admin | G36: ADMIN Credentials | H36: UI layout should match the Figma design to ensure client satisfaction. | I36: Different UI implementation has been found. | J36: Fail | K36: Low | L36: 015.png
A38: BR_016 | B38: Home | C38: User Management | D38: Unable to upload the mini admin profile picture. | E38: User needs to access the login portal using a web browser. | F38: 1. Open browser 2. Login with admin credentials 3. Goto User management section 4. Click on mini admin | G38: ADMIN Credentials | H38: User should be able to upload an admin profile. | I38: failed to upload image | J38: Fail | K38: High | L38: 016.png
A40: BR_017 | B40: Home | C40: User Management | D40: Field should be required when adding an admin, cleaner, or maintenance worker. | E40: User needs to access the login portal using a web browser. | F40: 1. Open browser 2. Login with admin credentials 3. Goto User management section 4. Click on mini admin | G40: ADMIN Credentials | H40: name , address , city etc fields should be required | I40: Fields are not required | J40: Fail | K40: Medium | L40: 017.png
A42: BR_018 | B42: Home | C42: User Management | D42: should be drop-down list | E42: User needs to access the login portal using a web browser. | F42: 1. Open browser 2. Login with admin credentials 3. Goto User management section 4. Click on mini admin | G42: ADMIN Credentials | H42: Design and feature implementation should match the Figma exactly. | I42: set as tag in frontend | J42: Fail | K42: Medium | L42: 018.png
A44: BR_019 | B44: Home | C44: Reports | D44: UI different from figma | E44: User needs to access the login portal using a web browser. | F44: 1. Open browser 2. Login with admin credentials 3. Goto Reports | G44: ADMIN Credentials | H44: UI layout should match the Figma design to ensure client satisfaction. | I44: Different UI implementation has been found. | J44: Fail | K44: Medium | L44: 019.png
A46: BR_020 | B46: Home | C46: Reports | D46: Action field is non-functional. | E46: User needs to access the login portal using a web browser. | F46: 1. Open browser 2. Login with admin credentials 3. Goto Reports | G46: ADMIN Credentials | H46: User should be able to view the full details of the issue according to the Figma design. | I46: Unable to view the issue details in the frontend. | J46: Fail | K46: High | L46: 020.png
A48: BR_021 | B48: Home | C48: Reports | D48: Report export feature failed. | E48: User needs to access the login portal using a web browser. | F48: 1. Open browser 2. Login with admin credentials 3. Goto Reports | G48: ADMIN Credentials | H48: user should be able to export report | I48: failed to export report | J48: Fail | K48: High | L48: 021.png
... A66: BR_030 | B66: Home | C66: Profile | D66: Failed to open notification under profile section | E66: User needs to access the login portal using a web browser. | F66: 1. Open browser 2. Login with admin credentials 3. Goto profile section 4. Click on notification icon | G66: ADMIN Credentials | H66: User should be able to access notification panel if the icon is visible | I66: Unable to open notification from the profile section. | J66: Fail | K66: High | L66: 030.png
A68: BR_031
A70: BR_032
A72: BR_033
A74: BR_034
A76: BR_035
A78: BR_036
A80: BR_037
A82: BR_038

Sheet Tahsin
A2: Tester : | D2: Severity | E2: Issues
A3: Project Name: | D3: High | E3: =COUNTIF(K14:K897, "High") -> 0
A4: Project URL: | D4: Medium | E4: =COUNTIF(K14:K898, "Medium") -> 0
A5: Developer: | D5: Low | E5: =COUNTIF(K14:K899, "Low") -> 0
A6: OS:
A7: Environment | D7: Total Test Cases: | E7: =SUM(E3:E5) -> 0
D8: Test Case Solved :
A10: Test ID | B10: Module | C10: Sub Module | D10: Test Case Description | E10: Preconditions | F10: Test Steps | G10: Test Data | H10: Expected Result | I10: Actual Result | J10: Status | K10: Severity | L10: Screen Shots | M10: Suggestion | N10: Feedback | O10: Stack | P10: Comment

Sheet Main Report
A2: Tester : | B2: Mohammed Fahad Faisal | D2: Severity | E2: Issues
A3: Project Name: | D3: High | E3: =COUNTIF(Tahsin!K14:K897, "High") + COUNTIF(Fahad!K8:K1004, "High") -> 17
A4: Project URL: | D4: Medium | E4: =COUNTIF(Tahsin!K14:K898, "Medium") + COUNTIF(Fahad!K8:K1005, "Medium") -> 11
A5: Developer: | D5: Low | E5: =COUNTIF(Fahad!K8:K1006, "Low") + COUNTIF(Tahsin!K14:K901, "Low") -> 2
A6: OS:
A7: Environment | D7: Total Test Cases: | E7: =SUM(E3:E5) -> 30
D8: Test Case Solved : | E8: =COUNTIF(N11:N2387, "Solved") -> 0
A10: Test Case ID | B10: Module | C10: Sub Module | D10: Test Case Description | E10: Preconditions | F10: Test Steps | G10: Test Data | H10: Expected Result | I10: Actual Result | J10: Status | K10: Severity | L10: Screen Shots | M10: Suggestion | N10: Feedback | O10: Stack | P10: Comment | Q10: Tester
A11: {=IF((LEN(B11:B100)+LEN(C11:C100))>0, "BR-" & TEXT(ROW(B11:B100)-ROW(B11)+1,"000"), "")} -> BR-001 | B11: =IFERROR(__xludf.DUMMYFUNCTION("QUERY( { ARRAYFORMULA({ TRIM(Fahad!B8:B2383), Fahad!C8:P2383, IF(LEN(Fahad!B8:B2383), ""Fahad"", """") }); ARRAYFORMULA({ TRIM(Tahsin!B15:B2383), Tahsin!C15:P2383, IF(LEN(Tahsin!B15:B2383), ""Tahsin"","&" """") }) }, ""SELECT * WHERE Col1 IS NOT NULL ORDER BY Col1 ASC, Col2 ASC"", 0 )"),"Home") -> Home | C11: =IFERROR(__xludf.DUMMYFUNCTION("""COMPUTED_VALUE"""),"Buildings") -> Buildings | D11: =IFERROR(__xludf.DUMMYFUNCTION("""COMPUTED_VALUE"""),"Should be highlighted when the user is in the buildings section.") -> Should be highlighted when the user is in the buildings section. | E11: =IFERROR(__xludf.DUMMYFUNCTION("""COMPUTED_VALUE"""),"User needs to access the login portal using a web browser.") -> User needs to access the login portal using a web browser. | F11: =IFERROR(__xludf.DUMMYFUNCTION("""COMPUTED_VALUE"""),"1. Open browser 2. Login with admin credentials 3. Goto Buildings section") -> 1. Open browser 2. Login with admin credentials 3. Goto Buildings section | G11: =IFERROR(__xludf.DUMMYFUNCTION("""COMPUTED_VALUE"""),"ADMIN Credentials") -> ADMIN Credentials | H11: =IFERROR(__xludf.DUMMYFUNCTION("""COMPUTED_VALUE"""),"Option should be highlighted when the user is within the segment.") -> Option should be highlighted when the user is within the segment. | I11: =IFERROR(__xludf.DUMMYFUNCTION("""COMPUTED_VALUE"""),"Not highlighted when the user is in the buildings section.") -> Not highlighted when the user is in the buildings section. | J11: =IFERROR(__xludf.DUMMYFUNCTION("""COMPUTED_VALUE"""),"Fail") -> Fail | K11: =IFERROR(__xludf.DUMMYFUNCTION("""COMPUTED_VALUE"""),"Medium") -> Medium | L11: =IFERROR(__xludf.DUMMYFUNCTION("""COMPUTED_VALUE"""),"009.png") -> 009.png | Q11: =IFERROR(__xludf.DUMMYFUNCTION("""COMPUTED_VALUE"""),"Fahad") -> Fahad
A12: BR-002 | B12: =IFERROR(__xludf.DUMMYFUNCTION("""COMPUTED_VALUE"""),"Home") -> Home | C12: =IFERROR(__xludf.DUMMYFUNCTION("""COMPUTED_VALUE"""),"Buildings") -> Buildings | D12: =IFERROR(__xludf.DUMMYFUNCTION("""COMPUTED_VALUE"""),"Missing edit details for flat") -> Missing edit details for flat | E12: =IFERROR(__xludf.DUMMYFUNCTION("""COMPUTED_VALUE"""),"User needs to access the login portal using a web browser.") -> User needs to access the login portal using a web browser. | F12: =IFERROR(__xludf.DUMMYFUNCTION("""COMPUTED_VALUE"""),"1. Open browser 2. Login with admin credentials 3. Goto Buildings section") -> 1. Open browser 2. Login with admin credentials 3. Goto Buildings section | G12: =IFERROR(__xludf.DUMMYFUNCTION("""COMPUTED_VALUE"""),"ADMIN Credentials") -> ADMIN Credentials | H12: =IFERROR(__xludf.DUMMYFUNCTION("""COMPUTED_VALUE"""),"Design and feature implementation should match the Figma exactly.") -> Design and feature implementation should match the Figma exactly. | I12: =IFERROR(__xludf.DUMMYFUNCTION("""COMPUTED_VALUE"""),"""Edit Details"" option is missing from the frontend.") -> "Edit Details" option is missing from the frontend. | J12: =IFERROR(__xludf.DUMMYFUNCTION("""COMPUTED_VALUE"""),"Fail") -> Fail | K12: =IFERROR(__xludf.DUMMYFUNCTION("""COMPUTED_VALUE"""),"High") -> High | L12: =IFERROR(__xludf.DUMMYFUNCTION("""COMPUTED_VALUE"""),"010.png") -> 010.png | Q12: =IFERROR(__xludf.DUMMYFUNCTION("""COMPUTED_VALUE"""),"Fahad") -> Fahad
A13: BR-003 | B13: =IFERROR(__xludf.DUMMYFUNCTION("""COMPUTED_VALUE"""),"Home") -> Home | C13: =IFERROR(__xludf.DUMMYFUNCTION("""COMPUTED_VALUE"""),"Buildings") -> Buildings | D13: =IFERROR(__xludf.DUMMYFUNCTION("""COMPUTED_VALUE"""),"UI layout differs from Figma") -> UI layout differs from Figma | E13: =IFERROR(__xludf.DUMMYFUNCTION("""COMPUTED_VALUE"""),"User needs to access the login portal using a web browser.") -> User needs to access the login portal using a web browser. | F13: =IFERROR(__xludf.DUMMYFUNCTION("""COMPUTED_VALUE"""),"1. Open browser 2. Login with admin credentials 3. Goto Buildings section") -> 1. Open browser 2. Login with admin credentials 3. Goto Buildings section | G13: =IFERROR(__xludf.DUMMYFUNCTION("""COMPUTED_VALUE"""),"ADMIN Credentials") -> ADMIN Credentials | H13: =IFERROR(__xludf.DUMMYFUNCTION("""COMPUTED_VALUE"""),"UI layout should match the Figma design to ensure client satisfaction.") -> UI layout should match the Figma design to ensure client satisfaction. | I13: =IFERROR(__xludf.DUMMYFUNCTION("""COMPUTED_VALUE"""),"Different UI implementation has been found.") -> Different UI implementation has been found. | J13: =IFERROR(__xludf.DUMMYFUNCTION("""COMPUTED_VALUE"""),"Fail") -> Fail | K13: =IFERROR(__xludf.DUMMYFUNCTION("""COMPUTED_VALUE"""),"Medium") -> Medium | L13: =IFERROR(__xludf.DUMMYFUNCTION("""COMPUTED_VALUE"""),"011.png") -> 011.png | Q13: =IFERROR(__xludf.DUMMYFUNCTION("""COMPUTED_VALUE"""),"Fahad") -> Fahad
A14: BR-004 | B14: =IFERROR(__xludf.DUMMYFUNCTION("""COMPUTED_VALUE"""),"Home") -> Home | C14: =IFERROR(__xludf.DUMMYFUNCTION("""COMPUTED_VALUE"""),"Buildings") -> Buildings | D14: =IFERROR(__xludf.DUMMYFUNCTION("""COMPUTED_VALUE"""),"layout design issue") -> layout design issue | E14: =IFERROR(__xludf.DUMMYFUNCTION("""COMPUTED_VALUE"""),"User needs to access the login portal using a web browser.") -> User needs to access the login portal using a web browser. | F14: =IFERROR(__xludf.DUMMYFUNCTION("""COMPUTED_VALUE"""),"1. Open browser 2. Login with admin credentials 3. Goto Buildings section") -> 1. Open browser 2. Login with admin credentials 3. Goto Buildings section | G14: =IFERROR(__xludf.DUMMYFUNCTION("""COMPUTED_VALUE"""),"ADMIN Credentials") -> ADMIN Credentials | H14: =IFERROR(__xludf.DUMMYFUNCTION("""COMPUTED_VALUE"""),"UI layout should match the Figma design to ensure client satisfaction.") -> UI layout should match the Figma design to ensure client satisfaction. | I14: =IFERROR(__xludf.DUMMYFUNCTION("""COMPUTED_VALUE"""),"Different UI implementation has been found.") -> Different UI implementation has been found. | J14: =IFERROR(__xludf.DUMMYFUNCTION("""COMPUTED_VALUE"""),"Fail") -> Fail | K14: =IFERROR(__xludf.DUMMYFUNCTION("""COMPUTED_VALUE"""),"Medium") -> Medium | L14: =IFERROR(__xludf.DUMMYFUNCTION("""COMPUTED_VALUE"""),"012.png") -> 012.png | Q14: =IFERROR(__xludf.DUMMYFUNCTION("""COMPUTED_VALUE"""),"Fahad") -> Fahad
A15: BR-005 | B15: =IFERROR(__xludf.DUMMYFUNCTION("""COMPUTED_VALUE"""),"Home") -> Home | C15: =IFERROR(__xludf.DUMMYFUNCTION("""COMPUTED_VALUE"""),"Dashboard") -> Dashboard | D15: =IFERROR(__xludf.DUMMYFUNCTION("""COMPUTED_VALUE"""),"not connected to the route") -> not connected to the route | E15: =IFERROR(__xludf.DUMMYFUNCTION("""COMPUTED_VALUE"""),"User needs to access the login portal using a web browser.") -> User needs to access the login portal using a web browser. | F15: =IFERROR(__xludf.DUMMYFUNCTION("""COMPUTED_VALUE"""),"1. Open browser 2. Login with admin credentials") -> 1. Open browser 2. Login with admin credentials | G15: =IFERROR(__xludf.DUMMYFUNCTION("""COMPUTED_VALUE"""),"ADMIN Credentials") -> ADMIN Credentials | H15: =IFERROR(__xludf.DUMMYFUNCTION("""COMPUTED_VALUE"""),"Clicking on the banners should redirect to the actual page.") -> Clicking on the banners should redirect to the actual page. | I15: =IFERROR(__xludf.DUMMYFUNCTION("""COMPUTED_VALUE"""),"Static feature has been detected.") -> Static feature has been detected. | J15: =IFERROR(__xludf.DUMMYFUNCTION("""COMPUTED_VALUE"""),"Fail") -> Fail | K15: =IFERROR(__xludf.DUMMYFUNCTION("""COMPUTED_VALUE"""),"High") -> High | L15: =IFERROR(__xludf.DUMMYFUNCTION("""COMPUTED_VALUE"""),"002.png") -> 002.png | Q15: =IFERROR(__xludf.DUMMYFUNCTION("""COMPUTED_VALUE"""),"Fahad") -> Fahad
A16: BR-006 | B16: =IFERROR(__xludf.DUMMYFUNCTION("""COMPUTED_VALUE"""),"Home") -> Home | C16: =IFERROR(__xludf.DUMMYFUNCTION("""COMPUTED_VALUE"""),"Dashboard") -> Dashboard | D16: =IFERROR(__xludf.DUMMYFUNCTION("""COMPUTED_VALUE"""),"Search module isn’t working.") -> Search module isn’t working. | E16: =IFERROR(__xludf.DUMMYFUNCTION("""COMPUTED_VALUE"""),"User needs to access the login portal using a web browser.") -> User needs to access the login portal using a web browser. | F16: =IFERROR(__xludf.DUMMYFUNCTION("""COMPUTED_VALUE"""),"1. Open browser 2. Login with admin credentials") -> 1. Open browser 2. Login with admin credentials | G16: =IFERROR(__xludf.DUMMYFUNCTION("""COMPUTED_VALUE"""),"ADMIN Credentials") -> ADMIN Credentials | H16: =IFERROR(__xludf.DUMMYFUNCTION("""COMPUTED_VALUE"""),"Search module should be functional") -> Search module should be functional | I16: =IFERROR(__xludf.DUMMYFUNCTION("""COMPUTED_VALUE"""),"Search module has been found to be non-functional.") -> Search module has been found to be non-functional. | J16: =IFERROR(__xludf.DUMMYFUNCTION("""COMPUTED_VALUE"""),"Fail") -> Fail | K16: =IFERROR(__xludf.DUMMYFUNCTION("""COMPUTED_VALUE"""),"High") -> High | L16: =IFERROR(__xludf.DUMMYFUNCTION("""COMPUTED_VALUE"""),"003.png") -> 003.png | Q16: =IFERROR(__xludf.DUMMYFUNCTION("""COMPUTED_VALUE"""),"Fahad") -> Fahad
A17: BR-007 | B17: =IFERROR(__xludf.DUMMYFUNCTION("""COMPUTED_VALUE"""),"Home") -> Home | C17: =IFERROR(__xludf.DUMMYFUNCTION("""COMPUTED_VALUE"""),"Dashboard") -> Dashboard | D17: =IFERROR(__xludf.DUMMYFUNCTION("""COMPUTED_VALUE"""),"Clicking on a username should take the user to their profile.") -> Clicking on a username should take the user to their profile. | E17: =IFERROR(__xludf.DUMMYFUNCTION("""COMPUTED_VALUE"""),"User needs to access the login portal using a web browser.") -> User needs to access the login portal using a web browser. | F17: =IFERROR(__xludf.DUMMYFUNCTION("""COMPUTED_VALUE"""),"1. Open browser 2. Login with admin credentials") -> 1. Open browser 2. Login with admin credentials | G17: =IFERROR(__xludf.DUMMYFUNCTION("""COMPUTED_VALUE"""),"ADMIN Credentials") -> ADMIN Credentials | H17: =IFERROR(__xludf.DUMMYFUNCTION("""COMPUTED_VALUE"""),"Click on user name on dashboard should redirect to user to profile section") -> Click on user name on dashboard should redirect to user to profile section | I17: =IFERROR(__xludf.DUMMYFUNCTION("""COMPUTED_VALUE"""),"Stay in place after clicking on the username.") -> Stay in place after clicking on the username. | J17: =IFERROR(__xludf.DUMMYFUNCTION("""COMPUTED_VALUE"""),"Fail") -> Fail | K17: =IFERROR(__xludf.DUMMYFUNCTION("""COMPUTED_VALUE"""),"High") -> High | L17: =IFERROR(__xludf.DUMMYFUNCTION("""COMPUTED_VALUE"""),"004.png") -> 004.png | Q17: =IFERROR(__xludf.DUMMYFUNCTION("""COMPUTED_VALUE"""),"Fahad") -> Fahad
A18: BR-008 | B18: =IFERROR(__xludf.DUMMYFUNCTION("""COMPUTED_VALUE"""),"Home") -> Home | C18: =IFERROR(__xludf.DUMMYFUNCTION("""COMPUTED_VALUE"""),"Dashboard") -> Dashboard | D18: =IFERROR(__xludf.DUMMYFUNCTION("""COMPUTED_VALUE"""),"Section title differs from Figma.") -> Section title differs from Figma. | E18: =IFERROR(__xludf.DUMMYFUNCTION("""COMPUTED_VALUE"""),"User needs to access the login portal using a web browser.") -> User needs to access the login portal using a web browser. | F18: =IFERROR(__xludf.DUMMYFUNCTION("""COMPUTED_VALUE"""),"1. Open browser 2. Login with admin credentials") -> 1. Open browser 2. Login with admin credentials | G18: =IFERROR(__xludf.DUMMYFUNCTION("""COMPUTED_VALUE"""),"ADMIN Credentials") -> ADMIN Credentials | H18: =IFERROR(__xludf.DUMMYFUNCTION("""COMPUTED_VALUE"""),"Design and alignment should be exactly the same as in Figma.") -> Design and alignment should be exactly the same as in Figma. | I18: =IFERROR(__xludf.DUMMYFUNCTION("""COMPUTED_VALUE"""),"Section differs from Figma.") -> Section differs from Figma. | J18: =IFERROR(__xludf.DUMMYFUNCTION("""COMPUTED_VALUE"""),"Fail") -> Fail | K18: =IFERROR(__xludf.DUMMYFUNCTION("""COMPUTED_VALUE"""),"Low") -> Low | L18: =IFERROR(__xludf.DUMMYFUNCTION("""COMPUTED_VALUE"""),"005.png") -> 005.png | Q18: =IFERROR(__xludf.DUMMYFUNCTION("""COMPUTED_VALUE"""),"Fahad") -> Fahad
A19: BR-009 | B19: =IFERROR(__xludf.DUMMYFUNCTION("""COMPUTED_VALUE"""),"Home") -> Home | C19: =IFERROR(__xludf.DUMMYFUNCTION("""COMPUTED_VALUE"""),"Dashboard") -> Dashboard | D19: =IFERROR(__xludf.DUMMYFUNCTION("""COMPUTED_VALUE"""),"Content design mismatch from Figma") -> Content design mismatch from Figma | E19: =IFERROR(__xludf.DUMMYFUNCTION("""COMPUTED_VALUE"""),"User needs to access the login portal using a web browser.") -> User needs to access the login portal using a web browser. | F19: =IFERROR(__xludf.DUMMYFUNCTION("""COMPUTED_VALUE"""),"1. Open browser 2. Login with admin credentials") -> 1. Open browser 2. Login with admin credentials | G19: =IFERROR(__xludf.DUMMYFUNCTION("""COMPUTED_VALUE"""),"ADMIN Credentials") -> ADMIN Credentials | H19: =IFERROR(__xludf.DUMMYFUNCTION("""COMPUTED_VALUE"""),"Design and alignment should be exactly the same as in Figma.") -> Design and alignment should be exactly the same as in Figma. | I19: =IFERROR(__xludf.DUMMYFUNCTION("""COMPUTED_VALUE"""),"Section differs from Figma.") -> Section differs from Figma. | J19: =IFERROR(__xludf.DUMMYFUNCTION("""COMPUTED_VALUE"""),"Fail") -> Fail | K19: =IFERROR(__xludf.DUMMYFUNCTION("""COMPUTED_VALUE"""),"Medium") -> Medium | L19: =IFERROR(__xludf.DUMMYFUNCTION("""COMPUTED_VALUE"""),"006.png") -> 006.png | Q19: =IFERROR(__xludf.DUMMYFUNCTION("""COMPUTED_VALUE"""),"Fahad") -> Fahad
A20: BR-010 | B20: =IFERROR(__xludf.DUMMYFUNCTION("""COMPUTED_VALUE"""),"Home") -> Home | C20: =IFERROR(__xludf.DUMMYFUNCTION("""COMPUTED_VALUE"""),"Dashboard") -> Dashboard | D20: =IFERROR(__xludf.DUMMYFUNCTION("""COMPUTED_VALUE"""),"Showing a number instead of theassigned persons name.") -> Showing a number instead of theassigned persons name. | E20: =IFERROR(__xludf.DUMMYFUNCTION("""COMPUTED_VALUE"""),"User needs to access the login portal using a web browser.") -> User needs to access the login portal using a web browser. | F20: =IFERROR(__xludf.DUMMYFUNCTION("""COMPUTED_VALUE"""),"1. Open browser 2. Login with admin credentials") -> 1. Open browser 2. Login with admin credentials | G20: =IFERROR(__xludf.DUMMYFUNCTION("""COMPUTED_VALUE"""),"ADMIN Credentials") -> ADMIN Credentials | H20: =IFERROR(__xludf.DUMMYFUNCTION("""COMPUTED_VALUE"""),"Assigned persons name should be displayed accurately in the Upcoming Tasks Today section") -> Assigned persons name should be displayed accurately in the Upcoming Tasks Today section | I20: =IFERROR(__xludf.DUMMYFUNCTION("""COMPUTED_VALUE"""),"Missing assigned persons name in Upcoming Tasks Today section") -> Missing assigned persons name in Upcoming Tasks Today section | J20: =IFERROR(__xludf.DUMMYFUNCTION("""COMPUTED_VALUE"""),"Fail") -> Fail | K20: =IFERROR(__xludf.DUMMYFUNCTION("""COMPUTED_VALUE"""),"High") -> High | L20: =IFERROR(__xludf.DUMMYFUNCTION("""COMPUTED_VALUE"""),"007.png") -> 007.png | Q20: =IFERROR(__xludf.DUMMYFUNCTION("""COMPUTED_VALUE"""),"Fahad") -> Fahad
A21: BR-011 | B21: =IFERROR(__xludf.DUMMYFUNCTION("""COMPUTED_VALUE"""),"Home") -> Home | C21: =IFERROR(__xludf.DUMMYFUNCTION("""COMPUTED_VALUE"""),"Dashboard") -> Dashboard | D21: =IFERROR(__xludf.DUMMYFUNCTION("""COMPUTED_VALUE"""),"Failed to view attached media") -> Failed to view attached media | E21: =IFERROR(__xludf.DUMMYFUNCTION("""COMPUTED_VALUE"""),"User needs to access the login portal using a web browser.") -> User needs to access the login portal using a web browser. | F21: =IFERROR(__xludf.DUMMYFUNCTION("""COMPUTED_VALUE"""),"1. Open browser 2. Login with admin credentials") -> 1. Open browser 2. Login with admin credentials | G21: =IFERROR(__xludf.DUMMYFUNCTION("""COMPUTED_VALUE"""),"ADMIN Credentials") -> ADMIN Credentials | H21: =IFERROR(__xludf.DUMMYFUNCTION("""COMPUTED_VALUE"""),"Media data should load perfectly.") -> Media data should load perfectly. | I21: =IFERROR(__xludf.DUMMYFUNCTION("""COMPUTED_VALUE"""),"Failed to load media data.") -> Failed to load media data. | J21: =IFERROR(__xludf.DUMMYFUNCTION("""COMPUTED_VALUE"""),"Fail") -> Fail | K21: =IFERROR(__xludf.DUMMYFUNCTION("""COMPUTED_VALUE"""),"High") -> High | L21: =IFERROR(__xludf.DUMMYFUNCTION("""COMPUTED_VALUE"""),"008.png") -> 008.png | Q21: =IFERROR(__xludf.DUMMYFUNCTION("""COMPUTED_VALUE"""),"Fahad") -> Fahad
A22: BR-012 | B22: =IFERROR(__xludf.DUMMYFUNCTION("""COMPUTED_VALUE"""),"Home") -> Home | C22: =IFERROR(__xludf.DUMMYFUNCTION("""COMPUTED_VALUE"""),"Dashboard") -> Dashboard | D22: =IFERROR(__xludf.DUMMYFUNCTION("""COMPUTED_VALUE"""),"Clicking on the notification icon changes the user name.") -> Clicking on the notification icon changes the user name. | E22: =IFERROR(__xludf.DUMMYFUNCTION("""COMPUTED_VALUE"""),"User needs to access the login portal using a web browser.") -> User needs to access the login portal using a web browser. | F22: =IFERROR(__xludf.DUMMYFUNCTION("""COMPUTED_VALUE"""),"1. Open browser 2. Login with admin credentials 3. Click on notification icon") -> 1. Open browser 2. Login with admin credentials 3. Click on notification icon | G22: =IFERROR(__xludf.DUMMYFUNCTION("""COMPUTED_VALUE"""),"ADMIN Credentials") -> ADMIN Credentials | H22: =IFERROR(__xludf.DUMMYFUNCTION("""COMPUTED_VALUE"""),"User name should be displayed correctly on the dashboard.") -> User name should be displayed correctly on the dashboard. | I22: =IFERROR(__xludf.DUMMYFUNCTION("""COMPUTED_VALUE"""),"Username changes when the notification icon is clicked.") -> Username changes when the notification icon is clicked. | J22: =IFERROR(__xludf.DUMMYFUNCTION("""COMPUTED_VALUE"""),"Fail") -> Fail | K22: =IFERROR(__xludf.DUMMYFUNCTION("""COMPUTED_VALUE"""),"Medium") -> Medium | L22: =IFERROR(__xludf.DUMMYFUNCTION("""COMPUTED_VALUE"""),"029.mp4") -> 029.mp4 | Q22: =IFERROR(__xludf.DUMMYFUNCTION("""COMPUTED_VALUE"""),"Fahad") -> Fahad
A23: BR-013 | B23: =IFERROR(__xludf.DUMMYFUNCTION("""COMPUTED_VALUE"""),"Home") -> Home | C23: =IFERROR(__xludf.DUMMYFUNCTION("""COMPUTED_VALUE"""),"Maintenance") -> Maintenance | D23: =IFERROR(__xludf.DUMMYFUNCTION("""COMPUTED_VALUE"""),"Status filter option is missing.") -> Status filter option is missing. | E23: =IFERROR(__xludf.DUMMYFUNCTION("""COMPUTED_VALUE"""),"User needs to access the login portal using a web browser.") -> User needs to access the login portal using a web browser. | F23: =IFERROR(__xludf.DUMMYFUNCTION("""COMPUTED_VALUE"""),"1. Open browser 2. Login with admin credentials 3. Goto Maintenance section") -> 1. Open browser 2. Login with admin credentials 3. Goto Maintenance section | G23: =IFERROR(__xludf.DUMMYFUNCTION("""COMPUTED_VALUE"""),"ADMIN Credentials") -> ADMIN Credentials | H23: =IFERROR(__xludf.DUMMYFUNCTION("""COMPUTED_VALUE"""),"Design and feature implementation should match the Figma exactly.") -> Design and feature implementation should match the Figma exactly. | I23: =IFERROR(__xludf.DUMMYFUNCTION("""COMPUTED_VALUE"""),"""Edit Details"" option is missing on frontend.") -> "Edit Details" option is missing on frontend. | J23: =IFERROR(__xludf.DUMMYFUNCTION("""COMPUTED_VALUE"""),"Fail") -> Fail | K23: =IFERROR(__xludf.DUMMYFUNCTION("""COMPUTED_VALUE"""),"High") -> High | L23: =IFERROR(__xludf.DUMMYFUNCTION("""COMPUTED_VALUE"""),"013.png") -> 013.png | Q23: =IFERROR(__xludf.DUMMYFUNCTION("""COMPUTED_VALUE"""),"Fahad") -> Fahad
A24: BR-014 | B24: =IFERROR(__xludf.DUMMYFUNCTION("""COMPUTED_VALUE"""),"Home") -> Home | C24: =IFERROR(__xludf.DUMMYFUNCTION("""COMPUTED_VALUE"""),"Maintenance") -> Maintenance | D24: =IFERROR(__xludf.DUMMYFUNCTION("""COMPUTED_VALUE"""),"View option is missing from the action segment.") -> View option is missing from the action segment. | E24: =IFERROR(__xludf.DUMMYFUNCTION("""COMPUTED_VALUE"""),"User needs to access the login portal using a web browser.") -> User needs to access the login portal using a web browser. | F24: =IFERROR(__xludf.DUMMYFUNCTION("""COMPUTED_VALUE"""),"1. Open browser 2. Login with admin credentials 3. Goto Maintenance section") -> 1. Open browser 2. Login with admin credentials 3. Goto Maintenance section | G24: =IFERROR(__xludf.DUMMYFUNCTION("""COMPUTED_VALUE"""),"ADMIN Credentials") -> ADMIN Credentials | H24: =IFERROR(__xludf.DUMMYFUNCTION("""COMPUTED_VALUE"""),"Design and feature implementation should match the Figma exactly.") -> Design and feature implementation should match the Figma exactly. | I24: =IFERROR(__xludf.DUMMYFUNCTION("""COMPUTED_VALUE"""),"""view"" option is missing on frontend.") -> "view" option is missing on frontend. | J24: =IFERROR(__xludf.DUMMYFUNCTION("""COMPUTED_VALUE"""),"Fail") -> Fail | K24: =IFERROR(__xludf.DUMMYFUNCTION("""COMPUTED_VALUE"""),"High") -> High | L24: =IFERROR(__xludf.DUMMYFUNCTION("""COMPUTED_VALUE"""),"014.png") -> 014.png | Q24: =IFERROR(__xludf.DUMMYFUNCTION("""COMPUTED_VALUE"""),"Fahad") -> Fahad
A25: BR-015 | B25: =IFERROR(__xludf.DUMMYFUNCTION("""COMPUTED_VALUE"""),"Home") -> Home | C25: =IFERROR(__xludf.DUMMYFUNCTION("""COMPUTED_VALUE"""),"Profile") -> Profile | D25: =IFERROR(__xludf.DUMMYFUNCTION("""COMPUTED_VALUE"""),"Failed to open notification under profile section") -> Failed to open notification under profile section | E25: =IFERROR(__xludf.DUMMYFUNCTION("""COMPUTED_VALUE"""),"User needs to access the login portal using a web browser.") -> User needs to access the login portal using a web browser. | F25: =IFERROR(__xludf.DUMMYFUNCTION("""COMPUTED_VALUE"""),"1. Open browser 2. Login with admin credentials 3. Goto profile section 4. Click on notification icon") -> 1. Open browser 2. Login with admin credentials 3. Goto profile section 4. Click on notification icon | G25: =IFERROR(__xludf.DUMMYFUNCTION("""COMPUTED_VALUE"""),"ADMIN Credentials") -> ADMIN Credentials | H25: =IFERROR(__xludf.DUMMYFUNCTION("""COMPUTED_VALUE"""),"User should be able to access notification panel if the icon is visible") -> User should be able to access notification panel if the icon is visible | I25: =IFERROR(__xludf.DUMMYFUNCTION("""COMPUTED_VALUE"""),"Unable to open notification from the profile section.") -> Unable to open notification from the profile section. | J25: =IFERROR(__xludf.DUMMYFUNCTION("""COMPUTED_VALUE"""),"Fail") -> Fail | K25: =IFERROR(__xludf.DUMMYFUNCTION("""COMPUTED_VALUE"""),"High") -> High | L25: =IFERROR(__xludf.DUMMYFUNCTION("""COMPUTED_VALUE"""),"030.png") -> 030.png | Q25: =IFERROR(__xludf.DUMMYFUNCTION("""COMPUTED_VALUE"""),"Fahad") -> Fahad
A26: BR-016 | B26: =IFERROR(__xludf.DUMMYFUNCTION("""COMPUTED_VALUE"""),"Home") -> Home | C26: =IFERROR(__xludf.DUMMYFUNCTION("""COMPUTED_VALUE"""),"Reports") -> Reports | D26: =IFERROR(__xludf.DUMMYFUNCTION("""COMPUTED_VALUE"""),"UI different from figma") -> UI different from figma | E26: =IFERROR(__xludf.DUMMYFUNCTION("""COMPUTED_VALUE"""),"User needs to access the login portal using a web browser.") -> User needs to access the login portal using a web browser. | F26: =IFERROR(__xludf.DUMMYFUNCTION("""COMPUTED_VALUE"""),"1. Open browser 2. Login with admin credentials 3. Goto Reports") -> 1. Open browser 2. Login with admin credentials 3. Goto Reports | G26: =IFERROR(__xludf.DUMMYFUNCTION("""COMPUTED_VALUE"""),"ADMIN Credentials") -> ADMIN Credentials | H26: =IFERROR(__xludf.DUMMYFUNCTION("""COMPUTED_VALUE"""),"UI layout should match the Figma design to ensure client satisfaction.") -> UI layout should match the Figma design to ensure client satisfaction. | I26: =IFERROR(__xludf.DUMMYFUNCTION("""COMPUTED_VALUE"""),"Different UI implementation has been found.") -> Different UI implementation has been found. | J26: =IFERROR(__xludf.DUMMYFUNCTION("""COMPUTED_VALUE"""),"Fail") -> Fail | K26: =IFERROR(__xludf.DUMMYFUNCTION("""COMPUTED_VALUE"""),"Medium") -> Medium | L26: =IFERROR(__xludf.DUMMYFUNCTION("""COMPUTED_VALUE"""),"019.png") -> 019.png | Q26: =IFERROR(__xludf.DUMMYFUNCTION("""COMPUTED_VALUE"""),"Fahad") -> Fahad
A27: BR-017 | B27: =IFERROR(__xludf.DUMMYFUNCTION("""COMPUTED_VALUE"""),"Home") -> Home | C27: =IFERROR(__xludf.DUMMYFUNCTION("""COMPUTED_VALUE"""),"Reports") -> Reports | D27: =IFERROR(__xludf.DUMMYFUNCTION("""COMPUTED_VALUE"""),"Action field is non-functional.") -> Action field is non-functional. | E27: =IFERROR(__xludf.DUMMYFUNCTION("""COMPUTED_VALUE"""),"User needs to access the login portal using a web browser.") -> User needs to access the login portal using a web browser. | F27: =IFERROR(__xludf.DUMMYFUNCTION("""COMPUTED_VALUE"""),"1. Open browser 2. Login with admin credentials 3. Goto Reports") -> 1. Open browser 2. Login with admin credentials 3. Goto Reports | G27: =IFERROR(__xludf.DUMMYFUNCTION("""COMPUTED_VALUE"""),"ADMIN Credentials") -> ADMIN Credentials | H27: =IFERROR(__xludf.DUMMYFUNCTION("""COMPUTED_VALUE"""),"User should be able to view the full details of the issue according to the Figma design.") -> User should be able to view the full details of the issue according to the Figma design. | I27: =IFERROR(__xludf.DUMMYFUNCTION("""COMPUTED_VALUE"""),"Unable to view the issue details in the frontend.") -> Unable to view the issue details in the frontend. | J27: =IFERROR(__xludf.DUMMYFUNCTION("""COMPUTED_VALUE"""),"Fail") -> Fail | K27: =IFERROR(__xludf.DUMMYFUNCTION("""COMPUTED_VALUE"""),"High") -> High | L27: =IFERROR(__xludf.DUMMYFUNCTION("""COMPUTED_VALUE"""),"020.png") -> 020.png | Q27: =IFERROR(__xludf.DUMMYFUNCTION("""COMPUTED_VALUE"""),"Fahad") -> Fahad
A28: BR-018 | B28: =IFERROR(__xludf.DUMMYFUNCTION("""COMPUTED_VALUE"""),"Home") -> Home | C28: =IFERROR(__xludf.DUMMYFUNCTION("""COMPUTED_VALUE"""),"Reports") -> Reports | D28: =IFERROR(__xludf.DUMMYFUNCTION("""COMPUTED_VALUE"""),"Report export feature failed.") -> Report export feature failed. | E28: =IFERROR(__xludf.DUMMYFUNCTION("""COMPUTED_VALUE"""),"User needs to access the login portal using a web browser.") -> User needs to access the login portal using a web browser. | F28: =IFERROR(__xludf.DUMMYFUNCTION("""COMPUTED_VALUE"""),"1. Open browser 2. Login with admin credentials 3. Goto Reports") -> 1. Open browser 2. Login with admin credentials 3. Goto Reports | G28: =IFERROR(__xludf.DUMMYFUNCTION("""COMPUTED_VALUE"""),"ADMIN Credentials") -> ADMIN Credentials | H28: =IFERROR(__xludf.DUMMYFUNCTION("""COMPUTED_VALUE"""),"user should be able to export report ") -> user should be able to export report | I28: =IFERROR(__xludf.DUMMYFUNCTION("""COMPUTED_VALUE"""),"failed to export report") -> failed to export report | J28: =IFERROR(__xludf.DUMMYFUNCTION("""COMPUTED_VALUE"""),"Fail") -> Fail | K28: =IFERROR(__xludf.DUMMYFUNCTION("""COMPUTED_VALUE"""),"High") -> High | L28: =IFERROR(__xludf.DUMMYFUNCTION("""COMPUTED_VALUE"""),"021.png") -> 021.png | Q28: =IFERROR(__xludf.DUMMYFUNCTION("""COMPUTED_VALUE"""),"Fahad") -> Fahad
A29: BR-019 | B29: =IFERROR(__xludf.DUMMYFUNCTION("""COMPUTED_VALUE"""),"Home") -> Home | C29: =IFERROR(__xludf.DUMMYFUNCTION("""COMPUTED_VALUE"""),"Reports") -> Reports | D29: =IFERROR(__xludf.DUMMYFUNCTION("""COMPUTED_VALUE"""),"message history is not dynamically updated") -> message history is not dynamically updated | E29: =IFERROR(__xludf.DUMMYFUNCTION("""COMPUTED_VALUE"""),"User needs to access the login portal using a web browser.") -> User needs to access the login portal using a web browser. | F29: =IFERROR(__xludf.DUMMYFUNCTION("""COMPUTED_VALUE"""),"1. Open browser 2. Login with admin credentials 3. Goto Reports") -> 1. Open browser 2. Login with admin credentials 3. Goto Reports | G29: =IFERROR(__xludf.DUMMYFUNCTION("""COMPUTED_VALUE"""),"ADMIN Credentials") -> ADMIN Credentials | H29: =IFERROR(__xludf.DUMMYFUNCTION("""COMPUTED_VALUE"""),"message history should dynamically update ") -> message history should dynamically update | I29: =IFERROR(__xludf.DUMMYFUNCTION("""COMPUTED_VALUE"""),"Failed to update message history dynamically.") -> Failed to update message history dynamically. | J29: =IFERROR(__xludf.DUMMYFUNCTION("""COMPUTED_VALUE"""),"Fail") -> Fail | K29: =IFERROR(__xludf.DUMMYFUNCTION("""COMPUTED_VALUE"""),"Medium") -> Medium | L29: =IFERROR(__xludf.DUMMYFUNCTION("""COMPUTED_VALUE"""),"022.mp4") -> 022.mp4 | Q29: =IFERROR(__xludf.DUMMYFUNCTION("""COMPUTED_VALUE"""),"Fahad") -> Fahad
A30: BR-020 | B30: =IFERROR(__xludf.DUMMYFUNCTION("""COMPUTED_VALUE"""),"Home") -> Home | C30: =IFERROR(__xludf.DUMMYFUNCTION("""COMPUTED_VALUE"""),"Reports") -> Reports | D30: =IFERROR(__xludf.DUMMYFUNCTION("""COMPUTED_VALUE"""),"Full admin report is showing up on the mini admin report page, which isn’t accurate.") -> Full admin report is showing up on the mini admin report page, which isn’t accurate. | E30: =IFERROR(__xludf.DUMMYFUNCTION("""COMPUTED_VALUE"""),"User needs to access the login portal using a web browser.") -> User needs to access the login portal using a web browser. | F30: =IFERROR(__xludf.DUMMYFUNCTION("""COMPUTED_VALUE"""),"1. Open browser 2. Login with mini admin credentials 3. Goto Reports") -> 1. Open browser 2. Login with mini admin credentials 3. Goto Reports | G30: =IFERROR(__xludf.DUMMYFUNCTION("""COMPUTED_VALUE"""),"MINI-ADMIN Credentials") -> MINI-ADMIN Credentials | H30: =IFERROR(__xludf.DUMMYFUNCTION("""COMPUTED_VALUE"""),"mini-admins should be able to view only the reports that are aligned with them.") -> mini-admins should be able to view only the reports that are aligned with them. | I30: =IFERROR(__xludf.DUMMYFUNCTION("""COMPUTED_VALUE"""),"Mini admin is able to see super admin report") -> Mini admin is able to see super admin report | J30: =IFERROR(__xludf.DUMMYFUNCTION("""COMPUTED_VALUE"""),"Fail") -> Fail | K30: =IFERROR(__xludf.DUMMYFUNCTION("""COMPUTED_VALUE"""),"High") -> High | L30: =IFERROR(__xludf.DUMMYFUNCTION("""COMPUTED_VALUE"""),"023.png") -> 023.png | Q30: =IFERROR(__xludf.DUMMYFUNCTION("""COMPUTED_VALUE"""),"Fahad") -> Fahad
A31: BR-021 | B31: =IFERROR(__xludf.DUMMYFUNCTION("""COMPUTED_VALUE"""),"Home") -> Home | C31: =IFERROR(__xludf.DUMMYFUNCTION("""COMPUTED_VALUE"""),"Reports") -> Reports | D31: =IFERROR(__xludf.DUMMYFUNCTION("""COMPUTED_VALUE"""),"Unable to update cleaning or maintenance task status") -> Unable to update cleaning or maintenance task status | E31: =IFERROR(__xludf.DUMMYFUNCTION("""COMPUTED_VALUE"""),"User needs to access the login portal using a web browser.") -> User needs to access the login portal using a web browser. | F31: =IFERROR(__xludf.DUMMYFUNCTION("""COMPUTED_VALUE"""),"1. Open browser 2. Login with mini admin credentials 3. Goto Reports") -> 1. Open browser 2. Login with mini admin credentials 3. Goto Reports | G31: =IFERROR(__xludf.DUMMYFUNCTION("""COMPUTED_VALUE"""),"ADMIN Credentials") -> ADMIN Credentials | H31: =IFERROR(__xludf.DUMMYFUNCTION("""COMPUTED_VALUE"""),"Admins should be able to update the status of tasks if they can manually enter the issue.") -> Admins should be able to update the status of tasks if they can manually enter the issue. | I31: =IFERROR(__xludf.DUMMYFUNCTION("""COMPUTED_VALUE"""),"Unable to update task status") -> Unable to update task status | J31: =IFERROR(__xludf.DUMMYFUNCTION("""COMPUTED_VALUE"""),"Fail") -> Fail | K31: =IFERROR(__xludf.DUMMYFUNCTION("""COMPUTED_VALUE"""),"High") -> High | L31: =IFERROR(__xludf.DUMMYFUNCTION("""COMPUTED_VALUE"""),"025.png") -> 025.png | Q31: =IFERROR(__xludf.DUMMYFUNCTION("""COMPUTED_VALUE"""),"Fahad") -> Fahad
A32: BR-022 | B32: =IFERROR(__xludf.DUMMYFUNCTION("""COMPUTED_VALUE"""),"Home") -> Home | C32: =IFERROR(__xludf.DUMMYFUNCTION("""COMPUTED_VALUE"""),"Reports") -> Reports | D32: =IFERROR(__xludf.DUMMYFUNCTION("""COMPUTED_VALUE"""),"Task calculation mismatch in the schedule and report section.") -> Task calculation mismatch in the schedule and report section. | E32: =IFERROR(__xludf.DUMMYFUNCTION("""COMPUTED_VALUE"""),"User needs to access the login portal using a web browser.") -> User needs to access the login portal using a web browser. | F32: =IFERROR(__xludf.DUMMYFUNCTION("""COMPUTED_VALUE"""),"1. Open browser 2. Login with mini admin credentials 3. Goto Reports") -> 1. Open browser 2. Login with mini admin credentials 3. Goto Reports | G32: =IFERROR(__xludf.DUMMYFUNCTION("""COMPUTED_VALUE"""),"ADMIN Credentials") -> ADMIN Credentials | H32: =IFERROR(__xludf.DUMMYFUNCTION("""COMPUTED_VALUE"""),"Total task value should be shown accurately in the admin panel.") -> Total task value should be shown accurately in the admin panel. | I32: =IFERROR(__xludf.DUMMYFUNCTION("""COMPUTED_VALUE"""),"Admin panel failed to show the correct task value.") -> Admin panel failed to show the correct task value. | J32: =IFERROR(__xludf.DUMMYFUNCTION("""COMPUTED_VALUE"""),"Fail") -> Fail | K32: =IFERROR(__xludf.DUMMYFUNCTION("""COMPUTED_VALUE"""),"High") -> High | L32: =IFERROR(__xludf.DUMMYFUNCTION("""COMPUTED_VALUE"""),"026.mp4") -> 026.mp4 | Q32: =IFERROR(__xludf.DUMMYFUNCTION("""COMPUTED_VALUE"""),"Fahad") -> Fahad
A33: BR-023 | B33: =IFERROR(__xludf.DUMMYFUNCTION("""COMPUTED_VALUE"""),"Home") -> Home | C33: =IFERROR(__xludf.DUMMYFUNCTION("""COMPUTED_VALUE"""),"Schedule") -> Schedule | D33: =IFERROR(__xludf.DUMMYFUNCTION("""COMPUTED_VALUE"""),"Search feature is only applied to the Building column.") -> Search feature is only applied to the Building column. | E33: =IFERROR(__xludf.DUMMYFUNCTION("""COMPUTED_VALUE"""),"User needs to access the login portal using a web browser.") -> User needs to access the login portal using a web browser. | F33: =IFERROR(__xludf.DUMMYFUNCTION("""COMPUTED_VALUE"""),"1. Open browser 2. Login with mini admin credentials 3. Goto Schedule") -> 1. Open browser 2. Login with mini admin credentials 3. Goto Schedule | G33: =IFERROR(__xludf.DUMMYFUNCTION("""COMPUTED_VALUE"""),"ADMIN Credentials") -> ADMIN Credentials | H33: =IFERROR(__xludf.DUMMYFUNCTION("""COMPUTED_VALUE"""),"Search functionality should filter specific columns such as flat, building, assigned to, and others.") -> Search functionality should filter specific columns such as flat, building, assigned to, and others. | I33: =IFERROR(__xludf.DUMMYFUNCTION("""COMPUTED_VALUE"""),"Search only filter bulding column") -> Search only filter bulding column | J33: =IFERROR(__xludf.DUMMYFUNCTION("""COMPUTED_VALUE"""),"Fail") -> Fail | K33: =IFERROR(__xludf.DUMMYFUNCTION("""COMPUTED_VALUE"""),"Medium") -> Medium | L33: =IFERROR(__xludf.DUMMYFUNCTION("""COMPUTED_VALUE"""),"027.png") -> 027.png | Q33: =IFERROR(__xludf.DUMMYFUNCTION("""COMPUTED_VALUE"""),"Fahad") -> Fahad
A34: BR-024 | B34: =IFERROR(__xludf.DUMMYFUNCTION("""COMPUTED_VALUE"""),"Home") -> Home | C34: =IFERROR(__xludf.DUMMYFUNCTION("""COMPUTED_VALUE"""),"Schedule") -> Schedule | D34: =IFERROR(__xludf.DUMMYFUNCTION("""COMPUTED_VALUE"""),"Instruction/notes section is missing from the scheduled task section.") -> Instruction/notes section is missing from the scheduled task section. | E34: =IFERROR(__xludf.DUMMYFUNCTION("""COMPUTED_VALUE"""),"User needs to access the login portal using a web browser.") -> User needs to access the login portal using a web browser. | F34: =IFERROR(__xludf.DUMMYFUNCTION("""COMPUTED_VALUE"""),"1. Open browser 2. Login with mini admin credentials 3. Goto Schedule") -> 1. Open browser 2. Login with mini admin credentials 3. Goto Schedule | G34: =IFERROR(__xludf.DUMMYFUNCTION("""COMPUTED_VALUE"""),"ADMIN Credentials") -> ADMIN Credentials | H34: =IFERROR(__xludf.DUMMYFUNCTION("""COMPUTED_VALUE"""),"Design and feature implementation should match the Figma exactly.") -> Design and feature implementation should match the Figma exactly. | I34: =IFERROR(__xludf.DUMMYFUNCTION("""COMPUTED_VALUE"""),"Notes section is missing from the scheduled task input section.") -> Notes section is missing from the scheduled task input section. | J34: =IFERROR(__xludf.DUMMYFUNCTION("""COMPUTED_VALUE"""),"Fail") -> Fail | K34: =IFERROR(__xludf.DUMMYFUNCTION("""COMPUTED_VALUE"""),"High") -> High | L34: =IFERROR(__xludf.DUMMYFUNCTION("""COMPUTED_VALUE"""),"028.png") -> 028.png | Q34: =IFERROR(__xludf.DUMMYFUNCTION("""COMPUTED_VALUE"""),"Fahad") -> Fahad
A35: BR-025 | B35: =IFERROR(__xludf.DUMMYFUNCTION("""COMPUTED_VALUE"""),"Home") -> Home | C35: =IFERROR(__xludf.DUMMYFUNCTION("""COMPUTED_VALUE"""),"Team Message") -> Team Message | D35: =IFERROR(__xludf.DUMMYFUNCTION("""COMPUTED_VALUE"""),"Alignment gets messed up when the message is too long.") -> Alignment gets messed up when the message is too long. | E35: =IFERROR(__xludf.DUMMYFUNCTION("""COMPUTED_VALUE"""),"User needs to access the login portal using a web browser.") -> User needs to access the login portal using a web browser. | F35: =IFERROR(__xludf.DUMMYFUNCTION("""COMPUTED_VALUE"""),"1. Open browser 2. Login with mini admin credentials 3. Goto Team message") -> 1. Open browser 2. Login with mini admin credentials 3. Goto Team message | G35: =IFERROR(__xludf.DUMMYFUNCTION("""COMPUTED_VALUE"""),"MINI-ADMIN Credentials") -> MINI-ADMIN Credentials | H35: =IFERROR(__xludf.DUMMYFUNCTION("""COMPUTED_VALUE"""),"Input limit should be set for the input field.") -> Input limit should be set for the input field. | I35: =IFERROR(__xludf.DUMMYFUNCTION("""COMPUTED_VALUE"""),"Alignment issue happens because of a long input.") -> Alignment issue happens because of a long input. | J35: =IFERROR(__xludf.DUMMYFUNCTION("""COMPUTED_VALUE"""),"Fail") -> Fail | K35: =IFERROR(__xludf.DUMMYFUNCTION("""COMPUTED_VALUE"""),"High") -> High | L35: =IFERROR(__xludf.DUMMYFUNCTION("""COMPUTED_VALUE"""),"024.mp4") -> 024.mp4 | Q35: =IFERROR(__xludf.DUMMYFUNCTION("""COMPUTED_VALUE"""),"Fahad") -> Fahad
A36: BR-026 | B36: =IFERROR(__xludf.DUMMYFUNCTION("""COMPUTED_VALUE"""),"Home") -> Home | C36: =IFERROR(__xludf.DUMMYFUNCTION("""COMPUTED_VALUE"""),"User Management") -> User Management | D36: =IFERROR(__xludf.DUMMYFUNCTION("""COMPUTED_VALUE"""),"Design layout differs from Figma.") -> Design layout differs from Figma. | E36: =IFERROR(__xludf.DUMMYFUNCTION("""COMPUTED_VALUE"""),"User needs to access the login portal using a web browser.") -> User needs to access the login portal using a web browser. | F36: =IFERROR(__xludf.DUMMYFUNCTION("""COMPUTED_VALUE"""),"1. Open browser 2. Login with admin credentials 3. Goto User management section 4. Click on mini admin") -> 1. Open browser 2. Login with admin credentials 3. Goto User management section 4. Click on mini admin | G36: =IFERROR(__xludf.DUMMYFUNCTION("""COMPUTED_VALUE"""),"ADMIN Credentials") -> ADMIN Credentials | H36: =IFERROR(__xludf.DUMMYFUNCTION("""COMPUTED_VALUE"""),"UI layout should match the Figma design to ensure client satisfaction.") -> UI layout should match the Figma design to ensure client satisfaction. | I36: =IFERROR(__xludf.DUMMYFUNCTION("""COMPUTED_VALUE"""),"Different UI implementation has been found.") -> Different UI implementation has been found. | J36: =IFERROR(__xludf.DUMMYFUNCTION("""COMPUTED_VALUE"""),"Fail") -> Fail | K36: =IFERROR(__xludf.DUMMYFUNCTION("""COMPUTED_VALUE"""),"Low") -> Low | L36: =IFERROR(__xludf.DUMMYFUNCTION("""COMPUTED_VALUE"""),"015.png") -> 015.png | Q36: =IFERROR(__xludf.DUMMYFUNCTION("""COMPUTED_VALUE"""),"Fahad") -> Fahad
A37: BR-027 | B37: =IFERROR(__xludf.DUMMYFUNCTION("""COMPUTED_VALUE"""),"Home") -> Home | C37: =IFERROR(__xludf.DUMMYFUNCTION("""COMPUTED_VALUE"""),"User Management") -> User Management | D37: =IFERROR(__xludf.DUMMYFUNCTION("""COMPUTED_VALUE"""),"Unable to upload the mini admin profile picture.") -> Unable to upload the mini admin profile picture. | E37: =IFERROR(__xludf.DUMMYFUNCTION("""COMPUTED_VALUE"""),"User needs to access the login portal using a web browser.") -> User needs to access the login portal using a web browser. | F37: =IFERROR(__xludf.DUMMYFUNCTION("""COMPUTED_VALUE"""),"1. Open browser 2. Login with admin credentials 3. Goto User management section 4. Click on mini admin") -> 1. Open browser 2. Login with admin credentials 3. Goto User management section 4. Click on mini admin | G37: =IFERROR(__xludf.DUMMYFUNCTION("""COMPUTED_VALUE"""),"ADMIN Credentials") -> ADMIN Credentials | H37: =IFERROR(__xludf.DUMMYFUNCTION("""COMPUTED_VALUE"""),"User should be able to upload an admin profile.") -> User should be able to upload an admin profile. | I37: =IFERROR(__xludf.DUMMYFUNCTION("""COMPUTED_VALUE"""),"failed to upload image ") -> failed to upload image | J37: =IFERROR(__xludf.DUMMYFUNCTION("""COMPUTED_VALUE"""),"Fail") -> Fail | K37: =IFERROR(__xludf.DUMMYFUNCTION("""COMPUTED_VALUE"""),"High") -> High | L37: =IFERROR(__xludf.DUMMYFUNCTION("""COMPUTED_VALUE"""),"016.png") -> 016.png | Q37: =IFERROR(__xludf.DUMMYFUNCTION("""COMPUTED_VALUE"""),"Fahad") -> Fahad
A38: BR-028 | B38: =IFERROR(__xludf.DUMMYFUNCTION("""COMPUTED_VALUE"""),"Home") -> Home | C38: =IFERROR(__xludf.DUMMYFUNCTION("""COMPUTED_VALUE"""),"User Management") -> User Management | D38: =IFERROR(__xludf.DUMMYFUNCTION("""COMPUTED_VALUE"""),"Field should be required when adding an admin, cleaner, or maintenance worker.") -> Field should be required when adding an admin, cleaner, or maintenance worker. | E38: =IFERROR(__xludf.DUMMYFUNCTION("""COMPUTED_VALUE"""),"User needs to access the login portal using a web browser.") -> User needs to access the login portal using a web browser. | F38: =IFERROR(__xludf.DUMMYFUNCTION("""COMPUTED_VALUE"""),"1. Open browser 2. Login with admin credentials 3. Goto User management section 4. Click on mini admin") -> 1. Open browser 2. Login with admin credentials 3. Goto User management section 4. Click on mini admin | G38: =IFERROR(__xludf.DUMMYFUNCTION("""COMPUTED_VALUE"""),"ADMIN Credentials") -> ADMIN Credentials | H38: =IFERROR(__xludf.DUMMYFUNCTION("""COMPUTED_VALUE"""),"name , address , city etc fields should be required ") -> name , address , city etc fields should be required | I38: =IFERROR(__xludf.DUMMYFUNCTION("""COMPUTED_VALUE"""),"Fields are not required ") -> Fields are not required | J38: =IFERROR(__xludf.DUMMYFUNCTION("""COMPUTED_VALUE"""),"Fail") -> Fail | K38: =IFERROR(__xludf.DUMMYFUNCTION("""COMPUTED_VALUE"""),"Medium") -> Medium | L38: =IFERROR(__xludf.DUMMYFUNCTION("""COMPUTED_VALUE"""),"017.png") -> 017.png | Q38: =IFERROR(__xludf.DUMMYFUNCTION("""COMPUTED_VALUE"""),"Fahad") -> Fahad
A39: BR-029 | B39: =IFERROR(__xludf.DUMMYFUNCTION("""COMPUTED_VALUE"""),"Home") -> Home | C39: =IFERROR(__xludf.DUMMYFUNCTION("""COMPUTED_VALUE"""),"User Management") -> User Management | D39: =IFERROR(__xludf.DUMMYFUNCTION("""COMPUTED_VALUE"""),"should be drop-down list") -> should be drop-down list | E39: =IFERROR(__xludf.DUMMYFUNCTION("""COMPUTED_VALUE"""),"User needs to access the login portal using a web browser.") -> User needs to access the login portal using a web browser. | F39: =IFERROR(__xludf.DUMMYFUNCTION("""COMPUTED_VALUE"""),"1. Open browser 2. Login with admin credentials 3. Goto User management section 4. Click on mini admin") -> 1. Open browser 2. Login with admin credentials 3. Goto User management section 4. Click on mini admin | G39: =IFERROR(__xludf.DUMMYFUNCTION("""COMPUTED_VALUE"""),"ADMIN Credentials") -> ADMIN Credentials | H39: =IFERROR(__xludf.DUMMYFUNCTION("""COMPUTED_VALUE"""),"Design and feature implementation should match the Figma exactly.") -> Design and feature implementation should match the Figma exactly. | I39: =IFERROR(__xludf.DUMMYFUNCTION("""COMPUTED_VALUE"""),"set as tag in frontend") -> set as tag in frontend | J39: =IFERROR(__xludf.DUMMYFUNCTION("""COMPUTED_VALUE"""),"Fail") -> Fail | K39: =IFERROR(__xludf.DUMMYFUNCTION("""COMPUTED_VALUE"""),"Medium") -> Medium | L39: =IFERROR(__xludf.DUMMYFUNCTION("""COMPUTED_VALUE"""),"018.png") -> 018.png | Q39: =IFERROR(__xludf.DUMMYFUNCTION("""COMPUTED_VALUE"""),"Fahad") -> Fahad
A40: BR-030 | B40: =IFERROR(__xludf.DUMMYFUNCTION("""COMPUTED_VALUE"""),"Login") -> Login | C40: =IFERROR(__xludf.DUMMYFUNCTION("""COMPUTED_VALUE"""),"Login") -> Login | D40: =IFERROR(__xludf.DUMMYFUNCTION("""COMPUTED_VALUE"""),"Strong password indicator needs to be implemented.") -> Strong password indicator needs to be implemented. | E40: =IFERROR(__xludf.DUMMYFUNCTION("""COMPUTED_VALUE"""),"User needs to access the login portal using a web browser.") -> User needs to access the login portal using a web browser. | F40: =IFERROR(__xludf.DUMMYFUNCTION("""COMPUTED_VALUE"""),"1. Open browser 2. Login with admin credentials") -> 1. Open browser 2. Login with admin credentials | G40: =IFERROR(__xludf.DUMMYFUNCTION("""COMPUTED_VALUE"""),"ADMIN Credentials") -> ADMIN Credentials | H40: =IFERROR(__xludf.DUMMYFUNCTION("""COMPUTED_VALUE"""),"Strong password indicator should be displayed while entering a password.") -> Strong password indicator should be displayed while entering a password. | I40: =IFERROR(__xludf.DUMMYFUNCTION("""COMPUTED_VALUE"""),"Login page is missing a password field indicator.") -> Login page is missing a password field indicator. | J40: =IFERROR(__xludf.DUMMYFUNCTION("""COMPUTED_VALUE"""),"Fail") -> Fail | K40: =IFERROR(__xludf.DUMMYFUNCTION("""COMPUTED_VALUE"""),"Medium") -> Medium | L40: =IFERROR(__xludf.DUMMYFUNCTION("""COMPUTED_VALUE"""),"001.png") -> 001.png | Q40: =IFERROR(__xludf.DUMMYFUNCTION("""COMPUTED_VALUE"""),"Fahad") -> Fahad

Sheet Summary Report
A1: Module | B1: Sub Module | C1: Test Case ID | D1: Bug Count | E1: Bug Rate % | F1: Bug Severity
A2: =IFERROR(__xludf.DUMMYFUNCTION("SORT( SPLIT( UNIQUE( FILTER('Main Report'!B11:B100 & ""♦"" & 'Main Report'!C11:C100, LEN('Main Report'!C11:C100)) ), ""♦"" ), 1, TRUE, 2, TRUE ) "),"Home") -> Home | B2: =IFERROR(__xludf.DUMMYFUNCTION("""COMPUTED_VALUE"""),"Buildings") -> Buildings | C2: =IFERROR(__xludf.DUMMYFUNCTION("TEXTJOIN("", "", TRUE, FILTER('Main Report'!A11:A100, ('Main Report'!B11:B100=A2) * ('Main Report'!C11:C100=B2) ) ) "),"BR-001, BR-002, BR-003, BR-004") -> BR-001, BR-002, BR-003, BR-004 | D2: =IFERROR(__xludf.DUMMYFUNCTION("COUNTA(UNIQUE(TRANSPOSE(SPLIT(C2, "", "")))) "),4.0) -> 4 | E2: =IF(D2="", "", TEXT((D2 / 'Main Report'!$E$7), "0.00%")) -> 13.33% | F2: =IFERROR(__xludf.DUMMYFUNCTION("IF(C2="""", """", TEXTJOIN("", "", TRUE, ""High: "" & COUNTIF(FILTER('Main Report'!K11:K100, ISNUMBER(MATCH('Main Report'!A11:A100, SPLIT(C2, "", ""), 0))), ""High"") & CHAR(10) & ""Medium: "" & COUNTIF(FILTER('Main Report'!K11:K100, ISNU"&"MBER(MATCH('Main Report'!A11:A100, SPLIT(C2, "", ""), 0))), ""Medium"") & CHAR(10) & ""Low: "" & COUNTIF(FILTER('Main Report'!K11:K100, ISNUMBER(MATCH('Main Report'!A11:A100, SPLIT(C2, "", ""), 0))), ""Low"") ) ) "),"High: 1 Medium: 3 Low: 0") -> High: 1 Medium: 3 Low: 0
A3: =IFERROR(__xludf.DUMMYFUNCTION("""COMPUTED_VALUE"""),"Home") -> Home | B3: =IFERROR(__xludf.DUMMYFUNCTION("""COMPUTED_VALUE"""),"Dashboard") -> Dashboard | C3: =IFERROR(__xludf.DUMMYFUNCTION("TEXTJOIN("", "", TRUE, FILTER('Main Report'!A12:A101, ('Main Report'!B12:B101=A3) * ('Main Report'!C12:C101=B3) ) ) "),"BR-005, BR-006, BR-007, BR-008, BR-009, BR-010, BR-011, BR-012") -> BR-005, BR-006, BR-007, BR-008, BR-009, BR-010, BR-011, BR-012 | D3: =IFERROR(__xludf.DUMMYFUNCTION("COUNTA(UNIQUE(TRANSPOSE(SPLIT(C3, "", "")))) "),8.0) -> 8 | E3: =IF(D3="", "", TEXT((D3 / 'Main Report'!$E$7), "0.00%")) -> 26.67% | F3: =IFERROR(__xludf.DUMMYFUNCTION("IF(C3="""", """", TEXTJOIN("", "", TRUE, ""High: "" & COUNTIF(FILTER('Main Report'!K12:K101, ISNUMBER(MATCH('Main Report'!A12:A101, SPLIT(C3, "", ""), 0))), ""High"") & CHAR(10) & ""Medium: "" & COUNTIF(FILTER('Main Report'!K12:K101, ISNU"&"MBER(MATCH('Main Report'!A12:A101, SPLIT(C3, "", ""), 0))), ""Medium"") & CHAR(10) & ""Low: "" & COUNTIF(FILTER('Main Report'!K12:K101, ISNUMBER(MATCH('Main Report'!A12:A101, SPLIT(C3, "", ""), 0))), ""Low"") ) ) "),"High: 5 Medium: 2 Low: 1") -> High: 5 Medium: 2 Low: 1
A4: =IFERROR(__xludf.DUMMYFUNCTION("""COMPUTED_VALUE"""),"Home") -> Home | B4: =IFERROR(__xludf.DUMMYFUNCTION("""COMPUTED_VALUE"""),"Maintenance") -> Maintenance | C4: =IFERROR(__xludf.DUMMYFUNCTION("TEXTJOIN("", "", TRUE, FILTER('Main Report'!A13:A102, ('Main Report'!B13:B102=A4) * ('Main Report'!C13:C102=B4) ) ) "),"BR-013, BR-014") -> BR-013, BR-014 | D4: =IFERROR(__xludf.DUMMYFUNCTION("COUNTA(UNIQUE(TRANSPOSE(SPLIT(C4, "", "")))) "),2.0) -> 2 | E4: =IF(D4="", "", TEXT((D4 / 'Main Report'!$E$7), "0.00%")) -> 6.67% | F4: =IFERROR(__xludf.DUMMYFUNCTION("IF(C4="""", """", TEXTJOIN("", "", TRUE, ""High: "" & COUNTIF(FILTER('Main Report'!K13:K102, ISNUMBER(MATCH('Main Report'!A13:A102, SPLIT(C4, "", ""), 0))), ""High"") & CHAR(10) & ""Medium: "" & COUNTIF(FILTER('Main Report'!K13:K102, ISNU"&"MBER(MATCH('Main Report'!A13:A102, SPLIT(C4, "", ""), 0))), ""Medium"") & CHAR(10) & ""Low: "" & COUNTIF(FILTER('Main Report'!K13:K102, ISNUMBER(MATCH('Main Report'!A13:A102, SPLIT(C4, "", ""), 0))), ""Low"") ) ) "),"High: 2 Medium: 0 Low: 0") -> High: 2 Medium: 0 Low: 0
