Workbook

Sheet Fahad
A1: Tester : | B1: Mohammed Fahad Faisal | E1: passenger : jvai57547@gmail.com || Password123# Driver : teamaithunder@gmail.com || Password123# | K1: driver : fahad.cseiiuc@gmail.com || pass : testdriver101 user : mdfahadfaisal7@gmail.com || pass : testuser101
A2: Project Name: | B2: Ulendo Connect
A3: Developer: | B3: AI Pulse
A4: OS: | B4: Windows 11 Pro Version:24H2 OS build:26100.4946
A5: Environment: | B5: Brave 1.81.135 (Official Build) (64-bit) Chromium: 139.0.7258.127 | N5: Place solve if the issue resolves | \/ | O5: Mention which Stack solved the issue | \/
A7: Test ID | B7: Module | C7: Sub Module | D7: Test Case Description | E7: Preconditions | F7: Test Steps | G7: Test Data | H7: Expected Result | I7: Actual Result | J7: Status | K7: Severity | L7: Screen Shots | M7: Suggestion | N7: Feedback | O7: Stack | P7: Comment
A8: BR_001 | B8: Onbording | C8: Onbording | D8: font alignment issue | E8: user need to install this app on their device | F8: 1. Open app | G8: N/A | H8: Design and alignment should match the Figma file as confirmed by the client. | I8: Font alignment issue has been noticed | J8: Fail | K8: Low | L8: 001.png | O8: Front-End | P8: changed
A10: BR_002 | B10: Onbording | C10: Onbording | D10: font alignment issue | E10: user need to install this app on their device | F10: 1. Open app | G10: N/A | H10: Design and alignment should match the Figma file as confirmed by the client. | I10: Font alignment issue has been noticed | J10: Fail | K10: Low | L10: 002.png | O10: Front-End | P10: changed
A12: BR_003 | B12: Onbording | C12: Onbording | D12: Icon needs to be bigger. | E12: user need to install this app on their device | F12: 1. Open app | G12: N/A | H12: Design and alignment should match the Figma file as confirmed by the client. | I12: Font alignment issue has been noticed | J12: Fail | K12: Low | L12: 003.png | O12: Front-End | P12: Taken whole as image..one will effect others
A14: BR_004 | B14: Onbording | C14: Onbording | D14: Title looks different from the Figma design, and there’s a font alignment issue. | E14: user need to install this app on their device | F14: 1. Open app | G14: N/A | H14: Design and alignment should match the Figma file as confirmed by the client. | I14: Font alignment issue has been noticed | J14: Fail | K14: Low | L14: 004.png | O14: Front-End | P14: chnaged
A16: BR_005 | B16: Role | C16: Role | D16: Should be under the driver, according to the Figma design. | E16: user need to install this app on their device | F16: 1. Open app 2. Select passenger role | G16: N/A | H16: Design and alignment should match the Figma file as confirmed by the client. | I16: Message should be placed below the driver button as shown in Figma. | J16: Fail | K16: Low | L16: 005.png | O16: Front-End | P16: changed
A18: BR_006 | B18: Passenger | C18: SignIn | D18: Should be slightly smaller, and the notification panel needs to be visible as per the Figma design. Should be in center | E18: user need to install this app on their device | F18: 1. Open app 2. Select passenger role 3. Goto signin page | G18: N/A | H18: Design should match the Figma layout, with the title centered and the notification panel clearly visible. | I18: Notification bar is missing, the header section is larger than in Figma, and the title is not centered. | J18: Fail | K18: Medium | L18: 006.png | O18: Front-End | P18: changed
A20: BR_007 | B20: Passenger | C20: SignUp | D20: Need to set an input limit on the signup page. | E20: user need to install this app on their device | F20: 1. Open app 2. Select passenger role 3. Goto signup page | G20: N/A | H20: Need to put input limit for users and driver | I20: Can take infinite input in the input field. | J20: Fail | K20: Medium | L20: 007.jpg
A22: BR_008 | B22: Passenger | C22: SignUp | D22: Non functional button | E22: user need to install this app on their device | F22: 1. Open app 2. Select passenger role 3. Goto signup page | G22: N/A | H22: Password visibility button should function as intended. | I22: Toggle function isn’t working as expected. | J22: Fail | K22: High | L22: 008.jpg | O22: Front-End | P22: MicrosoftTeams-video.mp4
A24: BR_009 | B24: Passenger | C24: SignUp | D24: Failed to sign up using Google. | E24: user need to install this app on their device | F24: 1. Open app 2. Select passenger role 3. Goto signup page | G24: N/A | H24: Users should be able to sign up with their Google account through Google sign-up. | I24: Failed to signup by google signup | J24: Fail | K24: High | L24: 009.png
A26: BR_010 | B26: Passenger | C26: SignUp | D26: Encountered a server error during sign-up. | E26: user need to install this app on their device | F26: 1. Open app 2. Select passenger role 3. Goto signup page | G26: N/A | H26: User should not get server error while signup | I26: Server error message displayed while signup | J26: Fail | K26: High | L26: 010.jpg | O26: Front-End | P26: number length problem fixed
A28: BR_011 | B28: Passenger | C28: OTP | D28: A jumping action has been observed when entering the OTP. | E28: user need to install this app on their device | F28: 1. Open app 2. Select passenger role 3. Goto signup page 4. Fillup necessary information and click next to get OTP | G28: User Credentials | H28: Should be stable when entering OTP | I28: Jumping action has been observed | J28: Fail | K28: Medium | L28: 011.mp4 | O28: Front-End | P28: Fixed
A30: BR_012 | B30: Passenger | C30: OTP | D30: Resend OTP failed | E30: user need to install this app on their device | F30: 1. Open app 2. Select passenger role 3. Goto signup page 4. Fillup necessary information and click next to get OTP | G30: User Credentials | H30: Function should work as expected | I30: Failed to resend OTP | J30: Fail | K30: High | L30: 012.png | O30: Front-End | P30: fixed
A32: BR_013 | B32: Passenger | C32: OTP | D32: Valid OTP is showing as invalid. Time is not expired | E32: user need to install this app on their device | F32: 1. Open app 2. Select passenger role 3. Goto signup page 4. Fillup necessary information and click next to get OTP | G32: User Credentials | H32: OTP should remain valid based on its designated validity period. | I32: OTP shows as invalid, but it’s still within its validity period. | J32: Fail | K32: High | L32: 013.png | O32: Front-End | P32: Validation time 10 min
A34: BR_014 | B34: Passenger | C34: SignUp | D34: Server error occurred while signing up as a driver. | E34: user need to install this app on their device | F34: 1. Open app 2. Select passenger role 3. Goto signup page | G34: N/A | H34: User should not get server error while signup | I34: Server error message displayed while signup | J34: Fail | K34: High | L34: 014.png | O34: Front-End | P34: Same phone number and same email won't work
A36: BR_015 | B36: Passenger | C36: SignIn | D36: Failed to store data when a user logs in with Google. | E36: user need to install this app on their device | F36: 1. Open app 2. Select passenger role 3. Goto signin page | G36: N/A | H36: User data should be visible when user signup by google | I36: Failed to | J36: Fail | K36: High | L36: 015.png
A38: BR_016 | B38: Passenger | C38: SignIn | D38: App name failed to display on Gmail which triggered during Google signup. | E38: user need to install this app on their device | F38: 1. Open app 2. Select passenger role 3. Goto signin page | G38: N/A | H38: App name should be displayed correctly in the email section. | I38: App name is missing, and it’s showing the project as a number instead. | J38: Fail | K38: Medium | L38: 016.png
A40: BR_017 | B40: Driver | C40: SignUp | D40: Backend shows the account as approved, but on the frontend, it’s still marked as under review. | E40: user need to install this app on their device | F40: 1. Open app 2. Select driver role 3. Goto signup page | G40: Driver Credentials | H40: Frontend should show the updated status once the user has been approved in the backend. | I40: Driver is still in review state even after they were approved from the backend. | J40: Fail | K40: High | L40: 017.png | O40: Front-End | P40: use pull to refresh
A42: BR_018 | B42: Driver | C42: Backend | D42: Displays unauthorized on continuous API calls. | E42: user need to install this app on their device | F42: 1. Open app 2. Login in backend framework | G42: Driver Credentials | H42: API calls fail rate should be reduce and should only call one time if it get 200 status | I42: API call should be control to reduce pressure on backend | J42: Fail | K42: High | L42: 018.png | O42: Front-End | P42: fixed
A44: BR_019 | B44: Driver | C44: Backend | D44: Constant API calls on my trips and messages. | E44: user need to install this app on their device | F44: 1. Open app 2. Login in backend framework | G44: Driver Credentials | H44: API call should be handled with limit | I44: Non-stop api call has been noticed on backed | J44: Fail | K44: High | L44: 019.mp4 | O44: Front-End | P44: fixed
A46: BR_020 | B46: Driver | C46: Notification | D46: Notification panel is empty, yet it still displays the unread notification icon. | E46: user need to install this app on their device | F46: 1. Open app 2. Select driver role 3. Login using valid credentials 4. Click on notifications | G46: Driver Credentials | H46: If notification is empty than, should display simple bell icon | I46: mark on notification has been displayed weather it has no notification unread | J46: Fail | K46: Medium | L46: 020.mp4 | O46: Front-End | P46: fixed
A48: BR_021 | B48: Driver | C48: Home | D48: Design is different from Figma. | E48: user need to install this app on their device | F48: 1. Open app 2. Select driver role 3. Login using valid credentials | G48: Driver Credentials | H48: Design and aligment should as same as figma for client satisfaction | I48: Icon missing from figma has been seen | J48: Fail | K48: Medium | L48: 021.png | O48: Front-End | P48: fixed
A50: BR_022 | B50: Driver | C50: Backend | D50: User was deleted on the backend, but after refreshing, they remained logged into the app. | E50: user need to install this app on their device | F50: 1. Open app 2. Login in backend framework | G50: Driver Credentials | H50: User session management need to be handled carefully | I50: User is deleted from the backend, but the login session still remains active on the frontend. | J50: Fail | K50: High | L50: 022.png | O50: Front-End | P50: App state whole so time
A52: BR_023 | B52: Driver | C52: Post New ride | D52: Unable to display location suggestions. | E52: user need to install this app on their device | F52: 1. Open app 2. Select driver role 3. Login using valid credentials 4. Click on post a new ride | G52: Driver Credentials | H52: Should display suggested locations for better user experience | I52: Failed to suggest locations | J52: Fail | K52: High | L52: 023.png | O52: Front-End
A54: BR_024 | B54: Driver | C54: Post New ride | D54: needs more polish in the text font and design | E54: user need to install this app on their device | F54: 1. Open app 2. Select driver role 3. Login using valid credentials 4. Click on post a new ride | G54: Driver Credentials | H54: App could use some extra polish on both the text and design. | I54: Need more polish on app | J54: Fail | K54: Medium | L54: 024.png
A56: BR_025 | B56: Driver | C56: Post New ride | D56: Function isn’t behaving as intended. | E56: user need to install this app on their device | F56: 1. Open app 2. Select driver role 3. Login using valid credentials 4. Click on post a new ride | G56: Driver Credentials | H56: Function should perform as intended. | I56: Failed to upload photos in the verification fields. | J56: Fail | K56: High | L56: 025.png | O56: Front-End
A58: BR_026 | B58: Driver | C58: Post New ride | D58: Can’t create a ride because it’s asking me to select a location from a dropdown, but the dropdown isn’t showing up. | E58: user need to install this app on their device | F58: 1. Open app 2. Select driver role 3. Login using valid credentials 4. Click on post a new ride | G58: Driver Credentials | H58: Suggested location should be clearly visible to avoid any conflict with the actual location. | I58: System failed to suggest the correct location, and the dropdown menu also didn’t provide any suggestions. | J58: Fail | K58: High | L58: 026.png | O58: Front-End
A60: BR_027 | B60: Driver | C60: SignIn | D60: Google signup failed and was unable to store the username and information. | E60: user need to install this app on their device | F60: 1. Open app 2. Select driver role 3. Signin using google signin | G60: Driver Credentials | H60: User should be able to signin using google account | I60: Failed to signin with google login | J60: Fail | K60: High | L60: 027.mp4
A62: BR_028 | B62: Driver | C62: SignUp | D62: Signup using google failed | E62: user need to install this app on their device | F62: 1. Open app 2. Select driver role 3. Click on signup and click on google signup | G62: Driver Credentials | H62: User should be able to signup using google account | I62: Failed to signup with google login | J62: Fail | K62: High | L62: 028.mp4
A64: BR_029 | B64: Driver | C64: Drive verification | D64: Validation failed on the frontend, causing a server-side validation issue. | E64: user need to install this app on their device | F64: 1. Open app 2. Select driver role 3. Click on signup and click on google signup 4. Fill necessary information and click on next | G64: Driver Credentials | H64: Should put validation in user input field | I64: No validation has been noticed in app | J64: Fail | K64: High | L64: 029.png | O64: Front-End | P64: Solved...field name change problem from backend
A66: BR_030 | B66: Driver | C66: Drive verification | D66: Notification popup should appear when the admin approves a driver's verification. | E66: user need to install this app on their device | F66: 1. Open app 2. Select driver role 3. Click on signup and click on google signup 4. Fill necessary information and click on next | G66: Driver Credentials | H66: User should receive a notification of account verification | I66: No notification received when admin approves user (driver) account | J66: Fail | K66: High | L66: 030.png
A68: BR_031 | B68: Driver | C68: Drive verification | D68: default name set for user | E68: user need to install this app on their device | F68: 1. Open app 2. Select driver role 3. Click on signup and click on google signup 4. Fill necessary information and click on next | G68: Driver Credentials | H68: Should be placeholder | I68: Name was set for default | J68: Fail | K68: Medium | L68: 031.png
A70: BR_032 | B70: Driver | C70: My Trips | D70: Offering multiple seats for sharing but displaying only one as available | E70: user need to install this app on their device | F70: 1. Open app 2. Select driver role 3. Login using valid credentials 4. Click on post ride | G70: Driver Credentials | H70: Seat availability should display properly on posted rides | I70: Display only one seat as available on every ride share post, even if the user lists more than one seat. | J70: Fail | K70: High | L70: 032.png
A72: BR_033 | B72: Driver | C72: My Trips | D72: Unable to find a ride through the search. | E72: user need to install this app on their device | F72: 1. Open app 2. Select driver role 3. Login using valid credentials 4. Click on post ride | G72: Driver Credentials | H72: User (passenger) should be able to get the ride if the time matches with rider | I72: Failed to get the ride, and no record was displayed. | J72: Fail | K72: High | L72: 033.mp4
A74: BR_034
...

Sheet Main Report
A2: Tester : | B2: Mohammed Fahad Faisal | D2: Severity | E2: Issues
A3: Project Name: | D3: High | E3: =COUNTIF(Tahsin!K14:K897, "High") + COUNTIF(Fahad!K8:K1004, "High") -> 20
A4: Project URL: | D4: Medium | E4: =COUNTIF(Tahsin!K14:K898, "Medium") + COUNTIF(Fahad!K8:K1005, "Medium") -> 8
A5: Developer: | D5: Low | E5: =COUNTIF(Fahad!K8:K1006, "Low") + COUNTIF(Tahsin!K14:K901, "Low") -> 5
A6: OS:
A7: Environment | D7: Total Test Cases: | E7: =SUM(E3:E5) -> 33
D8: Test Case Solved : | E8: =COUNTIF(N11:N2387, "Solved") -> 0
A10: Test Case ID | B10: Module | C10: Sub Module | D10: Test Case Description | E10: Preconditions | F10: Test Steps | G10: Test Data | H10: Expected Result | I10: Actual Result | J10: Status | K10: Severity | L10: Screen Shots | M10: Suggestion | N10: Feedback | O10: Stack | P10: Comment | Q10: Tester
A11: {=IF((LEN(B11:B100)+LEN(C11:C100))>0, "BR-" & TEXT(ROW(B11:B100)-ROW(B11)+1,"000"), "")} -> BR-001 | B11: =IFERROR(__xludf.DUMMYFUNCTION("QUERY( { ARRAYFORMULA({ TRIM(Fahad!B8:B2383), Fahad!C8:P2383, IF(LEN(Fahad!B8:B2383), ""Fahad"", """") }); ARRAYFORMULA({ TRIM(Tahsin!B15:B2383), Tahsin!C15:P2383, IF(LEN(Tahsin!B15:B2383), ""Tahsin"","&" """") }) }, ""SELECT * WHERE Col1 IS NOT NULL ORDER BY Col1 ASC, Col2 ASC"", 0 )"),"Driver") -> Driver | C11: =IFERROR(__xludf.DUMMYFUNCTION("""COMPUTED_VALUE"""),"Backend") -> Backend | D11: =IFERROR(__xludf.DUMMYFUNCTION("""COMPUTED_VALUE"""),"Displays unauthorized on continuous API calls.") -> Displays unauthorized on continuous API calls. | E11: =IFERROR(__xludf.DUMMYFUNCTION("""COMPUTED_VALUE"""),"user need to install this app on their device") -> user need to install this app on their device | F11: =IFERROR(__xludf.DUMMYFUNCTION("""COMPUTED_VALUE"""),"1. Open app 2. Login in backend framework") -> 1. Open app 2. Login in backend framework | G11: =IFERROR(__xludf.DUMMYFUNCTION("""COMPUTED_VALUE"""),"Driver Credentials") -> Driver Credentials | H11: =IFERROR(__xludf.DUMMYFUNCTION("""COMPUTED_VALUE"""),"API calls fail rate should be reduce and should only call one time if it get 200 status") -> API calls fail rate should be reduce and should only call one time if it get 200 status | I11: =IFERROR(__xludf.DUMMYFUNCTION("""COMPUTED_VALUE"""),"API call should be control to reduce pressure on backend") -> API call should be control to reduce pressure on backend | J11: =IFERROR(__xludf.DUMMYFUNCTION("""COMPUTED_VALUE"""),"Fail") -> Fail | K11: =IFERROR(__xludf.DUMMYFUNCTION("""COMPUTED_VALUE"""),"High") -> High | L11: =IFERROR(__xludf.DUMMYFUNCTION("""COMPUTED_VALUE"""),"018.png") -> 018.png | O11: =IFERROR(__xludf.DUMMYFUNCTION("""COMPUTED_VALUE"""),"Front-End") -> Front-End | P11: =IFERROR(__xludf.DUMMYFUNCTION("""COMPUTED_VALUE"""),"fixed") -> fixed | Q11: =IFERROR(__xludf.DUMMYFUNCTION("""COMPUTED_VALUE"""),"Fahad") -> Fahad
A12: BR-002 | B12: =IFERROR(__xludf.DUMMYFUNCTION("""COMPUTED_VALUE"""),"Driver") -> Driver | C12: =IFERROR(__xludf.DUMMYFUNCTION("""COMPUTED_VALUE"""),"Backend") -> Backend | D12: =IFERROR(__xludf.DUMMYFUNCTION("""COMPUTED_VALUE"""),"Constant API calls on my trips and messages.") -> Constant API calls on my trips and messages. | E12: =IFERROR(__xludf.DUMMYFUNCTION("""COMPUTED_VALUE"""),"user need to install this app on their device") -> user need to install this app on their device | F12: =IFERROR(__xludf.DUMMYFUNCTION("""COMPUTED_VALUE"""),"1. Open app 2. Login in backend framework") -> 1. Open app 2. Login in backend framework | G12: =IFERROR(__xludf.DUMMYFUNCTION("""COMPUTED_VALUE"""),"Driver Credentials") -> Driver Credentials | H12: =IFERROR(__xludf.DUMMYFUNCTION("""COMPUTED_VALUE"""),"API call should be handled with limit") -> API call should be handled with limit | I12: =IFERROR(__xludf.DUMMYFUNCTION("""COMPUTED_VALUE"""),"Non-stop api call has been noticed on backed") -> Non-stop api call has been noticed on backed | J12: =IFERROR(__xludf.DUMMYFUNCTION("""COMPUTED_VALUE"""),"Fail") -> Fail | K12: =IFERROR(__xludf.DUMMYFUNCTION("""COMPUTED_VALUE"""),"High") -> High | L12: =IFERROR(__xludf.DUMMYFUNCTION("""COMPUTED_VALUE"""),"019.mp4") -> 019.mp4 | O12: =IFERROR(__xludf.DUMMYFUNCTION("""COMPUTED_VALUE"""),"Front-End") -> Front-End | P12: =IFERROR(__xludf.DUMMYFUNCTION("""COMPUTED_VALUE"""),"fixed") -> fixed | Q12: =IFERROR(__xludf.DUMMYFUNCTION("""COMPUTED_VALUE"""),"Fahad") -> Fahad
A13: BR-003 | B13: =IFERROR(__xludf.DUMMYFUNCTION("""COMPUTED_VALUE"""),"Driver") -> Driver | C13: =IFERROR(__xludf.DUMMYFUNCTION("""COMPUTED_VALUE"""),"Backend") -> Backend | D13: =IFERROR(__xludf.DUMMYFUNCTION("""COMPUTED_VALUE"""),"User was deleted on the backend, but after refreshing, they remained logged into the app.") -> User was deleted on the backend, but after refreshing, they remained logged into the app. | E13: =IFERROR(__xludf.DUMMYFUNCTION("""COMPUTED_VALUE"""),"user need to install this app on their device") -> user need to install this app on their device | F13: =IFERROR(__xludf.DUMMYFUNCTION("""COMPUTED_VALUE"""),"1. Open app 2. Login in backend framework") -> 1. Open app 2. Login in backend framework | G13: =IFERROR(__xludf.DUMMYFUNCTION("""COMPUTED_VALUE"""),"Driver Credentials") -> Driver Credentials | H13: =IFERROR(__xludf.DUMMYFUNCTION("""COMPUTED_VALUE"""),"User session management need to be handled carefully") -> User session management need to be handled carefully | I13: =IFERROR(__xludf.DUMMYFUNCTION("""COMPUTED_VALUE"""),"User is deleted from the backend, but the login session still remains active on the frontend.") -> User is deleted from the backend, but the login session still remains active on the frontend. | J13: =IFERROR(__xludf.DUMMYFUNCTION("""COMPUTED_VALUE"""),"Fail") -> Fail | K13: =IFERROR(__xludf.DUMMYFUNCTION("""COMPUTED_VALUE"""),"High") -> High | L13: =IFERROR(__xludf.DUMMYFUNCTION("""COMPUTED_VALUE"""),"022.png") -> 022.png | O13: =IFERROR(__xludf.DUMMYFUNCTION("""COMPUTED_VALUE"""),"Front-End") -> Front-End | P13: =IFERROR(__xludf.DUMMYFUNCTION("""COMPUTED_VALUE"""),"App state whole so time") -> App state whole so time | Q13: =IFERROR(__xludf.DUMMYFUNCTION("""COMPUTED_VALUE"""),"Fahad") -> Fahad
A14: BR-004 | B14: =IFERROR(__xludf.DUMMYFUNCTION("""COMPUTED_VALUE"""),"Driver") -> Driver | C14: =IFERROR(__xludf.DUMMYFUNCTION("""COMPUTED_VALUE"""),"Drive verification") -> Drive verification | D14: =IFERROR(__xludf.DUMMYFUNCTION("""COMPUTED_VALUE"""),"Validation failed on the frontend, causing a server-side validation issue.") -> Validation failed on the frontend, causing a server-side validation issue. | E14: =IFERROR(__xludf.DUMMYFUNCTION("""COMPUTED_VALUE"""),"user need to install this app on their device") -> user need to install this app on their device | F14: =IFERROR(__xludf.DUMMYFUNCTION("""COMPUTED_VALUE"""),"1. Open app 2. Select driver role 3. Click on signup and click on google signup 4. Fill necessary information and click on next") -> 1. Open app 2. Select driver role 3. Click on signup and click on google signup 4. Fill necessary information and click on next | G14: =IFERROR(__xludf.DUMMYFUNCTION("""COMPUTED_VALUE"""),"Driver Credentials") -> Driver Credentials | H14: =IFERROR(__xludf.DUMMYFUNCTION("""COMPUTED_VALUE"""),"Should put validation in user input field") -> Should put validation in user input field | I14: =IFERROR(__xludf.DUMMYFUNCTION("""COMPUTED_VALUE"""),"No validation has been noticed in app") -> No validation has been noticed in app | J14: =IFERROR(__xludf.DUMMYFUNCTION("""COMPUTED_VALUE"""),"Fail") -> Fail | K14: =IFERROR(__xludf.DUMMYFUNCTION("""COMPUTED_VALUE"""),"High") -> High | L14: =IFERROR(__xludf.DUMMYFUNCTION("""COMPUTED_VALUE"""),"029.png") -> 029.png | O14: =IFERROR(__xludf.DUMMYFUNCTION("""COMPUTED_VALUE"""),"Front-End") -> Front-End | P14: =IFERROR(__xludf.DUMMYFUNCTION("""COMPUTED_VALUE"""),"Solved...field name change problem from backend") -> Solved...field name change problem from backend | Q14: =IFERROR(__xludf.DUMMYFUNCTION("""COMPUTED_VALUE"""),"Fahad") -> Fahad
A15: BR-005 | B15: =IFERROR(__xludf.DUMMYFUNCTION("""COMPUTED_VALUE"""),"Driver") -> Driver | C15: =IFERROR(__xludf.DUMMYFUNCTION("""COMPUTED_VALUE"""),"Drive verification") -> Drive verification | D15: =IFERROR(__xludf.DUMMYFUNCTION("""COMPUTED_VALUE"""),"Notification popup should appear when the admin approves a driver's verification.") -> Notification popup should appear when the admin approves a driver's verification. | E15: =IFERROR(__xludf.DUMMYFUNCTION("""COMPUTED_VALUE"""),"user need to install this app on their device") -> user need to install this app on their device | F15: =IFERROR(__xludf.DUMMYFUNCTION("""COMPUTED_VALUE"""),"1. Open app 2. Select driver role 3. Click on signup and click on google signup 4. Fill necessary information and click on next") -> 1. Open app 2. Select driver role 3. Click on signup and click on google signup 4. Fill necessary information and click on next | G15: =IFERROR(__xludf.DUMMYFUNCTION("""COMPUTED_VALUE"""),"Driver Credentials") -> Driver Credentials | H15: =IFERROR(__xludf.DUMMYFUNCTION("""COMPUTED_VALUE"""),"User should receive a notification of account verification") -> User should receive a notification of account verification | I15: =IFERROR(__xludf.DUMMYFUNCTION("""COMPUTED_VALUE"""),"No notification received when admin approves user (driver) account") -> No notification received when admin approves user (driver) account | J15: =IFERROR(__xludf.DUMMYFUNCTION("""COMPUTED_VALUE"""),"Fail") -> Fail | K15: =IFERROR(__xludf.DUMMYFUNCTION("""COMPUTED_VALUE"""),"High") -> High | L15: =IFERROR(__xludf.DUMMYFUNCTION("""COMPUTED_VALUE"""),"030.png") -> 030.png | Q15: =IFERROR(__xludf.DUMMYFUNCTION("""COMPUTED_VALUE"""),"Fahad") -> Fahad
A16: BR-006 | B16: =IFERROR(__xludf.DUMMYFUNCTION("""COMPUTED_VALUE"""),"Driver") -> Driver | C16: =IFERROR(__xludf.DUMMYFUNCTION("""COMPUTED_VALUE"""),"Drive verification") -> Drive verification | D16: =IFERROR(__xludf.DUMMYFUNCTION("""COMPUTED_VALUE"""),"default name set for user") -> default name set for user | E16: =IFERROR(__xludf.DUMMYFUNCTION("""COMPUTED_VALUE"""),"user need to install this app on their device") -> user need to install this app on their device | F16: =IFERROR(__xludf.DUMMYFUNCTION("""COMPUTED_VALUE"""),"1. Open app 2. Select driver role 3. Click on signup and click on google signup 4. Fill necessary information and click on next") -> 1. Open app 2. Select driver role 3. Click on signup and click on google signup 4. Fill necessary information and click on next | G16: =IFERROR(__xludf.DUMMYFUNCTION("""COMPUTED_VALUE"""),"Driver Credentials") -> Driver Credentials | H16: =IFERROR(__xludf.DUMMYFUNCTION("""COMPUTED_VALUE"""),"Should be placeholder ") -> Should be placeholder | I16: =IFERROR(__xludf.DUMMYFUNCTION("""COMPUTED_VALUE"""),"Name was set for default") -> Name was set for default | J16: =IFERROR(__xludf.DUMMYFUNCTION("""COMPUTED_VALUE"""),"Fail") -> Fail | K16: =IFERROR(__xludf.DUMMYFUNCTION("""COMPUTED_VALUE"""),"Medium") -> Medium | L16: =IFERROR(__xludf.DUMMYFUNCTION("""COMPUTED_VALUE"""),"031.png") -> 031.png | Q16: =IFERROR(__xludf.DUMMYFUNCTION("""COMPUTED_VALUE"""),"Fahad") -> Fahad
A17: BR-007 | B17: =IFERROR(__xludf.DUMMYFUNCTION("""COMPUTED_VALUE"""),"Driver") -> Driver | C17: =IFERROR(__xludf.DUMMYFUNCTION("""COMPUTED_VALUE"""),"Home") -> Home | D17: =IFERROR(__xludf.DUMMYFUNCTION("""COMPUTED_VALUE"""),"Design is different from Figma.") -> Design is different from Figma. | E17: =IFERROR(__xludf.DUMMYFUNCTION("""COMPUTED_VALUE"""),"user need to install this app on their device") -> user need to install this app on their device | F17: =IFERROR(__xludf.DUMMYFUNCTION("""COMPUTED_VALUE"""),"1. Open app 2. Select driver role 3. Login using valid credentials ") -> 1. Open app 2. Select driver role 3. Login using valid credentials | G17: =IFERROR(__xludf.DUMMYFUNCTION("""COMPUTED_VALUE"""),"Driver Credentials") -> Driver Credentials | H17: =IFERROR(__xludf.DUMMYFUNCTION("""COMPUTED_VALUE"""),"Design and aligment should as same as figma for client satisfaction") -> Design and aligment should as same as figma for client satisfaction | I17: =IFERROR(__xludf.DUMMYFUNCTION("""COMPUTED_VALUE"""),"Icon missing from figma has been seen") -> Icon missing from figma has been seen | J17: =IFERROR(__xludf.DUMMYFUNCTION("""COMPUTED_VALUE"""),"Fail") -> Fail | K17: =IFERROR(__xludf.DUMMYFUNCTION("""COMPUTED_VALUE"""),"Medium") -> Medium | L17: =IFERROR(__xludf.DUMMYFUNCTION("""COMPUTED_VALUE"""),"021.png") -> 021.png | O17: =IFERROR(__xludf.DUMMYFUNCTION("""COMPUTED_VALUE"""),"Front-End") -> Front-End | P17: =IFERROR(__xludf.DUMMYFUNCTION("""COMPUTED_VALUE"""),"fixed") -> fixed | Q17: =IFERROR(__xludf.DUMMYFUNCTION("""COMPUTED_VALUE"""),"Fahad") -> Fahad
A18: BR-008 | B18: =IFERROR(__xludf.DUMMYFUNCTION("""COMPUTED_VALUE"""),"Driver") -> Driver | C18: =IFERROR(__xludf.DUMMYFUNCTION("""COMPUTED_VALUE"""),"My Trips") -> My Trips | D18: =IFERROR(__xludf.DUMMYFUNCTION("""COMPUTED_VALUE"""),"Offering multiple seats for sharing but displaying only one as available") -> Offering multiple seats for sharing but displaying only one as available | E18: =IFERROR(__xludf.DUMMYFUNCTION("""COMPUTED_VALUE"""),"user need to install this app on their device") -> user need to install this app on their device | F18: =IFERROR(__xludf.DUMMYFUNCTION("""COMPUTED_VALUE"""),"1. Open app 2. Select driver role 3. Login using valid credentials 4. Click on post ride") -> 1. Open app 2. Select driver role 3. Login using valid credentials 4. Click on post ride | G18: =IFERROR(__xludf.DUMMYFUNCTION("""COMPUTED_VALUE"""),"Driver Credentials") -> Driver Credentials | H18: =IFERROR(__xludf.DUMMYFUNCTION("""COMPUTED_VALUE"""),"Seat availability should display properly on posted rides") -> Seat availability should display properly on posted rides | I18: =IFERROR(__xludf.DUMMYFUNCTION("""COMPUTED_VALUE"""),"Display only one seat as available on every ride share post, even if the user lists more than one seat.") -> Display only one seat as available on every ride share post, even if the user lists more than one seat. | J18: =IFERROR(__xludf.DUMMYFUNCTION("""COMPUTED_VALUE"""),"Fail") -> Fail | K18: =IFERROR(__xludf.DUMMYFUNCTION("""COMPUTED_VALUE"""),"High") -> High | L18: =IFERROR(__xludf.DUMMYFUNCTION("""COMPUTED_VALUE"""),"032.png") -> 032.png | Q18: =IFERROR(__xludf.DUMMYFUNCTION("""COMPUTED_VALUE"""),"Fahad") -> Fahad
A19: BR-009 | B19: =IFERROR(__xludf.DUMMYFUNCTION("""COMPUTED_VALUE"""),"Driver") -> Driver | C19: =IFERROR(__xludf.DUMMYFUNCTION("""COMPUTED_VALUE"""),"My Trips") -> My Trips | D19: =IFERROR(__xludf.DUMMYFUNCTION("""COMPUTED_VALUE"""),"Unable to find a ride through the search.") -> Unable to find a ride through the search. | E19: =IFERROR(__xludf.DUMMYFUNCTION("""COMPUTED_VALUE"""),"user need to install this app on their device") -> user need to install this app on their device | F19: =IFERROR(__xludf.DUMMYFUNCTION("""COMPUTED_VALUE"""),"1. Open app 2. Select driver role 3. Login using valid credentials 4. Click on post ride") -> 1. Open app 2. Select driver role 3. Login using valid credentials 4. Click on post ride | G19: =IFERROR(__xludf.DUMMYFUNCTION("""COMPUTED_VALUE"""),"Driver Credentials") -> Driver Credentials | H19: =IFERROR(__xludf.DUMMYFUNCTION("""COMPUTED_VALUE"""),"User (passenger) should be able to get the ride if the time matches with rider") -> User (passenger) should be able to get the ride if the time matches with rider | I19: =IFERROR(__xludf.DUMMYFUNCTION("""COMPUTED_VALUE"""),"Failed to get the ride, and no record was displayed.") -> Failed to get the ride, and no record was displayed. | J19: =IFERROR(__xludf.DUMMYFUNCTION("""COMPUTED_VALUE"""),"Fail") -> Fail | K19: =IFERROR(__xludf.DUMMYFUNCTION("""COMPUTED_VALUE"""),"High") -> High | L19: =IFERROR(__xludf.DUMMYFUNCTION("""COMPUTED_VALUE"""),"033.mp4") -> 033.mp4 | Q19: =IFERROR(__xludf.DUMMYFUNCTION("""COMPUTED_VALUE"""),"Fahad") -> Fahad
A20: BR-010 | B20: =IFERROR(__xludf.DUMMYFUNCTION("""COMPUTED_VALUE"""),"Driver") -> Driver | C20: =IFERROR(__xludf.DUMMYFUNCTION("""COMPUTED_VALUE"""),"Notification") -> Notification | D20: =IFERROR(__xludf.DUMMYFUNCTION("""COMPUTED_VALUE"""),"Notification panel is empty, yet it still displays the unread notification icon.") -> Notification panel is empty, yet it still displays the unread notification icon. | E20: =IFERROR(__xludf.DUMMYFUNCTION("""COMPUTED_VALUE"""),"user need to install this app on their device") -> user need to install this app on their device | F20: =IFERROR(__xludf.DUMMYFUNCTION("""COMPUTED_VALUE"""),"1. Open app 2. Select driver role 3. Login using valid credentials 4. Click on notifications") -> 1. Open app 2. Select driver role 3. Login using valid credentials 4. Click on notifications | G20: =IFERROR(__xludf.DUMMYFUNCTION("""COMPUTED_VALUE"""),"Driver Credentials") -> Driver Credentials | H20: =IFERROR(__xludf.DUMMYFUNCTION("""COMPUTED_VALUE"""),"If notification is empty than, should display simple bell icon") -> If notification is empty than, should display simple bell icon | I20: =IFERROR(__xludf.DUMMYFUNCTION("""COMPUTED_VALUE"""),"mark on notification has been displayed weather it has no notification unread") -> mark on notification has been displayed weather it has no notification unread | J20: =IFERROR(__xludf.DUMMYFUNCTION("""COMPUTED_VALUE"""),"Fail") -> Fail | K20: =IFERROR(__xludf.DUMMYFUNCTION("""COMPUTED_VALUE"""),"Medium") -> Medium | L20: =IFERROR(__xludf.DUMMYFUNCTION("""COMPUTED_VALUE"""),"020.mp4") -> 020.mp4 | O20: =IFERROR(__xludf.DUMMYFUNCTION("""COMPUTED_VALUE"""),"Front-End") -> Front-End | P20: =IFERROR(__xludf.DUMMYFUNCTION("""COMPUTED_VALUE"""),"fixed") -> fixed | Q20: =IFERROR(__xludf.DUMMYFUNCTION("""COMPUTED_VALUE"""),"Fahad") -> Fahad
A21: BR-011 | B21: =IFERROR(__xludf.DUMMYFUNCTION("""COMPUTED_VALUE"""),"Driver") -> Driver | C21: =IFERROR(__xludf.DUMMYFUNCTION("""COMPUTED_VALUE"""),"Post New ride") -> Post New ride | D21: =IFERROR(__xludf.DUMMYFUNCTION("""COMPUTED_VALUE"""),"Unable to display location suggestions.") -> Unable to display location suggestions. | E21: =IFERROR(__xludf.DUMMYFUNCTION("""COMPUTED_VALUE"""),"user need to install this app on their device") -> user need to install this app on their device | F21: =IFERROR(__xludf.DUMMYFUNCTION("""COMPUTED_VALUE"""),"1. Open app 2. Select driver role 3. Login using valid credentials 4. Click on post a new ride") -> 1. Open app 2. Select driver role 3. Login using valid credentials 4. Click on post a new ride | G21: =IFERROR(__xludf.DUMMYFUNCTION("""COMPUTED_VALUE"""),"Driver Credentials") -> Driver Credentials | H21: =IFERROR(__xludf.DUMMYFUNCTION("""COMPUTED_VALUE"""),"Should display suggested locations for better user experience") -> Should display suggested locations for better user experience | I21: =IFERROR(__xludf.DUMMYFUNCTION("""COMPUTED_VALUE"""),"Failed to suggest locations") -> Failed to suggest locations | J21: =IFERROR(__xludf.DUMMYFUNCTION("""COMPUTED_VALUE"""),"Fail") -> Fail | K21: =IFERROR(__xludf.DUMMYFUNCTION("""COMPUTED_VALUE"""),"High") -> High | L21: =IFERROR(__xludf.DUMMYFUNCTION("""COMPUTED_VALUE"""),"023.png") -> 023.png | O21: =IFERROR(__xludf.DUMMYFUNCTION("""COMPUTED_VALUE"""),"Front-End") -> Front-End | Q21: =IFERROR(__xludf.DUMMYFUNCTION("""COMPUTED_VALUE"""),"Fahad") -> Fahad
A22: BR-012 | B22: =IFERROR(__xludf.DUMMYFUNCTION("""COMPUTED_VALUE"""),"Driver") -> Driver | C22: =IFERROR(__xludf.DUMMYFUNCTION("""COMPUTED_VALUE"""),"Post New ride") -> Post New ride | D22: =IFERROR(__xludf.DUMMYFUNCTION("""COMPUTED_VALUE"""),"needs more polish in the text font and design") -> needs more polish in the text font and design | E22: =IFERROR(__xludf.DUMMYFUNCTION("""COMPUTED_VALUE"""),"user need to install this app on their device") -> user need to install this app on their device | F22: =IFERROR(__xludf.DUMMYFUNCTION("""COMPUTED_VALUE"""),"1. Open app 2. Select driver role 3. Login using valid credentials 4. Click on post a new ride") -> 1. Open app 2. Select driver role 3. Login using valid credentials 4. Click on post a new ride | G22: =IFERROR(__xludf.DUMMYFUNCTION("""COMPUTED_VALUE"""),"Driver Credentials") -> Driver Credentials | H22: =IFERROR(__xludf.DUMMYFUNCTION("""COMPUTED_VALUE"""),"App could use some extra polish on both the text and design.") -> App could use some extra polish on both the text and design. | I22: =IFERROR(__xludf.DUMMYFUNCTION("""COMPUTED_VALUE"""),"Need more polish on app") -> Need more polish on app | J22: =IFERROR(__xludf.DUMMYFUNCTION("""COMPUTED_VALUE"""),"Fail") -> Fail | K22: =IFERROR(__xludf.DUMMYFUNCTION("""COMPUTED_VALUE"""),"Medium") -> Medium | L22: =IFERROR(__xludf.DUMMYFUNCTION("""COMPUTED_VALUE"""),"024.png") -> 024.png | Q22: =IFERROR(__xludf.DUMMYFUNCTION("""COMPUTED_VALUE"""),"Fahad") -> Fahad
A23: BR-013 | B23: =IFERROR(__xludf.DUMMYFUNCTION("""COMPUTED_VALUE"""),"Driver") -> Driver | C23: =IFERROR(__xludf.DUMMYFUNCTION("""COMPUTED_VALUE"""),"Post New ride") -> Post New ride | D23: =IFERROR(__xludf.DUMMYFUNCTION("""COMPUTED_VALUE"""),"Function isn’t behaving as intended.") -> Function isn’t behaving as intended. | E23: =IFERROR(__xludf.DUMMYFUNCTION("""COMPUTED_VALUE"""),"user need to install this app on their device") -> user need to install this app on their device | F23: =IFERROR(__xludf.DUMMYFUNCTION("""COMPUTED_VALUE"""),"1. Open app 2. Select driver role 3. Login using valid credentials 4. Click on post a new ride") -> 1. Open app 2. Select driver role 3. Login using valid credentials 4. Click on post a new ride | G23: =IFERROR(__xludf.DUMMYFUNCTION("""COMPUTED_VALUE"""),"Driver Credentials") -> Driver Credentials | H23: =IFERROR(__xludf.DUMMYFUNCTION("""COMPUTED_VALUE"""),"Function should perform as intended.") -> Function should perform as intended. | I23: =IFERROR(__xludf.DUMMYFUNCTION("""COMPUTED_VALUE"""),"Failed to upload photos in the verification fields.") -> Failed to upload photos in the verification fields. | J23: =IFERROR(__xludf.DUMMYFUNCTION("""COMPUTED_VALUE"""),"Fail") -> Fail | K23: =IFERROR(__xludf.DUMMYFUNCTION("""COMPUTED_VALUE"""),"High") -> High | L23: =IFERROR(__xludf.DUMMYFUNCTION("""COMPUTED_VALUE"""),"025.png") -> 025.png | O23: =IFERROR(__xludf.DUMMYFUNCTION("""COMPUTED_VALUE"""),"Front-End") -> Front-End | Q23: =IFERROR(__xludf.DUMMYFUNCTION("""COMPUTED_VALUE"""),"Fahad") -> Fahad
A24: BR-014 | B24: =IFERROR(__xludf.DUMMYFUNCTION("""COMPUTED_VALUE"""),"Driver") -> Driver | C24: =IFERROR(__xludf.DUMMYFUNCTION("""COMPUTED_VALUE"""),"Post New ride") -> Post New ride | D24: =IFERROR(__xludf.DUMMYFUNCTION("""COMPUTED_VALUE"""),"Can’t create a ride because it’s asking me to select a location from a dropdown, but the dropdown isn’t showing up.") -> Can’t create a ride because it’s asking me to select a location from a dropdown, but the dropdown isn’t showing up. | E24: =IFERROR(__xludf.DUMMYFUNCTION("""COMPUTED_VALUE"""),"user need to install this app on their device") -> user need to install this app on their device | F24: =IFERROR(__xludf.DUMMYFUNCTION("""COMPUTED_VALUE"""),"1. Open app 2. Select driver role 3. Login using valid credentials 4. Click on post a new ride") -> 1. Open app 2. Select driver role 3. Login using valid credentials 4. Click on post a new ride | G24: =IFERROR(__xludf.DUMMYFUNCTION("""COMPUTED_VALUE"""),"Driver Credentials") -> Driver Credentials | H24: =IFERROR(__xludf.DUMMYFUNCTION("""COMPUTED_VALUE"""),"Suggested location should be clearly visible to avoid any conflict with the actual location.") -> Suggested location should be clearly visible to avoid any conflict with the actual location. | I24: =IFERROR(__xludf.DUMMYFUNCTION("""COMPUTED_VALUE"""),"System failed to suggest the correct location, and the dropdown menu also didn’t provide any suggestions.") -> System failed to suggest the correct location, and the dropdown menu also didn’t provide any suggestions. | J24: =IFERROR(__xludf.DUMMYFUNCTION("""COMPUTED_VALUE"""),"Fail") -> Fail | K24: =IFERROR(__xludf.DUMMYFUNCTION("""COMPUTED_VALUE"""),"High") -> High | L24: =IFERROR(__xludf.DUMMYFUNCTION("""COMPUTED_VALUE"""),"026.png") -> 026.png | O24: =IFERROR(__xludf.DUMMYFUNCTION("""COMPUTED_VALUE"""),"Front-End") -> Front-End | Q24: =IFERROR(__xludf.DUMMYFUNCTION("""COMPUTED_VALUE"""),"Fahad") -> Fahad
A25: BR-015 | B25: =IFERROR(__xludf.DUMMYFUNCTION("""COMPUTED_VALUE"""),"Driver") -> Driver | C25: =IFERROR(__xludf.DUMMYFUNCTION("""COMPUTED_VALUE"""),"SignIn") -> SignIn | D25: =IFERROR(__xludf.DUMMYFUNCTION("""COMPUTED_VALUE"""),"Google signup failed and was unable to store the username and information.") -> Google signup failed and was unable to store the username and information. | E25: =IFERROR(__xludf.DUMMYFUNCTION("""COMPUTED_VALUE"""),"user need to install this app on their device") -> user need to install this app on their device | F25: =IFERROR(__xludf.DUMMYFUNCTION("""COMPUTED_VALUE"""),"1. Open app 2. Select driver role 3. Signin using google signin") -> 1. Open app 2. Select driver role 3. Signin using google signin | G25: =IFERROR(__xludf.DUMMYFUNCTION("""COMPUTED_VALUE"""),"Driver Credentials") -> Driver Credentials | H25: =IFERROR(__xludf.DUMMYFUNCTION("""COMPUTED_VALUE"""),"User should be able to signin using google account") -> User should be able to signin using google account | I25: =IFERROR(__xludf.DUMMYFUNCTION("""COMPUTED_VALUE"""),"Failed to signin with google login") -> Failed to signin with google login | J25: =IFERROR(__xludf.DUMMYFUNCTION("""COMPUTED_VALUE"""),"Fail") -> Fail | K25: =IFERROR(__xludf.DUMMYFUNCTION("""COMPUTED_VALUE"""),"High") -> High | L25: =IFERROR(__xludf.DUMMYFUNCTION("""COMPUTED_VALUE"""),"027.mp4") -> 027.mp4 | Q25: =IFERROR(__xludf.DUMMYFUNCTION("""COMPUTED_VALUE"""),"Fahad") -> Fahad
A26: BR-016 | B26: =IFERROR(__xludf.DUMMYFUNCTION("""COMPUTED_VALUE"""),"Driver") -> Driver | C26: =IFERROR(__xludf.DUMMYFUNCTION("""COMPUTED_VALUE"""),"SignUp") -> SignUp | D26: =IFERROR(__xludf.DUMMYFUNCTION("""COMPUTED_VALUE"""),"Backend shows the account as approved, but on the frontend, it’s still marked as under review.") -> Backend shows the account as approved, but on the frontend, it’s still marked as under review. | E26: =IFERROR(__xludf.DUMMYFUNCTION("""COMPUTED_VALUE"""),"user need to install this app on their device") -> user need to install this app on their device | F26: =IFERROR(__xludf.DUMMYFUNCTION("""COMPUTED_VALUE"""),"1. Open app 2. Select driver role 3. Goto signup page") -> 1. Open app 2. Select driver role 3. Goto signup page | G26: =IFERROR(__xludf.DUMMYFUNCTION("""COMPUTED_VALUE"""),"Driver Credentials") -> Driver Credentials | H26: =IFERROR(__xludf.DUMMYFUNCTION("""COMPUTED_VALUE"""),"Frontend should show the updated status once the user has been approved in the backend.") -> Frontend should show the updated status once the user has been approved in the backend. | I26: =IFERROR(__xludf.DUMMYFUNCTION("""COMPUTED_VALUE"""),"Driver is still in review state even after they were approved from the backend.") -> Driver is still in review state even after they were approved from the backend. | J26: =IFERROR(__xludf.DUMMYFUNCTION("""COMPUTED_VALUE"""),"Fail") -> Fail | K26: =IFERROR(__xludf.DUMMYFUNCTION("""COMPUTED_VALUE"""),"High") -> High | L26: =IFERROR(__xludf.DUMMYFUNCTION("""COMPUTED_VALUE"""),"017.png") -> 017.png | O26: =IFERROR(__xludf.DUMMYFUNCTION("""COMPUTED_VALUE"""),"Front-End") -> Front-End | P26: =IFERROR(__xludf.DUMMYFUNCTION("""COMPUTED_VALUE"""),"use pull to refresh") -> use pull to refresh | Q26: =IFERROR(__xludf.DUMMYFUNCTION("""COMPUTED_VALUE"""),"Fahad") -> Fahad
A27: BR-017 | B27: =IFERROR(__xludf.DUMMYFUNCTION("""COMPUTED_VALUE"""),"Driver") -> Driver | C27: =IFERROR(__xludf.DUMMYFUNCTION("""COMPUTED_VALUE"""),"SignUp") -> SignUp | D27: =IFERROR(__xludf.DUMMYFUNCTION("""COMPUTED_VALUE"""),"Signup using google failed") -> Signup using google failed | E27: =IFERROR(__xludf.DUMMYFUNCTION("""COMPUTED_VALUE"""),"user need to install this app on their device") -> user need to install this app on their device | F27: =IFERROR(__xludf.DUMMYFUNCTION("""COMPUTED_VALUE"""),"1. Open app 2. Select driver role 3. Click on signup and click on google signup") -> 1. Open app 2. Select driver role 3. Click on signup and click on google signup | G27: =IFERROR(__xludf.DUMMYFUNCTION("""COMPUTED_VALUE"""),"Driver Credentials") -> Driver Credentials | H27: =IFERROR(__xludf.DUMMYFUNCTION("""COMPUTED_VALUE"""),"User should be able to signup using google account") -> User should be able to signup using google account | I27: =IFERROR(__xludf.DUMMYFUNCTION("""COMPUTED_VALUE"""),"Failed to signup with google login") -> Failed to signup with google login | J27: =IFERROR(__xludf.DUMMYFUNCTION("""COMPUTED_VALUE"""),"Fail") -> Fail | K27: =IFERROR(__xludf.DUMMYFUNCTION("""COMPUTED_VALUE"""),"High") -> High | L27: =IFERROR(__xludf.DUMMYFUNCTION("""COMPUTED_VALUE"""),"028.mp4") -> 028.mp4 | Q27: =IFERROR(__xludf.DUMMYFUNCTION("""COMPUTED_VALUE"""),"Fahad") -> Fahad
A28: BR-018 | B28: =IFERROR(__xludf.DUMMYFUNCTION("""COMPUTED_VALUE"""),"Onbording") -> Onbording | C28: =IFERROR(__xludf.DUMMYFUNCTION("""COMPUTED_VALUE"""),"Onbording") -> Onbording | D28: =IFERROR(__xludf.DUMMYFUNCTION("""COMPUTED_VALUE"""),"font alignment issue") -> font alignment issue | E28: =IFERROR(__xludf.DUMMYFUNCTION("""COMPUTED_VALUE"""),"user need to install this app on their device") -> user need to install this app on their device | F28: =IFERROR(__xludf.DUMMYFUNCTION("""COMPUTED_VALUE"""),"1. Open app") -> 1. Open app | G28: =IFERROR(__xludf.DUMMYFUNCTION("""COMPUTED_VALUE"""),"N/A") -> N/A | H28: =IFERROR(__xludf.DUMMYFUNCTION("""COMPUTED_VALUE"""),"Design and alignment should match the Figma file as confirmed by the client.") -> Design and alignment should match the Figma file as confirmed by the client. | I28: =IFERROR(__xludf.DUMMYFUNCTION("""COMPUTED_VALUE"""),"Font alignment issue has been noticed") -> Font alignment issue has been noticed | J28: =IFERROR(__xludf.DUMMYFUNCTION("""COMPUTED_VALUE"""),"Fail") -> Fail | K28: =IFERROR(__xludf.DUMMYFUNCTION("""COMPUTED_VALUE"""),"Low") -> Low | L28: =IFERROR(__xludf.DUMMYFUNCTION("""COMPUTED_VALUE"""),"001.png") -> 001.png | O28: =IFERROR(__xludf.DUMMYFUNCTION("""COMPUTED_VALUE"""),"Front-End") -> Front-End | P28: =IFERROR(__xludf.DUMMYFUNCTION("""COMPUTED_VALUE"""),"changed") -> changed | Q28: =IFERROR(__xludf.DUMMYFUNCTION("""COMPUTED_VALUE"""),"Fahad") -> Fahad
A29: BR-019 | B29: =IFERROR(__xludf.DUMMYFUNCTION("""COMPUTED_VALUE"""),"Onbording") -> Onbording | C29: =IFERROR(__xludf.DUMMYFUNCTION("""COMPUTED_VALUE"""),"Onbording") -> Onbording | D29: =IFERROR(__xludf.DUMMYFUNCTION("""COMPUTED_VALUE"""),"font alignment issue") -> font alignment issue | E29: =IFERROR(__xludf.DUMMYFUNCTION("""COMPUTED_VALUE"""),"user need to install this app on their device") -> user need to install this app on their device | F29: =IFERROR(__xludf.DUMMYFUNCTION("""COMPUTED_VALUE"""),"1. Open app") -> 1. Open app | G29: =IFERROR(__xludf.DUMMYFUNCTION("""COMPUTED_VALUE"""),"N/A") -> N/A | H29: =IFERROR(__xludf.DUMMYFUNCTION("""COMPUTED_VALUE"""),"Design and alignment should match the Figma file as confirmed by the client.") -> Design and alignment should match the Figma file as confirmed by the client. | I29: =IFERROR(__xludf.DUMMYFUNCTION("""COMPUTED_VALUE"""),"Font alignment issue has been noticed") -> Font alignment issue has been noticed | J29: =IFERROR(__xludf.DUMMYFUNCTION("""COMPUTED_VALUE"""),"Fail") -> Fail | K29: =IFERROR(__xludf.DUMMYFUNCTION("""COMPUTED_VALUE"""),"Low") -> Low | L29: =IFERROR(__xludf.DUMMYFUNCTION("""COMPUTED_VALUE"""),"002.png") -> 002.png | O29: =IFERROR(__xludf.DUMMYFUNCTION("""COMPUTED_VALUE"""),"Front-End") -> Front-End | P29: =IFERROR(__xludf.DUMMYFUNCTION("""COMPUTED_VALUE"""),"changed") -> changed | Q29: =IFERROR(__xludf.DUMMYFUNCTION("""COMPUTED_VALUE"""),"Fahad") -> Fahad
A30: BR-020 | B30: =IFERROR(__xludf.DUMMYFUNCTION("""COMPUTED_VALUE"""),"Onbording") -> Onbording | C30: =IFERROR(__xludf.DUMMYFUNCTION("""COMPUTED_VALUE"""),"Onbording") -> Onbording | D30: =IFERROR(__xludf.DUMMYFUNCTION("""COMPUTED_VALUE"""),"Icon needs to be bigger.") -> Icon needs to be bigger. | E30: =IFERROR(__xludf.DUMMYFUNCTION("""COMPUTED_VALUE"""),"user need to install this app on their device") -> user need to install this app on their device | F30: =IFERROR(__xludf.DUMMYFUNCTION("""COMPUTED_VALUE"""),"1. Open app") -> 1. Open app | G30: =IFERROR(__xludf.DUMMYFUNCTION("""COMPUTED_VALUE"""),"N/A") -> N/A | H30: =IFERROR(__xludf.DUMMYFUNCTION("""COMPUTED_VALUE"""),"Design and alignment should match the Figma file as confirmed by the client.") -> Design and alignment should match the Figma file as confirmed by the client. | I30: =IFERROR(__xludf.DUMMYFUNCTION("""COMPUTED_VALUE"""),"Font alignment issue has been noticed") -> Font alignment issue has been noticed | J30: =IFERROR(__xludf.DUMMYFUNCTION("""COMPUTED_VALUE"""),"Fail") -> Fail | K30: =IFERROR(__xludf.DUMMYFUNCTION("""COMPUTED_VALUE"""),"Low") -> Low | L30: =IFERROR(__xludf.DUMMYFUNCTION("""COMPUTED_VALUE"""),"003.png") -> 003.png | O30: =IFERROR(__xludf.DUMMYFUNCTION("""COMPUTED_VALUE"""),"Front-End") -> Front-End | P30: =IFERROR(__xludf.DUMMYFUNCTION("""COMPUTED_VALUE"""),"Taken whole as image..one will effect others") -> Taken whole as image..one will effect others | Q30: =IFERROR(__xludf.DUMMYFUNCTION("""COMPUTED_VALUE"""),"Fahad") -> Fahad
A31: BR-021 | B31: =IFERROR(__xludf.DUMMYFUNCTION("""COMPUTED_VALUE"""),"Onbording") -> Onbording | C31: =IFERROR(__xludf.DUMMYFUNCTION("""COMPUTED_VALUE"""),"Onbording") -> Onbording | D31: =IFERROR(__xludf.DUMMYFUNCTION("""COMPUTED_VALUE"""),"Title looks different from the Figma design, and there’s a font alignment issue.") -> Title looks different from the Figma design, and there’s a font alignment issue. | E31: =IFERROR(__xludf.DUMMYFUNCTION("""COMPUTED_VALUE"""),"user need to install this app on their device") -> user need to install this app on their device | F31: =IFERROR(__xludf.DUMMYFUNCTION("""COMPUTED_VALUE"""),"1. Open app") -> 1. Open app | G31: =IFERROR(__xludf.DUMMYFUNCTION("""COMPUTED_VALUE"""),"N/A") -> N/A | H31: =IFERROR(__xludf.DUMMYFUNCTION("""COMPUTED_VALUE"""),"Design and alignment should match the Figma file as confirmed by the client.") -> Design and alignment should match the Figma file as confirmed by the client. | I31: =IFERROR(__xludf.DUMMYFUNCTION("""COMPUTED_VALUE"""),"Font alignment issue has been noticed") -> Font alignment issue has been noticed | J31: =IFERROR(__xludf.DUMMYFUNCTION("""COMPUTED_VALUE"""),"Fail") -> Fail | K31: =IFERROR(__xludf.DUMMYFUNCTION("""COMPUTED_VALUE"""),"Low") -> Low | L31: =IFERROR(__xludf.DUMMYFUNCTION("""COMPUTED_VALUE"""),"004.png") -> 004.png | O31: =IFERROR(__xludf.DUMMYFUNCTION("""COMPUTED_VALUE"""),"Front-End") -> Front-End | P31: =IFERROR(__xludf.DUMMYFUNCTION("""COMPUTED_VALUE"""),"chnaged") -> chnaged | Q31: =IFERROR(__xludf.DUMMYFUNCTION("""COMPUTED_VALUE"""),"Fahad") -> Fahad
A32: BR-022 | B32: =IFERROR(__xludf.DUMMYFUNCTION("""COMPUTED_VALUE"""),"Passenger") -> Passenger | C32: =IFERROR(__xludf.DUMMYFUNCTION("""COMPUTED_VALUE"""),"OTP") -> OTP | D32: =IFERROR(__xludf.DUMMYFUNCTION("""COMPUTED_VALUE"""),"A jumping action has been observed when entering the OTP.") -> A jumping action has been observed when entering the OTP. | E32: =IFERROR(__xludf.DUMMYFUNCTION("""COMPUTED_VALUE"""),"user need to install this app on their device") -> user need to install this app on their device | F32: =IFERROR(__xludf.DUMMYFUNCTION("""COMPUTED_VALUE"""),"1. Open app 2. Select passenger role 3. Goto signup page 4. Fillup necessary information and click next to get OTP") -> 1. Open app 2. Select passenger role 3. Goto signup page 4. Fillup necessary information and click next to get OTP | G32: =IFERROR(__xludf.DUMMYFUNCTION("""COMPUTED_VALUE"""),"User Credentials") -> User Credentials | H32: =IFERROR(__xludf.DUMMYFUNCTION("""COMPUTED_VALUE"""),"Should be stable when entering OTP") -> Should be stable when entering OTP | I32: =IFERROR(__xludf.DUMMYFUNCTION("""COMPUTED_VALUE"""),"Jumping action has been observed ") -> Jumping action has been observed | J32: =IFERROR(__xludf.DUMMYFUNCTION("""COMPUTED_VALUE"""),"Fail") -> Fail | K32: =IFERROR(__xludf.DUMMYFUNCTION("""COMPUTED_VALUE"""),"Medium") -> Medium | L32: =IFERROR(__xludf.DUMMYFUNCTION("""COMPUTED_VALUE"""),"011.mp4") -> 011.mp4 | O32: =IFERROR(__xludf.DUMMYFUNCTION("""COMPUTED_VALUE"""),"Front-End") -> Front-End | P32: =IFERROR(__xludf.DUMMYFUNCTION("""COMPUTED_VALUE"""),"Fixed") -> Fixed | Q32: =IFERROR(__xludf.DUMMYFUNCTION("""COMPUTED_VALUE"""),"Fahad") -> Fahad
A33: BR-023 | B33: =IFERROR(__xludf.DUMMYFUNCTION("""COMPUTED_VALUE"""),"Passenger") -> Passenger | C33: =IFERROR(__xludf.DUMMYFUNCTION("""COMPUTED_VALUE"""),"OTP") -> OTP | D33: =IFERROR(__xludf.DUMMYFUNCTION("""COMPUTED_VALUE"""),"Resend OTP failed") -> Resend OTP failed | E33: =IFERROR(__xludf.DUMMYFUNCTION("""COMPUTED_VALUE"""),"user need to install this app on their device") -> user need to install this app on their device | F33: =IFERROR(__xludf.DUMMYFUNCTION("""COMPUTED_VALUE"""),"1. Open app 2. Select passenger role 3. Goto signup page 4. Fillup necessary information and click next to get OTP") -> 1. Open app 2. Select passenger role 3. Goto signup page 4. Fillup necessary information and click next to get OTP | G33: =IFERROR(__xludf.DUMMYFUNCTION("""COMPUTED_VALUE"""),"User Credentials") -> User Credentials | H33: =IFERROR(__xludf.DUMMYFUNCTION("""COMPUTED_VALUE"""),"Function should work as expected") -> Function should work as expected | I33: =IFERROR(__xludf.DUMMYFUNCTION("""COMPUTED_VALUE"""),"Failed to resend OTP ") -> Failed to resend OTP | J33: =IFERROR(__xludf.DUMMYFUNCTION("""COMPUTED_VALUE"""),"Fail") -> Fail | K33: =IFERROR(__xludf.DUMMYFUNCTION("""COMPUTED_VALUE"""),"High") -> High | L33: =IFERROR(__xludf.DUMMYFUNCTION("""COMPUTED_VALUE"""),"012.png") -> 012.png | O33: =IFERROR(__xludf.DUMMYFUNCTION("""COMPUTED_VALUE"""),"Front-End") -> Front-End | P33: =IFERROR(__xludf.DUMMYFUNCTION("""COMPUTED_VALUE"""),"fixed") -> fixed | Q33: =IFERROR(__xludf.DUMMYFUNCTION("""COMPUTED_VALUE"""),"Fahad") -> Fahad
A34: BR-024 | B34: =IFERROR(__xludf.DUMMYFUNCTION("""COMPUTED_VALUE"""),"Passenger") -> Passenger | C34: =IFERROR(__xludf.DUMMYFUNCTION("""COMPUTED_VALUE"""),"OTP") -> OTP | D34: =IFERROR(__xludf.DUMMYFUNCTION("""COMPUTED_VALUE"""),"Valid OTP is showing as invalid. Time is not expired") -> Valid OTP is showing as invalid. Time is not expired | E34: =IFERROR(__xludf.DUMMYFUNCTION("""COMPUTED_VALUE"""),"user need to install this app on their device") -> user need to install this app on their device | F34: =IFERROR(__xludf.DUMMYFUNCTION("""COMPUTED_VALUE"""),"1. Open app 2. Select passenger role 3. Goto signup page 4. Fillup necessary information and click next to get OTP") -> 1. Open app 2. Select passenger role 3. Goto signup page 4. Fillup necessary information and click next to get OTP | G34: =IFERROR(__xludf.DUMMYFUNCTION("""COMPUTED_VALUE"""),"User Credentials") -> User Credentials | H34: =IFERROR(__xludf.DUMMYFUNCTION("""COMPUTED_VALUE"""),"OTP should remain valid based on its designated validity period.") -> OTP should remain valid based on its designated validity period. | I34: =IFERROR(__xludf.DUMMYFUNCTION("""COMPUTED_VALUE"""),"OTP shows as invalid, but it’s still within its validity period.") -> OTP shows as invalid, but it’s still within its validity period. | J34: =IFERROR(__xludf.DUMMYFUNCTION("""COMPUTED_VALUE"""),"Fail") -> Fail | K34: =IFERROR(__xludf.DUMMYFUNCTION("""COMPUTED_VALUE"""),"High") -> High | L34: =IFERROR(__xludf.DUMMYFUNCTION("""COMPUTED_VALUE"""),"013.png") -> 013.png | O34: =IFERROR(__xludf.DUMMYFUNCTION("""COMPUTED_VALUE"""),"Front-End") -> Front-End | P34: =IFERROR(__xludf.DUMMYFUNCTION("""COMPUTED_VALUE"""),"Validation time 10 min") -> Validation time 10 min | Q34: =IFERROR(__xludf.DUMMYFUNCTION("""COMPUTED_VALUE"""),"Fahad") -> Fahad
A35: BR-025 | B35: =IFERROR(__xludf.DUMMYFUNCTION("""COMPUTED_VALUE"""),"Passenger") -> Passenger | C35: =IFERROR(__xludf.DUMMYFUNCTION("""COMPUTED_VALUE"""),"SignIn") -> SignIn | D35: =IFERROR(__xludf.DUMMYFUNCTION("""COMPUTED_VALUE"""),"Should be slightly smaller, and the notification panel needs to be visible as per the Figma design. Should be in center") -> Should be slightly smaller, and the notification panel needs to be visible as per the Figma design. Should be in center | E35: =IFERROR(__xludf.DUMMYFUNCTION("""COMPUTED_VALUE"""),"user need to install this app on their device") -> user need to install this app on their device | F35: =IFERROR(__xludf.DUMMYFUNCTION("""COMPUTED_VALUE"""),"1. Open app 2. Select passenger role 3. Goto signin page") -> 1. Open app 2. Select passenger role 3. Goto signin page | G35: =IFERROR(__xludf.DUMMYFUNCTION("""COMPUTED_VALUE"""),"N/A") -> N/A | H35: =IFERROR(__xludf.DUMMYFUNCTION("""COMPUTED_VALUE"""),"Design should match the Figma layout, with the title centered and the notification panel clearly visible.") -> Design should match the Figma layout, with the title centered and the notification panel clearly visible. | I35: =IFERROR(__xludf.DUMMYFUNCTION("""COMPUTED_VALUE"""),"Notification bar is missing, the header section is larger than in Figma, and the title is not centered.") -> Notification bar is missing, the header section is larger than in Figma, and the title is not centered. | J35: =IFERROR(__xludf.DUMMYFUNCTION("""COMPUTED_VALUE"""),"Fail") -> Fail | K35: =IFERROR(__xludf.DUMMYFUNCTION("""COMPUTED_VALUE"""),"Medium") -> Medium | L35: =IFERROR(__xludf.DUMMYFUNCTION("""COMPUTED_VALUE"""),"006.png") -> 006.png | O35: =IFERROR(__xludf.DUMMYFUNCTION("""COMPUTED_VALUE"""),"Front-End") -> Front-End | P35: =IFERROR(__xludf.DUMMYFUNCTION("""COMPUTED_VALUE"""),"changed") -> changed | Q35: =IFERROR(__xludf.DUMMYFUNCTION("""COMPUTED_VALUE"""),"Fahad") -> Fahad
A36: BR-026 | B36: =IFERROR(__xludf.DUMMYFUNCTION("""COMPUTED_VALUE"""),"Passenger") -> Passenger | C36: =IFERROR(__xludf.DUMMYFUNCTION("""COMPUTED_VALUE"""),"SignIn") -> SignIn | D36: =IFERROR(__xludf.DUMMYFUNCTION("""COMPUTED_VALUE"""),"Failed to store data when a user logs in with Google.") -> Failed to store data when a user logs in with Google. | E36: =IFERROR(__xludf.DUMMYFUNCTION("""COMPUTED_VALUE"""),"user need to install this app on their device") -> user need to install this app on their device | F36: =IFERROR(__xludf.DUMMYFUNCTION("""COMPUTED_VALUE"""),"1. Open app 2. Select passenger role 3. Goto signin page") -> 1. Open app 2. Select passenger role 3. Goto signin page | G36: =IFERROR(__xludf.DUMMYFUNCTION("""COMPUTED_VALUE"""),"N/A") -> N/A | H36: =IFERROR(__xludf.DUMMYFUNCTION("""COMPUTED_VALUE"""),"User data should be visible when user signup by google ") -> User data should be visible when user signup by google | I36: =IFERROR(__xludf.DUMMYFUNCTION("""COMPUTED_VALUE"""),"Failed to ") -> Failed to | J36: =IFERROR(__xludf.DUMMYFUNCTION("""COMPUTED_VALUE"""),"Fail") -> Fail | K36: =IFERROR(__xludf.DUMMYFUNCTION("""COMPUTED_VALUE"""),"High") -> High | L36: =IFERROR(__xludf.DUMMYFUNCTION("""COMPUTED_VALUE"""),"015.png") -> 015.png | Q36: =IFERROR(__xludf.DUMMYFUNCTION("""COMPUTED_VALUE"""),"Fahad") -> Fahad
