Workbook

Sheet Test_Plan
C2: Software Test Plan : [Porject Name]
A13: Project Information :
A16: Project Objective :
A19: Project Scope : | D19: In Scope : Out of scope :
A22: Project Scope :
A25: Test Strategy :
A28: Test Type : | D28: Functional : Non-Functional :
A31: Test Type :
A34: Test Enviroment :
A37: Test Data :

Sheet Test_Scenario
D1: Test Scenario
A5: Scenario ID | B5: Requirement ID | C5: Module | D5: Sub-Module | E5: Test Scenario | F5: Test Type | G5: Priority | H5: Precondition | I5: Test Data | J5: Expected Outcome | K5: Remarks

Sheet Test_Case
F1: Test Case
A6: Test Case ID | B6: Test Scenario ID | C6: Requirement ID | D6: Module | E6: Sub-Module | F6: Test Case Title | G6: Test Type | H6: Priority | I6: Preconditions | J6: Test Data | K6: Test Steps | L6: Expected Result | M6: Actual Result | N6: Status | O6: Severity | P6: Environment | Q6: Tester | R6: Evidence | S6: Remarks

Sheet Bug_report
A1: Tester : | B1: Mohammed Fahad Faisal | E1: mom : jvai57574@gmail.com || Password123# dad : teamaithunder@gmail.com || Password123#
A2: Project Name:
A3: Developer:
A4: OS: | B4: Windows 11 Pro Version:24H2 OS build:26100.4946
A5: Environment: | B5: Brave 1.81.135 (Official Build) (64-bit) Chromium: 139.0.7258.127 | N5: Place solve if the issue resolves | \/ | O5: Mention which Stack solved the issue | \/
A7: Test ID | B7: Module | C7: Sub Module | D7: Test Case Description | E7: Preconditions | F7: Test Steps | G7: Test Data | H7: Expected Result | I7: Actual Result | J7: Status | K7: Severity | L7: Screen Shots | M7: Suggestion | N7: Feedback | O7: Stack | P7: Comment
A8: BR_001 | B8: Mother Account | C8: OTP | D8: Failed to receive OTP for account verification | E8: User need to use the app on their mobile device | F8: 1. Open app | G8: MOM user credential | H8: User should be able to receive the OTP without any issues. | I8: Used failed to receive OTP | J8: Fail | K8: High | L8: 001.png
A10: BR_002 | B10: Mother Account | C10: OTP | D10: Toast stays in a constant state. Should be vanish after 3-4 seconds | E10: User need to use the app on their mobile device | F10: 1. Open app 2. Sign up by filling required field 3. Goto OTP page | G10: MOM user credential | H10: Toast error message should only appear for 3-5 seconds | I10: Toast message remains in app unless it was removed | J10: Fail | K10: Medium | L10: 002.png
A12: BR_003 | B12: Mother Account | C12: Subscription | D12: Spell mistake has been noticed | E12: User need to use the app on their mobile device | F12: 1. Open app 2. Sign up by filling required field 3. Goto OTP page 4. Verify OTP and go to next page | G12: MOM user credential | H12: Spell mistake should not be visible | I12: Spelling mistake has been noticed. | J12: Fail | K12: Low | L12: 003.png
A14: BR_004 | B14: Mother Account | C14: Subscription | D14: Yearly rate per month isn’t showing when a user selects the yearly subscription. | E14: User need to use the app on their mobile device | F14: 1. Open app 2. Sign up by filling required field 3. Goto OTP page 4. Verify OTP and go to next page | G14: MOM user credential | H14: Alignment and design should be as same as figma | I14: Alignment issue occurred when the user switched to a yearly subscription. | J14: Fail | K14: Medium | L14: 004.png
A16: BR_005 | B16: Mother Account | C16: Subscription | D16: Goes to the subscription page but then redirects to the website’s home page, where the user isn’t logged in. | E16: User need to use the app on their mobile device | F16: 1. Open app 2. Sign up by filling required field 3. Goto OTP page 4. Verify OTP and go to next page | G16: MOM user credential | H16: User should be redirected to a webpage with their login state intact, and from there, be taken to the subscription page. | I16: User is redirected to the web page in a logged-out state. | J16: Fail | K16: High | L16: 005.mp4
A18: BR_006 | B18: Mother Account | C18: Subscription | D18: Didn’t automatically redirect the user to app after they purchased it. | E18: User need to use the app on their mobile device | F18: 1. Open app 2. Sign up by filling required field 3. Goto OTP page 4. Verify OTP and go to next page | G18: MOM user credential | H18: Should redirect users to app | I18: Unable to redirect the user to the app after completing the subscription purchase. | J18: Fail | K18: Medium | L18: 006.mp4
A20: BR_007 | B20: Mother Account | C20: Subscription | D20: Highlight the discounted price when a user chooses the yearly package instead of the monthly package. | E20: User need to use the app on their mobile device | F20: 1. Open app 2. Login using valid credentials 3. Click on settings 4. Goto subscription | G20: MOM user credential | H20: Highlight the discount percentage for purchasing the yearly package instead of the monthly package. | I20: No discount price has been shown | J20: Fail | K20: Medium | L20: 007.png
A22: BR_008 | B22: Mother Account | C22: Message | D22: No send icon visible, but the image gets sent when clicking on the “crop” option. | E22: User need to use the app on their mobile device | F22: 1. Open app 2. Login using valid credentials 3. Click on message | G22: MOM user credential | H22: Send button should be visible. | I22: Send button is missing but can still send a picture by clicking on the crop option. | J22: Fail | K22: High | L22: 008.mp4
A24: BR_009 | B24: Mother Account | C24: Message | D24: Download chat redirects to the API backend page. | E24: User need to use the app on their mobile device | F24: 1. Open app 2. Login using valid credentials 3. Click on message | G24: MOM user credential | H24: Should be able to download full conversation | I24: Failed to download conversation, redirect to backend api page | J24: Fail | K24: High | L24: 009.mp4
A26: BR_010 | B26: Mother Account | C26: Call | D26: Alignment issue | E26: User need to use the app on their mobile device | F26: 1. Open app 2. Login using valid credentials 3. Click on call | G26: MOM user credential | H26: Design and alignment should be as same as figma | I26: Overlapp issue has been noticed | J26: Fail | K26: Medium | L26: 010.png
A28: BR_011 | B28: Mother Account | C28: Call | D28: Displays co-parent as offline even when no co-parent has been added. | E28: User need to use the app on their mobile device | F28: 1. Open app 2. Login using valid credentials 3. Click on call | G28: MOM user credential | H28: If no co-parent has been added, thanit should now display co-parent offline | I28: Display co-parent is offline where there is no co-parent added | J28: Fail | K28: High | L28: 011.png
A30: BR_012 | B30: Mother Account | C30: Document | D30: No document has been uploaded, yet the document banner is still showing. | E30: User need to use the app on their mobile device | F30: 1. Open app 2. Login using valid credentials 3. Click on Document | G30: MOM user credential | H30: Blank page should be displayed if there is not document | I30: Show document banner when there is not document | J30: Fail | K30: Medium | L30: 012.png
... A114: BR_054 | B114: Backend | C114: Profile | D114: Unable to save Twilio data after setting up a new account. | E114: User need to use the app on their mobile device | F114: 1. Open app 2. Login with valid credentials 3. Goto settings -> profile | G114: MOM user credential | H114: Twilio information should be stored after a user creates an account. | I114: Failed to store users twilio information in backend | J114: Fail | K114: High | L114: 054.png
A116: BR_055
A118: BR_056
A120: BR_057
A122: BR_058
A124: BR_059
A126: BR_060

Sheet Summary Report
A1: Module | B1: Sub Module | C1: Test Case ID | D1: Bug Count | E1: Bug Rate % | F1: Bug Severity
A2: =IFERROR(__xludf.DUMMYFUNCTION("SORT( SPLIT( UNIQUE( FILTER('Main Report'!B11:B100 & ""♦"" & 'Main Report'!C11:C100, LEN('Main Report'!C11:C100)) ), ""♦"" ), 1, TRUE, 2, TRUE ) "),"Backend") -> Backend | B2: =IFERROR(__xludf.DUMMYFUNCTION("""COMPUTED_VALUE"""),"Profile") -> Profile | C2: =IFERROR(__xludf.DUMMYFUNCTION("TEXTJOIN("", "", TRUE, FILTER('Main Report'!A11:A100, ('Main Report'!B11:B100=A2) * ('Main Report'!C11:C100=B2) ) ) "),"BR-001") -> BR-001 | D2: =IFERROR(__xludf.DUMMYFUNCTION("COUNTA(UNIQUE(TRANSPOSE(SPLIT(C2, "", "")))) "),1.0) -> 1 | E2: =IF(D2="", "", TEXT((D2 / 'Main Report'!$E$7), "0.00%")) -> 1.85% | F2: =IFERROR(__xludf.DUMMYFUNCTION("IF(C2="""", """", TEXTJOIN("", "", TRUE, ""High: "" & COUNTIF(FILTER('Main Report'!K11:K100, ISNUMBER(MATCH('Main Report'!A11:A100, SPLIT(C2, "", ""), 0))), ""High"") & CHAR(10) & ""Medium: "" & COUNTIF(FILTER('Main Report'!K11:K100, ISNU"&"MBER(MATCH('Main Report'!A11:A100, SPLIT(C2, "", ""), 0))), ""Medium"") & CHAR(10) & ""Low: "" & COUNTIF(FILTER('Main Report'!K11:K100, ISNUMBER(MATCH('Main Report'!A11:A100, SPLIT(C2, "", ""), 0))), ""Low"") ) ) "),"High: 1 Medium: 0 Low: 0") -> High: 1 Medium: 0 Low: 0
A3: =IFERROR(__xludf.DUMMYFUNCTION("""COMPUTED_VALUE"""),"Backend") -> Backend | B3: =IFERROR(__xludf.DUMMYFUNCTION("""COMPUTED_VALUE"""),"Wallet") -> Wallet | C3: =IFERROR(__xludf.DUMMYFUNCTION("TEXTJOIN("", "", TRUE, FILTER('Main Report'!A12:A101, ('Main Report'!B12:B101=A3) * ('Main Report'!C12:C101=B3) ) ) "),"BR-002") -> BR-002 | D3: =IFERROR(__xludf.DUMMYFUNCTION("COUNTA(UNIQUE(TRANSPOSE(SPLIT(C3, "", "")))) "),1.0) -> 1 | E3: =IF(D3="", "", TEXT((D3 / 'Main Report'!$E$7), "0.00%")) -> 1.85% | F3: =IFERROR(__xludf.DUMMYFUNCTION("IF(C3="""", """", TEXTJOIN("", "", TRUE, ""High: "" & COUNTIF(FILTER('Main Report'!K12:K101, ISNUMBER(MATCH('Main Report'!A12:A101, SPLIT(C3, "", ""), 0))), ""High"") & CHAR(10) & ""Medium: "" & COUNTIF(FILTER('Main Report'!K12:K101, ISNU"&"MBER(MATCH('Main Report'!A12:A101, SPLIT(C3, "", ""), 0))), ""Medium"") & CHAR(10) & ""Low: "" & COUNTIF(FILTER('Main Report'!K12:K101, ISNUMBER(MATCH('Main Report'!A12:A101, SPLIT(C3, "", ""), 0))), ""Low"") ) ) "),"High: 1 Medium: 0 Low: 0") -> High: 1 Medium: 0 Low: 0
A4: =IFERROR(__xludf.DUMMYFUNCTION("""COMPUTED_VALUE"""),"Father Account") -> Father Account | B4: =IFERROR(__xludf.DUMMYFUNCTION("""COMPUTED_VALUE"""),"Bridge Mode") -> Bridge Mode | C4: =IFERROR(__xludf.DUMMYFUNCTION("TEXTJOIN("", "", TRUE, FILTER('Main Report'!A13:A102, ('Main Report'!B13:B102=A4) * ('Main Report'!C13:C102=B4) ) ) "),"BR-003") -> BR-003 | D4: =IFERROR(__xludf.DUMMYFUNCTION("COUNTA(UNIQUE(TRANSPOSE(SPLIT(C4, "", "")))) "),1.0) -> 1 | E4: =IF(D4="", "", TEXT((D4 / 'Main Report'!$E$7), "0.00%")) -> 1.85% | F4: =IFERROR(__xludf.DUMMYFUNCTION("IF(C4="""", """", TEXTJOIN("", "", TRUE, ""High: "" & COUNTIF(FILTER('Main Report'!K13:K102, ISNUMBER(MATCH('Main Report'!A13:A102, SPLIT(C4, "", ""), 0))), ""High"") & CHAR(10) & ""Medium: "" & COUNTIF(FILTER('Main Report'!K13:K102, ISNU"&"MBER(MATCH('Main Report'!A13:A102, SPLIT(C4, "", ""), 0))), ""Medium"") & CHAR(10) & ""Low: "" & COUNTIF(FILTER('Main Report'!K13:K102, ISNUMBER(MATCH('Main Report'!A13:A102, SPLIT(C4, "", ""), 0))), ""Low"") ) ) "),"High: 1 Medium: 0 Low: 0") -> High: 1 Medium: 0 Low: 0
A5: =IFERROR(__xludf.DUMMYFUNCTION("""COMPUTED_VALUE"""),"Father Account") -> Father Account | B5: =IFERROR(__xludf.DUMMYFUNCTION("""COMPUTED_VALUE"""),"Event") -> Event | C5: =IFERROR(__xludf.DUMMYFUNCTION("TEXTJOIN("", "", TRUE, FILTER('Main Report'!A14:A103, ('Main Report'!B14:B103=A5) * ('Main Report'!C14:C103=B5) ) ) "),"BR-004, BR-005, BR-006, BR-007") -> BR-004, BR-005, BR-006, BR-007 | D5: =IFERROR(__xludf.DUMMYFUNCTION("COUNTA(UNIQUE(TRANSPOSE(SPLIT(C5, "", "")))) "),4.0) -> 4 | E5: =IF(D5="", "", TEXT((D5 / 'Main Report'!$E$7), "0.00%")) -> 7.41% | F5: =IFERROR(__xludf.DUMMYFUNCTION("IF(C5="""", """", TEXTJOIN("", "", TRUE, ""High: "" & COUNTIF(FILTER('Main Report'!K14:K103, ISNUMBER(MATCH('Main Report'!A14:A103, SPLIT(C5, "", ""), 0))), ""High"") & CHAR(10) & ""Medium: "" & COUNTIF(FILTER('Main Report'!K14:K103, ISNU"&"MBER(MATCH('Main Report'!A14:A103, SPLIT(C5, "", ""), 0))), ""Medium"") & CHAR(10) & ""Low: "" & COUNTIF(FILTER('Main Report'!K14:K103, ISNUMBER(MATCH('Main Report'!A14:A103, SPLIT(C5, "", ""), 0))), ""Low"") ) ) "),"High: 1 Medium: 3 Low: 0") -> High: 1 Medium: 3 Low: 0
A6: =IFERROR(__xludf.DUMMYFUNCTION("""COMPUTED_VALUE"""),"Father Account") -> Father Account | B6: =IFERROR(__xludf.DUMMYFUNCTION("""COMPUTED_VALUE"""),"Expense") -> Expense | C6: =IFERROR(__xludf.DUMMYFUNCTION("TEXTJOIN("", "", TRUE, FILTER('Main Report'!A15:A104, ('Main Report'!B15:B104=A6) * ('Main Report'!C15:C104=B6) ) ) "),"BR-008, BR-009, BR-010, BR-011, BR-012, BR-013, BR-014, BR-015") -> BR-008, BR-009, BR-010, BR-011, BR-012, BR-013, BR-014, BR-015 | D6: =IFERROR(__xludf.DUMMYFUNCTION("COUNTA(UNIQUE(TRANSPOSE(SPLIT(C6, "", "")))) "),8.0) -> 8 | E6: =IF(D6="", "", TEXT((D6 / 'Main Report'!$E$7), "0.00%")) -> 14.81% | F6: =IFERROR(__xludf.DUMMYFUNCTION("IF(C6="""", """", TEXTJOIN("", "", TRUE, ""High: "" & COUNTIF(FILTER('Main Report'!K15:K104, ISNUMBER(MATCH('Main Report'!A15:A104, SPLIT(C6, "", ""), 0))), ""High"") & CHAR(10) & ""Medium: "" & COUNTIF(FILTER('Main Report'!K15:K104, ISNU"&"MBER(MATCH('Main Report'!A15:A104, SPLIT(C6, "", ""), 0))), ""Medium"") & CHAR(10) & ""Low: "" & COUNTIF(FILTER('Main Report'!K15:K104, ISNUMBER(MATCH('Main Report'!A15:A104, SPLIT(C6, "", ""), 0))), ""Low"") ) ) "),"High: 4 Medium: 3 Low: 1") -> High: 4 Medium: 3 Low: 1
A7: =IFERROR(__xludf.DUMMYFUNCTION("""COMPUTED_VALUE"""),"Father Account") -> Father Account | B7: =IFERROR(__xludf.DUMMYFUNCTION("""COMPUTED_VALUE"""),"Home") -> Home | C7: =IFERROR(__xludf.DUMMYFUNCTION("TEXTJOIN("", "", TRUE, FILTER('Main Report'!A16:A105, ('Main Report'!B16:B105=A7) * ('Main Report'!C16:C105=B7) ) ) "),"BR-016") -> BR-016 | D7: =IFERROR(__xludf.DUMMYFUNCTION("COUNTA(UNIQUE(TRANSPOSE(SPLIT(C7, "", "")))) "),1.0) -> 1 | E7: =IF(D7="", "", TEXT((D7 / 'Main Report'!$E$7), "0.00%")) -> 1.85% | F7: =IFERROR(__xludf.DUMMYFUNCTION("IF(C7="""", """", TEXTJOIN("", "", TRUE, ""High: "" & COUNTIF(FILTER('Main Report'!K16:K105, ISNUMBER(MATCH('Main Report'!A16:A105, SPLIT(C7, "", ""), 0))), ""High"") & CHAR(10) & ""Medium: "" & COUNTIF(FILTER('Main Report'!K16:K105, ISNU"&"MBER(MATCH('Main Report'!A16:A105, SPLIT(C7, "", ""), 0))), ""Medium"") & CHAR(10) & ""Low: "" & COUNTIF(FILTER('Main Report'!K16:K105, ISNUMBER(MATCH('Main Report'!A16:A105, SPLIT(C7, "", ""), 0))), ""Low"") ) ) "),"High: 0 Medium: 1 Low: 0") -> High: 0 Medium: 1 Low: 0
A8: =IFERROR(__xludf.DUMMYFUNCTION("""COMPUTED_VALUE"""),"Father Account") -> Father Account | B8: =IFERROR(__xludf.DUMMYFUNCTION("""COMPUTED_VALUE"""),"Legal Records") -> Legal Records | C8: =IFERROR(__xludf.DUMMYFUNCTION("TEXTJOIN("", "", TRUE, FILTER('Main Report'!A17:A106, ('Main Report'!B17:B106=A8) * ('Main Report'!C17:C106=B8) ) ) "),"BR-017") -> BR-017 | D8: =IFERROR(__xludf.DUMMYFUNCTION("COUNTA(UNIQUE(TRANSPOSE(SPLIT(C8, "", "")))) "),1.0) -> 1 | E8: =IF(D8="", "", TEXT((D8 / 'Main Report'!$E$7), "0.00%")) -> 1.85% | F8: =IFERROR(__xludf.DUMMYFUNCTION("IF(C8="""", """", TEXTJOIN("", "", TRUE, ""High: "" & COUNTIF(FILTER('Main Report'!K17:K106, ISNUMBER(MATCH('Main Report'!A17:A106, SPLIT(C8, "", ""), 0))), ""High"") & CHAR(10) & ""Medium: "" & COUNTIF(FILTER('Main Report'!K17:K106, ISNU"&"MBER(MATCH('Main Report'!A17:A106, SPLIT(C8, "", ""), 0))), ""Medium"") & CHAR(10) & ""Low: "" & COUNTIF(FILTER('Main Report'!K17:K106, ISNUMBER(MATCH('Main Report'!A17:A106, SPLIT(C8, "", ""), 0))), ""Low"") ) ) "),"High: 1 Medium: 0 Low: 0") -> High: 1 Medium: 0 Low: 0
A9: =IFERROR(__xludf.DUMMYFUNCTION("""COMPUTED_VALUE"""),"Father Account") -> Father Account | B9: =IFERROR(__xludf.DUMMYFUNCTION("""COMPUTED_VALUE"""),"Login") -> Login | C9: =IFERROR(__xludf.DUMMYFUNCTION("TEXTJOIN("", "", TRUE, FILTER('Main Report'!A18:A107, ('Main Report'!B18:B107=A9) * ('Main Report'!C18:C107=B9) ) ) "),"BR-018, BR-019") -> BR-018, BR-019 | D9: =IFERROR(__xludf.DUMMYFUNCTION("COUNTA(UNIQUE(TRANSPOSE(SPLIT(C9, "", "")))) "),2.0) -> 2 | E9: =IF(D9="", "", TEXT((D9 / 'Main Report'!$E$7), "0.00%")) -> 3.70% | F9: =IFERROR(__xludf.DUMMYFUNCTION("IF(C9="""", """", TEXTJOIN("", "", TRUE, ""High: "" & COUNTIF(FILTER('Main Report'!K18:K107, ISNUMBER(MATCH('Main Report'!A18:A107, SPLIT(C9, "", ""), 0))), ""High"") & CHAR(10) & ""Medium: "" & COUNTIF(FILTER('Main Report'!K18:K107, ISNU"&"MBER(MATCH('Main Report'!A18:A107, SPLIT(C9, "", ""), 0))), ""Medium"") & CHAR(10) & ""Low: "" & COUNTIF(FILTER('Main Report'!K18:K107, ISNUMBER(MATCH('Main Report'!A18:A107, SPLIT(C9, "", ""), 0))), ""Low"") ) ) "),"High: 2 Medium: 0 Low: 0") -> High: 2 Medium: 0 Low: 0
A10: =IFERROR(__xludf.DUMMYFUNCTION("""COMPUTED_VALUE"""),"Father Account") -> Father Account | B10: =IFERROR(__xludf.DUMMYFUNCTION("""COMPUTED_VALUE"""),"Notification") -> Notification | C10: =IFERROR(__xludf.DUMMYFUNCTION("TEXTJOIN("", "", TRUE, FILTER('Main Report'!A19:A108, ('Main Report'!B19:B108=A10) * ('Main Report'!C19:C108=B10) ) ) "),"BR-020") -> BR-020 | D10: =IFERROR(__xludf.DUMMYFUNCTION("COUNTA(UNIQUE(TRANSPOSE(SPLIT(C10, "", "")))) "),1.0) -> 1 | E10: =IF(D10="", "", TEXT((D10 / 'Main Report'!$E$7), "0.00%")) -> 1.85% | F10: =IFERROR(__xludf.DUMMYFUNCTION("IF(C10="""", """", TEXTJOIN("", "", TRUE, ""High: "" & COUNTIF(FILTER('Main Report'!K19:K108, ISNUMBER(MATCH('Main Report'!A19:A108, SPLIT(C10, "", ""), 0))), ""High"") & CHAR(10) & ""Medium: "" & COUNTIF(FILTER('Main Report'!K19:K108, IS"&"NUMBER(MATCH('Main Report'!A19:A108, SPLIT(C10, "", ""), 0))), ""Medium"") & CHAR(10) & ""Low: "" & COUNTIF(FILTER('Main Report'!K19:K108, ISNUMBER(MATCH('Main Report'!A19:A108, SPLIT(C10, "", ""), 0))), ""Low"") ) ) "),"High: 1 Medium: 0 Low: 0") -> High: 1 Medium: 0 Low: 0
A11: =IFERROR(__xludf.DUMMYFUNCTION("""COMPUTED_VALUE"""),"Father Account") -> Father Account | B11: =IFERROR(__xludf.DUMMYFUNCTION("""COMPUTED_VALUE"""),"Settings -> Choose The App") -> Settings -> Choose The App | C11: =IFERROR(__xludf.DUMMYFUNCTION("TEXTJOIN("", "", TRUE, FILTER('Main Report'!A20:A109, ('Main Report'!B20:B109=A11) * ('Main Report'!C20:C109=B11) ) ) "),"BR-021") -> BR-021 | D11: =IFERROR(__xludf.DUMMYFUNCTION("COUNTA(UNIQUE(TRANSPOSE(SPLIT(C11, "", "")))) "),1.0) -> 1 | E11: =IF(D11="", "", TEXT((D11 / 'Main Report'!$E$7), "0.00%")) -> 1.85% | F11: =IFERROR(__xludf.DUMMYFUNCTION("IF(C11="""", """", TEXTJOIN("", "", TRUE, ""High: "" & COUNTIF(FILTER('Main Report'!K20:K109, ISNUMBER(MATCH('Main Report'!A20:A109, SPLIT(C11, "", ""), 0))), ""High"") & CHAR(10) & ""Medium: "" & COUNTIF(FILTER('Main Report'!K20:K109, IS"&"NUMBER(MATCH('Main Report'!A20:A109, SPLIT(C11, "", ""), 0))), ""Medium"") & CHAR(10) & ""Low: "" & COUNTIF(FILTER('Main Report'!K20:K109, ISNUMBER(MATCH('Main Report'!A20:A109, SPLIT(C11, "", ""), 0))), ""Low"") ) ) "),"High: 1 Medium: 0 Low: 0") -> High: 1 Medium: 0 Low: 0
A12: =IFERROR(__xludf.DUMMYFUNCTION("""COMPUTED_VALUE"""),"Father Account") -> Father Account | B12: =IFERROR(__xludf.DUMMYFUNCTION("""COMPUTED_VALUE"""),"Settings -> Co-Parent information") -> Settings -> Co-Parent information | C12: =IFERROR(__xludf.DUMMYFUNCTION("TEXTJOIN("", "", TRUE, FILTER('Main Report'!A21:A110, ('Main Report'!B21:B110=A12) * ('Main Report'!C21:C110=B12) ) ) "),"BR-022") -> BR-022 | D12: =IFERROR(__xludf.DUMMYFUNCTION("COUNTA(UNIQUE(TRANSPOSE(SPLIT(C12, "", "")))) "),1.0) -> 1 | E12: =IF(D12="", "", TEXT((D12 / 'Main Report'!$E$7), "0.00%")) -> 1.85% | F12: =IFERROR(__xludf.DUMMYFUNCTION("IF(C12="""", """", TEXTJOIN("", "", TRUE, ""High: "" & COUNTIF(FILTER('Main Report'!K21:K110, ISNUMBER(MATCH('Main Report'!A21:A110, SPLIT(C12, "", ""), 0))), ""High"") & CHAR(10) & ""Medium: "" & COUNTIF(FILTER('Main Report'!K21:K110, IS"&"NUMBER(MATCH('Main Report'!A21:A110, SPLIT(C12, "", ""), 0))), ""Medium"") & CHAR(10) & ""Low: "" & COUNTIF(FILTER('Main Report'!K21:K110, ISNUMBER(MATCH('Main Report'!A21:A110, SPLIT(C12, "", ""), 0))), ""Low"") ) ) "),"High: 1 Medium: 0 Low: 0") -> High: 1 Medium: 0 Low: 0
A13: =IFERROR(__xludf.DUMMYFUNCTION("""COMPUTED_VALUE"""),"Father Account") -> Father Account | B13: =IFERROR(__xludf.DUMMYFUNCTION("""COMPUTED_VALUE"""),"Settings -> Help & Support") -> Settings -> Help & Support | C13: =IFERROR(__xludf.DUMMYFUNCTION("TEXTJOIN("", "", TRUE, FILTER('Main Report'!A22:A111, ('Main Report'!B22:B111=A13) * ('Main Report'!C22:C111=B13) ) ) "),"BR-023") -> BR-023 | D13: =IFERROR(__xludf.DUMMYFUNCTION("COUNTA(UNIQUE(TRANSPOSE(SPLIT(C13, "", "")))) "),1.0) -> 1 | E13: =IF(D13="", "", TEXT((D13 / 'Main Report'!$E$7), "0.00%")) -> 1.85% | F13: =IFERROR(__xludf.DUMMYFUNCTION("IF(C13="""", """", TEXTJOIN("", "", TRUE, ""High: "" & COUNTIF(FILTER('Main Report'!K22:K111, ISNUMBER(MATCH('Main Report'!A22:A111, SPLIT(C13, "", ""), 0))), ""High"") & CHAR(10) & ""Medium: "" & COUNTIF(FILTER('Main Report'!K22:K111, IS"&"NUMBER(MATCH('Main Report'!A22:A111, SPLIT(C13, "", ""), 0))), ""Medium"") & CHAR(10) & ""Low: "" & COUNTIF(FILTER('Main Report'!K22:K111, ISNUMBER(MATCH('Main Report'!A22:A111, SPLIT(C13, "", ""), 0))), ""Low"") ) ) "),"High: 0 Medium: 0 Low: 1") -> High: 0 Medium: 0 Low: 1
A14: =IFERROR(__xludf.DUMMYFUNCTION("""COMPUTED_VALUE"""),"Father Account") -> Father Account | B14: =IFERROR(__xludf.DUMMYFUNCTION("""COMPUTED_VALUE"""),"Settings -> Legacy Contact") -> Settings -> Legacy Contact | C14: =IFERROR(__xludf.DUMMYFUNCTION("TEXTJOIN("", "", TRUE, FILTER('Main Report'!A23:A112, ('Main Report'!B23:B112=A14) * ('Main Report'!C23:C112=B14) ) ) "),"BR-024") -> BR-024 | D14: =IFERROR(__xludf.DUMMYFUNCTION("COUNTA(UNIQUE(TRANSPOSE(SPLIT(C14, "", "")))) "),1.0) -> 1 | E14: =IF(D14="", "", TEXT((D14 / 'Main Report'!$E$7), "0.00%")) -> 1.85% | F14: =IFERROR(__xludf.DUMMYFUNCTION("IF(C14="""", """", TEXTJOIN("", "", TRUE, ""High: "" & COUNTIF(FILTER('Main Report'!K23:K112, ISNUMBER(MATCH('Main Report'!A23:A112, SPLIT(C14, "", ""), 0))), ""High"") & CHAR(10) & ""Medium: "" & COUNTIF(FILTER('Main Report'!K23:K112, IS"&"NUMBER(MATCH('Main Report'!A23:A112, SPLIT(C14, "", ""), 0))), ""Medium"") & CHAR(10) & ""Low: "" & COUNTIF(FILTER('Main Report'!K23:K112, ISNUMBER(MATCH('Main Report'!A23:A112, SPLIT(C14, "", ""), 0))), ""Low"") ) ) "),"High: 1 Medium: 0 Low: 0") -> High: 1 Medium: 0 Low: 0
A15: =IFERROR(__xludf.DUMMYFUNCTION("""COMPUTED_VALUE"""),"Father Account") -> Father Account | B15: =IFERROR(__xludf.DUMMYFUNCTION("""COMPUTED_VALUE"""),"Settings -> Subscription") -> Settings -> Subscription | C15: =IFERROR(__xludf.DUMMYFUNCTION("TEXTJOIN("", "", TRUE, FILTER('Main Report'!A24:A113, ('Main Report'!B24:B113=A15) * ('Main Report'!C24:C113=B15) ) ) "),"BR-025") -> BR-025 | D15: =IFERROR(__xludf.DUMMYFUNCTION("COUNTA(UNIQUE(TRANSPOSE(SPLIT(C15, "", "")))) "),1.0) -> 1 | E15: =IF(D15="", "", TEXT((D15 / 'Main Report'!$E$7), "0.00%")) -> 1.85% | F15: =IFERROR(__xludf.DUMMYFUNCTION("IF(C15="""", """", TEXTJOIN("", "", TRUE, ""High: "" & COUNTIF(FILTER('Main Report'!K24:K113, ISNUMBER(MATCH('Main Report'!A24:A113, SPLIT(C15, "", ""), 0))), ""High"") & CHAR(10) & ""Medium: "" & COUNTIF(FILTER('Main Report'!K24:K113, IS"&"NUMBER(MATCH('Main Report'!A24:A113, SPLIT(C15, "", ""), 0))), ""Medium"") & CHAR(10) & ""Low: "" & COUNTIF(FILTER('Main Report'!K24:K113, ISNUMBER(MATCH('Main Report'!A24:A113, SPLIT(C15, "", ""), 0))), ""Low"") ) ) "),"High: 1 Medium: 0 Low: 0") -> High: 1 Medium: 0 Low: 0
A16: =IFERROR(__xludf.DUMMYFUNCTION("""COMPUTED_VALUE"""),"Father Account") -> Father Account | B16: =IFERROR(__xludf.DUMMYFUNCTION("""COMPUTED_VALUE"""),"Support Forum") -> Support Forum | C16: =IFERROR(__xludf.DUMMYFUNCTION("TEXTJOIN("", "", TRUE, FILTER('Main Report'!A25:A114, ('Main Report'!B25:B114=A16) * ('Main Report'!C25:C114=B16) ) ) "),"BR-026, BR-027, BR-028, BR-029, BR-030, BR-031, BR-032, BR-033, BR-034") -> BR-026, BR-027, BR-028, BR-029, BR-030, BR-031, BR-032, BR-033, BR-034 | D16: =IFERROR(__xludf.DUMMYFUNCTION("COUNTA(UNIQUE(TRANSPOSE(SPLIT(C16, "", "")))) "),9.0) -> 9 | E16: =IF(D16="", "", TEXT((D16 / 'Main Report'!$E$7), "0.00%")) -> 16.67% | F16: =IFERROR(__xludf.DUMMYFUNCTION("IF(C16="""", """", TEXTJOIN("", "", TRUE, ""High: "" & COUNTIF(FILTER('Main Report'!K25:K114, ISNUMBER(MATCH('Main Report'!A25:A114, SPLIT(C16, "", ""), 0))), ""High"") & CHAR(10) & ""Medium: "" & COUNTIF(FILTER('Main Report'!K25:K114, IS"&"NUMBER(MATCH('Main Report'!A25:A114, SPLIT(C16, "", ""), 0))), ""Medium"") & CHAR(10) & ""Low: "" & COUNTIF(FILTER('Main Report'!K25:K114, ISNUMBER(MATCH('Main Report'!A25:A114, SPLIT(C16, "", ""), 0))), ""Low"") ) ) "),"High: 3 Medium: 5 Low: 1") -> High: 3 Medium: 5 Low: 1
A17: =IFERROR(__xludf.DUMMYFUNCTION("""COMPUTED_VALUE"""),"Mother Account") -> Mother Account | B17: =IFERROR(__xludf.DUMMYFUNCTION("""COMPUTED_VALUE"""),"Call") -> Call | C17: =IFERROR(__xludf.DUMMYFUNCTION("TEXTJOIN("", "", TRUE, FILTER('Main Report'!A26:A115, ('Main Report'!B26:B115=A17) * ('Main Report'!C26:C115=B17) ) ) "),"BR-035, BR-036") -> BR-035, BR-036 | D17: =IFERROR(__xludf.DUMMYFUNCTION("COUNTA(UNIQUE(TRANSPOSE(SPLIT(C17, "", "")))) "),2.0) -> 2 | E17: =IF(D17="", "", TEXT((D17 / 'Main Report'!$E$7), "0.00%")) -> 3.70% | F17: =IFERROR(__xludf.DUMMYFUNCTION("IF(C17="""", """", TEXTJOIN("", "", TRUE, ""High: "" & COUNTIF(FILTER('Main Report'!K26:K115, ISNUMBER(MATCH('Main Report'!A26:A115, SPLIT(C17, "", ""), 0))), ""High"") & CHAR(10) & ""Medium: "" & COUNTIF(FILTER('Main Report'!K26:K115, IS"&"NUMBER(MATCH('Main Report'!A26:A115, SPLIT(C17, "", ""), 0))), ""Medium"") & CHAR(10) & ""Low: "" & COUNTIF(FILTER('Main Report'!K26:K115, ISNUMBER(MATCH('Main Report'!A26:A115, SPLIT(C17, "", ""), 0))), ""Low"") ) ) "),"High: 1 Medium: 1 Low: 0") -> High: 1 Medium: 1 Low: 0
A18: =IFERROR(__xludf.DUMMYFUNCTION("""COMPUTED_VALUE"""),"Mother Account") -> Mother Account | B18: =IFERROR(__xludf.DUMMYFUNCTION("""COMPUTED_VALUE"""),"Document") -> Document | C18: =IFERROR(__xludf.DUMMYFUNCTION("TEXTJOIN("", "", TRUE, FILTER('Main Report'!A27:A116, ('Main Report'!B27:B116=A18) * ('Main Report'!C27:C116=B18) ) ) "),"BR-037, BR-038, BR-039, BR-040, BR-041, BR-042, BR-043, BR-044") -> BR-037, BR-038, BR-039, BR-040, BR-041, BR-042, BR-043, BR-044 | D18: =IFERROR(__xludf.DUMMYFUNCTION("COUNTA(UNIQUE(TRANSPOSE(SPLIT(C18, "", "")))) "),8.0) -> 8 | E18: =IF(D18="", "", TEXT((D18 / 'Main Report'!$E$7), "0.00%")) -> 14.81% | F18: =IFERROR(__xludf.DUMMYFUNCTION("IF(C18="""", """", TEXTJOIN("", "", TRUE, ""High: "" & COUNTIF(FILTER('Main Report'!K27:K116, ISNUMBER(MATCH('Main Report'!A27:A116, SPLIT(C18, "", ""), 0))), ""High"") & CHAR(10) & ""Medium: "" & COUNTIF(FILTER('Main Report'!K27:K116, IS"&"NUMBER(MATCH('Main Report'!A27:A116, SPLIT(C18, "", ""), 0))), ""Medium"") & CHAR(10) & ""Low: "" & COUNTIF(FILTER('Main Report'!K27:K116, ISNUMBER(MATCH('Main Report'!A27:A116, SPLIT(C18, "", ""), 0))), ""Low"") ) ) "),"High: 4 Medium: 3 Low: 1") -> High: 4 Medium: 3 Low: 1
A19: =IFERROR(__xludf.DUMMYFUNCTION("""COMPUTED_VALUE"""),"Mother Account") -> Mother Account | B19: =IFERROR(__xludf.DUMMYFUNCTION("""COMPUTED_VALUE"""),"Home") -> Home | C19: =IFERROR(__xludf.DUMMYFUNCTION("TEXTJOIN("", "", TRUE, FILTER('Main Report'!A28:A117, ('Main Report'!B28:B117=A19) * ('Main Report'!C28:C117=B19) ) ) "),"BR-045") -> BR-045 | D19: =IFERROR(__xludf.DUMMYFUNCTION("COUNTA(UNIQUE(TRANSPOSE(SPLIT(C19, "", "")))) "),1.0) -> 1 | E19: =IF(D19="", "", TEXT((D19 / 'Main Report'!$E$7), "0.00%")) -> 1.85% | F19: =IFERROR(__xludf.DUMMYFUNCTION("IF(C19="""", """", TEXTJOIN("", "", TRUE, ""High: "" & COUNTIF(FILTER('Main Report'!K28:K117, ISNUMBER(MATCH('Main Report'!A28:A117, SPLIT(C19, "", ""), 0))), ""High"") & CHAR(10) & ""Medium: "" & COUNTIF(FILTER('Main Report'!K28:K117, IS"&"NUMBER(MATCH('Main Report'!A28:A117, SPLIT(C19, "", ""), 0))), ""Medium"") & CHAR(10) & ""Low: "" & COUNTIF(FILTER('Main Report'!K28:K117, ISNUMBER(MATCH('Main Report'!A28:A117, SPLIT(C19, "", ""), 0))), ""Low"") ) ) "),"High: 0 Medium: 1 Low: 0") -> High: 0 Medium: 1 Low: 0
A20: =IFERROR(__xludf.DUMMYFUNCTION("""COMPUTED_VALUE"""),"Mother Account") -> Mother Account | B20: =IFERROR(__xludf.DUMMYFUNCTION("""COMPUTED_VALUE"""),"Message") -> Message | C20: =IFERROR(__xludf.DUMMYFUNCTION("TEXTJOIN("", "", TRUE, FILTER('Main Report'!A29:A118, ('Main Report'!B29:B118=A20) * ('Main Report'!C29:C118=B20) ) ) "),"BR-046, BR-047") -> BR-046, BR-047 | D20: =IFERROR(__xludf.DUMMYFUNCTION("COUNTA(UNIQUE(TRANSPOSE(SPLIT(C20, "", "")))) "),2.0) -> 2 | E20: =IF(D20="", "", TEXT((D20 / 'Main Report'!$E$7), "0.00%")) -> 3.70% | F20: =IFERROR(__xludf.DUMMYFUNCTION("IF(C20="""", """", TEXTJOIN("", "", TRUE, ""High: "" & COUNTIF(FILTER('Main Report'!K29:K118, ISNUMBER(MATCH('Main Report'!A29:A118, SPLIT(C20, "", ""), 0))), ""High"") & CHAR(10) & ""Medium: "" & COUNTIF(FILTER('Main Report'!K29:K118, IS"&"NUMBER(MATCH('Main Report'!A29:A118, SPLIT(C20, "", ""), 0))), ""Medium"") & CHAR(10) & ""Low: "" & COUNTIF(FILTER('Main Report'!K29:K118, ISNUMBER(MATCH('Main Report'!A29:A118, SPLIT(C20, "", ""), 0))), ""Low"") ) ) "),"High: 2 Medium: 0 Low: 0") -> High: 2 Medium: 0 Low: 0
A21: =IFERROR(__xludf.DUMMYFUNCTION("""COMPUTED_VALUE"""),"Mother Account") -> Mother Account | B21: =IFERROR(__xludf.DUMMYFUNCTION("""COMPUTED_VALUE"""),"OTP") -> OTP | C21: =IFERROR(__xludf.DUMMYFUNCTION("TEXTJOIN("", "", TRUE, FILTER('Main Report'!A30:A119, ('Main Report'!B30:B119=A21) * ('Main Report'!C30:C119=B21) ) ) "),"BR-048, BR-049") -> BR-048, BR-049 | E21: =IF(D21="", "", TEXT((D21 / 'Main Report'!$E$7), "0.00%")) | F21: =IFERROR(__xludf.DUMMYFUNCTION("IF(C21="""", """", TEXTJOIN("", "", TRUE, ""High: "" & COUNTIF(FILTER('Main Report'!K30:K119, ISNUMBER(MATCH('Main Report'!A30:A119, SPLIT(C21, "", ""), 0))), ""High"") & CHAR(10) & ""Medium: "" & COUNTIF(FILTER('Main Report'!K30:K119, IS"&"NUMBER(MATCH('Main Report'!A30:A119, SPLIT(C21, "", ""), 0))), ""Medium"") & CHAR(10) & ""Low: "" & COUNTIF(FILTER('Main Report'!K30:K119, ISNUMBER(MATCH('Main Report'!A30:A119, SPLIT(C21, "", ""), 0))), ""Low"") ) ) "),"High: 1 Medium: 1 Low: 0") -> High: 1 Medium: 1 Low: 0
A22: =IFERROR(__xludf.DUMMYFUNCTION("""COMPUTED_VALUE"""),"Mother Account") -> Mother Account | B22: =IFERROR(__xludf.DUMMYFUNCTION("""COMPUTED_VALUE"""),"Subscription") -> Subscription

Sheet Main Report
A2: Tester : | B2: Mohammed Fahad Faisal | D2: Severity | E2: Issues
A3: Project Name: | D3: High | E3: =COUNTIF(Bug_report!K8:K1004, "High") -> 28
A4: Project URL: | D4: Medium | E4: =COUNTIF(Bug_report!K8:K1005, "Medium") -> 21
A5: Developer: | D5: Low | E5: =COUNTIF(Bug_report!K8:K1006, "Low") -> 5
A6: OS:
A7: Environment | D7: Total Test Cases: | E7: =SUM(E3:E5) -> 54
D8: Test Case Solved : | E8: =COUNTIF(N11:N2387, "Solved") -> 0
A10: Test Case ID | B10: Module | C10: Sub Module | D10: Test Case Description | E10: Preconditions | F10: Test Steps | G10: Test Data | H10: Expected Result | I10: Actual Result | J10: Status | K10: Severity | L10: Screen Shots | M10: Suggestion | N10: Feedback | O10: Stack | P10: Comment | Q10: Tester
A11: {=IF((LEN(B11:B100)+LEN(C11:C100))>0, "BR-" & TEXT(ROW(B11:B100)-ROW(B11)+1,"000"), "")} -> BR-001 | B11: =IFERROR(__xludf.DUMMYFUNCTION("QUERY( { ARRAYFORMULA({ TRIM(Bug_report!B8:B2383), Bug_report!C8:P2383, IF(LEN(Bug_report!B8:B2383), ""Fahad"", """") }) }, ""SELECT * WHERE Col1 IS NOT NULL ORDER BY Col1 ASC, Col2 ASC"", 0 )"),"Backend") -> Backend | C11: =IFERROR(__xludf.DUMMYFUNCTION("""COMPUTED_VALUE"""),"Profile") -> Profile | D11: =IFERROR(__xludf.DUMMYFUNCTION("""COMPUTED_VALUE"""),"Unable to save Twilio data after setting up a new account.") -> Unable to save Twilio data after setting up a new account. | E11: =IFERROR(__xludf.DUMMYFUNCTION("""COMPUTED_VALUE"""),"User need to use the app on their mobile device") -> User need to use the app on their mobile device | F11: =IFERROR(__xludf.DUMMYFUNCTION("""COMPUTED_VALUE"""),"1. Open app 2. Login with valid credentials 3. Goto settings -> profile") -> 1. Open app 2. Login with valid credentials 3. Goto settings -> profile | G11: =IFERROR(__xludf.DUMMYFUNCTION("""COMPUTED_VALUE"""),"MOM user credential") -> MOM user credential | H11: =IFERROR(__xludf.DUMMYFUNCTION("""COMPUTED_VALUE"""),"Twilio information should be stored after a user creates an account.") -> Twilio information should be stored after a user creates an account. | I11: =IFERROR(__xludf.DUMMYFUNCTION("""COMPUTED_VALUE"""),"Failed to store users twilio information in backend ") -> Failed to store users twilio information in backend | J11: =IFERROR(__xludf.DUMMYFUNCTION("""COMPUTED_VALUE"""),"Fail") -> Fail | K11: =IFERROR(__xludf.DUMMYFUNCTION("""COMPUTED_VALUE"""),"High") -> High | L11: =IFERROR(__xludf.DUMMYFUNCTION("""COMPUTED_VALUE"""),"054.png") -> 054.png | Q11: =IFERROR(__xludf.DUMMYFUNCTION("""COMPUTED_VALUE"""),"Fahad") -> Fahad
A12: BR-002 | B12: =IFERROR(__xludf.DUMMYFUNCTION("""COMPUTED_VALUE"""),"Backend") -> Backend | C12: =IFERROR(__xludf.DUMMYFUNCTION("""COMPUTED_VALUE"""),"Wallet") -> Wallet | D12: =IFERROR(__xludf.DUMMYFUNCTION("""COMPUTED_VALUE"""),"Unable to redirect the user to the home page after completing a subscription purchase.") -> Unable to redirect the user to the home page after completing a subscription purchase. | E12: =IFERROR(__xludf.DUMMYFUNCTION("""COMPUTED_VALUE"""),"User need to use the app on their mobile device") -> User need to use the app on their mobile device | F12: =IFERROR(__xludf.DUMMYFUNCTION("""COMPUTED_VALUE"""),"1. Open app 2. Login with valid credentials 3. Purchase plan") -> 1. Open app 2. Login with valid credentials 3. Purchase plan | G12: =IFERROR(__xludf.DUMMYFUNCTION("""COMPUTED_VALUE"""),"MOM user credential") -> MOM user credential | H12: =IFERROR(__xludf.DUMMYFUNCTION("""COMPUTED_VALUE"""),"User should redirect to home page after purchasing plan") -> User should redirect to home page after purchasing plan | I12: =IFERROR(__xludf.DUMMYFUNCTION("""COMPUTED_VALUE"""),"Failed to redirect user to home page") -> Failed to redirect user to home page | J12: =IFERROR(__xludf.DUMMYFUNCTION("""COMPUTED_VALUE"""),"Fail") -> Fail | K12: =IFERROR(__xludf.DUMMYFUNCTION("""COMPUTED_VALUE"""),"High") -> High | L12: =IFERROR(__xludf.DUMMYFUNCTION("""COMPUTED_VALUE"""),"053.png") -> 053.png | Q12: =IFERROR(__xludf.DUMMYFUNCTION("""COMPUTED_VALUE"""),"Fahad") -> Fahad
A13: BR-003 | B13: =IFERROR(__xludf.DUMMYFUNCTION("""COMPUTED_VALUE"""),"Father Account") -> Father Account | C13: =IFERROR(__xludf.DUMMYFUNCTION("""COMPUTED_VALUE"""),"Bridge Mode") -> Bridge Mode | D13: =IFERROR(__xludf.DUMMYFUNCTION("""COMPUTED_VALUE"""),"Code validation is not yet implemented in co-parent bridge mode.") -> Code validation is not yet implemented in co-parent bridge mode. | E13: =IFERROR(__xludf.DUMMYFUNCTION("""COMPUTED_VALUE"""),"User need to use the app on their mobile device") -> User need to use the app on their mobile device | F13: =IFERROR(__xludf.DUMMYFUNCTION("""COMPUTED_VALUE"""),"1. Open app 2. Login using valid credentials 3. Enter co-parent code") -> 1. Open app 2. Login using valid credentials 3. Enter co-parent code | G13: =IFERROR(__xludf.DUMMYFUNCTION("""COMPUTED_VALUE"""),"DAD user credential") -> DAD user credential | H13: =IFERROR(__xludf.DUMMYFUNCTION("""COMPUTED_VALUE"""),"Code validation should be implemented ") -> Code validation should be implemented | I13: =IFERROR(__xludf.DUMMYFUNCTION("""COMPUTED_VALUE"""),"Without invitation code validation, user can go to next step") -> Without invitation code validation, user can go to next step | J13: =IFERROR(__xludf.DUMMYFUNCTION("""COMPUTED_VALUE"""),"Fail") -> Fail | K13: =IFERROR(__xludf.DUMMYFUNCTION("""COMPUTED_VALUE"""),"High") -> High | L13: =IFERROR(__xludf.DUMMYFUNCTION("""COMPUTED_VALUE"""),"020.mp4") -> 020.mp4 | Q13: =IFERROR(__xludf.DUMMYFUNCTION("""COMPUTED_VALUE"""),"Fahad") -> Fahad
A14: BR-004 | B14: =IFERROR(__xludf.DUMMYFUNCTION("""COMPUTED_VALUE"""),"Father Account") -> Father Account | C14: =IFERROR(__xludf.DUMMYFUNCTION("""COMPUTED_VALUE"""),"Event") -> Event | D14: =IFERROR(__xludf.DUMMYFUNCTION("""COMPUTED_VALUE"""),"Event scheduled for the entire day.") -> Event scheduled for the entire day. | E14: =IFERROR(__xludf.DUMMYFUNCTION("""COMPUTED_VALUE"""),"User need to use the app on their mobile device") -> User need to use the app on their mobile device | F14: =IFERROR(__xludf.DUMMYFUNCTION("""COMPUTED_VALUE"""),"1. Open app 2. Login with valid credentials 3. Set event in calender") -> 1. Open app 2. Login with valid credentials 3. Set event in calender | G14: =IFERROR(__xludf.DUMMYFUNCTION("""COMPUTED_VALUE"""),"DAD user credential") -> DAD user credential | H14: =IFERROR(__xludf.DUMMYFUNCTION("""COMPUTED_VALUE"""),"Time and date should display properly") -> Time and date should display properly | I14: =IFERROR(__xludf.DUMMYFUNCTION("""COMPUTED_VALUE"""),"Set all day as event time but in playcard it shows blank") -> Set all day as event time but in playcard it shows blank | J14: =IFERROR(__xludf.DUMMYFUNCTION("""COMPUTED_VALUE"""),"Fail") -> Fail | K14: =IFERROR(__xludf.DUMMYFUNCTION("""COMPUTED_VALUE"""),"Medium") -> Medium | L14: =IFERROR(__xludf.DUMMYFUNCTION("""COMPUTED_VALUE"""),"029.png") -> 029.png | Q14: =IFERROR(__xludf.DUMMYFUNCTION("""COMPUTED_VALUE"""),"Fahad") -> Fahad
A15: BR-005 | B15: =IFERROR(__xludf.DUMMYFUNCTION("""COMPUTED_VALUE"""),"Father Account") -> Father Account | C15: =IFERROR(__xludf.DUMMYFUNCTION("""COMPUTED_VALUE"""),"Event") -> Event | D15: =IFERROR(__xludf.DUMMYFUNCTION("""COMPUTED_VALUE"""),"Can set the event to reverse time. Logical error") -> Can set the event to reverse time. Logical error | E15: =IFERROR(__xludf.DUMMYFUNCTION("""COMPUTED_VALUE"""),"User need to use the app on their mobile device") -> User need to use the app on their mobile device | F15: =IFERROR(__xludf.DUMMYFUNCTION("""COMPUTED_VALUE"""),"1. Open app 2. Login with valid credentials 3. Set event in calender") -> 1. Open app 2. Login with valid credentials 3. Set event in calender | G15: =IFERROR(__xludf.DUMMYFUNCTION("""COMPUTED_VALUE"""),"DAD user credential") -> DAD user credential | H15: =IFERROR(__xludf.DUMMYFUNCTION("""COMPUTED_VALUE"""),"start time should be smaller than end time") -> start time should be smaller than end time | I15: =IFERROR(__xludf.DUMMYFUNCTION("""COMPUTED_VALUE"""),"Can set event end time before event start time") -> Can set event end time before event start time | J15: =IFERROR(__xludf.DUMMYFUNCTION("""COMPUTED_VALUE"""),"Fail") -> Fail | K15: =IFERROR(__xludf.DUMMYFUNCTION("""COMPUTED_VALUE"""),"Medium") -> Medium | L15: =IFERROR(__xludf.DUMMYFUNCTION("""COMPUTED_VALUE"""),"030.png") -> 030.png | Q15: =IFERROR(__xludf.DUMMYFUNCTION("""COMPUTED_VALUE"""),"Fahad") -> Fahad
A16: BR-006 | B16: =IFERROR(__xludf.DUMMYFUNCTION("""COMPUTED_VALUE"""),"Father Account") -> Father Account | C16: =IFERROR(__xludf.DUMMYFUNCTION("""COMPUTED_VALUE"""),"Event") -> Event | D16: =IFERROR(__xludf.DUMMYFUNCTION("""COMPUTED_VALUE"""),"Event doesn’t update dynamically when it’s created and the user is logged in.") -> Event doesn’t update dynamically when it’s created and the user is logged in. | E16: =IFERROR(__xludf.DUMMYFUNCTION("""COMPUTED_VALUE"""),"User need to use the app on their mobile device") -> User need to use the app on their mobile device | F16: =IFERROR(__xludf.DUMMYFUNCTION("""COMPUTED_VALUE"""),"1. Open app 2. Login with valid credentials 3. Set event in calender") -> 1. Open app 2. Login with valid credentials 3. Set event in calender | G16: =IFERROR(__xludf.DUMMYFUNCTION("""COMPUTED_VALUE"""),"DAD user credential") -> DAD user credential | H16: =IFERROR(__xludf.DUMMYFUNCTION("""COMPUTED_VALUE"""),"Event should update dynamically with a notification popup.") -> Event should update dynamically with a notification popup. | I16: =IFERROR(__xludf.DUMMYFUNCTION("""COMPUTED_VALUE"""),"No popup is displayed, and the event doesn’t update dynamically.") -> No popup is displayed, and the event doesn’t update dynamically. | J16: =IFERROR(__xludf.DUMMYFUNCTION("""COMPUTED_VALUE"""),"Fail") -> Fail | K16: =IFERROR(__xludf.DUMMYFUNCTION("""COMPUTED_VALUE"""),"High") -> High | L16: =IFERROR(__xludf.DUMMYFUNCTION("""COMPUTED_VALUE"""),"031.png") -> 031.png | Q16: =IFERROR(__xludf.DUMMYFUNCTION("""COMPUTED_VALUE"""),"Fahad") -> Fahad
A17: BR-007 | B17: =IFERROR(__xludf.DUMMYFUNCTION("""COMPUTED_VALUE"""),"Father Account") -> Father Account | C17: =IFERROR(__xludf.DUMMYFUNCTION("""COMPUTED_VALUE"""),"Event") -> Event | D17: =IFERROR(__xludf.DUMMYFUNCTION("""COMPUTED_VALUE"""),"Difference between a real device and an emulator, must be precise") -> Difference between a real device and an emulator, must be precise | E17: =IFERROR(__xludf.DUMMYFUNCTION("""COMPUTED_VALUE"""),"User need to use the app on their mobile device") -> User need to use the app on their mobile device | F17: =IFERROR(__xludf.DUMMYFUNCTION("""COMPUTED_VALUE"""),"1. Open app 2. Login with valid credentials 3. Set event in calender") -> 1. Open app 2. Login with valid credentials 3. Set event in calender | G17: =IFERROR(__xludf.DUMMYFUNCTION("""COMPUTED_VALUE"""),"DAD user credential") -> DAD user credential | H17: =IFERROR(__xludf.DUMMYFUNCTION("""COMPUTED_VALUE"""),"Design should be as same as figma") -> Design should be as same as figma | I17: =IFERROR(__xludf.DUMMYFUNCTION("""COMPUTED_VALUE"""),"Difference in app on button has been noticed") -> Difference in app on button has been noticed | J17: =IFERROR(__xludf.DUMMYFUNCTION("""COMPUTED_VALUE"""),"Fail") -> Fail | K17: =IFERROR(__xludf.DUMMYFUNCTION("""COMPUTED_VALUE"""),"Medium") -> Medium | L17: =IFERROR(__xludf.DUMMYFUNCTION("""COMPUTED_VALUE"""),"032.png") -> 032.png | Q17: =IFERROR(__xludf.DUMMYFUNCTION("""COMPUTED_VALUE"""),"Fahad") -> Fahad
A18: BR-008 | B18: =IFERROR(__xludf.DUMMYFUNCTION("""COMPUTED_VALUE"""),"Father Account") -> Father Account | C18: =IFERROR(__xludf.DUMMYFUNCTION("""COMPUTED_VALUE"""),"Expense") -> Expense | D18: =IFERROR(__xludf.DUMMYFUNCTION("""COMPUTED_VALUE"""),"Failed to close the popup box by clicking on a random spot on the page.") -> Failed to close the popup box by clicking on a random spot on the page. | E18: =IFERROR(__xludf.DUMMYFUNCTION("""COMPUTED_VALUE"""),"User need to use the app on their mobile device") -> User need to use the app on their mobile device | F18: =IFERROR(__xludf.DUMMYFUNCTION("""COMPUTED_VALUE"""),"1. Open app 2. Login with valid credentials 3. Click on expense") -> 1. Open app 2. Login with valid credentials 3. Click on expense | G18: =IFERROR(__xludf.DUMMYFUNCTION("""COMPUTED_VALUE"""),"DAD user credential") -> DAD user credential | H18: =IFERROR(__xludf.DUMMYFUNCTION("""COMPUTED_VALUE"""),"Dialouge box should close when user clicks on random site than dialouge box") -> Dialouge box should close when user clicks on random site than dialouge box | I18: =IFERROR(__xludf.DUMMYFUNCTION("""COMPUTED_VALUE"""),"Failed to close the dialogue box by clicking on random places other than the dialogue box.") -> Failed to close the dialogue box by clicking on random places other than the dialogue box. | J18: =IFERROR(__xludf.DUMMYFUNCTION("""COMPUTED_VALUE"""),"Fail") -> Fail | K18: =IFERROR(__xludf.DUMMYFUNCTION("""COMPUTED_VALUE"""),"Medium") -> Medium | L18: =IFERROR(__xludf.DUMMYFUNCTION("""COMPUTED_VALUE"""),"033.mp4") -> 033.mp4 | Q18: =IFERROR(__xludf.DUMMYFUNCTION("""COMPUTED_VALUE"""),"Fahad") -> Fahad
A19: BR-009 | B19: =IFERROR(__xludf.DUMMYFUNCTION("""COMPUTED_VALUE"""),"Father Account") -> Father Account | C19: =IFERROR(__xludf.DUMMYFUNCTION("""COMPUTED_VALUE"""),"Expense") -> Expense | D19: =IFERROR(__xludf.DUMMYFUNCTION("""COMPUTED_VALUE"""),"Different font style used") -> Different font style used | E19: =IFERROR(__xludf.DUMMYFUNCTION("""COMPUTED_VALUE"""),"User need to use the app on their mobile device") -> User need to use the app on their mobile device | F19: =IFERROR(__xludf.DUMMYFUNCTION("""COMPUTED_VALUE"""),"1. Open app 2. Login with valid credentials 3. Click on expense") -> 1. Open app 2. Login with valid credentials 3. Click on expense | G19: =IFERROR(__xludf.DUMMYFUNCTION("""COMPUTED_VALUE"""),"DAD user credential") -> DAD user credential | H19: =IFERROR(__xludf.DUMMYFUNCTION("""COMPUTED_VALUE"""),"All text font should be same ") -> All text font should be same | I19: =IFERROR(__xludf.DUMMYFUNCTION("""COMPUTED_VALUE"""),"Different font used ") -> Different font used | J19: =IFERROR(__xludf.DUMMYFUNCTION("""COMPUTED_VALUE"""),"Fail") -> Fail | K19: =IFERROR(__xludf.DUMMYFUNCTION("""COMPUTED_VALUE"""),"Low") -> Low | L19: =IFERROR(__xludf.DUMMYFUNCTION("""COMPUTED_VALUE"""),"034.png") -> 034.png | Q19: =IFERROR(__xludf.DUMMYFUNCTION("""COMPUTED_VALUE"""),"Fahad") -> Fahad
A20: BR-010 | B20: =IFERROR(__xludf.DUMMYFUNCTION("""COMPUTED_VALUE"""),"Father Account") -> Father Account | C20: =IFERROR(__xludf.DUMMYFUNCTION("""COMPUTED_VALUE"""),"Expense") -> Expense | D20: =IFERROR(__xludf.DUMMYFUNCTION("""COMPUTED_VALUE"""),"Alignment broke when selecting catagory") -> Alignment broke when selecting catagory | E20: =IFERROR(__xludf.DUMMYFUNCTION("""COMPUTED_VALUE"""),"User need to use the app on their mobile device") -> User need to use the app on their mobile device | F20: =IFERROR(__xludf.DUMMYFUNCTION("""COMPUTED_VALUE"""),"1. Open app 2. Login with valid credentials 3. Click on expense") -> 1. Open app 2. Login with valid credentials 3. Click on expense | G20: =IFERROR(__xludf.DUMMYFUNCTION("""COMPUTED_VALUE"""),"DAD user credential") -> DAD user credential | H20: =IFERROR(__xludf.DUMMYFUNCTION("""COMPUTED_VALUE"""),"Alignment and design should be same ") -> Alignment and design should be same | I20: =IFERROR(__xludf.DUMMYFUNCTION("""COMPUTED_VALUE"""),"Broken alignment has been noticed when selecting catagory") -> Broken alignment has been noticed when selecting catagory | J20: =IFERROR(__xludf.DUMMYFUNCTION("""COMPUTED_VALUE"""),"Fail") -> Fail | K20: =IFERROR(__xludf.DUMMYFUNCTION("""COMPUTED_VALUE"""),"Medium") -> Medium | L20: =IFERROR(__xludf.DUMMYFUNCTION("""COMPUTED_VALUE"""),"035.png") -> 035.png | Q20: =IFERROR(__xludf.DUMMYFUNCTION("""COMPUTED_VALUE"""),"Fahad") -> Fahad
A21: BR-011 | B21: =IFERROR(__xludf.DUMMYFUNCTION("""COMPUTED_VALUE"""),"Father Account") -> Father Account | C21: =IFERROR(__xludf.DUMMYFUNCTION("""COMPUTED_VALUE"""),"Expense") -> Expense | D21: =IFERROR(__xludf.DUMMYFUNCTION("""COMPUTED_VALUE"""),"Flow broken") -> Flow broken | E21: =IFERROR(__xludf.DUMMYFUNCTION("""COMPUTED_VALUE"""),"User need to use the app on their mobile device") -> User need to use the app on their mobile device | F21: =IFERROR(__xludf.DUMMYFUNCTION("""COMPUTED_VALUE"""),"1. Open app 2. Login with valid credentials 3. Click on expense") -> 1. Open app 2. Login with valid credentials 3. Click on expense | G21: =IFERROR(__xludf.DUMMYFUNCTION("""COMPUTED_VALUE"""),"DAD user credential") -> DAD user credential | H21: =IFERROR(__xludf.DUMMYFUNCTION("""COMPUTED_VALUE"""),"There should be a validation process between two parents, where one submits a request and the other has the authority to approve or reject it. Additionally, a double validation should be implemented to verify whether the requested amount has been paid or "&"not.") -> There should be a validation process between two parents, where one submits a request and the other has the authority to approve or reject it. Additionally, a double validation should be implemented to verify whether the requested amount has been paid or not. | I21: =IFERROR(__xludf.DUMMYFUNCTION("""COMPUTED_VALUE"""),"Add expense and manage flow broken") -> Add expense and manage flow broken | J21: =IFERROR(__xludf.DUMMYFUNCTION("""COMPUTED_VALUE"""),"Fail") -> Fail | K21: =IFERROR(__xludf.DUMMYFUNCTION("""COMPUTED_VALUE"""),"High") -> High | L21: =IFERROR(__xludf.DUMMYFUNCTION("""COMPUTED_VALUE"""),"036.png") -> 036.png | Q21: =IFERROR(__xludf.DUMMYFUNCTION("""COMPUTED_VALUE"""),"Fahad") -> Fahad
A22: BR-012 | B22: =IFERROR(__xludf.DUMMYFUNCTION("""COMPUTED_VALUE"""),"Father Account") -> Father Account | C22: =IFERROR(__xludf.DUMMYFUNCTION("""COMPUTED_VALUE"""),"Expense") -> Expense | D22: =IFERROR(__xludf.DUMMYFUNCTION("""COMPUTED_VALUE"""),"All expenses are listed under the ""Paid"" category, but they don’t appear in the ""Approved"" tab.") -> All expenses are listed under the "Paid" category, but they don’t appear in the "Approved" tab. | E22: =IFERROR(__xludf.DUMMYFUNCTION("""COMPUTED_VALUE"""),"User need to use the app on their mobile device") -> User need to use the app on their mobile device | F22: =IFERROR(__xludf.DUMMYFUNCTION("""COMPUTED_VALUE"""),"1. Open app 2. Login with valid credentials 3. Click on expense") -> 1. Open app 2. Login with valid credentials 3. Click on expense | G22: =IFERROR(__xludf.DUMMYFUNCTION("""COMPUTED_VALUE"""),"DAD user credential") -> DAD user credential | H22: =IFERROR(__xludf.DUMMYFUNCTION("""COMPUTED_VALUE"""),"Expenses should be validated on both sides for authenticity.") -> Expenses should be validated on both sides for authenticity. | I22: =IFERROR(__xludf.DUMMYFUNCTION("""COMPUTED_VALUE"""),"Missing approve/reject on co-parent account ") -> Missing approve/reject on co-parent account | J22: =IFERROR(__xludf.DUMMYFUNCTION("""COMPUTED_VALUE"""),"Fail") -> Fail | K22: =IFERROR(__xludf.DUMMYFUNCTION("""COMPUTED_VALUE"""),"High") -> High | L22: =IFERROR(__xludf.DUMMYFUNCTION("""COMPUTED_VALUE"""),"037.mp4") -> 037.mp4 | Q22: =IFERROR(__xludf.DUMMYFUNCTION("""COMPUTED_VALUE"""),"Fahad") -> Fahad
A23: BR-013 | B23: =IFERROR(__xludf.DUMMYFUNCTION("""COMPUTED_VALUE"""),"Father Account") -> Father Account | C23: =IFERROR(__xludf.DUMMYFUNCTION("""COMPUTED_VALUE"""),"Expense") -> Expense | D23: =IFERROR(__xludf.DUMMYFUNCTION("""COMPUTED_VALUE"""),"Expense spent in August but showing in September") -> Expense spent in August but showing in September | E23: =IFERROR(__xludf.DUMMYFUNCTION("""COMPUTED_VALUE"""),"User need to use the app on their mobile device") -> User need to use the app on their mobile device | F23: =IFERROR(__xludf.DUMMYFUNCTION("""COMPUTED_VALUE"""),"1. Open app 2. Login with valid credentials 3. Click on expense") -> 1. Open app 2. Login with valid credentials 3. Click on expense | G23: =IFERROR(__xludf.DUMMYFUNCTION("""COMPUTED_VALUE"""),"DAD user credential") -> DAD user credential | H23: =IFERROR(__xludf.DUMMYFUNCTION("""COMPUTED_VALUE"""),"Expense month should be shown correctly.") -> Expense month should be shown correctly. | I23: =IFERROR(__xludf.DUMMYFUNCTION("""COMPUTED_VALUE"""),"August expenses are showing under the September month.") -> August expenses are showing under the September month. | J23: =IFERROR(__xludf.DUMMYFUNCTION("""COMPUTED_VALUE"""),"Fail") -> Fail | K23: =IFERROR(__xludf.DUMMYFUNCTION("""COMPUTED_VALUE"""),"High") -> High | L23: =IFERROR(__xludf.DUMMYFUNCTION("""COMPUTED_VALUE"""),"038.mp4") -> 038.mp4 | Q23: =IFERROR(__xludf.DUMMYFUNCTION("""COMPUTED_VALUE"""),"Fahad") -> Fahad
A24: BR-014 | B24: =IFERROR(__xludf.DUMMYFUNCTION("""COMPUTED_VALUE"""),"Father Account") -> Father Account | C24: =IFERROR(__xludf.DUMMYFUNCTION("""COMPUTED_VALUE"""),"Expense") -> Expense | D24: =IFERROR(__xludf.DUMMYFUNCTION("""COMPUTED_VALUE"""),"Not all categories are showing in the filter section.") -> Not all categories are showing in the filter section. | E24: =IFERROR(__xludf.DUMMYFUNCTION("""COMPUTED_VALUE"""),"User need to use the app on their mobile device") -> User need to use the app on their mobile device | F24: =IFERROR(__xludf.DUMMYFUNCTION("""COMPUTED_VALUE"""),"1. Open app 2. Login with valid credentials 3. Click on expense") -> 1. Open app 2. Login with valid credentials 3. Click on expense | G24: =IFERROR(__xludf.DUMMYFUNCTION("""COMPUTED_VALUE"""),"DAD user credential") -> DAD user credential | H24: =IFERROR(__xludf.DUMMYFUNCTION("""COMPUTED_VALUE"""),"All categories should be displayed to address the filter issue.") -> All categories should be displayed to address the filter issue. | I24: =IFERROR(__xludf.DUMMYFUNCTION("""COMPUTED_VALUE"""),"Only a limited number of categories are shown for filtering.") -> Only a limited number of categories are shown for filtering. | J24: =IFERROR(__xludf.DUMMYFUNCTION("""COMPUTED_VALUE"""),"Fail") -> Fail | K24: =IFERROR(__xludf.DUMMYFUNCTION("""COMPUTED_VALUE"""),"Medium") -> Medium | L24: =IFERROR(__xludf.DUMMYFUNCTION("""COMPUTED_VALUE"""),"039.png") -> 039.png | Q24: =IFERROR(__xludf.DUMMYFUNCTION("""COMPUTED_VALUE"""),"Fahad") -> Fahad
A25: BR-015 | B25: =IFERROR(__xludf.DUMMYFUNCTION("""COMPUTED_VALUE"""),"Father Account") -> Father Account | C25: =IFERROR(__xludf.DUMMYFUNCTION("""COMPUTED_VALUE"""),"Expense") -> Expense | D25: =IFERROR(__xludf.DUMMYFUNCTION("""COMPUTED_VALUE"""),"Calculation error was found, as the total spend is $170 and each share amounts to $85.") -> Calculation error was found, as the total spend is $170 and each share amounts to $85. | E25: =IFERROR(__xludf.DUMMYFUNCTION("""COMPUTED_VALUE"""),"User need to use the app on their mobile device") -> User need to use the app on their mobile device | F25: =IFERROR(__xludf.DUMMYFUNCTION("""COMPUTED_VALUE"""),"1. Open app 2. Login with valid credentials 3. Click on expense") -> 1. Open app 2. Login with valid credentials 3. Click on expense | G25: =IFERROR(__xludf.DUMMYFUNCTION("""COMPUTED_VALUE"""),"DAD user credential") -> DAD user credential | H25: =IFERROR(__xludf.DUMMYFUNCTION("""COMPUTED_VALUE"""),"Calculation needs to be accurate.") -> Calculation needs to be accurate. | I25: =IFERROR(__xludf.DUMMYFUNCTION("""COMPUTED_VALUE"""),"Calculation error has been noticed") -> Calculation error has been noticed | J25: =IFERROR(__xludf.DUMMYFUNCTION("""COMPUTED_VALUE"""),"Fail") -> Fail | K25: =IFERROR(__xludf.DUMMYFUNCTION("""COMPUTED_VALUE"""),"High") -> High | L25: =IFERROR(__xludf.DUMMYFUNCTION("""COMPUTED_VALUE"""),"040.png") -> 040.png | Q25: =IFERROR(__xludf.DUMMYFUNCTION("""COMPUTED_VALUE"""),"Fahad") -> Fahad
A26: BR-016 | B26: =IFERROR(__xludf.DUMMYFUNCTION("""COMPUTED_VALUE"""),"Father Account") -> Father Account | C26: =IFERROR(__xludf.DUMMYFUNCTION("""COMPUTED_VALUE"""),"Home") -> Home | D26: =IFERROR(__xludf.DUMMYFUNCTION("""COMPUTED_VALUE"""),"Clicking on the profile should redirect the user to their profile page.") -> Clicking on the profile should redirect the user to their profile page. | E26: =IFERROR(__xludf.DUMMYFUNCTION("""COMPUTED_VALUE"""),"User need to use the app on their mobile device") -> User need to use the app on their mobile device | F26: =IFERROR(__xludf.DUMMYFUNCTION("""COMPUTED_VALUE"""),"1. Open app 2. Login with valid credentials 3. Goto Home") -> 1. Open app 2. Login with valid credentials 3. Goto Home | G26: =IFERROR(__xludf.DUMMYFUNCTION("""COMPUTED_VALUE"""),"MOM user credential") -> MOM user credential | H26: =IFERROR(__xludf.DUMMYFUNCTION("""COMPUTED_VALUE"""),"Clicking the profile should take the user straight to their profile page.") -> Clicking the profile should take the user straight to their profile page. | I26: =IFERROR(__xludf.DUMMYFUNCTION("""COMPUTED_VALUE"""),"Clicking on the profile doesn’t redirect to the profile page.") -> Clicking on the profile doesn’t redirect to the profile page. | J26: =IFERROR(__xludf.DUMMYFUNCTION("""COMPUTED_VALUE"""),"Fail") -> Fail | K26: =IFERROR(__xludf.DUMMYFUNCTION("""COMPUTED_VALUE"""),"Medium") -> Medium | L26: =IFERROR(__xludf.DUMMYFUNCTION("""COMPUTED_VALUE"""),"051.png") -> 051.png | Q26: =IFERROR(__xludf.DUMMYFUNCTION("""COMPUTED_VALUE"""),"Fahad") -> Fahad
A27: BR-017 | B27: =IFERROR(__xludf.DUMMYFUNCTION("""COMPUTED_VALUE"""),"Father Account") -> Father Account | C27: =IFERROR(__xludf.DUMMYFUNCTION("""COMPUTED_VALUE"""),"Legal Records") -> Legal Records | D27: =IFERROR(__xludf.DUMMYFUNCTION("""COMPUTED_VALUE"""),"Failed to open legal records. Not working properly.") -> Failed to open legal records. Not working properly. | E27: =IFERROR(__xludf.DUMMYFUNCTION("""COMPUTED_VALUE"""),"User need to use the app on their mobile device") -> User need to use the app on their mobile device | F27: =IFERROR(__xludf.DUMMYFUNCTION("""COMPUTED_VALUE"""),"1. Open app 2. Login with valid credentials 3. Click on Legal Records") -> 1. Open app 2. Login with valid credentials 3. Click on Legal Records | G27: =IFERROR(__xludf.DUMMYFUNCTION("""COMPUTED_VALUE"""),"DAD user credential") -> DAD user credential | H27: =IFERROR(__xludf.DUMMYFUNCTION("""COMPUTED_VALUE"""),"Functions should works properly as expected") -> Functions should works properly as expected | I27: =IFERROR(__xludf.DUMMYFUNCTION("""COMPUTED_VALUE"""),"Function should work as expected") -> Function should work as expected | J27: =IFERROR(__xludf.DUMMYFUNCTION("""COMPUTED_VALUE"""),"Fail") -> Fail | K27: =IFERROR(__xludf.DUMMYFUNCTION("""COMPUTED_VALUE"""),"High") -> High | L27: =IFERROR(__xludf.DUMMYFUNCTION("""COMPUTED_VALUE"""),"050.png") -> 050.png | Q27: =IFERROR(__xludf.DUMMYFUNCTION("""COMPUTED_VALUE"""),"Fahad") -> Fahad
A28: BR-018 | B28: =IFERROR(__xludf.DUMMYFUNCTION("""COMPUTED_VALUE"""),"Father Account") -> Father Account | C28: =IFERROR(__xludf.DUMMYFUNCTION("""COMPUTED_VALUE"""),"Login") -> Login | D28: =IFERROR(__xludf.DUMMYFUNCTION("""COMPUTED_VALUE"""),"Number format should be displayed to match the correct code (country code + number).") -> Number format should be displayed to match the correct code (country code + number). | E28: =IFERROR(__xludf.DUMMYFUNCTION("""COMPUTED_VALUE"""),"User need to use the app on their mobile device") -> User need to use the app on their mobile device | F28: =IFERROR(__xludf.DUMMYFUNCTION("""COMPUTED_VALUE"""),"1. Open app 2. Login using valid credentials") -> 1. Open app 2. Login using valid credentials | G28: =IFERROR(__xludf.DUMMYFUNCTION("""COMPUTED_VALUE"""),"DAD user credential") -> DAD user credential | H28: =IFERROR(__xludf.DUMMYFUNCTION("""COMPUTED_VALUE"""),"Should suggest the number format to match with backend") -> Should suggest the number format to match with backend | I28: =IFERROR(__xludf.DUMMYFUNCTION("""COMPUTED_VALUE"""),"Valid account displays an invalid/unregistered number error when attempting to log in.") -> Valid account displays an invalid/unregistered number error when attempting to log in. | J28: =IFERROR(__xludf.DUMMYFUNCTION("""COMPUTED_VALUE"""),"Fail") -> Fail | K28: =IFERROR(__xludf.DUMMYFUNCTION("""COMPUTED_VALUE"""),"High") -> High | L28: =IFERROR(__xludf.DUMMYFUNCTION("""COMPUTED_VALUE"""),"021.png") -> 021.png | Q28: =IFERROR(__xludf.DUMMYFUNCTION("""COMPUTED_VALUE"""),"Fahad") -> Fahad
A29: BR-019 | B29: =IFERROR(__xludf.DUMMYFUNCTION("""COMPUTED_VALUE"""),"Father Account") -> Father Account | C29: =IFERROR(__xludf.DUMMYFUNCTION("""COMPUTED_VALUE"""),"Login") -> Login | D29: =IFERROR(__xludf.DUMMYFUNCTION("""COMPUTED_VALUE"""),"Failed to sign up using Google.") -> Failed to sign up using Google. | E29: =IFERROR(__xludf.DUMMYFUNCTION("""COMPUTED_VALUE"""),"User need to use the app on their mobile device") -> User need to use the app on their mobile device | F29: =IFERROR(__xludf.DUMMYFUNCTION("""COMPUTED_VALUE"""),"1. Open app 2. Signup using google signup") -> 1. Open app 2. Signup using google signup | G29: =IFERROR(__xludf.DUMMYFUNCTION("""COMPUTED_VALUE"""),"DAD user credential") -> DAD user credential | H29: =IFERROR(__xludf.DUMMYFUNCTION("""COMPUTED_VALUE"""),"User should be able to signup using google signup") -> User should be able to signup using google signup | I29: =IFERROR(__xludf.DUMMYFUNCTION("""COMPUTED_VALUE"""),"faile to signup using google signup") -> faile to signup using google signup | J29: =IFERROR(__xludf.DUMMYFUNCTION("""COMPUTED_VALUE"""),"Fail") -> Fail | K29: =IFERROR(__xludf.DUMMYFUNCTION("""COMPUTED_VALUE"""),"High") -> High | L29: =IFERROR(__xludf.DUMMYFUNCTION("""COMPUTED_VALUE"""),"022.png") -> 022.png | Q29: =IFERROR(__xludf.DUMMYFUNCTION("""COMPUTED_VALUE"""),"Fahad") -> Fahad
