Workbook

Sheet Main Report
A2: Tester : | B2: Mohammed Fahad Faisal | D2: Severity | E2: Issues
A3: Project Name: | B3: HealthDesk AI Web App(rgar6385) - App_Bloom | D3: High | E3: =COUNTIF(Tahsin!K14:K1005, "High") + COUNTIF(Fahad!K8:K1010, "High") -> 32
A4: Project URL: | B4: https://getkyroai.com/ | D4: Medium | E4: =COUNTIF(Tahsin!K14:K1006, "Medium") + COUNTIF(Fahad!K8:K1011, "Medium") -> 6
A5: Developer: | B5: AI Hunter | D5: Low | E5: =COUNTIF(Fahad!K8:K1012, "Low") + COUNTIF(Tahsin!K14:K1009, "Low") -> 1
A6: OS:
A7: Environment | D7: Total Test Cases: | E7: =SUM(E3:E5) -> 39
D8: Test Case Solved : | E8: =COUNTIF(O11:O1003, "Solved") -> 19
A10: Test Case ID | B10: Module | C10: Sub Module | D10: Test Case Description | E10: Preconditions | F10: Test Steps | G10: Test Data | H10: Expected Result | I10: Actual Result | J10: Status | K10: Severity | L10: Screen Shots | M10: Suggestion | N10: Tester | O10: Feedback | P10: Comment | Q10: Stack
A11: {=IF((LEN(B11:B100)+LEN(C11:C100))>0, "BR-" & TEXT(ROW(B11:B100)-ROW(B11)+1,"000"), "")} -> BR-001 | B11: =IFERROR(__xludf.DUMMYFUNCTION("QUERY( { ARRAYFORMULA({TRIM(Fahad!B8:B999), Fahad!C8:M999, IF(LEN(Fahad!B8:B999), ""Fahad"", """")}); ARRAYFORMULA({TRIM(Tahsin!B15:B999), Tahsin!C15:M999, IF(LEN(Tahsin!B15:B999), ""Tahsin"", """")}) }, ""SELECT * WHERE Col1 IS NOT NULL ORD"&"ER BY Col1 ASC, Col2 ASC"", 0 ) "),"AI Chat") -> AI Chat | C11: =IFERROR(__xludf.DUMMYFUNCTION("""COMPUTED_VALUE"""),"AI Chat") -> AI Chat | D11: =IFERROR(__xludf.DUMMYFUNCTION("""COMPUTED_VALUE"""),"Failed to summarize data from Image") -> Failed to summarize data from Image | E11: =IFERROR(__xludf.DUMMYFUNCTION("""COMPUTED_VALUE"""),"User need to access this web app through browser") -> User need to access this web app through browser | F11: =IFERROR(__xludf.DUMMYFUNCTION("""COMPUTED_VALUE"""),"1. Open link 2. Login with Admin Credentials 3. Click on AI Assistant") -> 1. Open link 2. Login with Admin Credentials 3. Click on AI Assistant | G11: =IFERROR(__xludf.DUMMYFUNCTION("""COMPUTED_VALUE"""),"Admin Credentials") -> Admin Credentials | H11: =IFERROR(__xludf.DUMMYFUNCTION("""COMPUTED_VALUE"""),"AI should response properly by image, pdf, docs and xls") -> AI should response properly by image, pdf, docs and xls | I11: =IFERROR(__xludf.DUMMYFUNCTION("""COMPUTED_VALUE"""),"Failed to summarize data by image ") -> Failed to summarize data by image | J11: =IFERROR(__xludf.DUMMYFUNCTION("""COMPUTED_VALUE"""),"Fail") -> Fail | K11: =IFERROR(__xludf.DUMMYFUNCTION("""COMPUTED_VALUE"""),"High") -> High | N11: =IFERROR(__xludf.DUMMYFUNCTION("""COMPUTED_VALUE"""),"Fahad") -> Fahad | O11: Solved | P11: Working:- But some time take time for response come from Ai:- Reza | Q11: AI
A12: BR-002 | B12: =IFERROR(__xludf.DUMMYFUNCTION("""COMPUTED_VALUE"""),"AI Chat") -> AI Chat | C12: =IFERROR(__xludf.DUMMYFUNCTION("""COMPUTED_VALUE"""),"AI Chat") -> AI Chat | D12: =IFERROR(__xludf.DUMMYFUNCTION("""COMPUTED_VALUE"""),"Show irrelevant information in the AI's response") -> Show irrelevant information in the AI's response | E12: =IFERROR(__xludf.DUMMYFUNCTION("""COMPUTED_VALUE"""),"User need to access this web app through browser") -> User need to access this web app through browser | F12: =IFERROR(__xludf.DUMMYFUNCTION("""COMPUTED_VALUE"""),"1. Open link 2. Login with Admin Credentials 3. Click on AI Assistant") -> 1. Open link 2. Login with Admin Credentials 3. Click on AI Assistant | G12: =IFERROR(__xludf.DUMMYFUNCTION("""COMPUTED_VALUE"""),"Admin Credentials") -> Admin Credentials | H12: =IFERROR(__xludf.DUMMYFUNCTION("""COMPUTED_VALUE"""),"AI should only response data which are connected on Medical matters") -> AI should only response data which are connected on Medical matters | I12: =IFERROR(__xludf.DUMMYFUNCTION("""COMPUTED_VALUE"""),"AI response shows dev name like (who create you ? I was created by Khairul) (which company developed you ? Developed by MySoft Heaven BD)") -> AI response shows dev name like (who create you ? I was created by Khairul) (which company developed you ? Developed by MySoft Heaven BD) | J12: =IFERROR(__xludf.DUMMYFUNCTION("""COMPUTED_VALUE"""),"Fail") -> Fail | K12: =IFERROR(__xludf.DUMMYFUNCTION("""COMPUTED_VALUE"""),"High") -> High | L12: =IFERROR(__xludf.DUMMYFUNCTION("""COMPUTED_VALUE"""),"https://jam.dev/c/fecf6ef5-fc42-4eda-b3ac-2b10fe8762f4 https://jam.dev/c/4c4c00d9-71bc-4b0a-a7b0-c141749ae460") -> https://jam.dev/c/fecf6ef5-fc42-4eda-b3ac-2b10fe8762f4 https://jam.dev/c/4c4c00d9-71bc-4b0a-a7b0-c141749ae460 | N12: =IFERROR(__xludf.DUMMYFUNCTION("""COMPUTED_VALUE"""),"Fahad") -> Fahad | O12: Solved | Q12: AI
A13: BR-003 | B13: =IFERROR(__xludf.DUMMYFUNCTION("""COMPUTED_VALUE"""),"AI Training") -> AI Training | C13: =IFERROR(__xludf.DUMMYFUNCTION("""COMPUTED_VALUE"""),"AI Training") -> AI Training | D13: =IFERROR(__xludf.DUMMYFUNCTION("""COMPUTED_VALUE"""),"Failed to provide an adequate response from the last training.") -> Failed to provide an adequate response from the last training. | E13: =IFERROR(__xludf.DUMMYFUNCTION("""COMPUTED_VALUE"""),"User need to access this web app through browser") -> User need to access this web app through browser | F13: =IFERROR(__xludf.DUMMYFUNCTION("""COMPUTED_VALUE"""),"1. Open link 2. Login with Admin Credentials 3. Click on AI Training") -> 1. Open link 2. Login with Admin Credentials 3. Click on AI Training | G13: =IFERROR(__xludf.DUMMYFUNCTION("""COMPUTED_VALUE"""),"President Credentials") -> President Credentials | H13: =IFERROR(__xludf.DUMMYFUNCTION("""COMPUTED_VALUE"""),"AI should capture the context from previous updates or training files to respond to the user more quickly.") -> AI should capture the context from previous updates or training files to respond to the user more quickly. | I13: =IFERROR(__xludf.DUMMYFUNCTION("""COMPUTED_VALUE"""),"Failed to respond to the previous message-based request.") -> Failed to respond to the previous message-based request. | J13: =IFERROR(__xludf.DUMMYFUNCTION("""COMPUTED_VALUE"""),"Fail") -> Fail | K13: =IFERROR(__xludf.DUMMYFUNCTION("""COMPUTED_VALUE"""),"High") -> High | L13: =IFERROR(__xludf.DUMMYFUNCTION("""COMPUTED_VALUE"""),"https://jam.dev/c/1af5c1a4-5d0f-4fab-b23a-dfd79868b6c4") -> https://jam.dev/c/1af5c1a4-5d0f-4fab-b23a-dfd79868b6c4 | N13: =IFERROR(__xludf.DUMMYFUNCTION("""COMPUTED_VALUE"""),"Fahad") -> Fahad | O13: Unsolved | Q13: AI
A14: BR-004 | B14: =IFERROR(__xludf.DUMMYFUNCTION("""COMPUTED_VALUE"""),"AI Training") -> AI Training | C14: =IFERROR(__xludf.DUMMYFUNCTION("""COMPUTED_VALUE"""),"View Docs") -> View Docs | D14: =IFERROR(__xludf.DUMMYFUNCTION("""COMPUTED_VALUE"""),"Failed to train AI by Image") -> Failed to train AI by Image | E14: =IFERROR(__xludf.DUMMYFUNCTION("""COMPUTED_VALUE"""),"User need to access this web app through browser") -> User need to access this web app through browser | F14: =IFERROR(__xludf.DUMMYFUNCTION("""COMPUTED_VALUE"""),"1. Open link 2. Login with Admin Credentials 3. Click on AI Training") -> 1. Open link 2. Login with Admin Credentials 3. Click on AI Training | G14: =IFERROR(__xludf.DUMMYFUNCTION("""COMPUTED_VALUE"""),"Admin Credentials") -> Admin Credentials | H14: =IFERROR(__xludf.DUMMYFUNCTION("""COMPUTED_VALUE"""),"As per as requirement, user should be able to train AI by images, pdf, doc, xls") -> As per as requirement, user should be able to train AI by images, pdf, doc, xls | I14: =IFERROR(__xludf.DUMMYFUNCTION("""COMPUTED_VALUE"""),"Failed to train AI by image") -> Failed to train AI by image | J14: =IFERROR(__xludf.DUMMYFUNCTION("""COMPUTED_VALUE"""),"Fail") -> Fail | K14: =IFERROR(__xludf.DUMMYFUNCTION("""COMPUTED_VALUE"""),"High") -> High | N14: =IFERROR(__xludf.DUMMYFUNCTION("""COMPUTED_VALUE"""),"Fahad") -> Fahad | O14: Solved
A15: BR-005 | B15: =IFERROR(__xludf.DUMMYFUNCTION("""COMPUTED_VALUE"""),"Clinicwise Chat") -> Clinicwise Chat | C15: =IFERROR(__xludf.DUMMYFUNCTION("""COMPUTED_VALUE"""),"Chats") -> Chats | D15: =IFERROR(__xludf.DUMMYFUNCTION("""COMPUTED_VALUE"""),"Chats are not displaying as clinicwise") -> Chats are not displaying as clinicwise | E15: =IFERROR(__xludf.DUMMYFUNCTION("""COMPUTED_VALUE"""),"User need to access this web app through browser") -> User need to access this web app through browser | F15: =IFERROR(__xludf.DUMMYFUNCTION("""COMPUTED_VALUE"""),"1. Open link 2. Login with Admin Credentials 3. Click on Clinicwise Chat") -> 1. Open link 2. Login with Admin Credentials 3. Click on Clinicwise Chat | G15: =IFERROR(__xludf.DUMMYFUNCTION("""COMPUTED_VALUE"""),"Admin Credentials") -> Admin Credentials | H15: =IFERROR(__xludf.DUMMYFUNCTION("""COMPUTED_VALUE"""),"Chats should be displayed as clinicwise") -> Chats should be displayed as clinicwise | I15: =IFERROR(__xludf.DUMMYFUNCTION("""COMPUTED_VALUE"""),"Failed to display chat as clinicwise") -> Failed to display chat as clinicwise | J15: =IFERROR(__xludf.DUMMYFUNCTION("""COMPUTED_VALUE"""),"Fail") -> Fail | K15: =IFERROR(__xludf.DUMMYFUNCTION("""COMPUTED_VALUE"""),"Low") -> Low | L15: =IFERROR(__xludf.DUMMYFUNCTION("""COMPUTED_VALUE"""),"https://jam.dev/c/5b228c92-e271-4c88-9432-71effc8f1d9e") -> https://jam.dev/c/5b228c92-e271-4c88-9432-71effc8f1d9e | N15: =IFERROR(__xludf.DUMMYFUNCTION("""COMPUTED_VALUE"""),"Fahad") -> Fahad | O15: Solved | P15: As per as client req
A16: BR-006 | B16: =IFERROR(__xludf.DUMMYFUNCTION("""COMPUTED_VALUE"""),"Communication") -> Communication | C16: =IFERROR(__xludf.DUMMYFUNCTION("""COMPUTED_VALUE"""),"AI Chat") -> AI Chat | D16: =IFERROR(__xludf.DUMMYFUNCTION("""COMPUTED_VALUE"""),"Like on response dosen't store but dislike store") -> Like on response dosen't store but dislike store | E16: =IFERROR(__xludf.DUMMYFUNCTION("""COMPUTED_VALUE"""),"User need to access this web app through browser") -> User need to access this web app through browser | F16: =IFERROR(__xludf.DUMMYFUNCTION("""COMPUTED_VALUE"""),"1. Open link 2. Login with President Credentials 3. Click on Communication 4. Click on AI chat") -> 1. Open link 2. Login with President Credentials 3. Click on Communication 4. Click on AI chat | G16: =IFERROR(__xludf.DUMMYFUNCTION("""COMPUTED_VALUE"""),"President Credential") -> President Credential | H16: =IFERROR(__xludf.DUMMYFUNCTION("""COMPUTED_VALUE"""),"Both Like or Dislike should be store in chat") -> Both Like or Dislike should be store in chat | I16: =IFERROR(__xludf.DUMMYFUNCTION("""COMPUTED_VALUE"""),"Only dislike store in chat, not like") -> Only dislike store in chat, not like | J16: =IFERROR(__xludf.DUMMYFUNCTION("""COMPUTED_VALUE"""),"Fail") -> Fail | K16: =IFERROR(__xludf.DUMMYFUNCTION("""COMPUTED_VALUE"""),"High") -> High | L16: =IFERROR(__xludf.DUMMYFUNCTION("""COMPUTED_VALUE"""),"https://jam.dev/c/c6437440-a8f3-4a89-87d5-973a60b7548f") -> https://jam.dev/c/c6437440-a8f3-4a89-87d5-973a60b7548f | N16: =IFERROR(__xludf.DUMMYFUNCTION("""COMPUTED_VALUE"""),"Fahad") -> Fahad | O16: Solved | P16: Like is solved | Q16: Backend
A17: BR-007 | B17: =IFERROR(__xludf.DUMMYFUNCTION("""COMPUTED_VALUE"""),"Communication") -> Communication | C17: =IFERROR(__xludf.DUMMYFUNCTION("""COMPUTED_VALUE"""),"Communication") -> Communication | D17: =IFERROR(__xludf.DUMMYFUNCTION("""COMPUTED_VALUE"""),"President profile picture is set as manager profile picture in chat") -> President profile picture is set as manager profile picture in chat | E17: =IFERROR(__xludf.DUMMYFUNCTION("""COMPUTED_VALUE"""),"User need to access this web app through browser") -> User need to access this web app through browser | F17: =IFERROR(__xludf.DUMMYFUNCTION("""COMPUTED_VALUE"""),"1. Open link 2. Login with Manager Credentials 3. Click on Chat") -> 1. Open link 2. Login with Manager Credentials 3. Click on Chat | G17: =IFERROR(__xludf.DUMMYFUNCTION("""COMPUTED_VALUE"""),"Manager Credentials") -> Manager Credentials | H17: =IFERROR(__xludf.DUMMYFUNCTION("""COMPUTED_VALUE"""),"user profile picture should be same in different platforms") -> user profile picture should be same in different platforms | I17: =IFERROR(__xludf.DUMMYFUNCTION("""COMPUTED_VALUE"""),"Different profile picture / conflited profile picture has been seen ") -> Different profile picture / conflited profile picture has been seen | J17: =IFERROR(__xludf.DUMMYFUNCTION("""COMPUTED_VALUE"""),"Fail") -> Fail | K17: =IFERROR(__xludf.DUMMYFUNCTION("""COMPUTED_VALUE"""),"Medium") -> Medium | L17: =IFERROR(__xludf.DUMMYFUNCTION("""COMPUTED_VALUE"""),"https://jam.dev/c/dc389bb1-f3df-42cd-b66c-ab6beca49611") -> https://jam.dev/c/dc389bb1-f3df-42cd-b66c-ab6beca49611 | N17: =IFERROR(__xludf.DUMMYFUNCTION("""COMPUTED_VALUE"""),"Fahad") -> Fahad | O17: Solved | P17: By Reza
A18: BR-008 | B18: =IFERROR(__xludf.DUMMYFUNCTION("""COMPUTED_VALUE"""),"Communication") -> Communication | C18: =IFERROR(__xludf.DUMMYFUNCTION("""COMPUTED_VALUE"""),"Communication") -> Communication | D18: =IFERROR(__xludf.DUMMYFUNCTION("""COMPUTED_VALUE"""),"User name is not dynamically update in group") -> User name is not dynamically update in group | E18: =IFERROR(__xludf.DUMMYFUNCTION("""COMPUTED_VALUE"""),"User need to access this web app through browser") -> User need to access this web app through browser | F18: =IFERROR(__xludf.DUMMYFUNCTION("""COMPUTED_VALUE"""),"1. Open link 2. Login with Manager Credentials 3. Click on Chat") -> 1. Open link 2. Login with Manager Credentials 3. Click on Chat | G18: =IFERROR(__xludf.DUMMYFUNCTION("""COMPUTED_VALUE"""),"Manager Credentials") -> Manager Credentials | H18: =IFERROR(__xludf.DUMMYFUNCTION("""COMPUTED_VALUE"""),"User name should be dynamically update in every group after it changes") -> User name should be dynamically update in every group after it changes | I18: =IFERROR(__xludf.DUMMYFUNCTION("""COMPUTED_VALUE"""),"Failed to show upated username in groups") -> Failed to show upated username in groups | J18: =IFERROR(__xludf.DUMMYFUNCTION("""COMPUTED_VALUE"""),"Fail") -> Fail | K18: =IFERROR(__xludf.DUMMYFUNCTION("""COMPUTED_VALUE"""),"High") -> High | L18: =IFERROR(__xludf.DUMMYFUNCTION("""COMPUTED_VALUE"""),"https://jam.dev/c/aec539c7-5efa-4816-92bc-9904efd640d6") -> https://jam.dev/c/aec539c7-5efa-4816-92bc-9904efd640d6 | N18: =IFERROR(__xludf.DUMMYFUNCTION("""COMPUTED_VALUE"""),"Fahad") -> Fahad | O18: Solved | P18: by Reza
A19: BR-009 | B19: =IFERROR(__xludf.DUMMYFUNCTION("""COMPUTED_VALUE"""),"Communication") -> Communication | C19: =IFERROR(__xludf.DUMMYFUNCTION("""COMPUTED_VALUE"""),"Communication") -> Communication | D19: =IFERROR(__xludf.DUMMYFUNCTION("""COMPUTED_VALUE"""),"Manager was removed automatically from group chat after updating their username") -> Manager was removed automatically from group chat after updating their username | E19: =IFERROR(__xludf.DUMMYFUNCTION("""COMPUTED_VALUE"""),"User need to access this web app through browser") -> User need to access this web app through browser | F19: =IFERROR(__xludf.DUMMYFUNCTION("""COMPUTED_VALUE"""),"1. Open link 2. Login with Manager Credentials 3. Click on Chat") -> 1. Open link 2. Login with Manager Credentials 3. Click on Chat | G19: =IFERROR(__xludf.DUMMYFUNCTION("""COMPUTED_VALUE"""),"Manager Credentials") -> Manager Credentials | H19: =IFERROR(__xludf.DUMMYFUNCTION("""COMPUTED_VALUE"""),"User should remain in group till higher autthority remove them from group") -> User should remain in group till higher autthority remove them from group | I19: =IFERROR(__xludf.DUMMYFUNCTION("""COMPUTED_VALUE"""),"User get remove automatically after changing their user name") -> User get remove automatically after changing their user name | J19: =IFERROR(__xludf.DUMMYFUNCTION("""COMPUTED_VALUE"""),"Fail") -> Fail | K19: =IFERROR(__xludf.DUMMYFUNCTION("""COMPUTED_VALUE"""),"High") -> High | L19: =IFERROR(__xludf.DUMMYFUNCTION("""COMPUTED_VALUE"""),"https://jam.dev/c/4e3e5c1c-0465-4cac-9b99-8f8cd9397648") -> https://jam.dev/c/4e3e5c1c-0465-4cac-9b99-8f8cd9397648 | N19: =IFERROR(__xludf.DUMMYFUNCTION("""COMPUTED_VALUE"""),"Fahad") -> Fahad | P19: Skip,Not present in Ui , also user can see the members list while click on Block member.Now if we display the member list another tab then another feature work will be come, like when click on the user create new message room
A20: BR-010 | B20: =IFERROR(__xludf.DUMMYFUNCTION("""COMPUTED_VALUE"""),"Communication") -> Communication | C20: =IFERROR(__xludf.DUMMYFUNCTION("""COMPUTED_VALUE"""),"Communication") -> Communication | D20: =IFERROR(__xludf.DUMMYFUNCTION("""COMPUTED_VALUE"""),"Automatically removes manager from group for deactive and reactive") -> Automatically removes manager from group for deactive and reactive | E20: =IFERROR(__xludf.DUMMYFUNCTION("""COMPUTED_VALUE"""),"User need to access this web app through browser") -> User need to access this web app through browser | F20: =IFERROR(__xludf.DUMMYFUNCTION("""COMPUTED_VALUE"""),"1. Open link 2. Login with Manager Credentials 3. Click on Chat") -> 1. Open link 2. Login with Manager Credentials 3. Click on Chat | G20: =IFERROR(__xludf.DUMMYFUNCTION("""COMPUTED_VALUE"""),"Manager Credentials") -> Manager Credentials | H20: =IFERROR(__xludf.DUMMYFUNCTION("""COMPUTED_VALUE"""),"User should remain in group till higher autthority remove them from group") -> User should remain in group till higher autthority remove them from group | I20: =IFERROR(__xludf.DUMMYFUNCTION("""COMPUTED_VALUE"""),"User get remove automatically after changing their user name") -> User get remove automatically after changing their user name | J20: =IFERROR(__xludf.DUMMYFUNCTION("""COMPUTED_VALUE"""),"Fail") -> Fail | K20: =IFERROR(__xludf.DUMMYFUNCTION("""COMPUTED_VALUE"""),"High") -> High | L20: =IFERROR(__xludf.DUMMYFUNCTION("""COMPUTED_VALUE"""),"https://jam.dev/c/f58fc153-873d-493b-ab77-3229f95067ae") -> https://jam.dev/c/f58fc153-873d-493b-ab77-3229f95067ae | N20: =IFERROR(__xludf.DUMMYFUNCTION("""COMPUTED_VALUE"""),"Fahad") -> Fahad | O20: Unsolved | P20: by Reza
A21: BR-011 | B21: =IFERROR(__xludf.DUMMYFUNCTION("""COMPUTED_VALUE"""),"Communication") -> Communication | C21: =IFERROR(__xludf.DUMMYFUNCTION("""COMPUTED_VALUE"""),"Communication") -> Communication | D21: =IFERROR(__xludf.DUMMYFUNCTION("""COMPUTED_VALUE"""),"Mobile responsiveness failed in communication") -> Mobile responsiveness failed in communication | E21: =IFERROR(__xludf.DUMMYFUNCTION("""COMPUTED_VALUE"""),"User need to access this web app through browser") -> User need to access this web app through browser | F21: =IFERROR(__xludf.DUMMYFUNCTION("""COMPUTED_VALUE"""),"1. Open link 2. Login with Manager Credentials 3. Click on Chat") -> 1. Open link 2. Login with Manager Credentials 3. Click on Chat | G21: =IFERROR(__xludf.DUMMYFUNCTION("""COMPUTED_VALUE"""),"Manager Credentials") -> Manager Credentials | H21: =IFERROR(__xludf.DUMMYFUNCTION("""COMPUTED_VALUE"""),"The interface should appear clean and seamless to the user.") -> The interface should appear clean and seamless to the user. | I21: =IFERROR(__xludf.DUMMYFUNCTION("""COMPUTED_VALUE"""),"The user interface in the communication section is malfunctioning on mobile devices.") -> The user interface in the communication section is malfunctioning on mobile devices. | J21: =IFERROR(__xludf.DUMMYFUNCTION("""COMPUTED_VALUE"""),"Fail") -> Fail | K21: =IFERROR(__xludf.DUMMYFUNCTION("""COMPUTED_VALUE"""),"High") -> High | L21: =IFERROR(__xludf.DUMMYFUNCTION("""COMPUTED_VALUE"""),"https://jam.dev/c/e7836ef5-4134-4470-95cb-079673316d19") -> https://jam.dev/c/e7836ef5-4134-4470-95cb-079673316d19 | N21: =IFERROR(__xludf.DUMMYFUNCTION("""COMPUTED_VALUE"""),"Fahad") -> Fahad | O21: Unsolved | P21: by- reza
A22: BR-012 | B22: =IFERROR(__xludf.DUMMYFUNCTION("""COMPUTED_VALUE"""),"Communication") -> Communication | C22: =IFERROR(__xludf.DUMMYFUNCTION("""COMPUTED_VALUE"""),"Communication") -> Communication | D22: =IFERROR(__xludf.DUMMYFUNCTION("""COMPUTED_VALUE"""),"The system was unable to respond as expected in different device screen") -> The system was unable to respond as expected in different device screen | E22: =IFERROR(__xludf.DUMMYFUNCTION("""COMPUTED_VALUE"""),"User need to access this web app through browser") -> User need to access this web app through browser | F22: =IFERROR(__xludf.DUMMYFUNCTION("""COMPUTED_VALUE"""),"1. Open link 2. Login with Manager Credentials 3. Click on Chat") -> 1. Open link 2. Login with Manager Credentials 3. Click on Chat | G22: =IFERROR(__xludf.DUMMYFUNCTION("""COMPUTED_VALUE"""),"Manager Credentials") -> Manager Credentials | H22: =IFERROR(__xludf.DUMMYFUNCTION("""COMPUTED_VALUE"""),"The interface should appear clean and seamless to the user.") -> The interface should appear clean and seamless to the user. | I22: =IFERROR(__xludf.DUMMYFUNCTION("""COMPUTED_VALUE"""),"The user interface in the communication section is malfunctioning on mobile devices.") -> The user interface in the communication section is malfunctioning on mobile devices. | J22: =IFERROR(__xludf.DUMMYFUNCTION("""COMPUTED_VALUE"""),"Fail") -> Fail | K22: =IFERROR(__xludf.DUMMYFUNCTION("""COMPUTED_VALUE"""),"High") -> High | L22: =IFERROR(__xludf.DUMMYFUNCTION("""COMPUTED_VALUE"""),"https://jam.dev/c/a5e294ce-6790-45f5-9d44-6b1262c66023") -> https://jam.dev/c/a5e294ce-6790-45f5-9d44-6b1262c66023 | N22: =IFERROR(__xludf.DUMMYFUNCTION("""COMPUTED_VALUE"""),"Fahad") -> Fahad | O22: Solved | Q22: .......
A23: BR-013 | B23: =IFERROR(__xludf.DUMMYFUNCTION("""COMPUTED_VALUE"""),"Communication") -> Communication | C23: =IFERROR(__xludf.DUMMYFUNCTION("""COMPUTED_VALUE"""),"Communication") -> Communication | D23: =IFERROR(__xludf.DUMMYFUNCTION("""COMPUTED_VALUE"""),"The notification bar ought to be positioned on the right side.") -> The notification bar ought to be positioned on the right side. | E23: =IFERROR(__xludf.DUMMYFUNCTION("""COMPUTED_VALUE"""),"User need to access this web app through browser") -> User need to access this web app through browser | F23: =IFERROR(__xludf.DUMMYFUNCTION("""COMPUTED_VALUE"""),"1. Open link 2. Login with Manager Credentials 3. Click on Chat") -> 1. Open link 2. Login with Manager Credentials 3. Click on Chat | G23: =IFERROR(__xludf.DUMMYFUNCTION("""COMPUTED_VALUE"""),"Manager Credentials") -> Manager Credentials | H23: =IFERROR(__xludf.DUMMYFUNCTION("""COMPUTED_VALUE"""),"The interface should appear clean and seamless to the user.") -> The interface should appear clean and seamless to the user. | I23: =IFERROR(__xludf.DUMMYFUNCTION("""COMPUTED_VALUE"""),"The user interface in the communication section is malfunctioning on mobile devices.") -> The user interface in the communication section is malfunctioning on mobile devices. | J23: =IFERROR(__xludf.DUMMYFUNCTION("""COMPUTED_VALUE"""),"Fail") -> Fail | K23: =IFERROR(__xludf.DUMMYFUNCTION("""COMPUTED_VALUE"""),"High") -> High | L23: =IFERROR(__xludf.DUMMYFUNCTION("""COMPUTED_VALUE"""),"https://jam.dev/c/fa09cf59-3308-4993-aca6-ddd17b45f8ba") -> https://jam.dev/c/fa09cf59-3308-4993-aca6-ddd17b45f8ba | N23: =IFERROR(__xludf.DUMMYFUNCTION("""COMPUTED_VALUE"""),"Fahad") -> Fahad | O23: Unsolved | P23: by reza
A24: BR-014 | B24: =IFERROR(__xludf.DUMMYFUNCTION("""COMPUTED_VALUE"""),"Communication") -> Communication | C24: =IFERROR(__xludf.DUMMYFUNCTION("""COMPUTED_VALUE"""),"Communication") -> Communication | D24: =IFERROR(__xludf.DUMMYFUNCTION("""COMPUTED_VALUE"""),"The user profile picture should be aligned to the right.") -> The user profile picture should be aligned to the right. | E24: =IFERROR(__xludf.DUMMYFUNCTION("""COMPUTED_VALUE"""),"User need to access this web app through browser") -> User need to access this web app through browser | F24: =IFERROR(__xludf.DUMMYFUNCTION("""COMPUTED_VALUE"""),"1. Open link 2. Login with Manager Credentials 3. Click on Chat") -> 1. Open link 2. Login with Manager Credentials 3. Click on Chat | G24: =IFERROR(__xludf.DUMMYFUNCTION("""COMPUTED_VALUE"""),"Manager Credentials") -> Manager Credentials | H24: =IFERROR(__xludf.DUMMYFUNCTION("""COMPUTED_VALUE"""),"The interface should appear clean and seamless to the user.") -> The interface should appear clean and seamless to the user. | I24: =IFERROR(__xludf.DUMMYFUNCTION("""COMPUTED_VALUE"""),"The user interface in the communication section is malfunctioning on mobile devices.") -> The user interface in the communication section is malfunctioning on mobile devices. | J24: =IFERROR(__xludf.DUMMYFUNCTION("""COMPUTED_VALUE"""),"Fail") -> Fail | K24: =IFERROR(__xludf.DUMMYFUNCTION("""COMPUTED_VALUE"""),"High") -> High | L24: =IFERROR(__xludf.DUMMYFUNCTION("""COMPUTED_VALUE"""),"https://jam.dev/c/32971bba-796d-4d5c-9a87-3a5eb634fc23") -> https://jam.dev/c/32971bba-796d-4d5c-9a87-3a5eb634fc23 | N24: =IFERROR(__xludf.DUMMYFUNCTION("""COMPUTED_VALUE"""),"Fahad") -> Fahad | O24: Unsolved | P24: This was the Client requirements:- reza
A25: BR-015 | B25: =IFERROR(__xludf.DUMMYFUNCTION("""COMPUTED_VALUE"""),"Communication") -> Communication | C25: =IFERROR(__xludf.DUMMYFUNCTION("""COMPUTED_VALUE"""),"Communication") -> Communication | D25: =IFERROR(__xludf.DUMMYFUNCTION("""COMPUTED_VALUE"""),"The request for the header information was unsuccessful.") -> The request for the header information was unsuccessful. | E25: =IFERROR(__xludf.DUMMYFUNCTION("""COMPUTED_VALUE"""),"User need to access this web app through browser") -> User need to access this web app through browser | F25: =IFERROR(__xludf.DUMMYFUNCTION("""COMPUTED_VALUE"""),"1. Open link 2. Login with Manager Credentials 3. Click on Chat") -> 1. Open link 2. Login with Manager Credentials 3. Click on Chat | G25: =IFERROR(__xludf.DUMMYFUNCTION("""COMPUTED_VALUE"""),"Manager Credentials") -> Manager Credentials | H25: =IFERROR(__xludf.DUMMYFUNCTION("""COMPUTED_VALUE"""),"The interface should appear clean and seamless to the user.") -> The interface should appear clean and seamless to the user. | I25: =IFERROR(__xludf.DUMMYFUNCTION("""COMPUTED_VALUE"""),"The user interface in the communication section is malfunctioning on mobile devices.") -> The user interface in the communication section is malfunctioning on mobile devices. | J25: =IFERROR(__xludf.DUMMYFUNCTION("""COMPUTED_VALUE"""),"Fail") -> Fail | K25: =IFERROR(__xludf.DUMMYFUNCTION("""COMPUTED_VALUE"""),"High") -> High | L25: =IFERROR(__xludf.DUMMYFUNCTION("""COMPUTED_VALUE"""),"https://jam.dev/c/4c79164f-e825-4284-bdcc-cac54a9ed931") -> https://jam.dev/c/4c79164f-e825-4284-bdcc-cac54a9ed931 | N25: =IFERROR(__xludf.DUMMYFUNCTION("""COMPUTED_VALUE"""),"Fahad") -> Fahad | O25: Unsolved | P25: by Reza
A26: BR-016 | B26: =IFERROR(__xludf.DUMMYFUNCTION("""COMPUTED_VALUE"""),"Communication") -> Communication | C26: =IFERROR(__xludf.DUMMYFUNCTION("""COMPUTED_VALUE"""),"Group Chat") -> Group Chat | D26: =IFERROR(__xludf.DUMMYFUNCTION("""COMPUTED_VALUE"""),"User name need to be displayed in the group chat for better user experience") -> User name need to be displayed in the group chat for better user experience | E26: =IFERROR(__xludf.DUMMYFUNCTION("""COMPUTED_VALUE"""),"User need to access this web app through browser") -> User need to access this web app through browser | F26: =IFERROR(__xludf.DUMMYFUNCTION("""COMPUTED_VALUE"""),"1. Open link 2. Login with Admin Credentials 3. Click on communication") -> 1. Open link 2. Login with Admin Credentials 3. Click on communication | G26: =IFERROR(__xludf.DUMMYFUNCTION("""COMPUTED_VALUE"""),"Admin Credentials") -> Admin Credentials | H26: =IFERROR(__xludf.DUMMYFUNCTION("""COMPUTED_VALUE"""),"User name need to be displayed in the group chat for better user engagement") -> User name need to be displayed in the group chat for better user engagement | I26: =IFERROR(__xludf.DUMMYFUNCTION("""COMPUTED_VALUE"""),"The username isn’t shown in the group chat, it’s hard to tell who sent the message.") -> The username isn’t shown in the group chat, it’s hard to tell who sent the message. | J26: =IFERROR(__xludf.DUMMYFUNCTION("""COMPUTED_VALUE"""),"Fail") -> Fail | K26: =IFERROR(__xludf.DUMMYFUNCTION("""COMPUTED_VALUE"""),"High") -> High | L26: =IFERROR(__xludf.DUMMYFUNCTION("""COMPUTED_VALUE"""),"https://jam.dev/c/606bcc70-9c47-4c54-9953-051b4bc39d60") -> https://jam.dev/c/606bcc70-9c47-4c54-9953-051b4bc39d60 | N26: =IFERROR(__xludf.DUMMYFUNCTION("""COMPUTED_VALUE"""),"Fahad") -> Fahad | O26: Unsolved | P26: by Reza
A27: BR-017 | B27: =IFERROR(__xludf.DUMMYFUNCTION("""COMPUTED_VALUE"""),"Communication") -> Communication | C27: =IFERROR(__xludf.DUMMYFUNCTION("""COMPUTED_VALUE"""),"Group Chat") -> Group Chat | D27: =IFERROR(__xludf.DUMMYFUNCTION("""COMPUTED_VALUE"""),"The group image doesn’t update dynamically.") -> The group image doesn’t update dynamically. | E27: =IFERROR(__xludf.DUMMYFUNCTION("""COMPUTED_VALUE"""),"User need to access this web app through browser") -> User need to access this web app through browser | F27: =IFERROR(__xludf.DUMMYFUNCTION("""COMPUTED_VALUE"""),"1. Open link 2. Login with Admin Credentials 3. Click on communication") -> 1. Open link 2. Login with Admin Credentials 3. Click on communication | G27: =IFERROR(__xludf.DUMMYFUNCTION("""COMPUTED_VALUE"""),"Admin Credentials") -> Admin Credentials | H27: =IFERROR(__xludf.DUMMYFUNCTION("""COMPUTED_VALUE"""),"The group image should be dynamically updated.") -> The group image should be dynamically updated. | I27: =IFERROR(__xludf.DUMMYFUNCTION("""COMPUTED_VALUE"""),"Unable to update the group image dynamically.") -> Unable to update the group image dynamically. | J27: =IFERROR(__xludf.DUMMYFUNCTION("""COMPUTED_VALUE"""),"Fail") -> Fail | K27: =IFERROR(__xludf.DUMMYFUNCTION("""COMPUTED_VALUE"""),"Medium") -> Medium | L27: =IFERROR(__xludf.DUMMYFUNCTION("""COMPUTED_VALUE"""),"https://jam.dev/c/58e41e2c-fd94-4d47-a548-31011fbbd2df") -> https://jam.dev/c/58e41e2c-fd94-4d47-a548-31011fbbd2df | N27: =IFERROR(__xludf.DUMMYFUNCTION("""COMPUTED_VALUE"""),"Fahad") -> Fahad | O27: Solved | P27: by reza
A28: BR-018 | B28: =IFERROR(__xludf.DUMMYFUNCTION("""COMPUTED_VALUE"""),"Communication") -> Communication | C28: =IFERROR(__xludf.DUMMYFUNCTION("""COMPUTED_VALUE"""),"Group Chat") -> Group Chat | D28: =IFERROR(__xludf.DUMMYFUNCTION("""COMPUTED_VALUE"""),"Group member list is missing in communication") -> Group member list is missing in communication | E28: =IFERROR(__xludf.DUMMYFUNCTION("""COMPUTED_VALUE"""),"User need to access this web app through browser") -> User need to access this web app through browser | F28: =IFERROR(__xludf.DUMMYFUNCTION("""COMPUTED_VALUE"""),"1. Open link 2. Login with Admin Credentials 3. Click on communication") -> 1. Open link 2. Login with Admin Credentials 3. Click on communication | G28: =IFERROR(__xludf.DUMMYFUNCTION("""COMPUTED_VALUE"""),"Admin Credentials") -> Admin Credentials | H28: =IFERROR(__xludf.DUMMYFUNCTION("""COMPUTED_VALUE"""),"In group details, member list should be displayed for better user experience") -> In group details, member list should be displayed for better user experience | I28: =IFERROR(__xludf.DUMMYFUNCTION("""COMPUTED_VALUE"""),"Group member list missing in group details") -> Group member list missing in group details | J28: =IFERROR(__xludf.DUMMYFUNCTION("""COMPUTED_VALUE"""),"Fail") -> Fail | K28: =IFERROR(__xludf.DUMMYFUNCTION("""COMPUTED_VALUE"""),"High") -> High | L28: =IFERROR(__xludf.DUMMYFUNCTION("""COMPUTED_VALUE"""),"https://jam.dev/c/b50b656c-a6e9-499e-8ec2-25c60607c463") -> https://jam.dev/c/b50b656c-a6e9-499e-8ec2-25c60607c463 | N28: =IFERROR(__xludf.DUMMYFUNCTION("""COMPUTED_VALUE"""),"Fahad") -> Fahad | O28: Unsolved | P28: by reza
A29: BR-019 | B29: =IFERROR(__xludf.DUMMYFUNCTION("""COMPUTED_VALUE"""),"Communication") -> Communication | C29: =IFERROR(__xludf.DUMMYFUNCTION("""COMPUTED_VALUE"""),"Group Chat") -> Group Chat | D29: =IFERROR(__xludf.DUMMYFUNCTION("""COMPUTED_VALUE"""),"Group action bar remains in each chat/group until it clicked") -> Group action bar remains in each chat/group until it clicked | E29: =IFERROR(__xludf.DUMMYFUNCTION("""COMPUTED_VALUE"""),"User need to access this web app through browser") -> User need to access this web app through browser | F29: =IFERROR(__xludf.DUMMYFUNCTION("""COMPUTED_VALUE"""),"1. Open link 2. Login with Admin Credentials 3. Click on communication") -> 1. Open link 2. Login with Admin Credentials 3. Click on communication | G29: =IFERROR(__xludf.DUMMYFUNCTION("""COMPUTED_VALUE"""),"Admin Credentials") -> Admin Credentials | H29: =IFERROR(__xludf.DUMMYFUNCTION("""COMPUTED_VALUE"""),"The action bar should appear when the icon is clicked and hide when the user switches to another chat.") -> The action bar should appear when the icon is clicked and hide when the user switches to another chat. | I29: =IFERROR(__xludf.DUMMYFUNCTION("""COMPUTED_VALUE"""),"The action bar stays in place even when the user switches chats.") -> The action bar stays in place even when the user switches chats. | J29: =IFERROR(__xludf.DUMMYFUNCTION("""COMPUTED_VALUE"""),"Fail") -> Fail | K29: =IFERROR(__xludf.DUMMYFUNCTION("""COMPUTED_VALUE"""),"Medium") -> Medium | L29: =IFERROR(__xludf.DUMMYFUNCTION("""COMPUTED_VALUE"""),"https://jam.dev/c/b9782c46-0840-46e6-80a6-d7dfdb0bf638") -> https://jam.dev/c/b9782c46-0840-46e6-80a6-d7dfdb0bf638 | N29: =IFERROR(__xludf.DUMMYFUNCTION("""COMPUTED_VALUE"""),"Fahad") -> Fahad | O29: Solved | P29: by reza
A30: BR-020 | B30: =IFERROR(__xludf.DUMMYFUNCTION("""COMPUTED_VALUE"""),"Dashboard") -> Dashboard | C30: =IFERROR(__xludf.DUMMYFUNCTION("""COMPUTED_VALUE"""),"Dashboard") -> Dashboard | D30: =IFERROR(__xludf.DUMMYFUNCTION("""COMPUTED_VALUE"""),"Cache is not remove when user logout") -> Cache is not remove when user logout | E30: =IFERROR(__xludf.DUMMYFUNCTION("""COMPUTED_VALUE"""),"User need to access this web app through browser") -> User need to access this web app through browser | F30: =IFERROR(__xludf.DUMMYFUNCTION("""COMPUTED_VALUE"""),"1. Open link 2. Login with President Credentials") -> 1. Open link 2. Login with President Credentials | G30: =IFERROR(__xludf.DUMMYFUNCTION("""COMPUTED_VALUE"""),"President Credential") -> President Credential | H30: =IFERROR(__xludf.DUMMYFUNCTION("""COMPUTED_VALUE"""),"Cache should remove after user logout") -> Cache should remove after user logout | I30: =IFERROR(__xludf.DUMMYFUNCTION("""COMPUTED_VALUE"""),"Still holds cache memory after user logout") -> Still holds cache memory after user logout | J30: =IFERROR(__xludf.DUMMYFUNCTION("""COMPUTED_VALUE"""),"Fail") -> Fail | K30: =IFERROR(__xludf.DUMMYFUNCTION("""COMPUTED_VALUE"""),"High") -> High | L30: =IFERROR(__xludf.DUMMYFUNCTION("""COMPUTED_VALUE"""),"https://jam.dev/c/e3d0f827-d799-451f-9e28-baa52b074e88") -> https://jam.dev/c/e3d0f827-d799-451f-9e28-baa52b074e88 | N30: =IFERROR(__xludf.DUMMYFUNCTION("""COMPUTED_VALUE"""),"Fahad") -> Fahad | O30: Solved
A31: BR-021 | B31: =IFERROR(__xludf.DUMMYFUNCTION("""COMPUTED_VALUE"""),"Dashboard") -> Dashboard | C31: =IFERROR(__xludf.DUMMYFUNCTION("""COMPUTED_VALUE"""),"Dashboard") -> Dashboard | D31: =IFERROR(__xludf.DUMMYFUNCTION("""COMPUTED_VALUE"""),"The dashboard isn’t updating in real time.") -> The dashboard isn’t updating in real time. | E31: =IFERROR(__xludf.DUMMYFUNCTION("""COMPUTED_VALUE"""),"User need to access this web app through browser") -> User need to access this web app through browser | F31: =IFERROR(__xludf.DUMMYFUNCTION("""COMPUTED_VALUE"""),"1. Open link 2. Login with President Credentials") -> 1. Open link 2. Login with President Credentials | G31: =IFERROR(__xludf.DUMMYFUNCTION("""COMPUTED_VALUE"""),"President Credential") -> President Credential | H31: =IFERROR(__xludf.DUMMYFUNCTION("""COMPUTED_VALUE"""),"Dashboard should be updated in real time") -> Dashboard should be updated in real time | I31: =IFERROR(__xludf.DUMMYFUNCTION("""COMPUTED_VALUE"""),"The dashboard isn’t updating in real time.") -> The dashboard isn’t updating in real time. | J31: =IFERROR(__xludf.DUMMYFUNCTION("""COMPUTED_VALUE"""),"Fail") -> Fail | K31: =IFERROR(__xludf.DUMMYFUNCTION("""COMPUTED_VALUE"""),"High") -> High | L31: =IFERROR(__xludf.DUMMYFUNCTION("""COMPUTED_VALUE"""),"https://jam.dev/c/e5a1ddc2-6959-414f-84b4-cd44982cf075") -> https://jam.dev/c/e5a1ddc2-6959-414f-84b4-cd44982cf075 | N31: =IFERROR(__xludf.DUMMYFUNCTION("""COMPUTED_VALUE"""),"Fahad") -> Fahad | O31: Solved | Q31: Backend
A32: BR-022 | B32: =IFERROR(__xludf.DUMMYFUNCTION("""COMPUTED_VALUE"""),"Dashboard") -> Dashboard | C32: =IFERROR(__xludf.DUMMYFUNCTION("""COMPUTED_VALUE"""),"Dashboard") -> Dashboard | D32: =IFERROR(__xludf.DUMMYFUNCTION("""COMPUTED_VALUE"""),"Clicking on Manage Clinic redirects to the login page.") -> Clicking on Manage Clinic redirects to the login page. | E32: =IFERROR(__xludf.DUMMYFUNCTION("""COMPUTED_VALUE"""),"User need to access this web app through browser") -> User need to access this web app through browser | F32: =IFERROR(__xludf.DUMMYFUNCTION("""COMPUTED_VALUE"""),"1. Open link 2. Login with President Credentials") -> 1. Open link 2. Login with President Credentials | G32: =IFERROR(__xludf.DUMMYFUNCTION("""COMPUTED_VALUE"""),"President Credential") -> President Credential | H32: =IFERROR(__xludf.DUMMYFUNCTION("""COMPUTED_VALUE"""),"Click on Manage Clinic should redirect user to Assigned Clinic") -> Click on Manage Clinic should redirect user to Assigned Clinic | I32: =IFERROR(__xludf.DUMMYFUNCTION("""COMPUTED_VALUE"""),"Redirect to Login page when user click on Manage clinic") -> Redirect to Login page when user click on Manage clinic | J32: =IFERROR(__xludf.DUMMYFUNCTION("""COMPUTED_VALUE"""),"Fail") -> Fail | K32: =IFERROR(__xludf.DUMMYFUNCTION("""COMPUTED_VALUE"""),"High") -> High | L32: =IFERROR(__xludf.DUMMYFUNCTION("""COMPUTED_VALUE"""),"https://jam.dev/c/508b63f7-8e56-4211-85be-1e4cd5afad9f") -> https://jam.dev/c/508b63f7-8e56-4211-85be-1e4cd5afad9f | N32: =IFERROR(__xludf.DUMMYFUNCTION("""COMPUTED_VALUE"""),"Fahad") -> Fahad | O32: Unsolved | Q32: backend check this
A33: BR-023 | B33: =IFERROR(__xludf.DUMMYFUNCTION("""COMPUTED_VALUE"""),"Login") -> Login | C33: =IFERROR(__xludf.DUMMYFUNCTION("""COMPUTED_VALUE"""),"Login") -> Login | D33: =IFERROR(__xludf.DUMMYFUNCTION("""COMPUTED_VALUE"""),"Forget Password or password reset action button missing in login page") -> Forget Password or password reset action button missing in login page | E33: =IFERROR(__xludf.DUMMYFUNCTION("""COMPUTED_VALUE"""),"User need to access this web app through browser") -> User need to access this web app through browser | F33: =IFERROR(__xludf.DUMMYFUNCTION("""COMPUTED_VALUE"""),"1. Open link") -> 1. Open link | G33: =IFERROR(__xludf.DUMMYFUNCTION("""COMPUTED_VALUE"""),"N/A") -> N/A | H33: =IFERROR(__xludf.DUMMYFUNCTION("""COMPUTED_VALUE"""),"Password reset / Forget Password option should be visible in the login page") -> Password reset / Forget Password option should be visible in the login page | I33: =IFERROR(__xludf.DUMMYFUNCTION("""COMPUTED_VALUE"""),"No password reset option has been implemented, if need to change, need to do it manually") -> No password reset option has been implemented, if need to change, need to do it manually | J33: =IFERROR(__xludf.DUMMYFUNCTION("""COMPUTED_VALUE"""),"Fail") -> Fail | K33: =IFERROR(__xludf.DUMMYFUNCTION("""COMPUTED_VALUE"""),"High") -> High | L33: =IFERROR(__xludf.DUMMYFUNCTION("""COMPUTED_VALUE"""),"https://jam.dev/c/67d6f6db-0260-4396-b48b-59593fc6f09b") -> https://jam.dev/c/67d6f6db-0260-4396-b48b-59593fc6f09b | N33: =IFERROR(__xludf.DUMMYFUNCTION("""COMPUTED_VALUE"""),"Fahad") -> Fahad | P33: U need give unique user id bucause no duplication id used in db client giv it manually | Q33: Backend Reply this.
A34: BR-024 | B34: =IFERROR(__xludf.DUMMYFUNCTION("""COMPUTED_VALUE"""),"Manage Clinic") -> Manage Clinic | C34: =IFERROR(__xludf.DUMMYFUNCTION("""COMPUTED_VALUE"""),"Add Clinic") -> Add Clinic | D34: =IFERROR(__xludf.DUMMYFUNCTION("""COMPUTED_VALUE"""),"The field required indicator hasn’t been implemented in the frontend.") -> The field required indicator hasn’t been implemented in the frontend. | E34: =IFERROR(__xludf.DUMMYFUNCTION("""COMPUTED_VALUE"""),"User need to access this web app through browser") -> User need to access this web app through browser | F34: =IFERROR(__xludf.DUMMYFUNCTION("""COMPUTED_VALUE"""),"1. Open link 2. Login with Admin Credentials 3. Click on Manage Clinic") -> 1. Open link 2. Login with Admin Credentials 3. Click on Manage Clinic | G34: =IFERROR(__xludf.DUMMYFUNCTION("""COMPUTED_VALUE"""),"Admin Credentials") -> Admin Credentials | H34: =IFERROR(__xludf.DUMMYFUNCTION("""COMPUTED_VALUE"""),"Adding a required field indicator in the frontend can greatly enhance the user experience.") -> Adding a required field indicator in the frontend can greatly enhance the user experience. | I34: =IFERROR(__xludf.DUMMYFUNCTION("""COMPUTED_VALUE"""),"Missing required indicator ") -> Missing required indicator | J34: =IFERROR(__xludf.DUMMYFUNCTION("""COMPUTED_VALUE"""),"Fail") -> Fail | K34: =IFERROR(__xludf.DUMMYFUNCTION("""COMPUTED_VALUE"""),"High") -> High | L34: =IFERROR(__xludf.DUMMYFUNCTION("""COMPUTED_VALUE"""),"https://jam.dev/c/f25a9504-20f8-43e9-abc1-c3c8a55191aa") -> https://jam.dev/c/f25a9504-20f8-43e9-abc1-c3c8a55191aa | N34: =IFERROR(__xludf.DUMMYFUNCTION("""COMPUTED_VALUE"""),"Fahad") -> Fahad | O34: Solved | Q34: backedn ,fixed the error response format
A35: BR-025 | B35: =IFERROR(__xludf.DUMMYFUNCTION("""COMPUTED_VALUE"""),"Manage Clinic") -> Manage Clinic | C35: =IFERROR(__xludf.DUMMYFUNCTION("""COMPUTED_VALUE"""),"Add Clinic") -> Add Clinic | D35: =IFERROR(__xludf.DUMMYFUNCTION("""COMPUTED_VALUE"""),"Validation required in the input field") -> Validation required in the input field | E35: =IFERROR(__xludf.DUMMYFUNCTION("""COMPUTED_VALUE"""),"User need to access this web app through browser") -> User need to access this web app through browser | F35: =IFERROR(__xludf.DUMMYFUNCTION("""COMPUTED_VALUE"""),"1. Open link 2. Login with Admin Credentials 3. Click on Manage Clinic") -> 1. Open link 2. Login with Admin Credentials 3. Click on Manage Clinic | G35: =IFERROR(__xludf.DUMMYFUNCTION("""COMPUTED_VALUE"""),"Admin Credentials") -> Admin Credentials | H35: =IFERROR(__xludf.DUMMYFUNCTION("""COMPUTED_VALUE"""),"Validation in input field need to set") -> Validation in input field need to set | I35: =IFERROR(__xludf.DUMMYFUNCTION("""COMPUTED_VALUE"""),"Failed on validation") -> Failed on validation | J35: =IFERROR(__xludf.DUMMYFUNCTION("""COMPUTED_VALUE"""),"Fail") -> Fail | K35: =IFERROR(__xludf.DUMMYFUNCTION("""COMPUTED_VALUE"""),"High") -> High | L35: =IFERROR(__xludf.DUMMYFUNCTION("""COMPUTED_VALUE"""),"https://jam.dev/c/60208152-77eb-4099-b4c6-10d8c86b57e8") -> https://jam.dev/c/60208152-77eb-4099-b4c6-10d8c86b57e8 | N35: =IFERROR(__xludf.DUMMYFUNCTION("""COMPUTED_VALUE"""),"Fahad") -> Fahad | O35: Unsolved | Q35: backend
A36: BR-026 | B36: =IFERROR(__xludf.DUMMYFUNCTION("""COMPUTED_VALUE"""),"Manage Clinic") -> Manage Clinic | C36: =IFERROR(__xludf.DUMMYFUNCTION("""COMPUTED_VALUE"""),"Add Clinic") -> Add Clinic | D36: =IFERROR(__xludf.DUMMYFUNCTION("""COMPUTED_VALUE"""),"Limit need to set in input field") -> Limit need to set in input field | E36: =IFERROR(__xludf.DUMMYFUNCTION("""COMPUTED_VALUE"""),"User need to access this web app through browser") -> User need to access this web app through browser | F36: =IFERROR(__xludf.DUMMYFUNCTION("""COMPUTED_VALUE"""),"1. Open link 2. Login with Admin Credentials 3. Click on Manage Clinic") -> 1. Open link 2. Login with Admin Credentials 3. Click on Manage Clinic | G36: =IFERROR(__xludf.DUMMYFUNCTION("""COMPUTED_VALUE"""),"Admin Credentials") -> Admin Credentials | H36: =IFERROR(__xludf.DUMMYFUNCTION("""COMPUTED_VALUE"""),"A limit needs to be set in the input field.") -> A limit needs to be set in the input field. | I36: =IFERROR(__xludf.DUMMYFUNCTION("""COMPUTED_VALUE"""),"No limit set in the input field") -> No limit set in the input field | J36: =IFERROR(__xludf.DUMMYFUNCTION("""COMPUTED_VALUE"""),"Fail") -> Fail | K36: =IFERROR(__xludf.DUMMYFUNCTION("""COMPUTED_VALUE"""),"Medium") -> Medium | L36: =IFERROR(__xludf.DUMMYFUNCTION("""COMPUTED_VALUE"""),"https://jam.dev/c/7697c7b5-f9ae-4e36-9a1e-ce335096382c") -> https://jam.dev/c/7697c7b5-f9ae-4e36-9a1e-ce335096382c | M36: =IFERROR(__xludf.DUMMYFUNCTION("""COMPUTED_VALUE"""),"https://jam.dev/c/605adc04-59a2-4636-a2e7-fc6e12097298 Better if the limit set to input fields") -> https://jam.dev/c/605adc04-59a2-4636-a2e7-fc6e12097298 Better if the limit set to input fields | N36: =IFERROR(__xludf.DUMMYFUNCTION("""COMPUTED_VALUE"""),"Fahad") -> Fahad | O36: Solved | P36: by reza
A37: BR-027 | B37: =IFERROR(__xludf.DUMMYFUNCTION("""COMPUTED_VALUE"""),"Settings") -> Settings | C37: =IFERROR(__xludf.DUMMYFUNCTION("""COMPUTED_VALUE"""),"Profile") -> Profile | D37: =IFERROR(__xludf.DUMMYFUNCTION("""COMPUTED_VALUE"""),"Validation in profile is not set ") -> Validation in profile is not set | E37: =IFERROR(__xludf.DUMMYFUNCTION("""COMPUTED_VALUE"""),"User need to access this web app through browser") -> User need to access this web app through browser | F37: =IFERROR(__xludf.DUMMYFUNCTION("""COMPUTED_VALUE"""),"1. Open link 2. Login with Admin Credentials 3. Click on Settings") -> 1. Open link 2. Login with Admin Credentials 3. Click on Settings | G37: =IFERROR(__xludf.DUMMYFUNCTION("""COMPUTED_VALUE"""),"Admin Credentials") -> Admin Credentials | H37: =IFERROR(__xludf.DUMMYFUNCTION("""COMPUTED_VALUE"""),"Validation in input field need to set") -> Validation in input field need to set | I37: =IFERROR(__xludf.DUMMYFUNCTION("""COMPUTED_VALUE"""),"Failed on validation") -> Failed on validation | J37: =IFERROR(__xludf.DUMMYFUNCTION("""COMPUTED_VALUE"""),"Fail") -> Fail | K37: =IFERROR(__xludf.DUMMYFUNCTION("""COMPUTED_VALUE"""),"High") -> High | L37: =IFERROR(__xludf.DUMMYFUNCTION("""COMPUTED_VALUE"""),"https://jam.dev/c/b1dec3b3-564e-413d-9fc7-6d05307cc235") -> https://jam.dev/c/b1dec3b3-564e-413d-9fc7-6d05307cc235 | N37: =IFERROR(__xludf.DUMMYFUNCTION("""COMPUTED_VALUE"""),"Fahad") -> Fahad | O37: Solved | P37: by reza
A38: BR-028 | B38: =IFERROR(__xludf.DUMMYFUNCTION("""COMPUTED_VALUE"""),"Settings") -> Settings | C38: =IFERROR(__xludf.DUMMYFUNCTION("""COMPUTED_VALUE"""),"Profile") -> Profile | D38: =IFERROR(__xludf.DUMMYFUNCTION("""COMPUTED_VALUE"""),"Need to put validation in Manager profie") -> Need to put validation in Manager profie | E38: =IFERROR(__xludf.DUMMYFUNCTION("""COMPUTED_VALUE"""),"User need to access this web app through browser") -> User need to access this web app through browser | F38: =IFERROR(__xludf.DUMMYFUNCTION("""COMPUTED_VALUE"""),"1. Open link 2. Login with Manager Credentials 3. Click on Settings") -> 1. Open link 2. Login with Manager Credentials 3. Click on Settings | G38: =IFERROR(__xludf.DUMMYFUNCTION("""COMPUTED_VALUE"""),"Manager Credentials") -> Manager Credentials | H38: =IFERROR(__xludf.DUMMYFUNCTION("""COMPUTED_VALUE"""),"Need to put validation in Manager profie") -> Need to put validation in Manager profie | I38: =IFERROR(__xludf.DUMMYFUNCTION("""COMPUTED_VALUE"""),"Validation failed") -> Validation failed | J38: =IFERROR(__xludf.DUMMYFUNCTION("""COMPUTED_VALUE"""),"Fail") -> Fail | K38: =IFERROR(__xludf.DUMMYFUNCTION("""COMPUTED_VALUE"""),"High") -> High | L38: =IFERROR(__xludf.DUMMYFUNCTION("""COMPUTED_VALUE"""),"https://jam.dev/c/a30bb76e-d565-4ef1-928f-bf6ec794fb35") -> https://jam.dev/c/a30bb76e-d565-4ef1-928f-bf6ec794fb35 | N38: =IFERROR(__xludf.DUMMYFUNCTION("""COMPUTED_VALUE"""),"Fahad") -> Fahad | O38: Unsolved
A39: BR-029 | B39: =IFERROR(__xludf.DUMMYFUNCTION("""COMPUTED_VALUE"""),"Settings") -> Settings | C39: =IFERROR(__xludf.DUMMYFUNCTION("""COMPUTED_VALUE"""),"Profile") -> Profile | D39: =IFERROR(__xludf.DUMMYFUNCTION("""COMPUTED_VALUE"""),"The username does not update dynamically in the profile.") -> The username does not update dynamically in the profile. | E39: =IFERROR(__xludf.DUMMYFUNCTION("""COMPUTED_VALUE"""),"User need to access this web app through browser") -> User need to access this web app through browser | F39: =IFERROR(__xludf.DUMMYFUNCTION("""COMPUTED_VALUE"""),"1. Open link 2. Login with Manager Credentials 3. Click on Settings") -> 1. Open link 2. Login with Manager Credentials 3. Click on Settings | G39: =IFERROR(__xludf.DUMMYFUNCTION("""COMPUTED_VALUE"""),"Manager Credentials") -> Manager Credentials | H39: =IFERROR(__xludf.DUMMYFUNCTION("""COMPUTED_VALUE"""),"User name should be dynamically update in every group after it changes") -> User name should be dynamically update in every group after it changes | I39: =IFERROR(__xludf.DUMMYFUNCTION("""COMPUTED_VALUE"""),"Failed to show upated username in groups") -> Failed to show upated username in groups | J39: =IFERROR(__xludf.DUMMYFUNCTION("""COMPUTED_VALUE"""),"Fail") -> Fail | K39: =IFERROR(__xludf.DUMMYFUNCTION("""COMPUTED_VALUE"""),"High") -> High | L39: =IFERROR(__xludf.DUMMYFUNCTION("""COMPUTED_VALUE"""),"https://jam.dev/c/c21c907e-9edd-439f-b0fa-e5f365a369eb") -> https://jam.dev/c/c21c907e-9edd-439f-b0fa-e5f365a369eb | M39: =IFERROR(__xludf.DUMMYFUNCTION("""COMPUTED_VALUE"""),"need to refresh after update to see the updated profile") -> need to refresh after update to see the updated profile | N39: =IFERROR(__xludf.DUMMYFUNCTION("""COMPUTED_VALUE"""),"Fahad") -> Fahad | O39: Unsolved
A40: BR-030 | B40: =IFERROR(__xludf.DUMMYFUNCTION("""COMPUTED_VALUE"""),"User Management") -> User Management | C40: =IFERROR(__xludf.DUMMYFUNCTION("""COMPUTED_VALUE"""),"User Management") -> User Management | D40: =IFERROR(__xludf.DUMMYFUNCTION("""COMPUTED_VALUE"""),"The field required indicator hasn’t been implemented in the frontend.") -> The field required indicator hasn’t been implemented in the frontend. | E40: =IFERROR(__xludf.DUMMYFUNCTION("""COMPUTED_VALUE"""),"User need to access this web app through browser") -> User need to access this web app through browser | F40: =IFERROR(__xludf.DUMMYFUNCTION("""COMPUTED_VALUE"""),"1. Open link 2. Login with Admin Credentials 3. Click on User Management") -> 1. Open link 2. Login with Admin Credentials 3. Click on User Management | G40: =IFERROR(__xludf.DUMMYFUNCTION("""COMPUTED_VALUE"""),"Admin Credentials") -> Admin Credentials | H40: =IFERROR(__xludf.DUMMYFUNCTION("""COMPUTED_VALUE"""),"Adding a required field indicator in the frontend can greatly enhance the user experience.") -> Adding a required field indicator in the frontend can greatly enhance the user experience. | I40: =IFERROR(__xludf.DUMMYFUNCTION("""COMPUTED_VALUE"""),"Missing required indicator ") -> Missing required indicator | J40: =IFERROR(__xludf.DUMMYFUNCTION("""COMPUTED_VALUE"""),"Fail") -> Fail | K40: =IFERROR(__xludf.DUMMYFUNCTION("""COMPUTED_VALUE"""),"High") -> High | L40: =IFERROR(__xludf.DUMMYFUNCTION("""COMPUTED_VALUE"""),"https://jam.dev/c/c7fed9af-b9d6-47ae-bb3f-3d23feac85a6") -> https://jam.dev/c/c7fed9af-b9d6-47ae-bb3f-3d23feac85a6 | N40: =IFERROR(__xludf.DUMMYFUNCTION("""COMPUTED_VALUE"""),"Fahad") -> Fahad | O40: Unsolved
A41: BR-031 | B41: =IFERROR(__xludf.DUMMYFUNCTION("""COMPUTED_VALUE"""),"User Management") -> User Management | C41: =IFERROR(__xludf.DUMMYFUNCTION("""COMPUTED_VALUE"""),"User Management") -> User Management | D41: =IFERROR(__xludf.DUMMYFUNCTION("""COMPUTED_VALUE"""),"Validation required in the input field") -> Validation required in the input field | E41: =IFERROR(__xludf.DUMMYFUNCTION("""COMPUTED_VALUE"""),"User need to access this web app through browser") -> User need to access this web app through browser | F41: =IFERROR(__xludf.DUMMYFUNCTION("""COMPUTED_VALUE"""),"1. Open link 2. Login with Admin Credentials 3. Click on User Management") -> 1. Open link 2. Login with Admin Credentials 3. Click on User Management | G41: =IFERROR(__xludf.DUMMYFUNCTION("""COMPUTED_VALUE"""),"Admin Credentials") -> Admin Credentials | H41: =IFERROR(__xludf.DUMMYFUNCTION("""COMPUTED_VALUE"""),"Validation in input field need to set") -> Validation in input field need to set | I41: =IFERROR(__xludf.DUMMYFUNCTION("""COMPUTED_VALUE"""),"Failed on validation") -> Failed on validation | J41: =IFERROR(__xludf.DUMMYFUNCTION("""COMPUTED_VALUE"""),"Fail") -> Fail | K41: =IFERROR(__xludf.DUMMYFUNCTION("""COMPUTED_VALUE"""),"High") -> High | L41: =IFERROR(__xludf.DUMMYFUNCTION("""COMPUTED_VALUE"""),"https://jam.dev/c/e506b2da-e9bc-4df0-8f96-4a58fc677d23") -> https://jam.dev/c/e506b2da-e9bc-4df0-8f96-4a58fc677d23 | M41: =IFERROR(__xludf.DUMMYFUNCTION("""COMPUTED_VALUE"""),"Still take number in name field") -> Still take number in name field | N41: =IFERROR(__xludf.DUMMYFUNCTION("""COMPUTED_VALUE"""),"Fahad") -> Fahad | O41: Unsolved
A42: BR-032 | B42: =IFERROR(__xludf.DUMMYFUNCTION("""COMPUTED_VALUE"""),"User Management") -> User Management | C42: =IFERROR(__xludf.DUMMYFUNCTION("""COMPUTED_VALUE"""),"User Management") -> User Management | D42: =IFERROR(__xludf.DUMMYFUNCTION("""COMPUTED_VALUE"""),"Failed to update role") -> Failed to update role | E42: =IFERROR(__xludf.DUMMYFUNCTION("""COMPUTED_VALUE"""),"User need to access this web app through browser") -> User need to access this web app through browser | F42: =IFERROR(__xludf.DUMMYFUNCTION("""COMPUTED_VALUE"""),"1. Open link 2. Login with Admin Credentials 3. Click on Manage Clinic") -> 1. Open link 2. Login with Admin Credentials 3. Click on Manage Clinic | G42: =IFERROR(__xludf.DUMMYFUNCTION("""COMPUTED_VALUE"""),"Admin Credentials") -> Admin Credentials | H42: =IFERROR(__xludf.DUMMYFUNCTION("""COMPUTED_VALUE"""),"Should be able to update user role from Admin side") -> Should be able to update user role from Admin side | I42: =IFERROR(__xludf.DUMMYFUNCTION("""COMPUTED_VALUE"""),"Failed to update user role ") -> Failed to update user role | J42: =IFERROR(__xludf.DUMMYFUNCTION("""COMPUTED_VALUE"""),"Fail") -> Fail | K42: =IFERROR(__xludf.DUMMYFUNCTION("""COMPUTED_VALUE"""),"High") -> High | L42: =IFERROR(__xludf.DUMMYFUNCTION("""COMPUTED_VALUE"""),"https://jam.dev/c/e6e4004c-24ea-47b1-939b-8281c9ed9dab") -> https://jam.dev/c/e6e4004c-24ea-47b1-939b-8281c9ed9dab | N42: =IFERROR(__xludf.DUMMYFUNCTION("""COMPUTED_VALUE"""),"Fahad") -> Fahad | O42: Solved
...

Sheet Fahad
A1: Tester : | B1: Mohammed Fahad Faisal
A2: Project Name:
A3: Developer: | B3: AI Hunter
A4: OS: | B4: Windows 11 Pro Version:24H2 OS build:26100.4946
A5: Environment: | B5: Brave 1.81.135 (Official Build) (64-bit) Chromium: 139.0.7258.127
A7: Test ID | B7: Module | C7: Sub Module | D7: Test Case Description | E7: Preconditions | F7: Test Steps | G7: Test Data | H7: Expected Result | I7: Actual Result | J7: Status | K7: Severity | L7: Screen Shots | M7: Suggestion | N7: Feedback | O7: Stack
A8: BR_001 | B8: Login | C8: Login | D8: Forget Password or password reset action button missing in login page | E8: User need to access this web app through browser | F8: 1. Open link | G8: N/A | H8: Password reset / Forget Password option should be visible in the login page | I8: No password reset option has been implemented, if need to change, need to do it manually | J8: Fail | K8: High | L8: https://jam.dev/c/67d6f6db-0260-4396-b48b-59593fc6f09b
A10: BR_002 | B10: Communication | C10: Group Chat | D10: User name need to be displayed in the group chat for better user experience | E10: User need to access this web app through browser | F10: 1. Open link 2. Login with Admin Credentials 3. Click on communication | G10: Admin Credentials | H10: User name need to be displayed in the group chat for better user engagement | I10: The username isn’t shown in the group chat, it’s hard to tell who sent the message. | J10: Fail | K10: High | L10: https://jam.dev/c/606bcc70-9c47-4c54-9953-051b4bc39d60
A12: BR_003 | B12: Communication | C12: Group Chat | D12: The group image doesn’t update dynamically. | E12: User need to access this web app through browser | F12: 1. Open link 2. Login with Admin Credentials 3. Click on communication | G12: Admin Credentials | H12: The group image should be dynamically updated. | I12: Unable to update the group image dynamically. | J12: Fail | K12: Medium | L12: https://jam.dev/c/58e41e2c-fd94-4d47-a548-31011fbbd2df
A14: BR_004 | B14: Communication | C14: Group Chat | D14: Group member list is missing in communication | E14: User need to access this web app through browser | F14: 1. Open link 2. Login with Admin Credentials 3. Click on communication | G14: Admin Credentials | H14: In group details, member list should be displayed for better user experience | I14: Group member list missing in group details | J14: Fail | K14: High | L14: https://jam.dev/c/b50b656c-a6e9-499e-8ec2-25c60607c463
A16: BR_005 | B16: Communication | C16: Group Chat | D16: Group action bar remains in each chat/group until it clicked | E16: User need to access this web app through browser | F16: 1. Open link 2. Login with Admin Credentials 3. Click on communication | G16: Admin Credentials | H16: The action bar should appear when the icon is clicked and hide when the user switches to another chat. | I16: The action bar stays in place even when the user switches chats. | J16: Fail | K16: Medium | L16: https://jam.dev/c/b9782c46-0840-46e6-80a6-d7dfdb0bf638
A18: BR_006 | B18: Manage Clinic | C18: Add Clinic | D18: The field required indicator hasn’t been implemented in the frontend. | E18: User need to access this web app through browser | F18: 1. Open link 2. Login with Admin Credentials 3. Click on Manage Clinic | G18: Admin Credentials | H18: Adding a required field indicator in the frontend can greatly enhance the user experience. | I18: Missing required indicator | J18: Fail | K18: High | L18: https://jam.dev/c/f25a9504-20f8-43e9-abc1-c3c8a55191aa
A20: BR_007 | B20: Manage Clinic | C20: Add Clinic | D20: Validation required in the input field | E20: User need to access this web app through browser | F20: 1. Open link 2. Login with Admin Credentials 3. Click on Manage Clinic | G20: Admin Credentials | H20: Validation in input field need to set | I20: Failed on validation | J20: Fail | K20: High | L20: https://jam.dev/c/60208152-77eb-4099-b4c6-10d8c86b57e8
A22: BR_008 | B22: Manage Clinic | C22: Add Clinic | D22: Limit need to set in input field | E22: User need to access this web app through browser | F22: 1. Open link 2. Login with Admin Credentials 3. Click on Manage Clinic | G22: Admin Credentials | H22: A limit needs to be set in the input field. | I22: No limit set in the input field | J22: Fail | K22: Medium | L22: https://jam.dev/c/7697c7b5-f9ae-4e36-9a1e-ce335096382c | M22: https://jam.dev/c/605adc04-59a2-4636-a2e7-fc6e12097298 Better if the limit set to input fields
A24: BR_009 | B24: User Management | C24: User Management | D24: The field required indicator hasn’t been implemented in the frontend. | E24: User need to access this web app through browser | F24: 1. Open link 2. Login with Admin Credentials 3. Click on User Management | G24: Admin Credentials | H24: Adding a required field indicator in the frontend can greatly enhance the user experience. | I24: Missing required indicator | J24: Fail | K24: High | L24: https://jam.dev/c/c7fed9af-b9d6-47ae-bb3f-3d23feac85a6
A26: BR_010 | B26: User Management | C26: User Management | D26: Validation required in the input field | E26: User need to access this web app through browser | F26: 1. Open link 2. Login with Admin Credentials 3. Click on User Management | G26: Admin Credentials | H26: Validation in input field need to set | I26: Failed on validation | J26: Fail | K26: High | L26: https://jam.dev/c/e506b2da-e9bc-4df0-8f96-4a58fc677d23 | M26: Still take number in name field
A28: BR_011 | B28: AI Training | C28: View Docs | D28: Failed to train AI by Image | E28: User need to access this web app through browser | F28: 1. Open link 2. Login with Admin Credentials 3. Click on AI Training | G28: Admin Credentials | H28: As per as requirement, user should be able to train AI by images, pdf, doc, xls | I28: Failed to train AI by image | J28: Fail | K28: High
