Workbook

Sheet Main Report
A2: Tester : | B2: Mohammed Fahad Faisal | D2: Severity | E2: Issues
A3: Project Name: | B3: Thai Massage | D3: High | E3: =COUNTIF(Tahsin!K14:K1005, "High") + COUNTIF(Fahad!K8:K1004, "High") -> 17
A4: Project URL: | D4: Medium | E4: =COUNTIF(Tahsin!K14:K1006, "Medium") + COUNTIF(Fahad!K8:K1005, "Medium") -> 9
A5: Developer: | B5: AI Venture | D5: Low | E5: =COUNTIF(Fahad!K8:K1006, "Low") + COUNTIF(Tahsin!K14:K1009, "Low") -> 21
A6: OS:
A7: Environment | D7: Total Test Cases: | E7: =SUM(E3:E5) -> 47
D8: Test Case Solved : | E8: =COUNTIF(O11:O1003, "Solved") -> 16
A10: Test Case ID | B10: Module | C10: Sub Module | D10: Test Case Description | E10: Preconditions | F10: Test Steps | G10: Test Data | H10: Expected Result | I10: Actual Result | J10: Status | K10: Severity | L10: Screen Shots | M10: Suggestion | N10: Tester | O10: Feedback | P10: Comment
A11: BR-001 | B11: =IFERROR(__xludf.DUMMYFUNCTION("QUERY( { ARRAYFORMULA({TRIM(Fahad!B8:B999), Fahad!C8:M999, IF(LEN(Fahad!B8:B999), ""Fahad"", """")}); ARRAYFORMULA({TRIM(Tahsin!B15:B999), Tahsin!C15:M999, IF(LEN(Tahsin!B15:B999), ""Tahsin"", """")}) }, ""SELECT * WHERE Col1 IS NOT NULL ORD"&"ER BY Col1 ASC, Col2 ASC"", 0 ) "),"Client (APK)") -> Client (APK) | C11: =IFERROR(__xludf.DUMMYFUNCTION("""COMPUTED_VALUE"""),"Add card") -> Add card | D11: =IFERROR(__xludf.DUMMYFUNCTION("""COMPUTED_VALUE"""),"Simplify the card addition bar in the mobile app.") -> Simplify the card addition bar in the mobile app. | E11: =IFERROR(__xludf.DUMMYFUNCTION("""COMPUTED_VALUE"""),"The user needs to have the APK running on their mobile device.") -> The user needs to have the APK running on their mobile device. | F11: =IFERROR(__xludf.DUMMYFUNCTION("""COMPUTED_VALUE"""),"1. Open app 2. Click on Client button 3. Login using valid credential 4. Goto profile section 5. Click on Add payment methode") -> 1. Open app 2. Click on Client button 3. Login using valid credential 4. Goto profile section 5. Click on Add payment methode | G11: =IFERROR(__xludf.DUMMYFUNCTION("""COMPUTED_VALUE"""),"email: itcrlbmzxpfmfowcfe@xfavaj.com password: 1122334455") -> email: itcrlbmzxpfmfowcfe@xfavaj.com password: 1122334455 | H11: =IFERROR(__xludf.DUMMYFUNCTION("""COMPUTED_VALUE"""),"All payment card gateways should be clearly visible to the client.") -> All payment card gateways should be clearly visible to the client. | I11: =IFERROR(__xludf.DUMMYFUNCTION("""COMPUTED_VALUE"""),"A reduction in the payment card border has been observed.") -> A reduction in the payment card border has been observed. | J11: =IFERROR(__xludf.DUMMYFUNCTION("""COMPUTED_VALUE"""),"Fail") -> Fail | K11: =IFERROR(__xludf.DUMMYFUNCTION("""COMPUTED_VALUE"""),"Medium") -> Medium | L11: =IFERROR(__xludf.DUMMYFUNCTION("""COMPUTED_VALUE"""),"https://drive.google.com/file/d/1u29w_Wa7h4bOdm9m9WXAH4cPvm-ZdEVi/view?usp=drive_link") -> https://drive.google.com/file/d/1u29w_Wa7h4bOdm9m9WXAH4cPvm-ZdEVi/view?usp=drive_link | N11: =IFERROR(__xludf.DUMMYFUNCTION("""COMPUTED_VALUE"""),"Fahad") -> Fahad
A12: BR-002 | B12: =IFERROR(__xludf.DUMMYFUNCTION("""COMPUTED_VALUE"""),"Client (APK)") -> Client (APK) | C12: =IFERROR(__xludf.DUMMYFUNCTION("""COMPUTED_VALUE"""),"Appointment") -> Appointment | D12: =IFERROR(__xludf.DUMMYFUNCTION("""COMPUTED_VALUE"""),"The location details input field is slightly different from the client's requirements.") -> The location details input field is slightly different from the client's requirements. | E12: =IFERROR(__xludf.DUMMYFUNCTION("""COMPUTED_VALUE"""),"The user needs to have the APK running on their mobile device.") -> The user needs to have the APK running on their mobile device. | F12: =IFERROR(__xludf.DUMMYFUNCTION("""COMPUTED_VALUE"""),"1. Open app 2. Click on Client button 3. Login using valid credential 4. Goto Appointment Section") -> 1. Open app 2. Click on Client button 3. Login using valid credential 4. Goto Appointment Section | G12: =IFERROR(__xludf.DUMMYFUNCTION("""COMPUTED_VALUE"""),"email: lowovip595@elobits.com password: 112244557788") -> email: lowovip595@elobits.com password: 112244557788 | H12: =IFERROR(__xludf.DUMMYFUNCTION("""COMPUTED_VALUE"""),"Alignment and design should match the client's requirements.") -> Alignment and design should match the client's requirements. | I12: =IFERROR(__xludf.DUMMYFUNCTION("""COMPUTED_VALUE"""),"A different design and layout have been observed.") -> A different design and layout have been observed. | J12: =IFERROR(__xludf.DUMMYFUNCTION("""COMPUTED_VALUE"""),"Fail") -> Fail | K12: =IFERROR(__xludf.DUMMYFUNCTION("""COMPUTED_VALUE"""),"Low") -> Low | L12: =IFERROR(__xludf.DUMMYFUNCTION("""COMPUTED_VALUE"""),"https://drive.google.com/file/d/1F6zNQsG49gDUpfguLk-u9nFlyuXhBEkF/view?usp=drive_link") -> https://drive.google.com/file/d/1F6zNQsG49gDUpfguLk-u9nFlyuXhBEkF/view?usp=drive_link | N12: =IFERROR(__xludf.DUMMYFUNCTION("""COMPUTED_VALUE"""),"Fahad") -> Fahad | O12: Solved
A13: BR-003 | B13: =IFERROR(__xludf.DUMMYFUNCTION("""COMPUTED_VALUE"""),"Client (APK)") -> Client (APK) | C13: =IFERROR(__xludf.DUMMYFUNCTION("""COMPUTED_VALUE"""),"Appointment") -> Appointment | D13: =IFERROR(__xludf.DUMMYFUNCTION("""COMPUTED_VALUE"""),"The age preference does not align with the client requirement.") -> The age preference does not align with the client requirement. | E13: =IFERROR(__xludf.DUMMYFUNCTION("""COMPUTED_VALUE"""),"The user needs to have the APK running on their mobile device.") -> The user needs to have the APK running on their mobile device. | F13: =IFERROR(__xludf.DUMMYFUNCTION("""COMPUTED_VALUE"""),"1. Open app 2. Click on Client button 3. Login using valid credential 4. Goto Appointment Section") -> 1. Open app 2. Click on Client button 3. Login using valid credential 4. Goto Appointment Section | G13: =IFERROR(__xludf.DUMMYFUNCTION("""COMPUTED_VALUE"""),"email: lowovip595@elobits.com password: 112244557788") -> email: lowovip595@elobits.com password: 112244557788 | H13: =IFERROR(__xludf.DUMMYFUNCTION("""COMPUTED_VALUE"""),"Alignment and design should match the client's requirements.") -> Alignment and design should match the client's requirements. | I13: =IFERROR(__xludf.DUMMYFUNCTION("""COMPUTED_VALUE"""),"A different design and layout have been observed.") -> A different design and layout have been observed. | J13: =IFERROR(__xludf.DUMMYFUNCTION("""COMPUTED_VALUE"""),"Fail") -> Fail | K13: =IFERROR(__xludf.DUMMYFUNCTION("""COMPUTED_VALUE"""),"Low") -> Low | L13: =IFERROR(__xludf.DUMMYFUNCTION("""COMPUTED_VALUE"""),"https://drive.google.com/file/d/1loH6gbOEVYxwdpQtNm0INqLyHo92xJbM/view?usp=drive_link") -> https://drive.google.com/file/d/1loH6gbOEVYxwdpQtNm0INqLyHo92xJbM/view?usp=drive_link | N13: =IFERROR(__xludf.DUMMYFUNCTION("""COMPUTED_VALUE"""),"Fahad") -> Fahad | O13: Solved
A14: BR-004 | B14: =IFERROR(__xludf.DUMMYFUNCTION("""COMPUTED_VALUE"""),"Client (APK)") -> Client (APK) | C14: =IFERROR(__xludf.DUMMYFUNCTION("""COMPUTED_VALUE"""),"Appointment") -> Appointment | D14: =IFERROR(__xludf.DUMMYFUNCTION("""COMPUTED_VALUE"""),"Error bars on selected therapist schedules") -> Error bars on selected therapist schedules | E14: =IFERROR(__xludf.DUMMYFUNCTION("""COMPUTED_VALUE"""),"The user needs to have the APK running on their mobile device.") -> The user needs to have the APK running on their mobile device. | F14: =IFERROR(__xludf.DUMMYFUNCTION("""COMPUTED_VALUE"""),"1. Open app 2. Click on Client button 3. Login using valid credential 4. Goto Appointment Section") -> 1. Open app 2. Click on Client button 3. Login using valid credential 4. Goto Appointment Section | G14: =IFERROR(__xludf.DUMMYFUNCTION("""COMPUTED_VALUE"""),"email: lowovip595@elobits.com password: 112244557788") -> email: lowovip595@elobits.com password: 112244557788 | H14: =IFERROR(__xludf.DUMMYFUNCTION("""COMPUTED_VALUE"""),"The error bar should not be visible on the client side.") -> The error bar should not be visible on the client side. | I14: =IFERROR(__xludf.DUMMYFUNCTION("""COMPUTED_VALUE"""),"An error bar on the ""Done"" button in the select schedule section has been identified.") -> An error bar on the "Done" button in the select schedule section has been identified. | J14: =IFERROR(__xludf.DUMMYFUNCTION("""COMPUTED_VALUE"""),"Fail") -> Fail | K14: =IFERROR(__xludf.DUMMYFUNCTION("""COMPUTED_VALUE"""),"Medium") -> Medium | L14: =IFERROR(__xludf.DUMMYFUNCTION("""COMPUTED_VALUE"""),"https://drive.google.com/file/d/1IeVWxa2y6sKCMgIvz9n6y_GsWL13OHBt/view?usp=drive_link") -> https://drive.google.com/file/d/1IeVWxa2y6sKCMgIvz9n6y_GsWL13OHBt/view?usp=drive_link | N14: =IFERROR(__xludf.DUMMYFUNCTION("""COMPUTED_VALUE"""),"Fahad") -> Fahad | O14: Solved
A15: BR-005 | B15: =IFERROR(__xludf.DUMMYFUNCTION("""COMPUTED_VALUE"""),"Client (APK)") -> Client (APK) | C15: =IFERROR(__xludf.DUMMYFUNCTION("""COMPUTED_VALUE"""),"Appointment") -> Appointment | D15: =IFERROR(__xludf.DUMMYFUNCTION("""COMPUTED_VALUE"""),"The agree button overlaps with the section bar.") -> The agree button overlaps with the section bar. | E15: =IFERROR(__xludf.DUMMYFUNCTION("""COMPUTED_VALUE"""),"The user needs to have the APK running on their mobile device.") -> The user needs to have the APK running on their mobile device. | F15: =IFERROR(__xludf.DUMMYFUNCTION("""COMPUTED_VALUE"""),"1. Open app 2. Click on Client button 3. Login using valid credential 4. Goto Appointment Section") -> 1. Open app 2. Click on Client button 3. Login using valid credential 4. Goto Appointment Section | G15: =IFERROR(__xludf.DUMMYFUNCTION("""COMPUTED_VALUE"""),"email: lowovip595@elobits.com password: 112244557788") -> email: lowovip595@elobits.com password: 112244557788 | H15: =IFERROR(__xludf.DUMMYFUNCTION("""COMPUTED_VALUE"""),"The field shadow effect should not exceed its boundary.") -> The field shadow effect should not exceed its boundary. | I15: =IFERROR(__xludf.DUMMYFUNCTION("""COMPUTED_VALUE"""),"The cross-boundary effect has been observed.") -> The cross-boundary effect has been observed. | J15: =IFERROR(__xludf.DUMMYFUNCTION("""COMPUTED_VALUE"""),"Fail") -> Fail | K15: =IFERROR(__xludf.DUMMYFUNCTION("""COMPUTED_VALUE"""),"Low") -> Low | L15: =IFERROR(__xludf.DUMMYFUNCTION("""COMPUTED_VALUE"""),"https://drive.google.com/file/d/1haRoWx_fzP2CktG0LbdGtOVcBGkZOyAs/view?usp=drive_link") -> https://drive.google.com/file/d/1haRoWx_fzP2CktG0LbdGtOVcBGkZOyAs/view?usp=drive_link | N15: =IFERROR(__xludf.DUMMYFUNCTION("""COMPUTED_VALUE"""),"Fahad") -> Fahad | O15: Solved
A16: BR-006 | B16: =IFERROR(__xludf.DUMMYFUNCTION("""COMPUTED_VALUE"""),"Client (APK)") -> Client (APK) | C16: =IFERROR(__xludf.DUMMYFUNCTION("""COMPUTED_VALUE"""),"Appointment") -> Appointment | D16: =IFERROR(__xludf.DUMMYFUNCTION("""COMPUTED_VALUE"""),"The layout varies for questions about medical appointments.") -> The layout varies for questions about medical appointments. | E16: =IFERROR(__xludf.DUMMYFUNCTION("""COMPUTED_VALUE"""),"The user needs to have the APK running on their mobile device.") -> The user needs to have the APK running on their mobile device. | F16: =IFERROR(__xludf.DUMMYFUNCTION("""COMPUTED_VALUE"""),"1. Open app 2. Click on Client button 3. Login using valid credential 4. Goto Appointment Section 5. After select required fields, goto medical questions") -> 1. Open app 2. Click on Client button 3. Login using valid credential 4. Goto Appointment Section 5. After select required fields, goto medical questions | G16: =IFERROR(__xludf.DUMMYFUNCTION("""COMPUTED_VALUE"""),"email: lowovip595@elobits.com password: 112244557788") -> email: lowovip595@elobits.com password: 112244557788 | H16: =IFERROR(__xludf.DUMMYFUNCTION("""COMPUTED_VALUE"""),"Alignment and design should match the client's requirements.") -> Alignment and design should match the client's requirements. | I16: =IFERROR(__xludf.DUMMYFUNCTION("""COMPUTED_VALUE"""),"A different design and layout have been observed.") -> A different design and layout have been observed. | J16: =IFERROR(__xludf.DUMMYFUNCTION("""COMPUTED_VALUE"""),"Fail") -> Fail | K16: =IFERROR(__xludf.DUMMYFUNCTION("""COMPUTED_VALUE"""),"Low") -> Low | L16: =IFERROR(__xludf.DUMMYFUNCTION("""COMPUTED_VALUE"""),"https://drive.google.com/file/d/15VG_T_k1OUzSG0xdJjXgTgkniEmLBDiK/view?usp=drive_link") -> https://drive.google.com/file/d/15VG_T_k1OUzSG0xdJjXgTgkniEmLBDiK/view?usp=drive_link | N16: =IFERROR(__xludf.DUMMYFUNCTION("""COMPUTED_VALUE"""),"Fahad") -> Fahad | O16: Solved
A17: BR-007 | B17: =IFERROR(__xludf.DUMMYFUNCTION("""COMPUTED_VALUE"""),"Client (APK)") -> Client (APK) | C17: =IFERROR(__xludf.DUMMYFUNCTION("""COMPUTED_VALUE"""),"Appointment") -> Appointment | D17: =IFERROR(__xludf.DUMMYFUNCTION("""COMPUTED_VALUE"""),"The button layout does not match the client's requirements.") -> The button layout does not match the client's requirements. | E17: =IFERROR(__xludf.DUMMYFUNCTION("""COMPUTED_VALUE"""),"The user needs to have the APK running on their mobile device.") -> The user needs to have the APK running on their mobile device. | F17: =IFERROR(__xludf.DUMMYFUNCTION("""COMPUTED_VALUE"""),"1. Open app 2. Click on Client button 3. Login using valid credential 4. Goto Appointment Section 5. After select required fields, goto medical questions") -> 1. Open app 2. Click on Client button 3. Login using valid credential 4. Goto Appointment Section 5. After select required fields, goto medical questions | G17: =IFERROR(__xludf.DUMMYFUNCTION("""COMPUTED_VALUE"""),"email: lowovip595@elobits.com password: 112244557788") -> email: lowovip595@elobits.com password: 112244557788 | H17: =IFERROR(__xludf.DUMMYFUNCTION("""COMPUTED_VALUE"""),"Alignment and design should match the client's requirements.") -> Alignment and design should match the client's requirements. | I17: =IFERROR(__xludf.DUMMYFUNCTION("""COMPUTED_VALUE"""),"A different design and layout have been observed.") -> A different design and layout have been observed. | J17: =IFERROR(__xludf.DUMMYFUNCTION("""COMPUTED_VALUE"""),"Fail") -> Fail | K17: =IFERROR(__xludf.DUMMYFUNCTION("""COMPUTED_VALUE"""),"Low") -> Low | L17: =IFERROR(__xludf.DUMMYFUNCTION("""COMPUTED_VALUE"""),"https://drive.google.com/file/d/13exhdxanyYbRnL4ACc2CJe65OBwTpcvO/view?usp=drive_link") -> https://drive.google.com/file/d/13exhdxanyYbRnL4ACc2CJe65OBwTpcvO/view?usp=drive_link | N17: =IFERROR(__xludf.DUMMYFUNCTION("""COMPUTED_VALUE"""),"Fahad") -> Fahad | O17: Solved
A18: BR-008 | B18: =IFERROR(__xludf.DUMMYFUNCTION("""COMPUTED_VALUE"""),"Client (APK)") -> Client (APK) | C18: =IFERROR(__xludf.DUMMYFUNCTION("""COMPUTED_VALUE"""),"Appointment") -> Appointment | D18: =IFERROR(__xludf.DUMMYFUNCTION("""COMPUTED_VALUE"""),"The button layout does not match the client's requirements.") -> The button layout does not match the client's requirements. | E18: =IFERROR(__xludf.DUMMYFUNCTION("""COMPUTED_VALUE"""),"The user needs to have the APK running on their mobile device.") -> The user needs to have the APK running on their mobile device. | F18: =IFERROR(__xludf.DUMMYFUNCTION("""COMPUTED_VALUE"""),"1. Open app 2. Click on Client button 3. Login using valid credential 4. Goto Appointment Section 5. After select required fields, goto medical questions") -> 1. Open app 2. Click on Client button 3. Login using valid credential 4. Goto Appointment Section 5. After select required fields, goto medical questions | G18: =IFERROR(__xludf.DUMMYFUNCTION("""COMPUTED_VALUE"""),"email: lowovip595@elobits.com password: 112244557788") -> email: lowovip595@elobits.com password: 112244557788 | H18: =IFERROR(__xludf.DUMMYFUNCTION("""COMPUTED_VALUE"""),"Alignment and design should match the client's requirements.") -> Alignment and design should match the client's requirements. | I18: =IFERROR(__xludf.DUMMYFUNCTION("""COMPUTED_VALUE"""),"A different design and layout have been observed.") -> A different design and layout have been observed. | J18: =IFERROR(__xludf.DUMMYFUNCTION("""COMPUTED_VALUE"""),"Fail") -> Fail | K18: =IFERROR(__xludf.DUMMYFUNCTION("""COMPUTED_VALUE"""),"Low") -> Low | L18: =IFERROR(__xludf.DUMMYFUNCTION("""COMPUTED_VALUE"""),"https://drive.google.com/file/d/1nkwEoAO2orWPxnW4t-8bcBiKzHGDoJ3k/view?usp=drive_link") -> https://drive.google.com/file/d/1nkwEoAO2orWPxnW4t-8bcBiKzHGDoJ3k/view?usp=drive_link | N18: =IFERROR(__xludf.DUMMYFUNCTION("""COMPUTED_VALUE"""),"Fahad") -> Fahad | O18: Solved
A19: BR-009 | B19: =IFERROR(__xludf.DUMMYFUNCTION("""COMPUTED_VALUE"""),"Client (APK)") -> Client (APK) | C19: =IFERROR(__xludf.DUMMYFUNCTION("""COMPUTED_VALUE"""),"Appointment") -> Appointment | D19: =IFERROR(__xludf.DUMMYFUNCTION("""COMPUTED_VALUE"""),"The button layout does not match the client's requirements.") -> The button layout does not match the client's requirements. | E19: =IFERROR(__xludf.DUMMYFUNCTION("""COMPUTED_VALUE"""),"The user needs to have the APK running on their mobile device.") -> The user needs to have the APK running on their mobile device. | F19: =IFERROR(__xludf.DUMMYFUNCTION("""COMPUTED_VALUE"""),"1. Open app 2. Click on Client button 3. Login using valid credential 4. Goto Appointment Section 5. After select required fields, goto medical questions") -> 1. Open app 2. Click on Client button 3. Login using valid credential 4. Goto Appointment Section 5. After select required fields, goto medical questions | G19: =IFERROR(__xludf.DUMMYFUNCTION("""COMPUTED_VALUE"""),"email: lowovip595@elobits.com password: 112244557788") -> email: lowovip595@elobits.com password: 112244557788 | H19: =IFERROR(__xludf.DUMMYFUNCTION("""COMPUTED_VALUE"""),"Alignment and design should match the client's requirements.") -> Alignment and design should match the client's requirements. | I19: =IFERROR(__xludf.DUMMYFUNCTION("""COMPUTED_VALUE"""),"A different design and layout have been observed.") -> A different design and layout have been observed. | J19: =IFERROR(__xludf.DUMMYFUNCTION("""COMPUTED_VALUE"""),"Fail") -> Fail | K19: =IFERROR(__xludf.DUMMYFUNCTION("""COMPUTED_VALUE"""),"Low") -> Low | L19: =IFERROR(__xludf.DUMMYFUNCTION("""COMPUTED_VALUE"""),"https://drive.google.com/file/d/14x0H8Cj1yGkq9nIRIMEkEh_BrqGUHyb1/view?usp=drive_link") -> https://drive.google.com/file/d/14x0H8Cj1yGkq9nIRIMEkEh_BrqGUHyb1/view?usp=drive_link | N19: =IFERROR(__xludf.DUMMYFUNCTION("""COMPUTED_VALUE"""),"Fahad") -> Fahad | O19: Solved
A20: BR-010 | B20: =IFERROR(__xludf.DUMMYFUNCTION("""COMPUTED_VALUE"""),"Client (APK)") -> Client (APK) | C20: =IFERROR(__xludf.DUMMYFUNCTION("""COMPUTED_VALUE"""),"Appointment") -> Appointment | D20: =IFERROR(__xludf.DUMMYFUNCTION("""COMPUTED_VALUE"""),"The button layout does not match the client's requirements.") -> The button layout does not match the client's requirements. | E20: =IFERROR(__xludf.DUMMYFUNCTION("""COMPUTED_VALUE"""),"The user needs to have the APK running on their mobile device.") -> The user needs to have the APK running on their mobile device. | F20: =IFERROR(__xludf.DUMMYFUNCTION("""COMPUTED_VALUE"""),"1. Open app 2. Click on Client button 3. Login using valid credential 4. Goto Appointment Section 5. After select required fields, goto medical questions") -> 1. Open app 2. Click on Client button 3. Login using valid credential 4. Goto Appointment Section 5. After select required fields, goto medical questions | G20: =IFERROR(__xludf.DUMMYFUNCTION("""COMPUTED_VALUE"""),"email: lowovip595@elobits.com password: 112244557788") -> email: lowovip595@elobits.com password: 112244557788 | H20: =IFERROR(__xludf.DUMMYFUNCTION("""COMPUTED_VALUE"""),"Medical questions should be properly submitted without any issues.") -> Medical questions should be properly submitted without any issues. | I20: =IFERROR(__xludf.DUMMYFUNCTION("""COMPUTED_VALUE"""),"Unable to submit client medical questions via the app.") -> Unable to submit client medical questions via the app. | J20: =IFERROR(__xludf.DUMMYFUNCTION("""COMPUTED_VALUE"""),"Fail") -> Fail | K20: =IFERROR(__xludf.DUMMYFUNCTION("""COMPUTED_VALUE"""),"High") -> High | L20: =IFERROR(__xludf.DUMMYFUNCTION("""COMPUTED_VALUE"""),"https://drive.google.com/file/d/1NY-OIs6XpToQOBkdBXzOT54gHBKu1Cqs/view?usp=drive_link") -> https://drive.google.com/file/d/1NY-OIs6XpToQOBkdBXzOT54gHBKu1Cqs/view?usp=drive_link | N20: =IFERROR(__xludf.DUMMYFUNCTION("""COMPUTED_VALUE"""),"Fahad") -> Fahad | O20: Solved
A21: BR-011 | B21: =IFERROR(__xludf.DUMMYFUNCTION("""COMPUTED_VALUE"""),"Client (APK)") -> Client (APK) | C21: =IFERROR(__xludf.DUMMYFUNCTION("""COMPUTED_VALUE"""),"Bookings") -> Bookings | D21: =IFERROR(__xludf.DUMMYFUNCTION("""COMPUTED_VALUE"""),"There seems to be an alignment issue.") -> There seems to be an alignment issue. | E21: =IFERROR(__xludf.DUMMYFUNCTION("""COMPUTED_VALUE"""),"The user needs to have the APK running on their mobile device.") -> The user needs to have the APK running on their mobile device. | F21: =IFERROR(__xludf.DUMMYFUNCTION("""COMPUTED_VALUE"""),"1. Open app 2. Click on Client button 3. Login using valid credential 4. Goto Home page 5. Click on Bookings") -> 1. Open app 2. Click on Client button 3. Login using valid credential 4. Goto Home page 5. Click on Bookings | G21: =IFERROR(__xludf.DUMMYFUNCTION("""COMPUTED_VALUE"""),"email: lowovip595@elobits.com password: 112244557788") -> email: lowovip595@elobits.com password: 112244557788 | H21: =IFERROR(__xludf.DUMMYFUNCTION("""COMPUTED_VALUE"""),"Alignment and design should match the client's requirements.") -> Alignment and design should match the client's requirements. | I21: =IFERROR(__xludf.DUMMYFUNCTION("""COMPUTED_VALUE"""),"A different design and layout have been observed.") -> A different design and layout have been observed. | J21: =IFERROR(__xludf.DUMMYFUNCTION("""COMPUTED_VALUE"""),"Fail") -> Fail | K21: =IFERROR(__xludf.DUMMYFUNCTION("""COMPUTED_VALUE"""),"Low") -> Low | L21: =IFERROR(__xludf.DUMMYFUNCTION("""COMPUTED_VALUE"""),"https://drive.google.com/file/d/1XULhwCogBaakOiUDnvk7CeZvdJsu3sA8/view?usp=drive_link") -> https://drive.google.com/file/d/1XULhwCogBaakOiUDnvk7CeZvdJsu3sA8/view?usp=drive_link | N21: =IFERROR(__xludf.DUMMYFUNCTION("""COMPUTED_VALUE"""),"Fahad") -> Fahad | O21: Unsolved
A22: BR-012 | B22: =IFERROR(__xludf.DUMMYFUNCTION("""COMPUTED_VALUE"""),"Client (APK)") -> Client (APK) | C22: =IFERROR(__xludf.DUMMYFUNCTION("""COMPUTED_VALUE"""),"Bookings") -> Bookings | D22: =IFERROR(__xludf.DUMMYFUNCTION("""COMPUTED_VALUE"""),"There seems to be an alignment issue.") -> There seems to be an alignment issue. | E22: =IFERROR(__xludf.DUMMYFUNCTION("""COMPUTED_VALUE"""),"The user needs to have the APK running on their mobile device.") -> The user needs to have the APK running on their mobile device. | F22: =IFERROR(__xludf.DUMMYFUNCTION("""COMPUTED_VALUE"""),"1. Open app 2. Click on Client button 3. Login using valid credential 4. Goto Home page 5. Click on Bookings") -> 1. Open app 2. Click on Client button 3. Login using valid credential 4. Goto Home page 5. Click on Bookings | G22: =IFERROR(__xludf.DUMMYFUNCTION("""COMPUTED_VALUE"""),"email: lowovip595@elobits.com password: 112244557788") -> email: lowovip595@elobits.com password: 112244557788 | H22: =IFERROR(__xludf.DUMMYFUNCTION("""COMPUTED_VALUE"""),"Alignment and design should match the client's requirements.") -> Alignment and design should match the client's requirements. | I22: =IFERROR(__xludf.DUMMYFUNCTION("""COMPUTED_VALUE"""),"A different design and layout have been observed.") -> A different design and layout have been observed. | J22: =IFERROR(__xludf.DUMMYFUNCTION("""COMPUTED_VALUE"""),"Fail") -> Fail | K22: =IFERROR(__xludf.DUMMYFUNCTION("""COMPUTED_VALUE"""),"Low") -> Low | L22: =IFERROR(__xludf.DUMMYFUNCTION("""COMPUTED_VALUE"""),"https://drive.google.com/file/d/1ZMLGhPiBHCYWW_rYz_vdbn7yGqNo7ufB/view?usp=drive_link") -> https://drive.google.com/file/d/1ZMLGhPiBHCYWW_rYz_vdbn7yGqNo7ufB/view?usp=drive_link | N22: =IFERROR(__xludf.DUMMYFUNCTION("""COMPUTED_VALUE"""),"Fahad") -> Fahad | O22: Solved
A23: BR-013 | B23: =IFERROR(__xludf.DUMMYFUNCTION("""COMPUTED_VALUE"""),"Client (APK)") -> Client (APK) | C23: =IFERROR(__xludf.DUMMYFUNCTION("""COMPUTED_VALUE"""),"Bookings") -> Bookings | D23: =IFERROR(__xludf.DUMMYFUNCTION("""COMPUTED_VALUE"""),"The review option is missing in the booking.") -> The review option is missing in the booking. | E23: =IFERROR(__xludf.DUMMYFUNCTION("""COMPUTED_VALUE"""),"The user needs to have the APK running on their mobile device.") -> The user needs to have the APK running on their mobile device. | F23: =IFERROR(__xludf.DUMMYFUNCTION("""COMPUTED_VALUE"""),"1. Open app 2. Click on Client button 3. Login using valid credential 4. Goto Home page 5. Click on Bookings") -> 1. Open app 2. Click on Client button 3. Login using valid credential 4. Goto Home page 5. Click on Bookings | G23: =IFERROR(__xludf.DUMMYFUNCTION("""COMPUTED_VALUE"""),"email: lowovip595@elobits.com password: 112244557788") -> email: lowovip595@elobits.com password: 112244557788 | H23: =IFERROR(__xludf.DUMMYFUNCTION("""COMPUTED_VALUE"""),"Users should have the option to rate their therapist in the booking section after receiving therapy.") -> Users should have the option to rate their therapist in the booking section after receiving therapy. | I23: =IFERROR(__xludf.DUMMYFUNCTION("""COMPUTED_VALUE"""),"Missing review option found.") -> Missing review option found. | J23: =IFERROR(__xludf.DUMMYFUNCTION("""COMPUTED_VALUE"""),"Fail") -> Fail | K23: =IFERROR(__xludf.DUMMYFUNCTION("""COMPUTED_VALUE"""),"Medium") -> Medium | L23: =IFERROR(__xludf.DUMMYFUNCTION("""COMPUTED_VALUE"""),"https://drive.google.com/file/d/1fdwYRTVFwtxj4a2cQUcNE-JxcPItyks3/view?usp=drive_link") -> https://drive.google.com/file/d/1fdwYRTVFwtxj4a2cQUcNE-JxcPItyks3/view?usp=drive_link | N23: =IFERROR(__xludf.DUMMYFUNCTION("""COMPUTED_VALUE"""),"Fahad") -> Fahad | O23: Solved
A24: BR-014 | B24: =IFERROR(__xludf.DUMMYFUNCTION("""COMPUTED_VALUE"""),"Client (APK)") -> Client (APK) | C24: =IFERROR(__xludf.DUMMYFUNCTION("""COMPUTED_VALUE"""),"Bookings") -> Bookings | D24: =IFERROR(__xludf.DUMMYFUNCTION("""COMPUTED_VALUE"""),"Cancellation policy alignment and design concern.") -> Cancellation policy alignment and design concern. | E24: =IFERROR(__xludf.DUMMYFUNCTION("""COMPUTED_VALUE"""),"The user needs to have the APK running on their mobile device.") -> The user needs to have the APK running on their mobile device. | F24: =IFERROR(__xludf.DUMMYFUNCTION("""COMPUTED_VALUE"""),"1. Open app 2. Click on Client button 3. Login using valid credential 4. Goto Home page 5. Click on Bookings") -> 1. Open app 2. Click on Client button 3. Login using valid credential 4. Goto Home page 5. Click on Bookings | G24: =IFERROR(__xludf.DUMMYFUNCTION("""COMPUTED_VALUE"""),"email: lowovip595@elobits.com password: 112244557788") -> email: lowovip595@elobits.com password: 112244557788 | H24: =IFERROR(__xludf.DUMMYFUNCTION("""COMPUTED_VALUE"""),"The paragraph title in the cancellation policy should be bold and easily noticeable.") -> The paragraph title in the cancellation policy should be bold and easily noticeable. | I24: =IFERROR(__xludf.DUMMYFUNCTION("""COMPUTED_VALUE"""),"An alignment issue was identified, and the bold formatting for the text topic is also missing.") -> An alignment issue was identified, and the bold formatting for the text topic is also missing. | J24: =IFERROR(__xludf.DUMMYFUNCTION("""COMPUTED_VALUE"""),"Fail") -> Fail | K24: =IFERROR(__xludf.DUMMYFUNCTION("""COMPUTED_VALUE"""),"Low") -> Low | L24: =IFERROR(__xludf.DUMMYFUNCTION("""COMPUTED_VALUE"""),"https://drive.google.com/file/d/1rJLjMwI8nniNOY5xZ4xPNHNk_XH0otlu/view?usp=drive_link") -> https://drive.google.com/file/d/1rJLjMwI8nniNOY5xZ4xPNHNk_XH0otlu/view?usp=drive_link | N24: =IFERROR(__xludf.DUMMYFUNCTION("""COMPUTED_VALUE"""),"Fahad") -> Fahad | O24: Solved | P24: Client approval
A25: BR-015 | B25: =IFERROR(__xludf.DUMMYFUNCTION("""COMPUTED_VALUE"""),"Client (APK)") -> Client (APK) | C25: =IFERROR(__xludf.DUMMYFUNCTION("""COMPUTED_VALUE"""),"Card Information") -> Card Information | D25: =IFERROR(__xludf.DUMMYFUNCTION("""COMPUTED_VALUE"""),"An overflow bar has been observed in the card information.") -> An overflow bar has been observed in the card information. | E25: =IFERROR(__xludf.DUMMYFUNCTION("""COMPUTED_VALUE"""),"The user needs to have the APK running on their mobile device.") -> The user needs to have the APK running on their mobile device. | F25: =IFERROR(__xludf.DUMMYFUNCTION("""COMPUTED_VALUE"""),"1. Open app 2. Click on Client button 3. Login using valid credential 4. Goto profile section 5. Click on Add payment methode") -> 1. Open app 2. Click on Client button 3. Login using valid credential 4. Goto profile section 5. Click on Add payment methode | G25: =IFERROR(__xludf.DUMMYFUNCTION("""COMPUTED_VALUE"""),"email: itcrlbmzxpfmfowcfe@xfavaj.com password: 1122334455") -> email: itcrlbmzxpfmfowcfe@xfavaj.com password: 1122334455 | H25: =IFERROR(__xludf.DUMMYFUNCTION("""COMPUTED_VALUE"""),"No overflow bar should appear from the client's perspective.") -> No overflow bar should appear from the client's perspective. | I25: =IFERROR(__xludf.DUMMYFUNCTION("""COMPUTED_VALUE"""),"The overflow bar appears on card information where the card number format is provided.") -> The overflow bar appears on card information where the card number format is provided. | J25: =IFERROR(__xludf.DUMMYFUNCTION("""COMPUTED_VALUE"""),"Fail") -> Fail | K25: =IFERROR(__xludf.DUMMYFUNCTION("""COMPUTED_VALUE"""),"High") -> High | L25: =IFERROR(__xludf.DUMMYFUNCTION("""COMPUTED_VALUE"""),"https://drive.google.com/file/d/1tkCaCf4ymxthAx4ysDqpZc37wM_ilSrc/view?usp=drive_link") -> https://drive.google.com/file/d/1tkCaCf4ymxthAx4ysDqpZc37wM_ilSrc/view?usp=drive_link | N25: =IFERROR(__xludf.DUMMYFUNCTION("""COMPUTED_VALUE"""),"Fahad") -> Fahad | O25: Unsolved
A26: BR-016 | B26: =IFERROR(__xludf.DUMMYFUNCTION("""COMPUTED_VALUE"""),"Client (APK)") -> Client (APK) | C26: =IFERROR(__xludf.DUMMYFUNCTION("""COMPUTED_VALUE"""),"Card Information") -> Card Information | D26: =IFERROR(__xludf.DUMMYFUNCTION("""COMPUTED_VALUE"""),"Data validation is yet to be implemented.") -> Data validation is yet to be implemented. | E26: =IFERROR(__xludf.DUMMYFUNCTION("""COMPUTED_VALUE"""),"The user needs to have the APK running on their mobile device.") -> The user needs to have the APK running on their mobile device. | F26: =IFERROR(__xludf.DUMMYFUNCTION("""COMPUTED_VALUE"""),"1. Open app 2. Click on Client button 3. Login using valid credential 4. Goto profile section 5. Click on Add payment methode") -> 1. Open app 2. Click on Client button 3. Login using valid credential 4. Goto profile section 5. Click on Add payment methode | G26: =IFERROR(__xludf.DUMMYFUNCTION("""COMPUTED_VALUE"""),"email: itcrlbmzxpfmfowcfe@xfavaj.com password: 1122334455") -> email: itcrlbmzxpfmfowcfe@xfavaj.com password: 1122334455 | H26: =IFERROR(__xludf.DUMMYFUNCTION("""COMPUTED_VALUE"""),"Can you use random characters and special symbols in the expiry date and CVV fields on card information?") -> Can you use random characters and special symbols in the expiry date and CVV fields on card information? | I26: =IFERROR(__xludf.DUMMYFUNCTION("""COMPUTED_VALUE"""),"Specific formatting should be applied to card data information, and accurate data validation formatting should be implemented.") -> Specific formatting should be applied to card data information, and accurate data validation formatting should be implemented. | J26: =IFERROR(__xludf.DUMMYFUNCTION("""COMPUTED_VALUE"""),"Fail") -> Fail | K26: =IFERROR(__xludf.DUMMYFUNCTION("""COMPUTED_VALUE"""),"High") -> High | L26: =IFERROR(__xludf.DUMMYFUNCTION("""COMPUTED_VALUE"""),"https://drive.google.com/file/d/1dDJVgs6mWVi6alCalMXd7yxJHutTTxwX/view?usp=drive_link") -> https://drive.google.com/file/d/1dDJVgs6mWVi6alCalMXd7yxJHutTTxwX/view?usp=drive_link | N26: =IFERROR(__xludf.DUMMYFUNCTION("""COMPUTED_VALUE"""),"Fahad") -> Fahad | O26: Solved
A27: BR-017 | B27: =IFERROR(__xludf.DUMMYFUNCTION("""COMPUTED_VALUE"""),"Client (APK)") -> Client (APK) | C27: =IFERROR(__xludf.DUMMYFUNCTION("""COMPUTED_VALUE"""),"Chat") -> Chat | D27: =IFERROR(__xludf.DUMMYFUNCTION("""COMPUTED_VALUE"""),"The chat and call section is missing in the APK.") -> The chat and call section is missing in the APK. | E27: =IFERROR(__xludf.DUMMYFUNCTION("""COMPUTED_VALUE"""),"The user needs to have the APK running on their mobile device.") -> The user needs to have the APK running on their mobile device. | F27: =IFERROR(__xludf.DUMMYFUNCTION("""COMPUTED_VALUE"""),"1. Open app 2. Login using valid credentials 3. Goto Chat") -> 1. Open app 2. Login using valid credentials 3. Goto Chat | G27: =IFERROR(__xludf.DUMMYFUNCTION("""COMPUTED_VALUE"""),"email : sayduntuhin.sta@gmail.com pass: 12345678") -> email : sayduntuhin.sta@gmail.com pass: 12345678 | H27: =IFERROR(__xludf.DUMMYFUNCTION("""COMPUTED_VALUE"""),"The chat section should include both chat and call logs to ensure client satisfaction and enable tracking.") -> The chat section should include both chat and call logs to ensure client satisfaction and enable tracking. | I27: =IFERROR(__xludf.DUMMYFUNCTION("""COMPUTED_VALUE"""),"The call log is missing in the chat section.") -> The call log is missing in the chat section. | J27: =IFERROR(__xludf.DUMMYFUNCTION("""COMPUTED_VALUE"""),"Fail") -> Fail | K27: =IFERROR(__xludf.DUMMYFUNCTION("""COMPUTED_VALUE"""),"High") -> High | L27: =IFERROR(__xludf.DUMMYFUNCTION("""COMPUTED_VALUE"""),"https://drive.google.com/file/d/1GnNqqEV4v5p5Ljd7anvErcGqlXhXMURA/view?usp=drive_link") -> https://drive.google.com/file/d/1GnNqqEV4v5p5Ljd7anvErcGqlXhXMURA/view?usp=drive_link | N27: =IFERROR(__xludf.DUMMYFUNCTION("""COMPUTED_VALUE"""),"Fahad") -> Fahad | O27: Solved
A28: BR-018 | B28: =IFERROR(__xludf.DUMMYFUNCTION("""COMPUTED_VALUE"""),"Client (APK)") -> Client (APK) | C28: =IFERROR(__xludf.DUMMYFUNCTION("""COMPUTED_VALUE"""),"Chat") -> Chat | D28: =IFERROR(__xludf.DUMMYFUNCTION("""COMPUTED_VALUE"""),"The call option is missing in the chat.") -> The call option is missing in the chat. | E28: =IFERROR(__xludf.DUMMYFUNCTION("""COMPUTED_VALUE"""),"The user needs to have the APK running on their mobile device.") -> The user needs to have the APK running on their mobile device. | F28: =IFERROR(__xludf.DUMMYFUNCTION("""COMPUTED_VALUE"""),"1. Open app 2. Login using valid credentials 3. Goto Chat") -> 1. Open app 2. Login using valid credentials 3. Goto Chat | G28: =IFERROR(__xludf.DUMMYFUNCTION("""COMPUTED_VALUE"""),"email : sayduntuhin.sta@gmail.com pass: 12345678") -> email : sayduntuhin.sta@gmail.com pass: 12345678 | H28: =IFERROR(__xludf.DUMMYFUNCTION("""COMPUTED_VALUE"""),"A call option in chat should be available for clients to directly call the therapist for further assistance.") -> A call option in chat should be available for clients to directly call the therapist for further assistance. | I28: =IFERROR(__xludf.DUMMYFUNCTION("""COMPUTED_VALUE"""),"The absence of a call option in the chat has been noted.") -> The absence of a call option in the chat has been noted. | J28: =IFERROR(__xludf.DUMMYFUNCTION("""COMPUTED_VALUE"""),"Fail") -> Fail | K28: =IFERROR(__xludf.DUMMYFUNCTION("""COMPUTED_VALUE"""),"High") -> High | L28: =IFERROR(__xludf.DUMMYFUNCTION("""COMPUTED_VALUE"""),"https://drive.google.com/file/d/1MU7PrtlmpF0l9Kd6tOG3EKwmh-MN_iBj/view?usp=drive_link") -> https://drive.google.com/file/d/1MU7PrtlmpF0l9Kd6tOG3EKwmh-MN_iBj/view?usp=drive_link | N28: =IFERROR(__xludf.DUMMYFUNCTION("""COMPUTED_VALUE"""),"Fahad") -> Fahad | O28: Solved
A29: BR-019 | B29: =IFERROR(__xludf.DUMMYFUNCTION("""COMPUTED_VALUE"""),"Client (APK)") -> Client (APK) | C29: =IFERROR(__xludf.DUMMYFUNCTION("""COMPUTED_VALUE"""),"Chat") -> Chat | D29: =IFERROR(__xludf.DUMMYFUNCTION("""COMPUTED_VALUE"""),"Sending voice messages from chat is missing.") -> Sending voice messages from chat is missing. | E29: =IFERROR(__xludf.DUMMYFUNCTION("""COMPUTED_VALUE"""),"The user needs to have the APK running on their mobile device.") -> The user needs to have the APK running on their mobile device. | F29: =IFERROR(__xludf.DUMMYFUNCTION("""COMPUTED_VALUE"""),"1. Open app 2. Login using valid credentials 3. Goto Chat") -> 1. Open app 2. Login using valid credentials 3. Goto Chat | G29: =IFERROR(__xludf.DUMMYFUNCTION("""COMPUTED_VALUE"""),"email : sayduntuhin.sta@gmail.com pass: 12345678") -> email : sayduntuhin.sta@gmail.com pass: 12345678 | H29: =IFERROR(__xludf.DUMMYFUNCTION("""COMPUTED_VALUE"""),"A voice send option should be integrated into chat for a better user experience.") -> A voice send option should be integrated into chat for a better user experience. | I29: =IFERROR(__xludf.DUMMYFUNCTION("""COMPUTED_VALUE"""),"The absence of the voice button has been observed.") -> The absence of the voice button has been observed. | J29: =IFERROR(__xludf.DUMMYFUNCTION("""COMPUTED_VALUE"""),"Fail") -> Fail | K29: =IFERROR(__xludf.DUMMYFUNCTION("""COMPUTED_VALUE"""),"High") -> High | L29: =IFERROR(__xludf.DUMMYFUNCTION("""COMPUTED_VALUE"""),"https://drive.google.com/file/d/1bdn-YJqS2VeAxlTuwYjr7VDnlWXHIEiW/view?usp=drive_link") -> https://drive.google.com/file/d/1bdn-YJqS2VeAxlTuwYjr7VDnlWXHIEiW/view?usp=drive_link | N29: =IFERROR(__xludf.DUMMYFUNCTION("""COMPUTED_VALUE"""),"Fahad") -> Fahad | O29: Solved
A30: BR-020 | B30: =IFERROR(__xludf.DUMMYFUNCTION("""COMPUTED_VALUE"""),"Client (APK)") -> Client (APK) | C30: =IFERROR(__xludf.DUMMYFUNCTION("""COMPUTED_VALUE"""),"Chat") -> Chat | D30: =IFERROR(__xludf.DUMMYFUNCTION("""COMPUTED_VALUE"""),"The option to send pictures is missing in the app.") -> The option to send pictures is missing in the app. | E30: =IFERROR(__xludf.DUMMYFUNCTION("""COMPUTED_VALUE"""),"The user needs to have the APK running on their mobile device.") -> The user needs to have the APK running on their mobile device. | F30: =IFERROR(__xludf.DUMMYFUNCTION("""COMPUTED_VALUE"""),"1. Open app 2. Login using valid credentials 3. Goto Chat") -> 1. Open app 2. Login using valid credentials 3. Goto Chat | G30: =IFERROR(__xludf.DUMMYFUNCTION("""COMPUTED_VALUE"""),"email : sayduntuhin.sta@gmail.com pass: 12345678") -> email : sayduntuhin.sta@gmail.com pass: 12345678 | H30: =IFERROR(__xludf.DUMMYFUNCTION("""COMPUTED_VALUE"""),"Adding a send picture option to the app would enhance the user experience.") -> Adding a send picture option to the app would enhance the user experience. | I30: =IFERROR(__xludf.DUMMYFUNCTION("""COMPUTED_VALUE"""),"The missing option for sending pictures has been noticed.") -> The missing option for sending pictures has been noticed. | J30: =IFERROR(__xludf.DUMMYFUNCTION("""COMPUTED_VALUE"""),"Fail") -> Fail | K30: =IFERROR(__xludf.DUMMYFUNCTION("""COMPUTED_VALUE"""),"High") -> High | L30: =IFERROR(__xludf.DUMMYFUNCTION("""COMPUTED_VALUE"""),"https://drive.google.com/file/d/1j8uc21xxRQ_ITR17s6bei4f8y8S6KfZm/view?usp=drive_link") -> https://drive.google.com/file/d/1j8uc21xxRQ_ITR17s6bei4f8y8S6KfZm/view?usp=drive_link | N30: =IFERROR(__xludf.DUMMYFUNCTION("""COMPUTED_VALUE"""),"Fahad") -> Fahad
A31: BR-021 | B31: =IFERROR(__xludf.DUMMYFUNCTION("""COMPUTED_VALUE"""),"Client (APK)") -> Client (APK) | C31: =IFERROR(__xludf.DUMMYFUNCTION("""COMPUTED_VALUE"""),"Chat") -> Chat | D31: =IFERROR(__xludf.DUMMYFUNCTION("""COMPUTED_VALUE"""),"The pattern of sending voice messages is different.") -> The pattern of sending voice messages is different. | E31: =IFERROR(__xludf.DUMMYFUNCTION("""COMPUTED_VALUE"""),"The user needs to have the APK running on their mobile device.") -> The user needs to have the APK running on their mobile device. | F31: =IFERROR(__xludf.DUMMYFUNCTION("""COMPUTED_VALUE"""),"1. Open app 2. Login using valid credentials 3. Goto Chat") -> 1. Open app 2. Login using valid credentials 3. Goto Chat | G31: =IFERROR(__xludf.DUMMYFUNCTION("""COMPUTED_VALUE"""),"email : sayduntuhin.sta@gmail.com pass: 12345678") -> email : sayduntuhin.sta@gmail.com pass: 12345678 | H31: =IFERROR(__xludf.DUMMYFUNCTION("""COMPUTED_VALUE"""),"Alignment and design should match the client's requirements.") -> Alignment and design should match the client's requirements. | I31: =IFERROR(__xludf.DUMMYFUNCTION("""COMPUTED_VALUE"""),"A different design and layout have been observed.") -> A different design and layout have been observed. | J31: =IFERROR(__xludf.DUMMYFUNCTION("""COMPUTED_VALUE"""),"Fail") -> Fail | K31: =IFERROR(__xludf.DUMMYFUNCTION("""COMPUTED_VALUE"""),"Low") -> Low | L31: =IFERROR(__xludf.DUMMYFUNCTION("""COMPUTED_VALUE"""),"https://drive.google.com/file/d/1qvXSarQEFjZqbinUQeb_-yuLm_mOg4ue/view?usp=drive_link") -> https://drive.google.com/file/d/1qvXSarQEFjZqbinUQeb_-yuLm_mOg4ue/view?usp=drive_link | N31: =IFERROR(__xludf.DUMMYFUNCTION("""COMPUTED_VALUE"""),"Fahad") -> Fahad
A32: BR-022 | B32: =IFERROR(__xludf.DUMMYFUNCTION("""COMPUTED_VALUE"""),"Client (APK)") -> Client (APK) | C32: =IFERROR(__xludf.DUMMYFUNCTION("""COMPUTED_VALUE"""),"Forget Password") -> Forget Password | D32: =IFERROR(__xludf.DUMMYFUNCTION("""COMPUTED_VALUE"""),"Forgot password OTP is set to email instead of phone number.") -> Forgot password OTP is set to email instead of phone number. | E32: =IFERROR(__xludf.DUMMYFUNCTION("""COMPUTED_VALUE"""),"The user needs to have the APK running on their mobile device.") -> The user needs to have the APK running on their mobile device. | F32: =IFERROR(__xludf.DUMMYFUNCTION("""COMPUTED_VALUE"""),"1. Open app 2. Click on Client button 3. Click on Login 4. Click on Forget Password") -> 1. Open app 2. Click on Client button 3. Click on Login 4. Click on Forget Password | G32: =IFERROR(__xludf.DUMMYFUNCTION("""COMPUTED_VALUE"""),"N/A") -> N/A | H32: =IFERROR(__xludf.DUMMYFUNCTION("""COMPUTED_VALUE"""),"The password reset OTP should align with the client's requirements.") -> The password reset OTP should align with the client's requirements. | I32: =IFERROR(__xludf.DUMMYFUNCTION("""COMPUTED_VALUE"""),"The OTP for the password reset was sent via email instead of the phone number, which did not align with the client's requirements.") -> The OTP for the password reset was sent via email instead of the phone number, which did not align with the client's requirements. | J32: =IFERROR(__xludf.DUMMYFUNCTION("""COMPUTED_VALUE"""),"Fail") -> Fail | K32: =IFERROR(__xludf.DUMMYFUNCTION("""COMPUTED_VALUE"""),"High") -> High | L32: =IFERROR(__xludf.DUMMYFUNCTION("""COMPUTED_VALUE"""),"https://drive.google.com/file/d/1KLex23-Fe5dyghKSBYH7lkrzS1-6VG83/view?usp=drive_link") -> https://drive.google.com/file/d/1KLex23-Fe5dyghKSBYH7lkrzS1-6VG83/view?usp=drive_link | N32: =IFERROR(__xludf.DUMMYFUNCTION("""COMPUTED_VALUE"""),"Fahad") -> Fahad
A33: BR-023 | B33: =IFERROR(__xludf.DUMMYFUNCTION("""COMPUTED_VALUE"""),"Client (APK)") -> Client (APK) | C33: =IFERROR(__xludf.DUMMYFUNCTION("""COMPUTED_VALUE"""),"Home") -> Home | D33: =IFERROR(__xludf.DUMMYFUNCTION("""COMPUTED_VALUE"""),"Category ""See All"" button is missing.") -> Category "See All" button is missing. | E33: =IFERROR(__xludf.DUMMYFUNCTION("""COMPUTED_VALUE"""),"The user needs to have the APK running on their mobile device.") -> The user needs to have the APK running on their mobile device. | F33: =IFERROR(__xludf.DUMMYFUNCTION("""COMPUTED_VALUE"""),"1. Open app 2. Click on Client button 3. Login using valid credential 4. Goto Home Section") -> 1. Open app 2. Click on Client button 3. Login using valid credential 4. Goto Home Section | G33: =IFERROR(__xludf.DUMMYFUNCTION("""COMPUTED_VALUE"""),"email: itcrlbmzxpfmfowcfe@xfavaj.com password: 1122334455") -> email: itcrlbmzxpfmfowcfe@xfavaj.com password: 1122334455 | H33: =IFERROR(__xludf.DUMMYFUNCTION("""COMPUTED_VALUE"""),"A ""See All"" button in the category should be included, allowing clients to view all types of massages and select the one that suits them best.") -> A "See All" button in the category should be included, allowing clients to view all types of massages and select the one that suits them best. | I33: =IFERROR(__xludf.DUMMYFUNCTION("""COMPUTED_VALUE"""),"The absence of a ""See All"" button in the category section might prevent users from accessing the full range of massage categories.") -> The absence of a "See All" button in the category section might prevent users from accessing the full range of massage categories. | J33: =IFERROR(__xludf.DUMMYFUNCTION("""COMPUTED_VALUE"""),"Fail") -> Fail | K33: =IFERROR(__xludf.DUMMYFUNCTION("""COMPUTED_VALUE"""),"High") -> High | L33: =IFERROR(__xludf.DUMMYFUNCTION("""COMPUTED_VALUE"""),"https://drive.google.com/file/d/1WdUwhoAKw9VJZP45R6Lp1FmGJsyFdL6E/view?usp=drive_link") -> https://drive.google.com/file/d/1WdUwhoAKw9VJZP45R6Lp1FmGJsyFdL6E/view?usp=drive_link | N33: =IFERROR(__xludf.DUMMYFUNCTION("""COMPUTED_VALUE"""),"Fahad") -> Fahad
A34: BR-024 | B34: =IFERROR(__xludf.DUMMYFUNCTION("""COMPUTED_VALUE"""),"Client (APK)") -> Client (APK) | C34: =IFERROR(__xludf.DUMMYFUNCTION("""COMPUTED_VALUE"""),"Home") -> Home | D34: =IFERROR(__xludf.DUMMYFUNCTION("""COMPUTED_VALUE"""),"Therapist names are missing in the Nearby Therapist section.") -> Therapist names are missing in the Nearby Therapist section. | E34: =IFERROR(__xludf.DUMMYFUNCTION("""COMPUTED_VALUE"""),"The user needs to have the APK running on their mobile device.") -> The user needs to have the APK running on their mobile device. | F34: =IFERROR(__xludf.DUMMYFUNCTION("""COMPUTED_VALUE"""),"1. Open app 2. Click on Client button 3. Login using valid credential 4. Goto Home Section") -> 1. Open app 2. Click on Client button 3. Login using valid credential 4. Goto Home Section | G34: =IFERROR(__xludf.DUMMYFUNCTION("""COMPUTED_VALUE"""),"email: itcrlbmzxpfmfowcfe@xfavaj.com password: 1122334455") -> email: itcrlbmzxpfmfowcfe@xfavaj.com password: 1122334455 | H34: =IFERROR(__xludf.DUMMYFUNCTION("""COMPUTED_VALUE"""),"Therapists nearby should be easily accessible to clients, ensuring shorter travel distances and better engagement.") -> Therapists nearby should be easily accessible to clients, ensuring shorter travel distances and better engagement. | I34: =IFERROR(__xludf.DUMMYFUNCTION("""COMPUTED_VALUE"""),"Unable to refresh the list of nearby therapists.") -> Unable to refresh the list of nearby therapists. | J34: =IFERROR(__xludf.DUMMYFUNCTION("""COMPUTED_VALUE"""),"Fail") -> Fail | K34: =IFERROR(__xludf.DUMMYFUNCTION("""COMPUTED_VALUE"""),"High") -> High | L34: =IFERROR(__xludf.DUMMYFUNCTION("""COMPUTED_VALUE"""),"https://drive.google.com/file/d/1vRuK4G_c6ytmt6_kN1NbkV66uglkd5sg/view?usp=drive_link") -> https://drive.google.com/file/d/1vRuK4G_c6ytmt6_kN1NbkV66uglkd5sg/view?usp=drive_link | N34: =IFERROR(__xludf.DUMMYFUNCTION("""COMPUTED_VALUE"""),"Fahad") -> Fahad
A35: BR-025 | B35: =IFERROR(__xludf.DUMMYFUNCTION("""COMPUTED_VALUE"""),"Client (APK)") -> Client (APK) | C35: =IFERROR(__xludf.DUMMYFUNCTION("""COMPUTED_VALUE"""),"Home") -> Home | D35: =IFERROR(__xludf.DUMMYFUNCTION("""COMPUTED_VALUE"""),"The therapist search feature is not working.") -> The therapist search feature is not working. | E35: =IFERROR(__xludf.DUMMYFUNCTION("""COMPUTED_VALUE"""),"The user needs to have the APK running on their mobile device.") -> The user needs to have the APK running on their mobile device. | F35: =IFERROR(__xludf.DUMMYFUNCTION("""COMPUTED_VALUE"""),"1. Open app 2. Click on Client button 3. Login using valid credential 4. Goto Home page 5. Click search bar") -> 1. Open app 2. Click on Client button 3. Login using valid credential 4. Goto Home page 5. Click search bar | G35: =IFERROR(__xludf.DUMMYFUNCTION("""COMPUTED_VALUE"""),"email: lowovip595@elobits.com password: 112244557788") -> email: lowovip595@elobits.com password: 112244557788 | H35: =IFERROR(__xludf.DUMMYFUNCTION("""COMPUTED_VALUE"""),"Recommended and searched therapists should appear correctly in the search field.") -> Recommended and searched therapists should appear correctly in the search field. | I35: =IFERROR(__xludf.DUMMYFUNCTION("""COMPUTED_VALUE"""),"The search functionality is broken, but therapists can be found using filters.") -> The search functionality is broken, but therapists can be found using filters. | J35: =IFERROR(__xludf.DUMMYFUNCTION("""COMPUTED_VALUE"""),"Fail") -> Fail | K35: =IFERROR(__xludf.DUMMYFUNCTION("""COMPUTED_VALUE"""),"High") -> High | L35: =IFERROR(__xludf.DUMMYFUNCTION("""COMPUTED_VALUE"""),"https://drive.google.com/file/d/1YMgFbIWV65v8MTTx_AxcKyawpTNmhx-6/view?usp=drive_link") -> https://drive.google.com/file/d/1YMgFbIWV65v8MTTx_AxcKyawpTNmhx-6/view?usp=drive_link | N35: =IFERROR(__xludf.DUMMYFUNCTION("""COMPUTED_VALUE"""),"Fahad") -> Fahad
A36: BR-026 | B36: =IFERROR(__xludf.DUMMYFUNCTION("""COMPUTED_VALUE"""),"Client (APK)") -> Client (APK) | C36: =IFERROR(__xludf.DUMMYFUNCTION("""COMPUTED_VALUE"""),"Login") -> Login | D36: =IFERROR(__xludf.DUMMYFUNCTION("""COMPUTED_VALUE"""),"The login and signup buttons remain as ""Client"" when the user has already selected ""Client"" in a previous operation.") -> The login and signup buttons remain as "Client" when the user has already selected "Client" in a previous operation. | E36: =IFERROR(__xludf.DUMMYFUNCTION("""COMPUTED_VALUE"""),"The user needs to have the APK running on their mobile device.") -> The user needs to have the APK running on their mobile device. | F36: =IFERROR(__xludf.DUMMYFUNCTION("""COMPUTED_VALUE"""),"1. Open app 2. Click on Client button ") -> 1. Open app 2. Click on Client button | G36: =IFERROR(__xludf.DUMMYFUNCTION("""COMPUTED_VALUE"""),"N/A") -> N/A | H36: =IFERROR(__xludf.DUMMYFUNCTION("""COMPUTED_VALUE"""),"Button names should align with client requirements.") -> Button names should align with client requirements. | I36: =IFERROR(__xludf.DUMMYFUNCTION("""COMPUTED_VALUE"""),"The button name ""Login as client"" is displayed instead of ""Login.""") -> The button name "Login as client" is displayed instead of "Login." | J36: =IFERROR(__xludf.DUMMYFUNCTION("""COMPUTED_VALUE"""),"Fail") -> Fail | K36: =IFERROR(__xludf.DUMMYFUNCTION("""COMPUTED_VALUE"""),"Low") -> Low | L36: =IFERROR(__xludf.DUMMYFUNCTION("""COMPUTED_VALUE"""),"https://jam.dev/c/ee57675a-f88f-48a4-a150-f334c0b3b244") -> https://jam.dev/c/ee57675a-f88f-48a4-a150-f334c0b3b244 | N36: =IFERROR(__xludf.DUMMYFUNCTION("""COMPUTED_VALUE"""),"Fahad") -> Fahad
A37: BR-027 | B37: =IFERROR(__xludf.DUMMYFUNCTION("""COMPUTED_VALUE"""),"Client (APK)") -> Client (APK) | C37: =IFERROR(__xludf.DUMMYFUNCTION("""COMPUTED_VALUE"""),"Login") -> Login | D37: =IFERROR(__xludf.DUMMYFUNCTION("""COMPUTED_VALUE"""),"The app logo appears slightly shorter than usual.") -> The app logo appears slightly shorter than usual. | E37: =IFERROR(__xludf.DUMMYFUNCTION("""COMPUTED_VALUE"""),"The user needs to have the APK running on their mobile device.") -> The user needs to have the APK running on their mobile device. | F37: =IFERROR(__xludf.DUMMYFUNCTION("""COMPUTED_VALUE"""),"1. Open app 2. Click on Client button 3. Click on Login") -> 1. Open app 2. Click on Client button 3. Click on Login | G37: =IFERROR(__xludf.DUMMYFUNCTION("""COMPUTED_VALUE"""),"N/A") -> N/A | H37: =IFERROR(__xludf.DUMMYFUNCTION("""COMPUTED_VALUE"""),"The app logo should be prominently displayed to catch users' attention.") -> The app logo should be prominently displayed to catch users' attention. | I37: =IFERROR(__xludf.DUMMYFUNCTION("""COMPUTED_VALUE"""),"A slightly shorter logo was noticed.") -> A slightly shorter logo was noticed. | J37: =IFERROR(__xludf.DUMMYFUNCTION("""COMPUTED_VALUE"""),"Fail") -> Fail | K37: =IFERROR(__xludf.DUMMYFUNCTION("""COMPUTED_VALUE"""),"Low") -> Low | L37: =IFERROR(__xludf.DUMMYFUNCTION("""COMPUTED_VALUE"""),"1.png") -> 1.png | M37: =IFERROR(__xludf.DUMMYFUNCTION("""COMPUTED_VALUE"""),"Make it slightly larger to catch the user's attention.") -> Make it slightly larger to catch the user's attention. | N37: =IFERROR(__xludf.DUMMYFUNCTION("""COMPUTED_VALUE"""),"Fahad") -> Fahad
A38: BR-028 | B38: =IFERROR(__xludf.DUMMYFUNCTION("""COMPUTED_VALUE"""),"Client (APK)") -> Client (APK) | C38: =IFERROR(__xludf.DUMMYFUNCTION("""COMPUTED_VALUE"""),"Login") -> Login | D38: =IFERROR(__xludf.DUMMYFUNCTION("""COMPUTED_VALUE"""),"The password visibility icon is missing on the client login page.") -> The password visibility icon is missing on the client login page. | E38: =IFERROR(__xludf.DUMMYFUNCTION("""COMPUTED_VALUE"""),"The user needs to have the APK running on their mobile device.") -> The user needs to have the APK running on their mobile device. | F38: =IFERROR(__xludf.DUMMYFUNCTION("""COMPUTED_VALUE"""),"1. Open app 2. Click on Client button 3. Click on Login") -> 1. Open app 2. Click on Client button 3. Click on Login | G38: =IFERROR(__xludf.DUMMYFUNCTION("""COMPUTED_VALUE"""),"N/A") -> N/A | H38: =IFERROR(__xludf.DUMMYFUNCTION("""COMPUTED_VALUE"""),"The password field should display the password visibly with a hide icon to enhance user convenience.") -> The password field should display the password visibly with a hide icon to enhance user convenience. | I38: =IFERROR(__xludf.DUMMYFUNCTION("""COMPUTED_VALUE"""),"The absence of the password visibility icon has been noted.") -> The absence of the password visibility icon has been noted. | J38: =IFERROR(__xludf.DUMMYFUNCTION("""COMPUTED_VALUE"""),"Fail") -> Fail | K38: =IFERROR(__xludf.DUMMYFUNCTION("""COMPUTED_VALUE"""),"Medium") -> Medium | L38: =IFERROR(__xludf.DUMMYFUNCTION("""COMPUTED_VALUE"""),"https://jam.dev/c/7e6fdbbf-6f54-4449-933b-872542d4e03c") -> https://jam.dev/c/7e6fdbbf-6f54-4449-933b-872542d4e03c | N38: =IFERROR(__xludf.DUMMYFUNCTION("""COMPUTED_VALUE"""),"Fahad") -> Fahad
A39: BR-029 | B39: =IFERROR(__xludf.DUMMYFUNCTION("""COMPUTED_VALUE"""),"Client (APK)") -> Client (APK) | C39: =IFERROR(__xludf.DUMMYFUNCTION("""COMPUTED_VALUE"""),"Notification") -> Notification | D39: =IFERROR(__xludf.DUMMYFUNCTION("""COMPUTED_VALUE"""),"Notification failed to load") -> Notification failed to load | E39: =IFERROR(__xludf.DUMMYFUNCTION("""COMPUTED_VALUE"""),"The user needs to have the APK running on their mobile device.") -> The user needs to have the APK running on their mobile device. | F39: =IFERROR(__xludf.DUMMYFUNCTION("""COMPUTED_VALUE"""),"1. Open app 2. Click on Client button 3. Login using valid credential 4. Goto Notification Section") -> 1. Open app 2. Click on Client button 3. Login using valid credential 4. Goto Notification Section | G39: =IFERROR(__xludf.DUMMYFUNCTION("""COMPUTED_VALUE"""),"email: lowovip595@elobits.com password: 112244557788") -> email: lowovip595@elobits.com password: 112244557788 | H39: =IFERROR(__xludf.DUMMYFUNCTION("""COMPUTED_VALUE"""),"Notifications should load correctly on the client side for smoother interaction.") -> Notifications should load correctly on the client side for smoother interaction. | I39: =IFERROR(__xludf.DUMMYFUNCTION("""COMPUTED_VALUE"""),"Notification missing. Error displayed: No room found.") -> Notification missing. Error displayed: No room found. | J39: =IFERROR(__xludf.DUMMYFUNCTION("""COMPUTED_VALUE"""),"Fail") -> Fail | K39: =IFERROR(__xludf.DUMMYFUNCTION("""COMPUTED_VALUE"""),"High") -> High | L39: =IFERROR(__xludf.DUMMYFUNCTION("""COMPUTED_VALUE"""),"https://drive.google.com/file/d/17Qe2pumq6nLmzLEcvseV514o8eAPVwvk/view?usp=drive_link") -> https://drive.google.com/file/d/17Qe2pumq6nLmzLEcvseV514o8eAPVwvk/view?usp=drive_link | N39: =IFERROR(__xludf.DUMMYFUNCTION("""COMPUTED_VALUE"""),"Fahad") -> Fahad
A40: BR-030 | B40: =IFERROR(__xludf.DUMMYFUNCTION("""COMPUTED_VALUE"""),"Client (APK)") -> Client (APK) | C40: =IFERROR(__xludf.DUMMYFUNCTION("""COMPUTED_VALUE"""),"OTP Mail") -> OTP Mail | D40: =IFERROR(__xludf.DUMMYFUNCTION("""COMPUTED_VALUE"""),"The OTP email came from a personal Gmail account.") -> The OTP email came from a personal Gmail account. | E40: =IFERROR(__xludf.DUMMYFUNCTION("""COMPUTED_VALUE"""),"The user needs to have the APK running on their mobile device.") -> The user needs to have the APK running on their mobile device. | F40: =IFERROR(__xludf.DUMMYFUNCTION("""COMPUTED_VALUE"""),"1. Open app 2. Click on Client button 3. Click on signup") -> 1. Open app 2. Click on Client button 3. Click on signup | G40: =IFERROR(__xludf.DUMMYFUNCTION("""COMPUTED_VALUE"""),"email: itcrlbmzxpfmfowcfe@xfavaj.com password: 1122334455") -> email: itcrlbmzxpfmfowcfe@xfavaj.com password: 1122334455 | H40: =IFERROR(__xludf.DUMMYFUNCTION("""COMPUTED_VALUE"""),"OTP should come from the app's email to address user trust issues.") -> OTP should come from the app's email to address user trust issues. | I40: =IFERROR(__xludf.DUMMYFUNCTION("""COMPUTED_VALUE"""),"An OTP sent from a personal email can appear suspicious from the user's perspective.") -> An OTP sent from a personal email can appear suspicious from the user's perspective. | J40: =IFERROR(__xludf.DUMMYFUNCTION("""COMPUTED_VALUE"""),"Fail") -> Fail | K40: =IFERROR(__xludf.DUMMYFUNCTION("""COMPUTED_VALUE"""),"Medium") -> Medium | L40: =IFERROR(__xludf.DUMMYFUNCTION("""COMPUTED_VALUE"""),"https://drive.google.com/file/d/1JrtbpqQLDuv5_lQH09pimvpog6-DRnfk/view?usp=drive_link") -> https://drive.google.com/file/d/1JrtbpqQLDuv5_lQH09pimvpog6-DRnfk/view?usp=drive_link | N40: =IFERROR(__xludf.DUMMYFUNCTION("""COMPUTED_VALUE"""),"Fahad") -> Fahad
A41: BR-031 | B41: =IFERROR(__xludf.DUMMYFUNCTION("""COMPUTED_VALUE"""),"Client (APK)") -> Client (APK) | C41: =IFERROR(__xludf.DUMMYFUNCTION("""COMPUTED_VALUE"""),"Payment") -> Payment | D41: =IFERROR(__xludf.DUMMYFUNCTION("""COMPUTED_VALUE"""),"The payment page failed to load.") -> The payment page failed to load. | E41: =IFERROR(__xludf.DUMMYFUNCTION("""COMPUTED_VALUE"""),"The user needs to have the APK running on their mobile device.") -> The user needs to have the APK running on their mobile device. | F41: =IFERROR(__xludf.DUMMYFUNCTION("""COMPUTED_VALUE"""),"1. Open app 2. Click on Client button 3. Login using valid credential 4. Goto Appointment Section") -> 1. Open app 2. Click on Client button 3. Login using valid credential 4. Goto Appointment Section | G41: =IFERROR(__xludf.DUMMYFUNCTION("""COMPUTED_VALUE"""),"email: lowovip595@elobits.com password: 112244557788") -> email: lowovip595@elobits.com password: 112244557788 | H41: =IFERROR(__xludf.DUMMYFUNCTION("""COMPUTED_VALUE"""),"The payment gateway should load smoothly and function accurately.") -> The payment gateway should load smoothly and function accurately. | I41: =IFERROR(__xludf.DUMMYFUNCTION("""COMPUTED_VALUE"""),"An error appears indicating the payment page failed to load.") -> An error appears indicating the payment page failed to load. | J41: =IFERROR(__xludf.DUMMYFUNCTION("""COMPUTED_VALUE"""),"Fail") -> Fail | K41: =IFERROR(__xludf.DUMMYFUNCTION("""COMPUTED_VALUE"""),"High") -> High | L41: =IFERROR(__xludf.DUMMYFUNCTION("""COMPUTED_VALUE"""),"https://drive.google.com/file/d/13f38e09rp29Hk6b4D8ZGRbUSFG2lR1oh/view?usp=drive_link") -> https://drive.google.com/file/d/13f38e09rp29Hk6b4D8ZGRbUSFG2lR1oh/view?usp=drive_link | N41: =IFERROR(__xludf.DUMMYFUNCTION("""COMPUTED_VALUE"""),"Fahad") -> Fahad
